Workbook

Sheet Index
B9: Click to go
B10: Assumption
B11: Historical P & L
B12: Historical Balance Sheet
B13: Revenue Build_Up
B14: Cost Build_Up
B15: Working Capital Schedules
B16: Debt Schedules
B17: Balance_Sheet Forecasting
B18: Forecasted Income Statement
B19: Forecasted Balance Sheet
B20: Common Size Statement
B21: Cash Flow | H21: ISIN Code | J21: INE769A01020
B22: Equity Market | H22: NSE | J22: AARTIIND
B23: Beta | H23: BSE | J23: 524208
B24: Relative Valuation
B25: WACC | G25: Detailed & Dynamic DCF Analysis
B26: DCF Model
B27: FootBall Field Analysis | G27: - Dhiraj Mehta
B28: Ratios Analysis
B29: Charts

Sheet Assumption
B8: BSE: 524208 | NSE: AARTIIND
B11: Scenario | E11: Company Name | F11: Aarti Industries Ltd
B12: Base Case | C12: =IF(B12="Best Case",1,IF(B12="Base Case",2,3)) -> 2 | E12: ISIN Code | F12: INE769A01020
E13: Sector Name | F13: Specialty Chemicals
E14: Industry | F14: Chemicals & Petrochemicals
B15: Assumptions | E15: Exchange Name | F15: BSE: 524208 | NSE: AARTIIND
B16: Transaction Date | C16: 45888 | E16: Website | F16: www.aarti-industries.com
B17: Fiscal Year End | C17: 46112 | E17: Company Description | F17: Aarti Industries Ltd, the flagship company of the Aarti group, manufacturing organic and inorganic chemicals at its major facilities in Vapi, Jhagadia, Dahej and Kutch, in Gujarat and in Tarapur in Maharashtra. The company has a strong market position in the NCB-based specialty chemicals segment. Aarti Industries is a diversified chemicals company engaged in specialty chemicals, agrochemicals and fertilizers, dyes, pigments and printing inks, pharmaceutical intermediates, polymer and additives, energy-related chemicals, and other specialty applications.
B18: Annual growth Tapering | C18: ='Revenue Build_up'!C29 -> 0.08
B19: Risk Free Rate | C19: 0.06512
B20: Tax Rate | C20: ='Cost Build_up'!H39 -> 0.061471938
B21: EV/EBITDA Multiple | C21: ='Comps '!E40 -> 27.029875
B22: Perpetual Growth Rate | C22: 0.06
B23: Discount Rate | C23: =WACC!F53 -> 0.10941091
B24: Shares Outstanding(Cr.) | C24: 36.26
B25: Current Market Price | C25: 389.45
B26: Market Cap (Cr.) | C26: =C25*C24 -> 14121.457
B28: Colour Code
B29: Blue colour | C29: Hardcoded Figures
B30: Black colour | C30: Calculated Figures
B31: Green Colour | C31: Link Data figures
B33: Items | C33: Sheet | D33: Reference | F33: Assumption
B35: Revenue from operation | C35: Revenue Buildup | D35: B32:Q39 | F35: Revenue from operation is forecasted on the three case , base, best and worst case. For this I make a scenario and take max for the best case, min for the worst case and average for the base case. Max, min and Average is consider from the last four year growth rate. for best case there is 37 % growth rate , for average 13% and for worst it is -4%. also take the annual growth tapering of 8 %.
B39: Total Net Revenue | C39: Revenue Buildup | D39: B18:Q19 | F39: The total net Revenue is forecasted by using Revenue from operation Minus the GST tax.
B41: Other Income | C41: Revenue Buildup | D41: B27:Q28 | F41: The Other Income is compared with the % as the revenue and for the future projection I took average of the 5 year historical data.
B43: GST Collected | C43: Revenue Buildup | D43: B16:Q16 | F43: The GST collected is compared with the % as the revenue and for the future projection I took average of the 5 year historical data which is 10%.
B45: Cost of materials consumed | C45: Cost Build_up | D45: B16:Q17 | F45: Cost of material Consumed is compare with the % of revenue , and take the average of the 5 Year for the future prediction.
B49: Purchases of stock, Changes in inventories of finished goods, wip and stock in-trade | C49: Cost Build_up | D49: B19:Q23 | F49: Purchase of stocks and Changes in inventories of the finished goods, works in progress and stock in trade is compare with the % of revenue , for the forecasted year I take the average of the 5 year historical for both items.
B54: Employee benefits expense, Other Expenses | C54: Cost Build_up | D54: B30:Q34 | F54: Employee Benefits Expenses & Other Expenses is compare with the % of revenue , for the forecasted year I take the average of the 5 year historical for the employee benefits and for the other expenses I take average for the future year.
B58: Perpetual Growth Rate | C58: Assumptions | D58: C21 | F58: I take the 6 % Growth rate for the terminal Value as india GDP growth rate for the year is forecasted 6.4%.
B60: Effective Tax Rate | C60: Cost Build_up | D60: B39:Q39 | F60: Effective Tax Rate is compare with the % of EBT , for the forecasted year I take the 6% , which is average of the last 5 year.
B62: Non -Current Assets Items | C62: B_sheet | D62: B14:Q21 | F62: The Non-Current Assets items taken as the average of the historical year with Compare with the % of the Reveneu.
B65: Current Assets | C65: B_sheet | D65: B23:Q31 | F65: The Current Assets items taken as the average of the historical year with Compare with the % of the Reveneu.
... B104: Comparable valuation | C104: Comps | D104: B37:L47 | F104: The Comparable valustion is calculated by taking the peers company which same industry and taken Average and median data of EV/EBITDA, EV/sales and P/E ratio for company Valuation.

Sheet Historical P&L
B7: BSE: 524208 | NSE: AARTIIND
B8: Income Statement
B9: All Figure In INR Cr.
B10: Particulars | C10: 2021 | D10: =C10+1 -> 2022 | E10: =D10+1 -> 2023 | F10: =E10+1 -> 2024 | G10: =F10+1 -> 2025
B11: REVENUE
B12: Revenue from Operations | C12: 5023.28 | D12: 6871.05 | E12: 7282.62 | F12: 7010.56 | G12: 8046.01
B13: Less: GST Collected | C13: -517.18 | D13: -785.54 | E13: -664.04 | F13: -639.76 | G13: -774.69
B14: Net Revenue from Operations | C14: =SUM(C12:C13) -> 4506.1 | D14: =SUM(D12:D13) -> 6085.51 | E14: =SUM(E12:E13) -> 6618.58 | F14: =SUM(F12:F13) -> 6370.8 | G14: =SUM(G12:G13) -> 7271.32
B15: Other Income | C15: 0.7 | D15: 0.77 | E15: 0.86 | F15: 10.86 | G15: 14.12
B16: Total Revenue | C16: =SUM(C14:C15) -> 4506.8 | D16: =SUM(D14:D15) -> 6086.28 | E16: =SUM(E14:E15) -> 6619.44 | F16: =SUM(F14:F15) -> 6381.66 | G16: =SUM(G14:G15) -> 7285.44
B17: EXPENSES
B18: Cost of Materials Consumed (Incl. Packing Material, Fuel, Stores & Spares) | C18: 1937.57 | D18: 2794.06 | E18: 3462.03 | F18: 3771.5 | G18: 4381.36
B19: Purchases of Stock-in-Trade | C19: 244.24 | D19: 270.88 | E19: 313.94 | F19: 203.95 | G19: 219.73
B20: Changes in Inventories of Finished Goods, Work-in-progress and Stock-in-Trade | C20: -53.25 | D20: -210.49 | E20: 65.7 | F20: -93.57 | G20: 54.03
B21: Employee Benefits Expenses | C21: 371.38 | D21: 356.96 | E21: 385.33 | F21: 403.74 | G21: 422.42
B22: Finance Costs | C22: 86.37 | D22: 102.33 | E22: 168.28 | F22: 211.47 | G22: 275.44
B23: Depreciation and Amortisation Expenses | C23: 231.31 | D23: 246.4 | E23: 310.45 | F23: 378.12 | G23: 434.27
B24: Other Expenses | C24: 1024.63 | D24: 1153.99 | E24: 1302.61 | F24: 1111.03 | G24: 1193.33
B25: Total Expenses | C25: =-SUM(C18:C24) -> -3842.25 | D25: =-SUM(D18:D24) -> -4714.13 | E25: =-SUM(E18:E24) -> -6008.34 | F25: =-SUM(F18:F24) -> -5986.24 | G25: =-SUM(G18:G24) -> -6980.58
B26: PROFIT BEFORE TAX | C26: =SUM(C16,C25) -> 664.55 | D26: =SUM(D16,D25) -> 1372.15 | E26: =SUM(E16,E25) -> 611.1 | F26: =SUM(F16,F25) -> 395.42 | G26: =SUM(G16,G25) -> 304.86
B27: Exceptional Item
B28: Gain on Disposal of step down subsidiary | C28: 0 | D28: 0 | E28: 0 | F28: 0 | G28: 2.37
B29: PROFIT AFTER EXCEPTIONAL ITEMS | C29: =SUM(C26:C28) -> 664.55 | D29: =SUM(D26:D28) -> 1372.15 | E29: =SUM(E26:E28) -> 611.1 | F29: =SUM(F26:F28) -> 395.42 | G29: =SUM(G26:G28) -> 307.23
B30: Total Tax Expenses | C30: -129.33 | D30: -186.25 | E30: -65.87 | F30: 21.05 | G30: 23.64
B31: PROFIT AFTER TAX BEFORE NON CONTROLLING INTEREST AND SHARE OF PROFIT/(LOSS) OF ASSOCIATES | C31: =SUM(C29:C30) -> 535.22 | D31: =SUM(D29:D30) -> 1185.9 | E31: =SUM(E29:E30) -> 545.23 | F31: =SUM(F29:F30) -> 416.47 | G31: =SUM(G29:G30) -> 330.87
B32: Profit attributable to Non Controlling Interest | C32: -11.75 | D32: -0.23 | E32: 0 | F32: 0 | G32: 0
B33: Profit/(Loss) for the period | C33: =SUM(C31:C32) -> 523.47 | D33: =SUM(D31:D32) -> 1185.67 | E33: =SUM(E31:E32) -> 545.23 | F33: =SUM(F31:F32) -> 416.47 | G33: =SUM(G31:G32) -> 330.87
B35: Earnings Per Equity Share (EPS) (in `)
B36: Basic/Diluted | C36: 30.04 | D36: 36.06 | E36: 15.04 | F36: 11.49 | G36: 9.13
B37: Basic/Diluted after considering issue of bonus equity shares | C37: 15.02 | D37: 36.06 | E37: 15.04 | F37: 11.49 | G37: 9.12

Sheet Historical balance Sheet
B9: BSE: 524208 | NSE: AARTIIND
B10: Particulars | C10: 2021 | D10: =C10+1 -> 2022 | E10: =D10+1 -> 2023 | F10: =E10+1 -> 2024 | G10: =F10+1 -> 2025
B11: All Figure In INR Cr.
B12: Assets
B13: Non-Current Assets
B14: Property Plant and Equipment | C14: 3592.48 | D14: 3577.7 | E14: 4829.18 | F14: 5583.06 | G14: 6277.48
B15: Capital Work-in-Progress | C15: 1297.91 | D15: 1303.02 | E15: 988.98 | F15: 1058.54 | G15: 1273.8
B16: Right of use Assets | C16: 0 | D16: 16.95 | E16: 30.3 | F16: 53.42 | G16: 51.06
B17: Intangible Assets | C17: 0.1 | D17: 0 | E17: 1.47 | F17: 12.92 | G17: 48.25
B18: Intangible Assets under Development | C18: 0 | D18: 42.97 | E18: 107.24 | F18: 170.51 | G18: 180.41
B19: Financial Assets
B20: Investments | C20: 63.52 | D20: 28.29 | E20: 17.17 | F20: 22.92 | G20: 47.63
B21: Loans & Advances | C21: 320.07 | D21: 0 | E21: 0.01 | F21: 0.3 | G21: 0.06
B22: Deferred Tax Assets | C22: 0 | D22: 27.74 | E22: 52.78 | F22: 143.55 | G22: 217.99
B23: Other Non-Current Assets | C23: 0 | D23: 155.19 | E23: 94.5 | F23: 110.89 | G23: 122.1
B25: Total Non-Current Assets | C25: =SUM(C14:C23) -> 5274.08 | D25: =SUM(D14:D23) -> 5151.86 | E25: =SUM(E14:E23) -> 6121.63 | F25: =SUM(F14:F23) -> 7156.11 | G25: =SUM(G14:G23) -> 8218.78
B27: Current Assets:
B28: Inventories | C28: 935.68 | D28: 934.12 | E28: 1031.05 | F28: 1159.65 | G28: 1454.02
B29: Financial Assets:
B30: Trade Receivables | C30: 793.73 | D30: 1091.52 | E30: 940.49 | F30: 854.18 | G30: 786.06
B31: Cash and Cash Equivalents | C31: 412.32 | D31: 93.63 | E31: 167.45 | F31: 428.29 | G31: 199.39
B32: Bank Balances | C32: 0 | D32: 79.93 | E32: 33.28 | F32: 87.95 | G32: 95.58
B33: Loans and Advances | C33: 0 | D33: 0 | E33: 32.03 | F33: 8.28 | G33: 6.27
B34: Others Current Financial Assets | C34: 187.48 | D34: 407.3 | E34: 160.74 | F34: 16.71 | G34: 16.32
B35: Current Tax Assets (Net) | C35: 0 | D35: 55.42 | E35: 55.48 | F35: 71.16 | G35: 13.89
B36: Other Current Assets | C36: 38.39 | D36: 36.91 | E36: 38.75 | F36: 332.84 | G36: 323.21
B38: Total Current Assets | C38: =SUM(C28:C36) -> 2367.6 | D38: =SUM(D28:D36) -> 2698.83 | E38: =SUM(E28:E36) -> 2459.27 | F38: =SUM(F28:F36) -> 2959.06 | G38: =SUM(G28:G36) -> 2894.74
B40: TOTAL ASSETS | C40: =C38+C25 -> 7641.68 | D40: =D38+D25 -> 7850.69 | E40: =E38+E25 -> 8580.9 | F40: =F38+F25 -> 10115.17 | G40: =G38+G25 -> 11113.52
B42: EQUITY AND LIABILITIES
B43: EQUITY
B44: Equity Share Capital | C44: 87.12 | D44: 181.25 | E44: 181.25 | F44: 181.25 | G44: 181.26
B45: Other Equity | C45: 3415.78 | D45: 4334.73 | E45: 4738.83 | F45: 5108.52 | G45: 5423.86
B46: Non Controlling Interest | C46: 12.24 | D46: 0.72 | E46: 0.72 | F46: 0.72 | G46: 0.1
B47: Total Equity | C47: =SUM(C44:C46) -> 3515.14 | D47: =SUM(D44:D46) -> 4516.7 | E47: =SUM(E44:E46) -> 4920.8 | F47: =SUM(F44:F46) -> 5290.49 | G47: =SUM(G44:G46) -> 5605.22
B49: LIABILITIES
B50: Non-Current Liabilities:
B51: Financial Liabilities
B52: (i) Borrowings | C52: 1268.05 | D52: 929.85 | E52: 634.71 | F52: 1523.87 | G52: 1867.42
B53: (ii) Lease Liabilities | D53: 14.91 | E53: 25.26 | F53: 49.31 | G53: 47.13
B54: Other Non-Current Liabilitie | C54: 224.41 | D54: 223.58 | E54: 216.81 | F54: 175.29 | G54: 112.16
...

Sheet Revenue Build_up
B7: BSE: 524208 | NSE: AARTIIND
B8: Revenue Build_up
B9: All Figure In INR Cr.
B10: Particulars | C10: 2021 | D10: =C10+1 -> 2022 | E10: =D10+1 -> 2023 | F10: =E10+1 -> 2024 | G10: =F10+1 -> 2025 | H10: =G10+1 -> 2026 | I10: =H10+1 -> 2027 | J10: =I10+1 -> 2028 | K10: =J10+1 -> 2029 | ... Q10: =P10+1 -> 2035
C11: Aduited | D11: Aduited | E11: Aduited | F11: Aduited | G11: Aduited | H11: Forecasted | I11: Forecasted | J11: Forecasted | K11: Forecasted | L11: Forecasted | M11: Forecasted | N11: Forecasted | O11: Forecasted | P11: Forecasted | Q11: Forecasted
B14: Revenue from Operation | C14: ='Historical P&L'!C12 -> 5023.28 | D14: ='Historical P&L'!D12 -> 6871.05 | E14: ='Historical P&L'!E12 -> 7282.62 | F14: ='Historical P&L'!F12 -> 7010.56 | G14: ='Historical P&L'!G12 -> 8046.01 | H14: =G14*(1+H15) -> 9128.3626 | I14: =H14*(1+I15) -> 10258.078 | J14: =I14*(1+J15) -> 11426.043 | K14: =J14*(1+K15) -> 12622.914 | L14: =K14*(1+L15) -> 13839.378 | M14: =L14*(1+M15) -> 15066.376 | N14: =M14*(1+N15) -> 16295.297 | O14: =N14*(1+O15) -> 17518.124 | ... Q14: =P14*(1+Q15) -> 19917.035
B15: Growth | D15: =D14/C14-1 -> 0.36784133 | E15: =E14/D14-1 -> 0.059899142 | F15: =F14/E14-1 -> -0.037357435 | G15: =G14/F14-1 -> 0.14769861 | H15: =CHOOSE(Assumption!$C$12,'Revenue Build_up'!$H$26:$Q$26,'Revenue Build_up'!$H$27:$Q$27,'Revenue Build_up'!$H$28:$Q$28) -> 0.13452041 | I15: =CHOOSE(Assumption!$C$12,'Revenue Build_up'!$H$26:$Q$26,'Revenue Build_up'!$H$27:$Q$27,'Revenue Build_up'!$H$28:$Q$28) -> 0.12375878 | J15: =CHOOSE(Assumption!$C$12,'Revenue Build_up'!$H$26:$Q$26,'Revenue Build_up'!$H$27:$Q$27,'Revenue Build_up'!$H$28:$Q$28) -> 0.11385808 | K15: =CHOOSE(Assumption!$C$12,'Revenue Build_up'!$H$26:$Q$26,'Revenue Build_up'!$H$27:$Q$27,'Revenue Build_up'!$H$28:$Q$28) -> 0.10474943 | L15: =CHOOSE(Assumption!$C$12,'Revenue Build_up'!$H$26:$Q$26,'Revenue Build_up'!$H$27:$Q$27,'Revenue Build_up'!$H$28:$Q$28) -> 0.096369477 | M15: =CHOOSE(Assumption!$C$12,'Revenue Build_up'!$H$26:$Q$26,'Revenue Build_up'!$H$27:$Q$27,'Revenue Build_up'!$H$28:$Q$28) -> 0.088659919 | N15: =CHOOSE(Assumption!$C$12,'Revenue Build_up'!$H$26:$Q$26,'Revenue Build_up'!$H$27:$Q$27,'Revenue Build_up'!$H$28:$Q$28) -> 0.081567125 | O15: =CHOOSE(Assumption!$C$12,'Revenue Build_up'!$H$26:$Q$26,'Revenue Build_up'!$H$27:$Q$27,'Revenue Build_up'!$H$28:$Q$28) -> 0.075041755 | ... Q15: =CHOOSE(Assumption!$C$12,'Revenue Build_up'!$H$26:$Q$26,'Revenue Build_up'!$H$27:$Q$27,'Revenue Build_up'!$H$28:$Q$28) -> 0.063515342
B16: Less: GST Collected | C16: 517.18 | D16: 785.54 | E16: 664.04 | F16: 639.76 | G16: 774.69 | H16: =H14*H17 -> 905.53955 | I16: =I14*I17 -> 1017.608 | J16: =J14*J17 -> 1133.4709 | K16: =K14*K17 -> 1252.2014 | L16: =L14*L17 -> 1372.8753 | M16: =M14*M17 -> 1494.5944 | N16: =N14*N17 -> 1616.5041 | O16: =O14*O17 -> 1737.8094 | ... Q16: =Q14*Q17 -> 1975.7829
B17: % of Gross Revenue | C17: =C16/C14 -> 0.10295663 | D17: =D16/D14 -> 0.11432605 | E17: =E16/E14 -> 0.09118147 | F17: =F16/F14 -> 0.091256619 | G17: =G16/G14 -> 0.096282505 | H17: =AVERAGE(C17:G17) -> 0.099200655 | I17: =H17 -> 0.099200655 | J17: =I17 -> 0.099200655 | K17: =J17 -> 0.099200655 | L17: =K17 -> 0.099200655 | M17: =L17 -> 0.099200655 | N17: =M17 -> 0.099200655 | O17: =N17 -> 0.099200655 | P17: =O17 -> 0.099200655 | Q17: =P17 -> 0.099200655
B18: Total Revenue (Net) | C18: =C14-C16 -> 4506.1 | D18: =D14-D16 -> 6085.51 | E18: =E14-E16 -> 6618.58 | F18: =F14-F16 -> 6370.8 | G18: =G14-G16 -> 7271.32 | H18: =H14-H16 -> 8222.823 | I18: =I14-I16 -> 9240.4696 | J18: =J14-J16 -> 10292.572 | ... Q18: =Q14-Q16 -> 17941.252
B21: Other Income | C21: ='Historical P&L'!C15 -> 0.7 | D21: ='Historical P&L'!D15 -> 0.77 | E21: ='Historical P&L'!E15 -> 0.86 | F21: ='Historical P&L'!F15 -> 10.86 | G21: ='Historical P&L'!G15 -> 14.12 | H21: =H22*H18 -> 6.6742032 | I21: =I22*I18 -> 7.5001944 | J21: =J22*J18 -> 8.3541521 | K21: =K22*K18 -> 9.2292448 | L21: =L22*L18 -> 10.118662 | M21: =M22*M18 -> 11.015782 | N21: =N22*N18 -> 11.914308 | O21: =O22*O18 -> 12.808378 | ... Q21: =Q22*Q18 -> 14.562342
B22: % of Net Revenue | C22: =C21/C18 -> 0.00015534498 | D22: =D21/D18 -> 0.00012653007 | E22: =E21/E18 -> 0.00012993724 | F22: =F21/F18 -> 0.0017046525 | G22: =G21/G18 -> 0.0019418758 | H22: =AVERAGE(C22:G22) -> 0.0008116681 | I22: =H22 -> 0.0008116681 | J22: =I22 -> 0.0008116681 | K22: =J22 -> 0.0008116681 | L22: =K22 -> 0.0008116681 | M22: =L22 -> 0.0008116681 | N22: =M22 -> 0.0008116681 | O22: =N22 -> 0.0008116681 | P22: =O22 -> 0.0008116681 | Q22: =P22 -> 0.0008116681
B25: Scenario | C25: Growth
B26: Best Case | C26: =MAX(D15:G15) -> 0.36784133 | H26: =C26 -> 0.36784133 | I26: =H26*(1-$C$29) -> 0.33841402 | J26: =I26*(1-$C$29) -> 0.3113409 | K26: =J26*(1-$C$29) -> 0.28643363 | L26: =K26*(1-$C$29) -> 0.26351894 | M26: =L26*(1-$C$29) -> 0.24243742 | N26: =M26*(1-$C$29) -> 0.22304243 | O26: =N26*(1-$C$29) -> 0.20519904 | P26: =O26*(1-$C$29) -> 0.18878311 | Q26: =P26*(1-$C$29) -> 0.17368046
B27: Base Case | C27: =AVERAGE(D15:G15) -> 0.13452041 | H27: =C27 -> 0.13452041 | I27: =H27*(1-$C$29) -> 0.12375878 | J27: =I27*(1-$C$29) -> 0.11385808 | K27: =J27*(1-$C$29) -> 0.10474943 | L27: =K27*(1-$C$29) -> 0.096369477 | M27: =L27*(1-$C$29) -> 0.088659919 | N27: =M27*(1-$C$29) -> 0.081567125 | O27: =N27*(1-$C$29) -> 0.075041755 | P27: =O27*(1-$C$29) -> 0.069038415 | Q27: =P27*(1-$C$29) -> 0.063515342
B28: Worst Case | C28: =MIN(D15:G15) -> -0.037357435 | H28: =C28 -> -0.037357435 | I28: =H28*(1-$C$29) -> -0.03436884 | J28: =I28*(1-$C$29) -> -0.031619333 | K28: =J28*(1-$C$29) -> -0.029089786 | L28: =K28*(1-$C$29) -> -0.026762603 | M28: =L28*(1-$C$29) -> -0.024621595 | N28: =M28*(1-$C$29) -> -0.022651867 | O28: =N28*(1-$C$29) -> -0.020839718 | P28: =O28*(1-$C$29) -> -0.01917254 | Q28: =P28*(1-$C$29) -> -0.017638737
B29: Annual growth Tapering | C29: 0.08

Sheet Cost Build_up
B7: BSE: 524208 | NSE: AARTIIND
B8: Cost Build_Up
B9: All Figure In INR Cr.
B10: Particulars | C10: 2021 | D10: =C10+1 -> 2022 | E10: =D10+1 -> 2023 | F10: =E10+1 -> 2024 | G10: =F10+1 -> 2025 | H10: =G10+1 -> 2026 | I10: =H10+1 -> 2027 | J10: =I10+1 -> 2028 | K10: =J10+1 -> 2029 | ... Q10: =P10+1 -> 2035
C11: Aduited | D11: Aduited | E11: Aduited | F11: Aduited | G11: Aduited | H11: Forecasted | I11: Forecasted | J11: Forecasted | K11: Forecasted | L11: Forecasted | M11: Forecasted | N11: Forecasted | O11: Forecasted | P11: Forecasted | Q11: Forecasted
B13: Revenue | C13: ='Revenue Build_up'!C18 -> 4506.1 | D13: ='Revenue Build_up'!D18 -> 6085.51 | E13: ='Revenue Build_up'!E18 -> 6618.58 | F13: ='Revenue Build_up'!F18 -> 6370.8 | G13: ='Revenue Build_up'!G18 -> 7271.32 | H13: ='Revenue Build_up'!H18 -> 8222.823 | I13: ='Revenue Build_up'!I18 -> 9240.4696 | J13: ='Revenue Build_up'!J18 -> 10292.572 | ... Q13: ='Revenue Build_up'!Q18 -> 17941.252
B16: Cost of materials consumed | C16: ='Historical P&L'!C18 -> 1937.57 | D16: ='Historical P&L'!D18 -> 2794.06 | E16: ='Historical P&L'!E18 -> 3462.03 | F16: ='Historical P&L'!F18 -> 3771.5 | G16: ='Historical P&L'!G18 -> 4381.36 | H16: =H13*H17 -> 4286.9695 | I16: =I13*I17 -> 4817.5196 | J16: =J13*J17 -> 5366.0331 | K16: =K13*K17 -> 5928.122 | L16: =L13*L17 -> 6499.412 | M16: =M13*M17 -> 7075.6494 | N16: =N13*N17 -> 7652.7897 | O16: =O13*O17 -> 8227.0685 | ... Q16: =Q13*Q17 -> 9353.673
B17: % of Revenue | C17: =C16/C13 -> 0.42998824 | D17: =D16/D13 -> 0.45913325 | E17: =E16/E13 -> 0.52307746 | F17: =F16/F13 -> 0.59199787 | G17: =G16/G13 -> 0.60255359 | H17: =AVERAGE(C17:G17) -> 0.52135008 | I17: =H17 -> 0.52135008 | J17: =I17 -> 0.52135008 | K17: =J17 -> 0.52135008 | L17: =K17 -> 0.52135008 | M17: =L17 -> 0.52135008 | N17: =M17 -> 0.52135008 | O17: =N17 -> 0.52135008 | P17: =O17 -> 0.52135008 | Q17: =P17 -> 0.52135008
B19: Purchases of stock-in-trade | C19: ='Historical P&L'!C19 -> 244.24 | D19: ='Historical P&L'!D19 -> 270.88 | E19: ='Historical P&L'!E19 -> 313.94 | F19: ='Historical P&L'!F19 -> 203.95 | G19: ='Historical P&L'!G19 -> 219.73 | H19: =H20*H13 -> 342.69352 | I19: =I20*I13 -> 385.10485 | J19: =J20*J13 -> 428.95215 | K19: =K20*K13 -> 473.88464 | L19: =L20*L13 -> 519.55265 | M19: =M20*M13 -> 565.61615 | N19: =N20*N13 -> 611.75183 | O19: =O20*O13 -> 657.65877 | ... Q19: =Q20*Q13 -> 747.71774
B20: % of Revenue | C20: =C19/C13 -> 0.054202082 | D20: =D19/D13 -> 0.044512292 | E20: =E19/E13 -> 0.047433135 | F20: =F19/F13 -> 0.032013248 | G20: =G19/G13 -> 0.030218722 | H20: =AVERAGE(C20:G20) -> 0.041675896 | I20: =H20 -> 0.041675896 | J20: =I20 -> 0.041675896 | K20: =J20 -> 0.041675896 | L20: =K20 -> 0.041675896 | M20: =L20 -> 0.041675896 | N20: =M20 -> 0.041675896 | O20: =N20 -> 0.041675896 | P20: =O20 -> 0.041675896 | Q20: =P20 -> 0.041675896
B22: Changes in inventories of finished goods, work-in-progress and stock in-trade | C22: ='Historical P&L'!C20 -> -53.25 | D22: ='Historical P&L'!D20 -> -210.49 | E22: ='Historical P&L'!E20 -> 65.7 | F22: ='Historical P&L'!F20 -> -93.57 | G22: ='Historical P&L'!G20 -> 54.03 | H22: =H13*H23 -> -71.926997 | I22: =I13*I23 -> -80.828594 | J22: =J13*J23 -> -90.031583 | K22: =K13*K23 -> -99.46234 | L22: =L13*L23 -> -109.04747 | M22: =M13*M23 -> -118.71561 | N22: =N13*N23 -> -128.3989 | O22: =O13*O23 -> -138.03418 | ... Q22: =Q13*Q23 -> -156.93641
B23: % of Revenue | C23: =C22/C13 -> -0.011817314 | D23: =D22/D13 -> -0.03458872 | E23: =E22/E13 -> 0.0099266006 | F23: =F22/F13 -> -0.014687323 | G23: =G22/G13 -> 0.0074305628 | H23: =AVERAGE(C23:G23) -> -0.0087472388 | I23: =H23 -> -0.0087472388 | J23: =I23 -> -0.0087472388 | K23: =J23 -> -0.0087472388 | L23: =K23 -> -0.0087472388 | M23: =L23 -> -0.0087472388 | N23: =M23 -> -0.0087472388 | O23: =N23 -> -0.0087472388 | P23: =O23 -> -0.0087472388 | Q23: =P23 -> -0.0087472388
B25: COGS | C25: =C22+C19+C16 -> 2128.56 | D25: =D22+D19+D16 -> 2854.45 | E25: =E22+E19+E16 -> 3841.67 | F25: =F22+F19+F16 -> 3881.88 | G25: =G22+G19+G16 -> 4655.12 | H25: =H22+H19+H16 -> 4557.736 | I25: =I22+I19+I16 -> 5121.7958 | J25: =J22+J19+J16 -> 5704.9537 | ... Q25: =Q22+Q19+Q16 -> 9944.4544
B26: % of Revenue | C26: =C25/C13 -> 0.47237301 | D26: =D25/D13 -> 0.46905683 | E26: =E25/E13 -> 0.58043719 | F26: =F25/F13 -> 0.60932379 | G26: =G25/G13 -> 0.64020288 | H26: =H25/H13 -> 0.55427874 | I26: =I25/I13 -> 0.55427874 | J26: =J25/J13 -> 0.55427874 | ... Q26: =Q25/Q13 -> 0.55427874
B28: Gross Profit Margin | C28: =(C13-C25)/C13 -> 0.52762699 | D28: =(D13-D25)/D13 -> 0.53094317 | E28: =(E13-E25)/E13 -> 0.41956281 | F28: =(F13-F25)/F13 -> 0.39067621 | G28: =(G13-G25)/G13 -> 0.35979712 | H28: =(H13-H25)/H13 -> 0.44572126 | I28: =(I13-I25)/I13 -> 0.44572126 | J28: =(J13-J25)/J13 -> 0.44572126 | ... Q28: =(Q13-Q25)/Q13 -> 0.44572126
B30: Employee benefits expense | C30: ='Historical P&L'!C21 -> 371.38 | D30: ='Historical P&L'!D21 -> 356.96 | E30: ='Historical P&L'!E21 -> 385.33 | F30: ='Historical P&L'!F21 -> 403.74 | G30: ='Historical P&L'!G21 -> 422.42 | H30: =H31*H13 -> 527.51298 | I30: =I31*I13 -> 592.79734 | J30: =J31*J13 -> 660.29211 | K30: =K31*K13 -> 729.45733 | L30: =L31*L13 -> 799.75475 | M30: =M31*M13 -> 870.66094 | N30: =N31*N13 -> 941.67825 | O30: =O31*O13 -> 1012.3434 | ... Q30: =Q31*Q13 -> 1150.9725
B31: % of Revenue | C31: =C30/C13 -> 0.082417168 | D31: =D30/D13 -> 0.058657368 | E31: =E30/E13 -> 0.058219437 | F31: =F30/F13 -> 0.063373517 | G31: =G30/G13 -> 0.058093991 | H31: =AVERAGE(C31:G31) -> 0.064152296 | I31: =H31 -> 0.064152296 | J31: =I31 -> 0.064152296 | K31: =J31 -> 0.064152296 | L31: =K31 -> 0.064152296 | M31: =L31 -> 0.064152296 | N31: =M31 -> 0.064152296 | O31: =N31 -> 0.064152296 | P31: =O31 -> 0.064152296 | Q31: =P31 -> 0.064152296
B33: Other expenses | C33: ='Historical P&L'!C24 -> 1024.63 | D33: ='Historical P&L'!D24 -> 1153.99 | E33: ='Historical P&L'!E24 -> 1302.61 | F33: ='Historical P&L'!F24 -> 1111.03 | G33: ='Historical P&L'!G24 -> 1193.33 | H33: =H34*H13 -> 1566.1786 | I33: =I34*I13 -> 1760.0069 | J33: =J34*J13 -> 1960.3979 | K33: =K34*K13 -> 2165.7485 | L33: =L34*L13 -> 2374.4605 | M33: =M34*M13 -> 2584.98 | N33: =N34*N13 -> 2795.8294 | O33: =O34*O13 -> 3005.6333 | ... Q33: =Q34*Q13 -> 3417.221
B34: % of Revenue | C34: =C33/C13 -> 0.22738732 | D34: =D33/D13 -> 0.18962914 | E34: =E33/E13 -> 0.1968111 | F34: =F33/F13 -> 0.17439411 | G34: =G33/G13 -> 0.16411463 | H34: =AVERAGE(C34:G34) -> 0.19046726 | I34: =H34 -> 0.19046726 | J34: =I34 -> 0.19046726 | K34: =J34 -> 0.19046726 | L34: =K34 -> 0.19046726 | M34: =L34 -> 0.19046726 | N34: =M34 -> 0.19046726 | O34: =N34 -> 0.19046726 | P34: =O34 -> 0.19046726 | Q34: =P34 -> 0.19046726
B36: Opex | C36: =C33+C30 -> 1396.01 | D36: =D33+D30 -> 1510.95 | E36: =E33+E30 -> 1687.94 | F36: =F33+F30 -> 1514.77 | G36: =G33+G30 -> 1615.75 | H36: =H33+H30 -> 2093.6915 | I36: =I33+I30 -> 2352.8043 | J36: =J33+J30 -> 2620.69 | ... Q36: =Q33+Q30 -> 4568.1935
B37: % of Revenue | C37: =C36/C13 -> 0.30980449 | D37: =D36/D13 -> 0.2482865 | E37: =E36/E13 -> 0.25503054 | F37: =F36/F13 -> 0.23776763 | G37: =G36/G13 -> 0.22220862 | H37: =H36/H13 -> 0.25461956 | I37: =I36/I13 -> 0.25461956 | J37: =J36/J13 -> 0.25461956 | ... Q37: =Q36/Q13 -> 0.25461956
B39: Effective Tax Rate | C39: =-'Historical P&L'!C30/'Historical P&L'!C26 -> 0.1946129 | D39: =-'Historical P&L'!D30/'Historical P&L'!D26 -> 0.13573589 | E39: =-'Historical P&L'!E30/'Historical P&L'!E26 -> 0.10778923 | F39: =-'Historical P&L'!F30/'Historical P&L'!F26 -> -0.053234535 | G39: =-'Historical P&L'!G30/'Historical P&L'!G26 -> -0.077543791 | H39: =AVERAGE(C39:G39) -> 0.061471938 | I39: =H39 -> 0.061471938 | J39: =I39 -> 0.061471938 | K39: =J39 -> 0.061471938 | L39: =K39 -> 0.061471938 | M39: =L39 -> 0.061471938 | N39: =M39 -> 0.061471938 | O39: =N39 -> 0.061471938 | P39: =O39 -> 0.061471938 | Q39: =P39 -> 0.061471938

Sheet Working Capital Schedules
B7: BSE: 524208 | NSE: AARTIIND
B8: Working Capital Schedules
B9: All Figure In INR Cr.
B10: Particulars | C10: 2021 | D10: =C10+1 -> 2022 | E10: =D10+1 -> 2023 | F10: =E10+1 -> 2024 | G10: =F10+1 -> 2025 | H10: =G10+1 -> 2026 | I10: =H10+1 -> 2027 | J10: =I10+1 -> 2028 | K10: =J10+1 -> 2029 | ... Q10: =P10+1 -> 2035
C11: Aduited | D11: Aduited | E11: Aduited | F11: Aduited | G11: Aduited | H11: Forecasted | I11: Forecasted | J11: Forecasted | K11: Forecasted | L11: Forecasted | M11: Forecasted | N11: Forecasted | O11: Forecasted | P11: Forecasted | Q11: Forecasted
B12: Days of operation | C12: 365 | D12: =C12 -> 365 | E12: =D12 -> 365 | F12: =E12 -> 365 | G12: =F12 -> 365 | H12: =G12 -> 365 | I12: =H12 -> 365 | J12: =I12 -> 365 | K12: =J12 -> 365 | ... Q12: =P12 -> 365
B14: Inventores | C14: ='Historical balance Sheet'!C28 -> 935.68 | D14: ='Historical balance Sheet'!D28 -> 934.12 | E14: ='Historical balance Sheet'!E28 -> 1031.05 | F14: ='Historical balance Sheet'!F28 -> 1159.65 | G14: ='Historical balance Sheet'!G28 -> 1454.02 | H14: =(H21*'Cost Build_up'!H25)/'Working Capital Schedules'!H12 -> 1500.6825 | I14: =(I21*'Cost Build_up'!I25)/'Working Capital Schedules'!I12 -> 1686.4051 | J14: =(J21*'Cost Build_up'!J25)/'Working Capital Schedules'!J12 -> 1878.416 | K14: =(K21*'Cost Build_up'!K25)/'Working Capital Schedules'!K12 -> 2075.179 | L14: =(L21*'Cost Build_up'!L25)/'Working Capital Schedules'!L12 -> 2275.1629 | M14: =(M21*'Cost Build_up'!M25)/'Working Capital Schedules'!M12 -> 2476.8786 | N14: =(N21*'Cost Build_up'!N25)/'Working Capital Schedules'!N12 -> 2678.9105 | O14: =(O21*'Cost Build_up'!O25)/'Working Capital Schedules'!O12 -> 2879.9406 | ... Q14: =(Q21*'Cost Build_up'!Q25)/'Working Capital Schedules'!Q12 -> 3274.3161
B15: Recievables | C15: ='Historical balance Sheet'!C30 -> 793.73 | D15: ='Historical balance Sheet'!D30 -> 1091.52 | E15: ='Historical balance Sheet'!E30 -> 940.49 | F15: ='Historical balance Sheet'!F30 -> 854.18 | G15: ='Historical balance Sheet'!G30 -> 786.06 | H15: =(H22*'Cost Build_up'!H13)/'Working Capital Schedules'!H12 -> 1216.6315 | I15: =(I22*'Cost Build_up'!I13)/'Working Capital Schedules'!I12 -> 1367.2003 | J15: =(J22*'Cost Build_up'!J13)/'Working Capital Schedules'!J12 -> 1522.8671 | K15: =(K22*'Cost Build_up'!K13)/'Working Capital Schedules'!K12 -> 1682.3866 | L15: =(L22*'Cost Build_up'!L13)/'Working Capital Schedules'!L12 -> 1844.5173 | M15: =(M22*'Cost Build_up'!M13)/'Working Capital Schedules'!M12 -> 2008.052 | N15: =(N22*'Cost Build_up'!N13)/'Working Capital Schedules'!N12 -> 2171.8431 | O15: =(O22*'Cost Build_up'!O13)/'Working Capital Schedules'!O12 -> 2334.822 | ... Q15: =(Q22*'Cost Build_up'!Q13)/'Working Capital Schedules'!Q12 -> 2654.5496
B16: Trade payables | C16: ='Historical balance Sheet'!C64+'Historical balance Sheet'!C65 -> 576.33 | D16: ='Historical balance Sheet'!D64+'Historical balance Sheet'!D65 -> 344.85 | E16: ='Historical balance Sheet'!E64+'Historical balance Sheet'!E65 -> 215.6 | F16: ='Historical balance Sheet'!F64+'Historical balance Sheet'!F65 -> 724.92 | G16: ='Historical balance Sheet'!G64+'Historical balance Sheet'!G65 -> 1237.48 | H16: =(H23*'Cost Build_up'!H25)/'Working Capital Schedules'!H12 -> 820.63851 | I16: =(I23*'Cost Build_up'!I25)/'Working Capital Schedules'!I12 -> 922.19973 | J16: =(J23*'Cost Build_up'!J25)/'Working Capital Schedules'!J12 -> 1027.1996 | K16: =(K23*'Cost Build_up'!K25)/'Working Capital Schedules'!K12 -> 1134.7982 | L16: =(L23*'Cost Build_up'!L25)/'Working Capital Schedules'!L12 -> 1244.1581 | M16: =(M23*'Cost Build_up'!M25)/'Working Capital Schedules'!M12 -> 1354.4651 | N16: =(N23*'Cost Build_up'!N25)/'Working Capital Schedules'!N12 -> 1464.9449 | O16: =(O23*'Cost Build_up'!O25)/'Working Capital Schedules'!O12 -> 1574.8769 | ... Q16: =(Q23*'Cost Build_up'!Q25)/'Working Capital Schedules'!Q12 -> 1790.5386
B17: Net Working Capital | C17: =C14+C15-C16 -> 1153.08 | D17: =D14+D15-D16 -> 1680.79 | E17: =E14+E15-E16 -> 1755.94 | F17: =F14+F15-F16 -> 1288.91 | G17: =G14+G15-G16 -> 1002.6 | H17: =H14+H15-H16 -> 1896.6755 | I17: =I14+I15-I16 -> 2131.4057 | J17: =J14+J15-J16 -> 2374.0835 | ... Q17: =Q14+Q15-Q16 -> 4138.3272
B21: DIO | C21: =(C14/'Cost Build_up'!C25)*'Working Capital Schedules'!C12 -> 160.448 | D21: =(D14/'Cost Build_up'!D25)*'Working Capital Schedules'!D12 -> 119.44641 | E21: =(E14/'Cost Build_up'!E25)*'Working Capital Schedules'!E12 -> 97.960848 | F21: =(F14/'Cost Build_up'!F25)*'Working Capital Schedules'!F12 -> 109.03795 | G21: =(G14/'Cost Build_up'!G25)*'Working Capital Schedules'!G12 -> 114.00722 | H21: =AVERAGE(C21:G21) -> 120.18009 | I21: =H21 -> 120.18009 | J21: =I21 -> 120.18009 | K21: =J21 -> 120.18009 | L21: =K21 -> 120.18009 | M21: =L21 -> 120.18009 | N21: =M21 -> 120.18009 | O21: =N21 -> 120.18009 | P21: =O21 -> 120.18009 | Q21: =P21 -> 120.18009
B22: DSO | C22: =C15/'Revenue Build_up'!C18*'Working Capital Schedules'!C12 -> 64.293169 | D22: =D15/'Revenue Build_up'!D18*'Working Capital Schedules'!D12 -> 65.467775 | E22: =E15/'Revenue Build_up'!E18*'Working Capital Schedules'!E12 -> 51.865936 | F22: =F15/'Revenue Build_up'!F18*'Working Capital Schedules'!F12 -> 48.938234 | G22: =G15/'Revenue Build_up'!G18*'Working Capital Schedules'!G12 -> 39.458021 | H22: =AVERAGE(C22:G22) -> 54.004627 | I22: =H22 -> 54.004627 | J22: =I22 -> 54.004627 | K22: =J22 -> 54.004627 | L22: =K22 -> 54.004627 | M22: =L22 -> 54.004627 | N22: =M22 -> 54.004627 | O22: =N22 -> 54.004627 | P22: =O22 -> 54.004627 | Q22: =P22 -> 54.004627
B23: DPO | C23: =C16/'Cost Build_up'!C25*'Working Capital Schedules'!C12 -> 98.827588 | D23: =D16/'Cost Build_up'!D25*'Working Capital Schedules'!D12 -> 44.096148 | E23: =E16/'Cost Build_up'!E25*'Working Capital Schedules'!E12 -> 20.484321 | F23: =F16/'Cost Build_up'!F25*'Working Capital Schedules'!F12 -> 68.161767 | G23: =G16/'Cost Build_up'!G25*'Working Capital Schedules'!G12 -> 97.028691 | H23: =AVERAGE(C23:G23) -> 65.719703 | I23: =H23 -> 65.719703 | J23: =I23 -> 65.719703 | K23: =J23 -> 65.719703 | L23: =K23 -> 65.719703 | M23: =L23 -> 65.719703 | N23: =M23 -> 65.719703 | O23: =N23 -> 65.719703 | P23: =O23 -> 65.719703 | Q23: =P23 -> 65.719703
B24: Net Trade Cycle | C24: =C21+C22-C23 -> 125.91358 | D24: =D21+D22-D23 -> 140.81804 | E24: =E21+E22-E23 -> 129.34246 | F24: =F21+F22-F23 -> 89.81442 | G24: =G21+G22-G23 -> 56.436553 | H24: =H21+H22-H23 -> 108.46501 | I24: =I21+I22-I23 -> 108.46501 | J24: =J21+J22-J23 -> 108.46501 | ... Q24: =Q21+Q22-Q23 -> 108.46501

Sheet Dep and Capex Schedules
B7: BSE: 524208 | NSE: AARTIIND
B8: Dep and Capex Schedules
B9: All Figure In INR Cr.
B10: Particulars | C10: 2021 | D10: =C10+1 -> 2022 | E10: =D10+1 -> 2023 | F10: =E10+1 -> 2024 | G10: =F10+1 -> 2025 | H10: =G10+1 -> 2026 | I10: =H10+1 -> 2027 | J10: =I10+1 -> 2028 | K10: =J10+1 -> 2029 | ... Q10: =P10+1 -> 2035
B11: Deperciation schedules
B12: PPE Opening | D12: =C15 -> 4890.49 | E12: =D15 -> 4940.64 | F12: =E15 -> 5957.17 | G12: =F15 -> 6878.45 | H12: =G15 -> 7831 | I12: =H15 -> 8420.4297 | J12: =I15 -> 9151.7759 | K12: =J15 -> 10031.488 | ... Q12: =P15 -> 18641.109
B13: Plus -Capex | D13: =D15-D12-D14 -> 296.55 | E13: =E15-E12-E14 -> 1326.98 | F13: =F15-F12-F14 -> 1299.4 | G13: =G15-G12-G14 -> 1386.82 | H13: =H18*'Revenue Build_up'!H18 -> 1058.9518 | I13: =I18*'Revenue Build_up'!I18 -> 1236.2088 | J13: =J18*'Revenue Build_up'!J18 -> 1428.424 | K13: =K18*'Revenue Build_up'!K18 -> 1634.9042 | L13: =L18*'Revenue Build_up'!L18 -> 1854.7915 | M13: =M18*'Revenue Build_up'!M18 -> 2087.0961 | N13: =N18*'Revenue Build_up'!N18 -> 2330.7285 | O13: =O18*'Revenue Build_up'!O18 -> 2584.532 | ... Q13: =Q18*'Revenue Build_up'!Q18 -> 3117.8671
B14: Less-Dep | C14: =-'Historical P&L'!C23 -> -231.31 | D14: =-'Historical P&L'!D23 -> -246.4 | E14: =-'Historical P&L'!E23 -> -310.45 | F14: =-'Historical P&L'!F23 -> -378.12 | G14: =-'Historical P&L'!G23 -> -434.27 | H14: =-H17*H12 -> -469.52218 | I14: =-I17*I12 -> -504.86253 | J14: =-J17*J12 -> -548.71175 | K14: =-K17*K12 -> -601.45654 | L14: =-L17*L12 -> -663.41881 | M14: =-M17*M12 -> -734.84978 | N14: =-N17*N12 -> -815.92623 | O14: =-O17*O12 -> -906.74901 | ... Q14: =-Q17*Q12 -> -1117.6624
B15: PPE Closing | C15: =SUM('Historical balance Sheet'!C14:C18) -> 4890.49 | D15: =SUM('Historical balance Sheet'!D14:D18) -> 4940.64 | E15: =SUM('Historical balance Sheet'!E14:E18) -> 5957.17 | F15: =SUM('Historical balance Sheet'!F14:F18) -> 6878.45 | G15: =SUM('Historical balance Sheet'!G14:G18) -> 7831 | H15: =SUM(H12:H14) -> 8420.4297 | I15: =SUM(I12:I14) -> 9151.7759 | J15: =SUM(J12:J14) -> 10031.488 | K15: =SUM(K12:K14) -> 11064.936 | L15: =SUM(L12:L14) -> 12256.308 | M15: =SUM(M12:M14) -> 13608.555 | N15: =SUM(N12:N14) -> 15123.357 | O15: =SUM(O12:O14) -> 16801.14 | ... Q15: =SUM(Q12:Q14) -> 20641.314
B17: Deperciation & Amotisartion Exp. (%of PPE) | C17: 0 | D17: =-D14/D12 -> 0.050383499 | E17: =-E14/E12 -> 0.062835989 | F17: =-F14/F12 -> 0.063473092 | G17: =-G14/G12 -> 0.063134863 | H17: =AVERAGE(D17:G17) -> 0.059956861 | I17: =H17 -> 0.059956861 | J17: =I17 -> 0.059956861 | K17: =J17 -> 0.059956861 | L17: =K17 -> 0.059956861 | M17: =L17 -> 0.059956861 | N17: =M17 -> 0.059956861 | O17: =N17 -> 0.059956861 | P17: =O17 -> 0.059956861 | Q17: =P17 -> 0.059956861
B18: Capex % of Revenue | C18: 0 | D18: =D13/'Revenue Build_up'!D18 -> 0.048730509 | E18: =E13/'Revenue Build_up'!E18 -> 0.20049316 | F18: =F13/'Revenue Build_up'!F18 -> 0.20396183 | G18: =G13/'Revenue Build_up'!G18 -> 0.19072466 | H18: =AVERAGE(C18:G18) -> 0.12878203 | I18: =H18+0.5% -> 0.13378203 | J18: =I18+0.5% -> 0.13878203 | K18: =J18+0.5% -> 0.14378203 | L18: =K18+0.5% -> 0.14878203 | M18: =L18+0.5% -> 0.15378203 | N18: =M18+0.5% -> 0.15878203 | O18: =N18+0.5% -> 0.16378203 | P18: =O18+0.5% -> 0.16878203 | Q18: =P18+0.5% -> 0.17378203

Sheet Debt Schedules
B7: BSE: 524208 | NSE: AARTIIND
B8: Debt Schedules
B9: All Figure In INR Cr.
B10: Particulars | C10: 2021 | D10: =C10+1 -> 2022 | E10: =D10+1 -> 2023 | F10: =E10+1 -> 2024 | G10: =F10+1 -> 2025 | H10: =G10+1 -> 2026 | I10: =H10+1 -> 2027 | J10: =I10+1 -> 2028 | K10: =J10+1 -> 2029 | ... Q10: =P10+1 -> 2035
C11: Aduited | D11: Aduited | E11: Aduited | F11: Aduited | G11: Aduited | H11: Forecasted | I11: Forecasted | J11: Forecasted | K11: Forecasted | L11: Forecasted | M11: Forecasted | N11: Forecasted | O11: Forecasted | P11: Forecasted | Q11: Forecasted
B13: Opening Balance | D13: =C15 -> 2492.12 | E13: =D15 -> 2586.95 | F13: =E15 -> 2907.31 | G13: =F15 -> 3622.67 | H13: =G15 -> 3847.79 | I13: =H15 -> 4136.4578 | J13: =I15 -> 4648.3808 | K13: =J15 -> 5177.6365 | ... Q13: =P15 -> 8486.2659
B14: New Issuance/ Repayment | D14: =D15-D13 -> 94.83 | E14: =E15-E13 -> 320.36 | F14: =F15-F13 -> 715.36 | G14: =G15-G13 -> 225.12 | H14: =H15-H13 -> 288.66779 | I14: =I15-I13 -> 511.92297 | J14: =J15-J13 -> 529.2557 | K14: =K15-K13 -> 542.35448 | ... Q14: =Q15-Q13 -> 539.00808
B15: Closing Balance | C15: ='Historical balance Sheet'!C52+'Historical balance Sheet'!C53+'Historical balance Sheet'!C61+'Historical balance Sheet'!C62 -> 2492.12 | D15: ='Historical balance Sheet'!D52+'Historical balance Sheet'!D53+'Historical balance Sheet'!D61+'Historical balance Sheet'!D62 -> 2586.95 | E15: ='Historical balance Sheet'!E52+'Historical balance Sheet'!E53+'Historical balance Sheet'!E61+'Historical balance Sheet'!E62 -> 2907.31 | F15: ='Historical balance Sheet'!F52+'Historical balance Sheet'!F53+'Historical balance Sheet'!F61+'Historical balance Sheet'!F62 -> 3622.67 | G15: ='Historical balance Sheet'!G52+'Historical balance Sheet'!G53+'Historical balance Sheet'!G61+'Historical balance Sheet'!G62 -> 3847.79 | H15: =Balance_Sheet!H36+Balance_Sheet!H38+Balance_Sheet!H48+Balance_Sheet!H50 -> 4136.4578 | I15: =Balance_Sheet!I36+Balance_Sheet!I38+Balance_Sheet!I48+Balance_Sheet!I50 -> 4648.3808 | J15: =Balance_Sheet!J36+Balance_Sheet!J38+Balance_Sheet!J48+Balance_Sheet!J50 -> 5177.6365 | K15: =Balance_Sheet!K36+Balance_Sheet!K38+Balance_Sheet!K48+Balance_Sheet!K50 -> 5719.9909 | L15: =Balance_Sheet!L36+Balance_Sheet!L38+Balance_Sheet!L48+Balance_Sheet!L50 -> 6271.2235 | M15: =Balance_Sheet!M36+Balance_Sheet!M38+Balance_Sheet!M48+Balance_Sheet!M50 -> 6827.2296 | N15: =Balance_Sheet!N36+Balance_Sheet!N38+Balance_Sheet!N48+Balance_Sheet!N50 -> 7384.1071 | O15: =Balance_Sheet!O36+Balance_Sheet!O38+Balance_Sheet!O48+Balance_Sheet!O50 -> 7938.2235 | ... Q15: =Balance_Sheet!Q36+Balance_Sheet!Q38+Balance_Sheet!Q48+Balance_Sheet!Q50 -> 9025.2739
B16: Interest rate | D16: ='Historical P&L'!D22/'Debt Schedules'!D13 -> 0.041061426 | E16: ='Historical P&L'!E22/'Debt Schedules'!E13 -> 0.065049576 | F16: ='Historical P&L'!F22/'Debt Schedules'!F13 -> 0.072737341 | G16: ='Historical P&L'!G22/'Debt Schedules'!G13 -> 0.076032319 | H16: =AVERAGE(D16:G16) -> 0.063720165 | I16: =H16 -> 0.063720165 | J16: =I16 -> 0.063720165 | K16: =J16 -> 0.063720165 | L16: =K16 -> 0.063720165 | M16: =L16 -> 0.063720165 | N16: =M16 -> 0.063720165 | O16: =N16 -> 0.063720165 | P16: =O16 -> 0.063720165 | Q16: =P16 -> 0.063720165
B17: Interest Expense | C17: ='Historical P&L'!C22 -> 86.37 | D17: ='Historical P&L'!D22 -> 102.33 | E17: ='Historical P&L'!E22 -> 168.28 | F17: ='Historical P&L'!F22 -> 211.47 | G17: ='Historical P&L'!G22 -> 275.44 | H17: =H16*H13 -> 245.18182 | I17: =I16*I13 -> 263.57577 | J17: =J16*J13 -> 296.19559 | K17: =K16*K13 -> 329.91985 | L17: =L16*L13 -> 364.47877 | M17: =M16*M13 -> 399.6034 | N17: =N16*N13 -> 435.0322 | O17: =O16*O13 -> 470.51653 | ... Q17: =Q16*Q13 -> 540.74626

Sheet Balance_Sheet
B7: BSE: 524208 | NSE: AARTIIND
B8: Balance _Sheet Forecasting
B9: All Figure In INR Cr.
B10: Particulars | C10: 2021 | D10: =C10+1 -> 2022 | E10: =D10+1 -> 2023 | F10: =E10+1 -> 2024 | G10: =F10+1 -> 2025 | H10: =G10+1 -> 2026 | I10: =H10+1 -> 2027 | J10: =I10+1 -> 2028 | K10: =J10+1 -> 2029 | ... Q10: =P10+1 -> 2035
C11: Aduited | D11: Aduited | E11: Aduited | F11: Aduited | G11: Aduited | H11: Forecasted | I11: Forecasted | J11: Forecasted | K11: Forecasted | L11: Forecasted | M11: Forecasted | N11: Forecasted | O11: Forecasted | P11: Forecasted | Q11: Forecasted
B12: Assets
B13: Non-Current Assets
B14: Investments | C14: ='Historical balance Sheet'!C20 -> 63.52 | D14: ='Historical balance Sheet'!D20 -> 28.29 | E14: ='Historical balance Sheet'!E20 -> 17.17 | F14: ='Historical balance Sheet'!F20 -> 22.92 | G14: ='Historical balance Sheet'!G20 -> 47.63 | H14: =H15*'Revenue Build_up'!H$18 -> 51.783168 | I14: =I15*'Revenue Build_up'!I$18 -> 58.19179 | J14: =J15*'Revenue Build_up'!J$18 -> 64.817395 | K14: =K15*'Revenue Build_up'!K$18 -> 71.60698 | L14: =L15*'Revenue Build_up'!L$18 -> 78.507708 | M14: =M15*'Revenue Build_up'!M$18 -> 85.468195 | N14: =N15*'Revenue Build_up'!N$18 -> 92.43959 | O14: =O15*'Revenue Build_up'!O$18 -> 99.376419 | ... Q14: =Q15*'Revenue Build_up'!Q$18 -> 112.9849
B15: % of Revenue | C15: =C14/'Revenue Build_up'!C$18 -> 0.014096447 | D15: =D14/'Revenue Build_up'!D$18 -> 0.0046487476 | E15: =E14/'Revenue Build_up'!E$18 -> 0.0025942121 | F15: =F14/'Revenue Build_up'!F$18 -> 0.0035976643 | G15: =G14/'Revenue Build_up'!G$18 -> 0.0065503925 | H15: =AVERAGE(C15:G15) -> 0.0062974927 | I15: =H15 -> 0.0062974927 | J15: =I15 -> 0.0062974927 | K15: =J15 -> 0.0062974927 | L15: =K15 -> 0.0062974927 | M15: =L15 -> 0.0062974927 | N15: =M15 -> 0.0062974927 | O15: =N15 -> 0.0062974927 | P15: =O15 -> 0.0062974927 | Q15: =P15 -> 0.0062974927
B16: Loans & Advances | C16: ='Historical balance Sheet'!C21 -> 320.07 | D16: ='Historical balance Sheet'!D21 -> 0 | E16: ='Historical balance Sheet'!E21 -> 0.01 | F16: ='Historical balance Sheet'!F21 -> 0.3 | G16: ='Historical balance Sheet'!G21 -> 0.06 | H16: =H17*'Revenue Build_up'!H$18 -> 0.11687169 | I16: =I17*'Revenue Build_up'!I$18 -> 0.13133558 | J16: =J17*'Revenue Build_up'!J$18 -> 0.1462892 | K16: =K17*'Revenue Build_up'!K$18 -> 0.16161291 | L16: =L17*'Revenue Build_up'!L$18 -> 0.17718746 | M16: =M17*'Revenue Build_up'!M$18 -> 0.19289689 | N16: =N17*'Revenue Build_up'!N$18 -> 0.20863094 | O16: =O17*'Revenue Build_up'!O$18 -> 0.22428697 | ... Q16: =Q17*'Revenue Build_up'!Q$18 -> 0.25500055
B17: % of Revenue | C17: =C16/'Revenue Build_up'!C$18 -> 0.071030381 | D17: =D16/'Revenue Build_up'!D$18 -> 0 | E17: =E16/'Revenue Build_up'!E$18 -> 1.5108981e-06 | F17: =F16/'Revenue Build_up'!F$18 -> 4.7089847e-05 | G17: =G16/'Revenue Build_up'!G$18 -> 8.2515967e-06 | H17: =AVERAGE(D17:G17) -> 1.4213086e-05 | I17: =H17 -> 1.4213086e-05 | J17: =I17 -> 1.4213086e-05 | K17: =J17 -> 1.4213086e-05 | L17: =K17 -> 1.4213086e-05 | M17: =L17 -> 1.4213086e-05 | N17: =M17 -> 1.4213086e-05 | O17: =N17 -> 1.4213086e-05 | P17: =O17 -> 1.4213086e-05 | Q17: =P17 -> 1.4213086e-05
B18: Deferred Tax Assets | C18: ='Historical balance Sheet'!C22 -> 0 | D18: ='Historical balance Sheet'!D22 -> 27.74 | E18: ='Historical balance Sheet'!E22 -> 52.78 | F18: ='Historical balance Sheet'!F22 -> 143.55 | G18: ='Historical balance Sheet'!G22 -> 217.99 | H18: =H19*'Revenue Build_up'!H$18 -> 106.97039 | I18: =I19*'Revenue Build_up'!I$18 -> 120.20891 | J18: =J19*'Revenue Build_up'!J$18 -> 133.89567 | K18: =K19*'Revenue Build_up'!K$18 -> 147.92116 | L18: =L19*'Revenue Build_up'!L$18 -> 162.17625 | M18: =M19*'Revenue Build_up'!M$18 -> 176.55478 | N18: =N19*'Revenue Build_up'!N$18 -> 190.95585 | O18: =O19*'Revenue Build_up'!O$18 -> 205.28551 | ... Q18: =Q19*'Revenue Build_up'!Q$18 -> 233.39705
B19: % of Revenue | C19: =C18/'Revenue Build_up'!C$18 -> 0 | D19: =D18/'Revenue Build_up'!D$18 -> 0.004558369 | E19: =E18/'Revenue Build_up'!E$18 -> 0.0079745202 | F19: =F18/'Revenue Build_up'!F$18 -> 0.022532492 | G19: =G18/'Revenue Build_up'!G$18 -> 0.029979426 | H19: =AVERAGE(C19:G19) -> 0.013008961 | I19: =H19 -> 0.013008961 | J19: =I19 -> 0.013008961 | K19: =J19 -> 0.013008961 | L19: =K19 -> 0.013008961 | M19: =L19 -> 0.013008961 | N19: =M19 -> 0.013008961 | O19: =N19 -> 0.013008961 | P19: =O19 -> 0.013008961 | Q19: =P19 -> 0.013008961
B20: Other Non-Current Assets | C20: ='Historical balance Sheet'!C23 -> 0 | D20: ='Historical balance Sheet'!D23 -> 155.19 | E20: ='Historical balance Sheet'!E23 -> 94.5 | F20: ='Historical balance Sheet'!F23 -> 110.89 | G20: ='Historical balance Sheet'!G23 -> 122.1 | H20: =H21*'Revenue Build_up'!H$18 -> 121.66082 | I20: =I21*'Revenue Build_up'!I$18 -> 136.71741 | J20: =J21*'Revenue Build_up'!J$18 -> 152.28379 | K20: =K21*'Revenue Build_up'!K$18 -> 168.23543 | L20: =L21*'Revenue Build_up'!L$18 -> 184.4482 | M20: =M21*'Revenue Build_up'!M$18 -> 200.80136 | N20: =N21*'Revenue Build_up'!N$18 -> 217.18015 | O20: =O21*'Revenue Build_up'!O$18 -> 233.47773 | ... Q20: =Q21*'Revenue Build_up'!Q$18 -> 265.44988
B21: % of Revenue | C21: =C20/'Revenue Build_up'!C$18 -> 0 | D21: =D20/'Revenue Build_up'!D$18 -> 0.02550156 | E21: =E20/'Revenue Build_up'!E$18 -> 0.014277987 | F21: =F20/'Revenue Build_up'!F$18 -> 0.017405977 | G21: =G20/'Revenue Build_up'!G$18 -> 0.016791999 | H21: =AVERAGE(C21:G21) -> 0.014795505 | I21: =H21 -> 0.014795505 | J21: =I21 -> 0.014795505 | K21: =J21 -> 0.014795505 | L21: =K21 -> 0.014795505 | M21: =L21 -> 0.014795505 | N21: =M21 -> 0.014795505 | O21: =N21 -> 0.014795505 | P21: =O21 -> 0.014795505 | Q21: =P21 -> 0.014795505
B23: Current Assets:
B24: Loans and Advances | C24: ='Historical balance Sheet'!C33 -> 0 | D24: ='Historical balance Sheet'!D33 -> 0 | E24: ='Historical balance Sheet'!E33 -> 32.03 | F24: ='Historical balance Sheet'!F33 -> 8.28 | G24: ='Historical balance Sheet'!G33 -> 6.27 | H24: =H25*'Revenue Build_up'!H$18 -> 11.514219 | I24: =I25*'Revenue Build_up'!I$18 -> 12.939205 | J24: =J25*'Revenue Build_up'!J$18 -> 14.412438 | K24: =K25*'Revenue Build_up'!K$18 -> 15.922132 | L24: =L25*'Revenue Build_up'!L$18 -> 17.45654 | M24: =M25*'Revenue Build_up'!M$18 -> 19.004235 | N24: =N25*'Revenue Build_up'!N$18 -> 20.554356 | O24: =O25*'Revenue Build_up'!O$18 -> 22.096791 | ... Q24: =Q25*'Revenue Build_up'!Q$18 -> 25.122698
B25: % of Revenue | C25: =C24/'Revenue Build_up'!C$18 -> 0 | D25: =D24/'Revenue Build_up'!D$18 -> 0 | E25: =E24/'Revenue Build_up'!E$18 -> 0.0048394066 | F25: =F24/'Revenue Build_up'!F$18 -> 0.0012996798 | G25: =G24/'Revenue Build_up'!G$18 -> 0.00086229185 | H25: =AVERAGE(C25:G25) -> 0.0014002757 | I25: =H25 -> 0.0014002757 | J25: =I25 -> 0.0014002757 | K25: =J25 -> 0.0014002757 | L25: =K25 -> 0.0014002757 | M25: =L25 -> 0.0014002757 | N25: =M25 -> 0.0014002757 | O25: =N25 -> 0.0014002757 | P25: =O25 -> 0.0014002757 | Q25: =P25 -> 0.0014002757
B26: Others Current Financial Assets | C26: ='Historical balance Sheet'!C34 -> 187.48 | D26: ='Historical balance Sheet'!D34 -> 407.3 | E26: ='Historical balance Sheet'!E34 -> 160.74 | F26: ='Historical balance Sheet'!F34 -> 16.71 | G26: ='Historical balance Sheet'!G34 -> 16.32 | H26: =H27*'Revenue Build_up'!H$18 -> 226.43815 | I26: =I27*'Revenue Build_up'!I$18 -> 254.46186 | J26: =J27*'Revenue Build_up'!J$18 -> 283.4344 | K26: =K27*'Revenue Build_up'!K$18 -> 313.12399 | L26: =L27*'Revenue Build_up'!L$18 -> 343.29959 | M26: =M27*'Revenue Build_up'!M$18 -> 373.7365 | N26: =N27*'Revenue Build_up'!N$18 -> 404.22111 | O26: =O27*'Revenue Build_up'!O$18 -> 434.55457 | ... Q26: =Q27*'Revenue Build_up'!Q$18 -> 494.06194
B27: % of Revenue | C27: =C26/'Revenue Build_up'!C$18 -> 0.041605823 | D27: =D26/'Revenue Build_up'!D$18 -> 0.066929477 | E27: =E26/'Revenue Build_up'!E$18 -> 0.024286176 | F27: =F26/'Revenue Build_up'!F$18 -> 0.0026229045 | G27: =G26/'Revenue Build_up'!G$18 -> 0.0022444343 | H27: =AVERAGE(C27:G27) -> 0.027537763 | I27: =H27 -> 0.027537763 | J27: =I27 -> 0.027537763 | K27: =J27 -> 0.027537763 | L27: =K27 -> 0.027537763 | M27: =L27 -> 0.027537763 | N27: =M27 -> 0.027537763 | O27: =N27 -> 0.027537763 | P27: =O27 -> 0.027537763 | Q27: =P27 -> 0.027537763
B28: Current Tax Assets (Net) | C28: ='Historical balance Sheet'!C35 -> 0 | D28: ='Historical balance Sheet'!D35 -> 55.42 | E28: ='Historical balance Sheet'!E35 -> 55.48 | F28: ='Historical balance Sheet'!F35 -> 71.16 | G28: ='Historical balance Sheet'!G35 -> 13.89 | H28: =H29*'Revenue Build_up'!H$18 -> 50.273185 | I28: =I29*'Revenue Build_up'!I$18 -> 56.494933 | J28: =J29*'Revenue Build_up'!J$18 -> 62.927337 | K28: =K29*'Revenue Build_up'!K$18 -> 69.51894 | L28: =L29*'Revenue Build_up'!L$18 -> 76.218444 | M28: =M29*'Revenue Build_up'!M$18 -> 82.975965 | N28: =N29*'Revenue Build_up'!N$18 -> 89.744076 | O28: =O29*'Revenue Build_up'!O$18 -> 96.478629 | ... Q28: =Q29*'Revenue Build_up'!Q$18 -> 109.69029
B29: % of Revenue | C29: =C28/'Revenue Build_up'!C$18 -> 0 | D29: =D28/'Revenue Build_up'!D$18 -> 0.0091068785 | E29: =E28/'Revenue Build_up'!E$18 -> 0.0083824627 | F29: =F28/'Revenue Build_up'!F$18 -> 0.011169712 | G29: =G28/'Revenue Build_up'!G$18 -> 0.0019102446 | H29: =AVERAGE(C29:G29) -> 0.0061138595 | I29: =H29 -> 0.0061138595 | J29: =I29 -> 0.0061138595 | K29: =J29 -> 0.0061138595 | L29: =K29 -> 0.0061138595 | M29: =L29 -> 0.0061138595 | N29: =M29 -> 0.0061138595 | O29: =N29 -> 0.0061138595 | P29: =O29 -> 0.0061138595 | Q29: =P29 -> 0.0061138595
B30: Other Current Assets | C30: ='Historical balance Sheet'!C36 -> 38.39 | D30: ='Historical balance Sheet'!D36 -> 36.91 | E30: ='Historical balance Sheet'!E36 -> 38.75 | F30: ='Historical balance Sheet'!F36 -> 332.84 | G30: ='Historical balance Sheet'!G36 -> 323.21 | H30: =H31*'Revenue Build_up'!H$18 -> 192.63461 | I30: =I31*'Revenue Build_up'!I$18 -> 216.47484 | J30: =J31*'Revenue Build_up'!J$18 -> 241.12225 | K30: =K31*'Revenue Build_up'!K$18 -> 266.37967 | L30: =L31*'Revenue Build_up'!L$18 -> 292.05054 | M30: =M31*'Revenue Build_up'!M$18 -> 317.94371 | N30: =N31*'Revenue Build_up'!N$18 -> 343.87747 | O30: =O31*'Revenue Build_up'!O$18 -> 369.68264 | ... Q30: =Q31*'Revenue Build_up'!Q$18 -> 420.30652
B31: % of Revenue | C31: =C30/'Revenue Build_up'!C$18 -> 0.0085195624 | D31: =D30/'Revenue Build_up'!D$18 -> 0.0060652271 | E31: =E30/'Revenue Build_up'!E$18 -> 0.0058547302 | F31: =F30/'Revenue Build_up'!F$18 -> 0.052244616 | G31: =G30/'Revenue Build_up'!G$18 -> 0.044449976 | H31: =AVERAGE(C31:G31) -> 0.023426822 | I31: =H31 -> 0.023426822 | J31: =I31 -> 0.023426822 | K31: =J31 -> 0.023426822 | L31: =K31 -> 0.023426822 | M31: =L31 -> 0.023426822 | N31: =M31 -> 0.023426822 | O31: =N31 -> 0.023426822 | P31: =O31 -> 0.023426822 | Q31: =P31 -> 0.023426822
B34: LIABILITIES
B35: Non-Current Liabilities:
B36: (i) Borrowings | C36: ='Historical balance Sheet'!C52 -> 1268.05 | D36: ='Historical balance Sheet'!D52 -> 929.85 | E36: ='Historical balance Sheet'!E52 -> 634.71 | F36: ='Historical balance Sheet'!F52 -> 1523.87 | G36: ='Historical balance Sheet'!G52 -> 1867.42 | H36: =H37*'Revenue Build_up'!H$18 -> 1687.519 | I36: =I37*'Revenue Build_up'!I$18 -> 1896.3643 | J36: =J37*'Revenue Build_up'!J$18 -> 2112.2806 | K36: =K37*'Revenue Build_up'!K$18 -> 2333.5408 | L36: =L37*'Revenue Build_up'!L$18 -> 2558.423 | M36: =M37*'Revenue Build_up'!M$18 -> 2785.2525 | N36: =N37*'Revenue Build_up'!N$18 -> 3012.4376 | O36: =O37*'Revenue Build_up'!O$18 -> 3238.4962 | ... Q36: =Q37*'Revenue Build_up'!Q$18 -> 3681.9718
B37: % of Revenue | C37: =C36/'Revenue Build_up'!C$18 -> 0.28140743 | D37: =D36/'Revenue Build_up'!D$18 -> 0.15279738 | E37: =E36/'Revenue Build_up'!E$18 -> 0.095898214 | F37: =F36/'Revenue Build_up'!F$18 -> 0.23919602 | G37: =G36/'Revenue Build_up'!G$18 -> 0.25681994 | H37: =AVERAGE(C37:G37) -> 0.2052238 | I37: =H37 -> 0.2052238 | J37: =I37 -> 0.2052238 | K37: =J37 -> 0.2052238 | L37: =K37 -> 0.2052238 | M37: =L37 -> 0.2052238 | N37: =M37 -> 0.2052238 | O37: =N37 -> 0.2052238 | P37: =O37 -> 0.2052238 | Q37: =P37 -> 0.2052238
B38: (ii) Lease Liabilities | C38: ='Historical balance Sheet'!C53 -> 0 | D38: ='Historical balance Sheet'!D53 -> 14.91 | E38: ='Historical balance Sheet'!E53 -> 25.26 | F38: ='Historical balance Sheet'!F53 -> 49.31 | G38: ='Historical balance Sheet'!G53 -> 47.13 | H38: =H39*'Revenue Build_up'!H$18 -> 33.694237 | I38: =I39*'Revenue Build_up'!I$18 -> 37.864194 | J38: =J39*'Revenue Build_up'!J$18 -> 42.175339 | K38: =K39*'Revenue Build_up'!K$18 -> 46.593181 | L38: =L39*'Revenue Build_up'!L$18 -> 51.083342 | M38: =M39*'Revenue Build_up'!M$18 -> 55.612387 | N38: =N39*'Revenue Build_up'!N$18 -> 60.148529 | O38: =O39*'Revenue Build_up'!O$18 -> 64.66218 | ... Q38: =Q39*'Revenue Build_up'!Q$18 -> 73.516939
B39: % of Revenue | C39: =C38/'Revenue Build_up'!C$18 -> 0 | D39: =D38/'Revenue Build_up'!D$18 -> 0.0024500822 | E39: =E38/'Revenue Build_up'!E$18 -> 0.0038165286 | F39: =F38/'Revenue Build_up'!F$18 -> 0.0077400013 | G39: =G38/'Revenue Build_up'!G$18 -> 0.0064816292 | H39: =AVERAGE(C39:G39) -> 0.0040976483 | I39: =H39 -> 0.0040976483 | J39: =I39 -> 0.0040976483 | K39: =J39 -> 0.0040976483 | L39: =K39 -> 0.0040976483 | M39: =L39 -> 0.0040976483 | N39: =M39 -> 0.0040976483 | O39: =N39 -> 0.0040976483 | P39: =O39 -> 0.0040976483 | Q39: =P39 -> 0.0040976483
B40: Other Non-Current Liabilitie | C40: ='Historical balance Sheet'!C54 -> 224.41 | D40: ='Historical balance Sheet'!D54 -> 223.58 | E40: ='Historical balance Sheet'!E54 -> 216.81 | F40: ='Historical balance Sheet'!F54 -> 175.29 | G40: ='Historical balance Sheet'!G54 -> 112.16 | H40: =H41*'Revenue Build_up'!H$18 -> 266.81166 | I40: =I41*'Revenue Build_up'!I$18 -> 299.83194 | J40: =J41*'Revenue Build_up'!J$18 -> 333.97023 | K40: =K41*'Revenue Build_up'!K$18 -> 368.95342 | L40: =L41*'Revenue Build_up'!L$18 -> 404.50927 | M40: =M41*'Revenue Build_up'!M$18 -> 440.37303 | N40: =N41*'Revenue Build_up'!N$18 -> 476.29299 | O40: =O41*'Revenue Build_up'!O$18 -> 512.03485 | ... Q40: =Q41*'Revenue Build_up'!Q$18 -> 582.15227
B41: % of Revenue | C41: =C40/'Revenue Build_up'!C$18 -> 0.04980138 | D41: =D40/'Revenue Build_up'!D$18 -> 0.036739731 | E41: =E40/'Revenue Build_up'!E$18 -> 0.032757782 | F41: =F40/'Revenue Build_up'!F$18 -> 0.027514598 | G41: =G40/'Revenue Build_up'!G$18 -> 0.015424985 | H41: =AVERAGE(C41:G41) -> 0.032447695 | I41: =H41 -> 0.032447695 | J41: =I41 -> 0.032447695 | K41: =J41 -> 0.032447695 | L41: =K41 -> 0.032447695 | M41: =L41 -> 0.032447695 | N41: =M41 -> 0.032447695 | O41: =N41 -> 0.032447695 | P41: =O41 -> 0.032447695 | Q41: =P41 -> 0.032447695
B42: Provisions | C42: ='Historical balance Sheet'!C56 -> 0 | D42: ='Historical balance Sheet'!D56 -> 0 | E42: ='Historical balance Sheet'!E56 -> 0 | F42: ='Historical balance Sheet'!F56 -> 13.76 | G42: ='Historical balance Sheet'!G56 -> 15.19 | H42: =H43*'Revenue Build_up'!H$18 -> 8.7344544 | I42: =I43*'Revenue Build_up'!I$18 -> 9.8154198 | J42: =J43*'Revenue Build_up'!J$18 -> 10.932985 | K42: =K43*'Revenue Build_up'!K$18 -> 12.078209 | L42: =L43*'Revenue Build_up'!L$18 -> 13.242179 | M42: =M43*'Revenue Build_up'!M$18 -> 14.41623 | N42: =N43*'Revenue Build_up'!N$18 -> 15.59212 | O42: =O43*'Revenue Build_up'!O$18 -> 16.76218 | ... Q42: =Q43*'Revenue Build_up'!Q$18 -> 19.057572
B43: % of Revenue | C43: =C42/'Revenue Build_up'!C$18 -> 0 | D43: =D42/'Revenue Build_up'!D$18 -> 0 | E43: =E42/'Revenue Build_up'!E$18 -> 0 | F43: =F42/'Revenue Build_up'!F$18 -> 0.0021598543 | G43: =G42/'Revenue Build_up'!G$18 -> 0.0020890292 | H43: =AVERAGE(D43:G43) -> 0.0010622209 | I43: =H43 -> 0.0010622209 | J43: =I43 -> 0.0010622209 | K43: =J43 -> 0.0010622209 | L43: =K43 -> 0.0010622209 | M43: =L43 -> 0.0010622209 | N43: =M43 -> 0.0010622209 | O43: =N43 -> 0.0010622209 | P43: =O43 -> 0.0010622209 | Q43: =P43 -> 0.0010622209
B44: Deferred Tax Liabilities (Net) | C44: ='Historical balance Sheet'!C55 -> 233.94 | D44: ='Historical balance Sheet'!D55 -> 0 | E44: ='Historical balance Sheet'!E55 -> 0 | F44: ='Historical balance Sheet'!F55 -> 0 | G44: ='Historical balance Sheet'!G55 -> 0 | H44: =H45*'Revenue Build_up'!H$18 -> 85.379695 | I44: =I45*'Revenue Build_up'!I$18 -> 95.946182 | J44: =J45*'Revenue Build_up'!J$18 -> 106.87043 | K44: =K45*'Revenue Build_up'!K$18 -> 118.06505 | L44: =L45*'Revenue Build_up'!L$18 -> 129.44291 | M44: =M45*'Revenue Build_up'!M$18 -> 140.91931 | N44: =N45*'Revenue Build_up'!N$18 -> 152.41369 | O44: =O45*'Revenue Build_up'!O$18 -> 163.85109 | ... Q44: =Q45*'Revenue Build_up'!Q$18 -> 186.28865
B45: % of Revenue | C45: =C44/'Revenue Build_up'!C$18 -> 0.051916291 | D45: =D44/'Revenue Build_up'!D$18 -> 0 | E45: =E44/'Revenue Build_up'!E$18 -> 0 | F45: =F44/'Revenue Build_up'!F$18 -> 0 | G45: =G44/'Revenue Build_up'!G$18 -> 0 | H45: =AVERAGE(C45:G45) -> 0.010383258 | I45: =H45 -> 0.010383258 | J45: =I45 -> 0.010383258 | K45: =J45 -> 0.010383258 | L45: =K45 -> 0.010383258 | M45: =L45 -> 0.010383258 | N45: =M45 -> 0.010383258 | O45: =N45 -> 0.010383258 | P45: =O45 -> 0.010383258 | Q45: =P45 -> 0.010383258
B47: Current Liabilities:
B48: (i) Borrowings | C48: ='Historical balance Sheet'!C61 -> 1224.07 | D48: ='Historical balance Sheet'!D61 -> 1638.12 | E48: ='Historical balance Sheet'!E61 -> 2239.32 | F48: ='Historical balance Sheet'!F61 -> 2040.42 | G48: ='Historical balance Sheet'!G61 -> 1922.13 | H48: =H49*'Revenue Build_up'!H$18 -> 2407.2978 | I48: =I49*'Revenue Build_up'!I$18 -> 2705.2221 | J48: =J49*'Revenue Build_up'!J$18 -> 3013.2334 | K48: =K49*'Revenue Build_up'!K$18 -> 3328.8679 | L48: =L49*'Revenue Build_up'!L$18 -> 3649.6692 | M48: =M49*'Revenue Build_up'!M$18 -> 3973.2486 | N48: =N49*'Revenue Build_up'!N$18 -> 4297.335 | O48: =O49*'Revenue Build_up'!O$18 -> 4619.8146 | ... Q48: =Q49*'Revenue Build_up'!Q$18 -> 5252.4462
B49: % of Revenue | C49: =C48/'Revenue Build_up'!C$18 -> 0.27164732 | D49: =D48/'Revenue Build_up'!D$18 -> 0.26918368 | E49: =E48/'Revenue Build_up'!E$18 -> 0.33833844 | F49: =F48/'Revenue Build_up'!F$18 -> 0.32027689 | G49: =G48/'Revenue Build_up'!G$18 -> 0.26434403 | H49: =AVERAGE(C49:G49) -> 0.29275807 | I49: =H49 -> 0.29275807 | J49: =I49 -> 0.29275807 | K49: =J49 -> 0.29275807 | L49: =K49 -> 0.29275807 | M49: =L49 -> 0.29275807 | N49: =M49 -> 0.29275807 | O49: =N49 -> 0.29275807 | P49: =O49 -> 0.29275807 | Q49: =P49 -> 0.29275807
B50: (ii) Lease Liabilities | C50: ='Historical balance Sheet'!C62 -> 0 | D50: ='Historical balance Sheet'!D62 -> 4.07 | E50: ='Historical balance Sheet'!E62 -> 8.02 | F50: ='Historical balance Sheet'!F62 -> 9.07 | G50: ='Historical balance Sheet'!G62 -> 11.11 | H50: =H51*'Revenue Build_up'!H$18 -> 7.9467759 | I50: =I51*'Revenue Build_up'!I$18 -> 8.9302592 | J50: =J51*'Revenue Build_up'!J$18 -> 9.9470414 | K50: =K51*'Revenue Build_up'!K$18 -> 10.988988 | L50: =L51*'Revenue Build_up'!L$18 -> 12.047991 | M50: =M51*'Revenue Build_up'!M$18 -> 13.116165 | N50: =N51*'Revenue Build_up'!N$18 -> 14.186013 | O50: =O51*'Revenue Build_up'!O$18 -> 15.250557 | ... Q50: =Q51*'Revenue Build_up'!Q$18 -> 17.338949
...

Sheet Income statement
B7: BSE: 524208 | NSE: AARTIIND
B8: Income Statement
B9: All Figure In INR Cr.
B10: Particulars | C10: 2021 | D10: =C10+1 -> 2022 | E10: =D10+1 -> 2023 | F10: =E10+1 -> 2024 | G10: =F10+1 -> 2025 | H10: =G10+1 -> 2026 | I10: =H10+1 -> 2027 | J10: =I10+1 -> 2028 | K10: =J10+1 -> 2029 | ... Q10: =P10+1 -> 2035
C11: Aduited | D11: Aduited | E11: Aduited | F11: Aduited | G11: Aduited | H11: Forecasted | I11: Forecasted | J11: Forecasted | K11: Forecasted | L11: Forecasted | M11: Forecasted | N11: Forecasted | O11: Forecasted | P11: Forecasted | Q11: Forecasted
B13: Revenue | C13: ='Historical P&L'!C14 -> 4506.1 | D13: ='Historical P&L'!D14 -> 6085.51 | E13: ='Historical P&L'!E14 -> 6618.58 | F13: ='Historical P&L'!F14 -> 6370.8 | G13: ='Historical P&L'!G14 -> 7271.32 | H13: ='Revenue Build_up'!H18 -> 8222.823 | I13: ='Revenue Build_up'!I18 -> 9240.4696 | J13: ='Revenue Build_up'!J18 -> 10292.572 | K13: ='Revenue Build_up'!K18 -> 11370.713 | L13: ='Revenue Build_up'!L18 -> 12466.502 | M13: ='Revenue Build_up'!M18 -> 13571.781 | N13: ='Revenue Build_up'!N18 -> 14678.793 | O13: ='Revenue Build_up'!O18 -> 15780.315 | ... Q13: ='Revenue Build_up'!Q18 -> 17941.252
B14: COGS | C14: =-SUM('Historical P&L'!C18:C20) -> -2128.56 | D14: =-SUM('Historical P&L'!D18:D20) -> -2854.45 | E14: =-SUM('Historical P&L'!E18:E20) -> -3841.67 | F14: =-SUM('Historical P&L'!F18:F20) -> -3881.88 | G14: =-SUM('Historical P&L'!G18:G20) -> -4655.12 | H14: =-'Cost Build_up'!H25 -> -4557.736 | I14: =-'Cost Build_up'!I25 -> -5121.7958 | J14: =-'Cost Build_up'!J25 -> -5704.9537 | K14: =-'Cost Build_up'!K25 -> -6302.5443 | L14: =-'Cost Build_up'!L25 -> -6909.9172 | M14: =-'Cost Build_up'!M25 -> -7522.5499 | N14: =-'Cost Build_up'!N25 -> -8136.1427 | O14: =-'Cost Build_up'!O25 -> -8746.6931 | ... Q14: =-'Cost Build_up'!Q25 -> -9944.4544
