Workbook

Sheet Assumptions
B8: Scenario
B9: Base | C9: =IF(B9="Base",2,IF(B9="Best",1,3)) -> 2
B11: Assumptions
B12: Transaction Date | C12: 45879
B13: Fiscal Year End | C13: 46112
B14: Risk Free Rate | C14: 0.0637
B15: Tax Rate | C15: ='Cost Build_Up'!H38 -> 0.25354554
B16: Perpetual Growth Rate | C16: 0.05
B17: Discount Rate | C17: =WACC!C25 -> 0.10338768
B18: Shares Outstanding(Mn) | C18: 580.8
B19: Current Market Price | C19: 1042
B20: Market Cap (mn.) | C20: =C19*C18 -> 605193.6

Sheet P&L
B6: P&L Statement
B8: Particulars | C8: 2020 | D8: =C8+1 -> 2021 | E8: =D8+1 -> 2022 | F8: =E8+1 -> 2023 | G8: =F8+1 -> 2024
B9: INCOME
B10: Revenue from operations | C10: 230985.1 | D10: 247746.2 | E10: 234554.9 | F10: 248553.8 | G10: 290018.7
B11: Other income | C11: 1918.7 | D11: 3808.5 | E11: 3203.5 | F11: 2905.9 | G11: 5573.8
B12: Total Income | C12: =SUM(C10:C11) -> 232903.8 | D12: =SUM(D10:D11) -> 251554.7 | E12: =SUM(E10:E11) -> 237758.4 | F12: =SUM(F10:F11) -> 251459.7 | G12: =SUM(G10:G11) -> 295592.5
B13: EXPENSES
B14: Cost of materials consumed | C14: 77249.8 | D14: 83172.6 | E14: 73718.3 | F14: 96525.1 | G14: 107761.4
B15: Purchases of stock-in-trade | C15: 21121.1 | D15: 23154.2 | E15: 19517.7 | F15: 20504.3 | G15: 27729.3
B16: Changes in inventories of finished goods, stock-in-trade and wip | C16: -1018.6 | D16: -7302.1 | E16: 8166.8 | F16: -4096.8 | G16: -9461.7
B17: Employee benefits expense | C17: 32191.8 | D17: 35350.2 | E17: 34509.2 | F17: 35222.5 | G17: 39229.4
B18: Finance costs | C18: 3051.3 | D18: 744.9 | E18: 486.4 | F18: 1404.8 | G18: 2897.1
B19: Depreciation, amortisation and impairment expense | C19: 9667.1 | D19: 10553.9 | E19: 11265.2 | F19: 12445.8 | G19: 15216.6
B20: Other expenses | C20: 52797.9 | D20: 60037.3 | E20: 54775.2 | F20: 63212.3 | G20: 66330.3
B21: Total Expenses | C21: =-SUM(C14:C20) -> -195060.4 | D21: =-SUM(D14:D20) -> -205711 | E21: =-SUM(E14:E20) -> -202438.8 | F21: =-SUM(F14:F20) -> -225218 | G21: =-SUM(G14:G20) -> -249702.4
B23: PROFIT BEFORE SHARE OF LOSS OF JOINT VENTURES AND ASSOCIATES, EXCEPTIONAL ITEMS AND TAX | C23: =SUM(C12,C21) -> 37843.4 | D23: =SUM(D12,D21) -> 45843.7 | E23: =SUM(E12,E21) -> 35319.6 | F23: =SUM(F12,F21) -> 26241.7 | G23: =SUM(G12,G21) -> 45890.1
B24: Share of loss of joint ventures and associates (net of tax) | C24: -151.7 | D24: -553.6 | E24: -312.5 | F24: -116.7 | G24: -171.6
B25: PROFIT BEFORE EXCEPTIONAL ITEMS AND TAX | C25: =SUM(C23:C24) -> 37691.7 | D25: =SUM(D23:D24) -> 45290.1 | E25: =SUM(E23:E24) -> 35007.1 | F25: =SUM(F23:F24) -> 26125 | G25: =SUM(G23:G24) -> 45718.5
B26: Exceptional items | C26: 261.3 | D26: -28145.8 | E26: 1279.7 | G26: 1918.6
B27: PROFIT BEFORE TAX | C27: =C25-C26 -> 37430.4 | D27: =D25-D26 -> 73435.9 | E27: =E25-E26 -> 33727.4 | F27: =F25-F26 -> 26125 | G27: =G25-G26 -> 43799.9
B28: TAX | C28: -8993.5 | D28: -20097.7 | E28: -7256.3 | F28: -6848.5 | G28: -12110.2
B29: PROFIT FOR THE YEAR | C29: =SUM(C27:C28) -> 28436.9 | D29: =SUM(D27:D28) -> 53338.2 | E29: =SUM(E27:E28) -> 26471.1 | F29: =SUM(F27:F28) -> 19276.5 | G29: =SUM(G27:G28) -> 31689.7

Sheet Balance_sheet
B6: Balance Sheet
B8: Particulars | C8: 2020 | D8: =C8+1 -> 2021 | E8: =D8+1 -> 2022 | F8: =E8+1 -> 2023 | G8: =F8+1 -> 2024 | H8: =G8+1 -> 2025 | I8: =H8+1 -> 2026 | J8: =I8+1 -> 2027 | K8: =J8+1 -> 2028 | ... Q8: =P8+1 -> 2034
B9: ASSETS
B10: Non-current assets
B11: Property, plant and equipment | C11: 64948.1 | D11: 64731.7 | E11: 72204.3 | F11: 75433.7 | G11: 112608.3 | H11: =FAS!H27 -> 118858.13 | I11: =FAS!I27 -> 125349.44 | J11: =FAS!J27 -> 132102.43 | K11: =FAS!K27 -> 139137.4 | L11: =FAS!L27 -> 146474.84 | M11: =FAS!M27 -> 154135.52 | N11: =FAS!N27 -> 162140.6 | O11: =FAS!O27 -> 170511.74 | ... Q11: =FAS!Q27 -> 188441.71
B12: Capital work-in-progress | C12: 16218 | D12: 24288.9 | E12: 29375.6 | F12: 44964 | G12: 27393.9 | H12: =FAS!H97 -> 30187.875 | I12: =FAS!I97 -> 33261.247 | J12: =FAS!J97 -> 36641.957 | K12: =FAS!K97 -> 40360.738 | L12: =FAS!L97 -> 44451.397 | M12: =FAS!M97 -> 48951.121 | N12: =FAS!N97 -> 53900.819 | O12: =FAS!O97 -> 59345.485 | ... Q12: =FAS!Q97 -> 71922.666
B13: Right-of-use assets | D13: 4134.5 | E13: 5080.1 | F13: 4520.1 | G13: 2846.8 | H13: =FAS!H69 -> 2776.3869 | I13: =FAS!I69 -> 2753.1831 | J13: =FAS!J69 -> 2772.5736 | K13: =FAS!K69 -> 2830.9875 | L13: =FAS!L69 -> 2925.7512 | M13: =FAS!M69 -> 3054.9677 | N13: =FAS!N69 -> 3217.4186 | O13: =FAS!O69 -> 3412.4845 | ... Q13: =FAS!Q69 -> 3900.613
B14: Goodwill | C14: 9159.4 | D14: 4289 | E14: 4754.2 | F14: 5960.7 | G14: 5951.5 | H14: =G14 -> 5951.5 | I14: =H14 -> 5951.5 | J14: =I14 -> 5951.5 | K14: =J14 -> 5951.5 | L14: =K14 -> 5951.5 | M14: =L14 -> 5951.5 | N14: =M14 -> 5951.5 | O14: =N14 -> 5951.5 | ... Q14: =P14 -> 5951.5
B15: Other intangible assets | C15: 19857.2 | D15: 20580.6 | E15: 23282.3 | F15: 24322.4 | G15: 23521.3 | H15: =FAS!H48 -> 23752.566 | I15: =FAS!I48 -> 24674.701 | J15: =FAS!J48 -> 26220.862 | K15: =FAS!K48 -> 28352.374 | L15: =FAS!L48 -> 31053.681 | M15: =FAS!M48 -> 34328.7 | N15: =FAS!N48 -> 38198.264 | O15: =FAS!O48 -> 42698.433 | ... Q15: =FAS!Q48 -> 53805.558
B16: Intangible assets under development | C16: 3641.2 | D16: 6326.4 | E16: 8096.4 | F16: 8936.1 | G16: 11293.3
B17: Investments accounted for using the equity method | C17: 4096.1 | D17: 947 | E17: 793.5 | F17: 900 | G17: 947.8
B18: Financial assets
B19: Investments | C19: 1450.8 | D19: 3365.2 | E19: 5389.5 | F19: 3017.4 | G19: 2268.7 | H19: ='BalanceSheet Forecast'!H11 -> 3918.8579 | I19: ='BalanceSheet Forecast'!I11 -> 4233.0472 | J19: ='BalanceSheet Forecast'!J11 -> 4592.5312 | K19: ='BalanceSheet Forecast'!K11 -> 5005.8769 | L19: ='BalanceSheet Forecast'!L11 -> 5483.456 | M19: ='BalanceSheet Forecast'!M11 -> 6037.8409 | N19: ='BalanceSheet Forecast'!N11 -> 6684.2903 | O19: ='BalanceSheet Forecast'!O11 -> 7441.3428 | ... Q19: ='BalanceSheet Forecast'!Q11 -> 9382.3361
B20: Loans | C20: 58.4 | D20: 72.6 | E20: 63.2 | F20: 55.7 | G20: 58.3 | H20: ='BalanceSheet Forecast'!H13 -> 77.400816 | I20: ='BalanceSheet Forecast'!I13 -> 83.606325 | J20: ='BalanceSheet Forecast'!J13 -> 90.706442 | K20: ='BalanceSheet Forecast'!K13 -> 98.870376 | L20: ='BalanceSheet Forecast'!L13 -> 108.30297 | M20: ='BalanceSheet Forecast'!M13 -> 119.25255 | N20: ='BalanceSheet Forecast'!N13 -> 132.02049 | O20: ='BalanceSheet Forecast'!O13 -> 146.97292 | ... Q20: ='BalanceSheet Forecast'!Q13 -> 185.30921
B21: Other financial assets | C21: 1170.3 | D21: 1433 | E21: 1289.2 | F21: 1503.7 | G21: 3510 | H21: ='BalanceSheet Forecast'!H15 -> 2152.7041 | I21: ='BalanceSheet Forecast'!I15 -> 2325.2943 | J21: ='BalanceSheet Forecast'!J15 -> 2522.7657 | K21: ='BalanceSheet Forecast'!K15 -> 2749.8245 | L21: ='BalanceSheet Forecast'!L15 -> 3012.1679 | M21: ='BalanceSheet Forecast'!M15 -> 3316.7022 | N21: ='BalanceSheet Forecast'!N15 -> 3671.8093 | O21: ='BalanceSheet Forecast'!O15 -> 4087.6728 | ... Q21: ='BalanceSheet Forecast'!Q15 -> 5153.8977
B22: Deferred tax assets (net | C22: 1632 | D22: 4526.8 | E22: 2885.9 | F22: 6774.9 | G22: 12126.4 | H22: ='BalanceSheet Forecast'!H17 -> 6658.5462 | I22: ='BalanceSheet Forecast'!I17 -> 7192.3864 | J22: ='BalanceSheet Forecast'!J17 -> 7803.187 | K22: ='BalanceSheet Forecast'!K17 -> 8505.5042 | L22: ='BalanceSheet Forecast'!L17 -> 9316.9606 | M22: ='BalanceSheet Forecast'!M17 -> 10258.918 | N22: ='BalanceSheet Forecast'!N17 -> 11357.303 | O22: ='BalanceSheet Forecast'!O17 -> 12643.614 | ... Q22: ='BalanceSheet Forecast'!Q17 -> 15941.562
B23: Non-current tax assets (net) | C23: 845.3 | D23: 1282.6 | E23: 3189.7 | F23: 2885.2 | G23: 3832.9 | H23: ='BalanceSheet Forecast'!H19 -> 2948.9045 | I23: ='BalanceSheet Forecast'!I19 -> 3185.329 | J23: ='BalanceSheet Forecast'!J19 -> 3455.8374 | K23: ='BalanceSheet Forecast'!K19 -> 3766.8762 | L23: ='BalanceSheet Forecast'!L19 -> 4126.2501 | M23: ='BalanceSheet Forecast'!M19 -> 4543.4196 | N23: ='BalanceSheet Forecast'!N19 -> 5029.8669 | O23: ='BalanceSheet Forecast'!O19 -> 5599.5419 | ... Q23: ='BalanceSheet Forecast'!Q19 -> 7060.1214
B24: Other non-current asset | C24: 2075.5 | D24: 4326.5 | E24: 1586.4 | F24: 4169.3 | G24: 2299.6 | H24: ='BalanceSheet Forecast'!H21 -> 3613.8265 | I24: ='BalanceSheet Forecast'!I21 -> 3903.5603 | J24: ='BalanceSheet Forecast'!J21 -> 4235.0632 | K24: ='BalanceSheet Forecast'!K21 -> 4616.2354 | L24: ='BalanceSheet Forecast'!L21 -> 5056.6412 | M24: ='BalanceSheet Forecast'!M21 -> 5567.8746 | N24: ='BalanceSheet Forecast'!N21 -> 6164.0065 | O24: ='BalanceSheet Forecast'!O21 -> 6862.1324 | ... Q24: ='BalanceSheet Forecast'!Q21 -> 8652.0449
B26: Total non-current assets | C26: =SUM(C11:C24) -> 125152.3 | D26: =SUM(D11:D24) -> 140304.8 | E26: =SUM(E11:E24) -> 157990.3 | F26: =SUM(F11:F24) -> 183443.2 | G26: =SUM(G11:G24) -> 208658.8 | H26: =SUM(H11:H24) -> 200896.7 | I26: =SUM(I11:I24) -> 212913.29 | J26: =SUM(J11:J24) -> 226389.41 | ... Q26: =SUM(Q11:Q24) -> 370397.32
B28: Current assets
B29: Inventories | C29: 76998.7 | D29: 90265.7 | E29: 75538.5 | F29: 85112.3 | G29: 98082.3 | H29: ='Working Capital'!H11 -> 106392.4 | I29: ='Working Capital'!I11 -> 114922.27 | J29: ='Working Capital'!J11 -> 124681.84 | K29: ='Working Capital'!K11 -> 135903.69 | L29: ='Working Capital'!L11 -> 148869.4 | M29: ='Working Capital'!M11 -> 163920.3 | N29: ='Working Capital'!N11 -> 181470.64 | O29: ='Working Capital'!O11 -> 202023.73 | ... Q29: ='Working Capital'!Q11 -> 254719.42
B30: Financial assets
B31: Investments | C31: 0.2 | D31: 1597.9 | E31: 3788.5 | F31: 1510 | G31: 505.8 | H31: ='BalanceSheet Forecast'!H26 -> 1898.2517 | I31: ='BalanceSheet Forecast'!I26 -> 2050.4416 | J31: ='BalanceSheet Forecast'!J26 -> 2224.5716 | K31: ='BalanceSheet Forecast'!K26 -> 2424.7918 | L31: ='BalanceSheet Forecast'!L26 -> 2656.1258 | M31: ='BalanceSheet Forecast'!M26 -> 2924.6638 | N31: ='BalanceSheet Forecast'!N26 -> 3237.7968 | O31: ='BalanceSheet Forecast'!O26 -> 3604.5047 | ... Q31: ='BalanceSheet Forecast'!Q26 -> 4544.7005
B32: Trade receivables | C32: 43151.6 | D32: 35032.8 | E32: 40122.6 | F32: 44663.8 | G32: 48167.4 | H32: ='Working Capital'!H12 -> 52730.003 | I32: ='Working Capital'!I12 -> 56957.561 | J32: ='Working Capital'!J12 -> 61794.58 | K32: ='Working Capital'!K12 -> 67356.334 | L32: ='Working Capital'!L12 -> 73782.376 | M32: ='Working Capital'!M12 -> 81241.875 | N32: ='Working Capital'!N12 -> 89940.144 | O32: ='Working Capital'!O12 -> 100126.63 | ... Q32: ='Working Capital'!Q12 -> 126243.57
B33: Cash and cash equivalents | C33: 27637.1 | D33: 53734.7 | E33: 41625.1 | F33: 43962.9 | G33: 33934.8 | H33: =H79-SUM(H35:H39,H29:H32,H26) -> 96054.64 | I33: =I79-SUM(I35:I39,I29:I32,I26) -> 113759.93 | J33: =J79-SUM(J35:J39,J29:J32,J26) -> 132845.46 | K33: =K79-SUM(K35:K39,K29:K32,K26) -> 153642.81 | L33: =L79-SUM(L35:L39,L29:L32,L26) -> 176548.41 | M33: =M79-SUM(M35:M39,M29:M32,M26) -> 202041.42 | N33: =N79-SUM(N35:N39,N29:N32,N26) -> 230705.12 | O33: =O79-SUM(O35:O39,O29:O32,O26) -> 263252.68 | ... Q33: =Q79-SUM(Q35:Q39,Q29:Q32,Q26) -> 343696.36
B34: Bank balances | C34: 784.4 | D34: 1008.1 | E34: 275 | F34: 16879.1 | G34: 28848.2
B35: Loans | C35: 136.8 | D35: 143.2 | E35: 127.1 | F35: 124.3 | G35: 128.6 | H35: ='BalanceSheet Forecast'!H28 -> 165.7072 | I35: ='BalanceSheet Forecast'!I28 -> 178.99256 | J35: ='BalanceSheet Forecast'!J28 -> 194.19318 | K35: ='BalanceSheet Forecast'!K28 -> 211.67132 | L35: ='BalanceSheet Forecast'!L28 -> 231.86554 | M35: ='BalanceSheet Forecast'!M28 -> 255.30747 | N35: ='BalanceSheet Forecast'!N28 -> 282.6423 | O35: ='BalanceSheet Forecast'!O28 -> 314.65394 | ... Q35: ='BalanceSheet Forecast'!Q28 -> 396.72799
B36: Other financial assets | C36: 400.8 | D36: 338.7 | E36: 709.1 | F36: 2903.5 | G36: 2631.1 | H36: ='BalanceSheet Forecast'!H30 -> 1677.2113 | I36: ='BalanceSheet Forecast'!I30 -> 1811.6795 | J36: ='BalanceSheet Forecast'!J30 -> 1965.5331 | K36: ='BalanceSheet Forecast'!K30 -> 2142.4388 | L36: ='BalanceSheet Forecast'!L30 -> 2346.8353 | M36: ='BalanceSheet Forecast'!M30 -> 2584.1036 | N36: ='BalanceSheet Forecast'!N30 -> 2860.774 | O36: ='BalanceSheet Forecast'!O30 -> 3184.7809 | ... Q36: ='BalanceSheet Forecast'!Q30 -> 4015.4963
B37: Current tax assets (net | C37: 157.6 | D37: 789.8 | E37: 2699.9 | F37: 756.2 | G37: 56.7 | H37: ='BalanceSheet Forecast'!H32 -> 1161.7817 | I37: ='BalanceSheet Forecast'!I32 -> 1254.926 | J37: ='BalanceSheet Forecast'!J32 -> 1361.4984 | K37: ='BalanceSheet Forecast'!K32 -> 1484.0386 | L37: ='BalanceSheet Forecast'!L32 -> 1625.6213 | M37: ='BalanceSheet Forecast'!M32 -> 1789.9738 | N37: ='BalanceSheet Forecast'!N32 -> 1981.6197 | O37: ='BalanceSheet Forecast'!O32 -> 2206.055 | ... Q37: ='BalanceSheet Forecast'!Q32 -> 2781.4804
B38: Other current assets | C38: 14857.9 | D38: 14488.1 | E38: 15550.1 | F38: 18687 | G38: 25364.3 | H38: ='BalanceSheet Forecast'!H34 -> 21947.907 | I38: ='BalanceSheet Forecast'!I34 -> 23707.552 | J38: ='BalanceSheet Forecast'!J34 -> 25720.874 | K38: ='BalanceSheet Forecast'!K34 -> 28035.853 | L38: ='BalanceSheet Forecast'!L34 -> 30710.576 | M38: ='BalanceSheet Forecast'!M34 -> 33815.457 | N38: ='BalanceSheet Forecast'!N34 -> 37435.954 | O38: ='BalanceSheet Forecast'!O34 -> 41675.893 | ... Q38: ='BalanceSheet Forecast'!Q34 -> 52546.596
B39: Assets held for sale | D39: 836.1 | E39: 791 | F39: 857.6 | G39: 4337.1 | H39: ='BalanceSheet Forecast'!H36 -> 1569.441 | I39: ='BalanceSheet Forecast'!I36 -> 1695.2688 | J39: ='BalanceSheet Forecast'!J36 -> 1839.2365 | K39: ='BalanceSheet Forecast'!K36 -> 2004.775 | L39: ='BalanceSheet Forecast'!L36 -> 2196.0379 | M39: ='BalanceSheet Forecast'!M36 -> 2418.0603 | N39: ='BalanceSheet Forecast'!N36 -> 2676.9532 | O39: ='BalanceSheet Forecast'!O36 -> 2980.1408 | ... Q39: ='BalanceSheet Forecast'!Q36 -> 3757.4781
B41: Total current assets | C41: =SUM(C29:C39) -> 164125.1 | D41: =SUM(D29:D39) -> 198235.1 | E41: =SUM(E29:E39) -> 181226.9 | F41: =SUM(F29:F39) -> 215456.7 | G41: =SUM(G29:G39) -> 242056.3 | H41: =SUM(H29:H39) -> 283597.34 | I41: =SUM(I29:I39) -> 316338.62 | J41: =SUM(J29:J39) -> 352627.79 | ... Q41: =SUM(Q29:Q39) -> 792701.83
B43: TOTAL ASSETS | C43: =SUM(C41,C26) -> 289277.4 | D43: =SUM(D41,D26) -> 338539.9 | E43: =SUM(E41,E26) -> 339217.2 | F43: =SUM(F41,F26) -> 398899.9 | G43: =SUM(G41,G26) -> 450715.1 | H43: =SUM(H41,H26) -> 484494.04 | I43: =SUM(I41,I26) -> 529251.91 | J43: =SUM(J41,J26) -> 579017.2 | ... Q43: =SUM(Q41,Q26) -> 1163099.1
B45: EQUITY AND LIABILITIES
B46: Equity
B47: Equity share capital | C47: 585.9 | D47: 585.9 | E47: 585.9 | F47: 585.9 | G47: 585.9 | H47: =G47 -> 585.9 | I47: =H47 -> 585.9 | J47: =I47 -> 585.9 | K47: =J47 -> 585.9 | L47: =K47 -> 585.9 | M47: =L47 -> 585.9 | N47: =M47 -> 585.9 | O47: =N47 -> 585.9 | ... Q47: =P47 -> 585.9
B48: Other equity | C48: 167660.8 | D48: 218712.8 | E48: 245173.9 | F48: 267812.6 | G48: 297842.1 | H48: =G48+'Income Statement'!H33+'Income Statement'!H39 -> 330881.01 | I48: =H48+'Income Statement'!I33+'Income Statement'!I39 -> 363376.55 | J48: =I48+'Income Statement'!J33+'Income Statement'!J39 -> 399111.71 | K48: =J48+'Income Statement'!K33+'Income Statement'!K39 -> 438544.85 | L48: =K48+'Income Statement'!L33+'Income Statement'!L39 -> 482251.26 | M48: =L48+'Income Statement'!M33+'Income Statement'!M39 -> 530943.23 | N48: =M48+'Income Statement'!N33+'Income Statement'!N39 -> 585495.85 | O48: =N48+'Income Statement'!O33+'Income Statement'!O39 -> 646979.66 | ... Q48: =P48+'Income Statement'!Q33+'Income Statement'!Q39 -> 796254.78
B49: Equity attributable to owners of the Parent Company | C49: =SUM(C47:C48) -> 168246.7 | D49: =SUM(D47:D48) -> 219298.7 | E49: =SUM(E47:E48) -> 245759.8 | F49: =SUM(F47:F48) -> 268398.5 | G49: =SUM(G47:G48) -> 298428 | H49: =SUM(H47:H48) -> 331466.91 | I49: =SUM(I47:I48) -> 363962.45 | J49: =SUM(J47:J48) -> 399697.61 | ... Q49: =SUM(Q47:Q48) -> 796840.68
B50: Non-controlling interest | C50: 1.4 | D50: -8.8 | E50: -19.3 | F50: 120 | G50: 80 | H50: 80 | I50: 80 | J50: 80 | K50: 80 | L50: 80 | M50: 80 | N50: 80 | O50: 80 | P50: 80 | Q50: 80
B51: Total equity | C51: =SUM(C49:C50) -> 168248.1 | D51: =SUM(D49:D50) -> 219289.9 | E51: =SUM(E49:E50) -> 245740.5 | F51: =SUM(F49:F50) -> 268518.5 | G51: =SUM(G49:G50) -> 298508 | H51: =SUM(H49:H50) -> 331546.91 | I51: =SUM(I49:I50) -> 364042.45 | J51: =SUM(J49:J50) -> 399777.61 | ... Q51: =SUM(Q49:Q50) -> 796920.68
...

Sheet FAS
B6: Fixed Assets Schedules
B8: Particulars | C8: 2020 | D8: =C8+1 -> 2021 | E8: =D8+1 -> 2022 | F8: =E8+1 -> 2023 | G8: =F8+1 -> 2024 | H8: =G8+1 -> 2025 | I8: =H8+1 -> 2026 | J8: =I8+1 -> 2027 | K8: =J8+1 -> 2028 | ... Q8: =P8+1 -> 2034
B9: PPE
B10: Opening Gross | C10: 74283.3 | D10: =C18 -> 89775.2 | E10: 94579.4 | F10: =E18 -> 108972 | G10: =F18 -> 129175.1 | H10: =G18 -> 174703.9 | I10: =H18 -> 193864.76 | J10: =I18 -> 213983.66 | K10: =J18 -> 235108.51 | L10: =K18 -> 257289.6 | M10: =L18 -> 280579.75 | ... Q10: =P18 -> 385982.36
B11: Additions | C11: 15361.3 | D11: 9627.5 | E11: 16164.9 | F11: 8771.6 | G11: 45879 | H11: =AVERAGE(C11:G11) -> 19160.86 | I11: =H11*(1+5%) -> 20118.903 | J11: =I11*(1+5%) -> 21124.848 | K11: =J11*(1+5%) -> 22181.091 | L11: =K11*(1+5%) -> 23290.145 | M11: =L11*(1+5%) -> 24454.652 | N11: =M11*(1+5%) -> 25677.385 | O11: =N11*(1+5%) -> 26961.254 | P11: =O11*(1+5%) -> 28309.317 | Q11: =P11*(1+5%) -> 29724.783
B12: Disposals / adjustments | C12: -499.5 | D12: -2233.2 | E12: -2166.1 | F12: -540.1 | G12: -748.4
B13: Reclassified to Assets held for sale | D13: -995.3 | G13: -14.8
B14: Acquisition through business combination | D14: 5423.2 | F14: 10600.6
B15: Disposal of Subsidiary | D15: -970.7
B16: - Reclasified to Right-of-use assets | C16: -913
B17: Foreign currency translation adjustments | C17: 1543.1 | D17: -303.4 | E17: 393.8 | F17: 1371 | G17: 413
B18: Gross Closing | C18: =SUM(C10:C17) -> 89775.2 | D18: =SUM(D10:D17) -> 100323.3 | E18: =SUM(E10:E17) -> 108972 | F18: =SUM(F10:F17) -> 129175.1 | G18: =SUM(G10:G17) -> 174703.9 | H18: =SUM(H10:H17) -> 193864.76 | I18: =SUM(I10:I17) -> 213983.66 | J18: =SUM(J10:J17) -> 235108.51 | ... Q18: =SUM(Q10:Q17) -> 415707.14
B19: Accumulated depreciation | C19: -17346.8 | D19: -24827.1 | E19: -29847.7 | F19: -36767.8 | G19: -53741.4 | H19: =SUM(G19:G26) -> -62095.6 | I19: =SUM(H19:H26) -> -75006.629 | J19: =SUM(I19:I26) -> -88634.228 | K19: =SUM(J19:J26) -> -103006.08 | L19: =SUM(K19:K26) -> -118152.2 | M19: =SUM(L19:L26) -> -134104.9 | N19: =SUM(M19:M26) -> -150898.88 | O19: =SUM(N19:N26) -> -168571.18 | ... Q19: =SUM(P19:P26) -> -206711.21
B20: Charge for the year | C20: -7307 | D20: -8016.4 | E20: -7196.3 | F20: -7601.9 | G20: -8648.8 | H20: =G20/F27*G27 -> -12911.029 | I20: =H20/G27*H27 -> -13627.599 | J20: =I20/H27*I27 -> -14371.855 | K20: =J20/I27*J27 -> -15146.115 | L20: =K20/J27*K27 -> -15952.705 | M20: =L20/K27*L27 -> -16793.974 | N20: =M20/L27*M27 -> -17672.304 | O20: =N20/M27*N27 -> -18590.121 | ... Q20: =P20/O27*P27 -> -20554.212
B21: Disposals / adjustments | C21: 119.4 | D21: -1299.4 | E21: 405.4 | F21: 272.9 | G21: 519.3
B22: Reclassified to Assets held for sale | D22: -159.2 | G22: 6.8
B23: Acquisition through business combination | D23: -576.8 | F23: -9127.5
B24: Disposal of Subsidiary | D24: -410.4
B25: Reclasified to Right-of-use assets | C25: 115 | D25: -208.1
B26: Foreign currency translation adjustments | C26: -407.7 | D26: -94.2 | E26: -129.1 | F26: -517.1 | G26: -231.5
B27: Net PPE | C27: =SUM(C18:C26) -> 64948.1 | D27: =SUM(D18:D26) -> 64731.7 | E27: =SUM(E18:E26) -> 72204.3 | F27: =SUM(F18:F26) -> 75433.7 | G27: =SUM(G18:G26) -> 112608.3 | H27: =SUM(H18:H26) -> 118858.13 | I27: =SUM(I18:I26) -> 125349.44 | J27: =SUM(J18:J26) -> 132102.43 | ... Q27: =SUM(Q18:Q26) -> 188441.71
B30: Other intangible assets
B31: Opening Gross | C31: 22367.8 | D31: =C39 -> 25478 | E31: =D39 -> 27264 | F31: =E39 -> 34526.7 | G31: =F39 -> 39924.3 | H31: =G39 -> 44817.7 | I31: =H39 -> 50597.685 | J31: =I39 -> 57123.095 | K31: =J39 -> 64490.064 | ... Q31: =P39 -> 133530.14
B32: Additions | C32: 385.5 | D32: 3505.3 | E32: 2658.3 | F32: 2371.6 | G32: 5148.9 | H32: =G32/F39*G39 -> 5779.985 | I32: =H32/G39*H39 -> 6525.4098 | J32: =I32/H39*I39 -> 7366.9696 | K32: =J32/I39*J39 -> 8317.0624 | L32: =K32/J39*K39 -> 9389.6854 | M32: =L32/K39*L39 -> 10600.641 | N32: =M32/L39*M39 -> 11967.769 | O32: =N32/M39*N39 -> 13511.211 | ... Q32: =P32/O39*P39 -> 17220.924
B33: Disposals / adjustments | C33: -116.7 | D33: -198.5 | E33: -366.2 | F33: -287.8 | G33: -653
B34: Reclassified to Assets held for sale
B35: Acquisition through business combination | C35: 1244.8 | D35: 978.7 | E35: 4495.6 | F35: 888.3
B36: Disposal of Subsidiary | D36: -2433.1
B37: - Reclasified to Right-of-use assets | C37: -260
B38: Foreign currency translation adjustments | C38: 1856.6 | D38: -66.4 | E38: 475 | F38: 2425.5 | G38: 397.5
B39: Gross Closing | C39: =SUM(C31:C38) -> 25478 | D39: =SUM(D31:D38) -> 27264 | E39: =SUM(E31:E38) -> 34526.7 | F39: =SUM(F31:F38) -> 39924.3 | G39: =SUM(G31:G38) -> 44817.7 | H39: =SUM(H31:H38) -> 50597.685 | I39: =SUM(I31:I38) -> 57123.095 | J39: =SUM(J31:J38) -> 64490.064 | ... Q39: =SUM(Q31:Q38) -> 150751.06
B40: Accumulated depreciation | C40: -2880.9 | D40: -5620.8 | E40: -6683.4 | F40: -11244.4 | G40: -15601.9 | H40: =SUM(G40:G47) -> -21296.4 | I40: =SUM(H40:H47) -> -26845.119 | J40: =SUM(I40:I47) -> -32448.394 | K40: =SUM(J40:J47) -> -38269.203 | L40: =SUM(K40:K47) -> -44454.753 | M40: =SUM(L40:L47) -> -51143.132 | N40: =SUM(M40:M47) -> -58468.753 | O40: =SUM(N40:N47) -> -66566.958 | ... Q40: =SUM(P40:P47) -> -85650.641
B41: Charge for the year | C41: -2358.6 | D41: -2558.9 | E41: -3286.6 | F41: -4042.6 | G41: -5737.7 | H41: =G41/F48*G48 -> -5548.719 | I41: =H41/G48*H48 -> -5603.2751 | J41: =I41/H48*I48 -> -5820.8084 | K41: =J41/I48*J48 -> -6185.5507 | L41: =K41/J48*K48 -> -6688.3784 | M41: =L41/K48*L48 -> -7325.6218 | N41: =M41/L48*M48 -> -8098.2049 | O41: =N41/M48*N48 -> -9011.0424 | ... Q41: =P41/O48*P48 -> -11294.864
B42: Disposals / adjustments | C42: -26.9 | D42: -75.7 | E42: -1175.7 | F42: 576.9 | G42: 252.2
B43: Reclassified to Assets held for sale
B44: Acquisition through business combination | D44: 60.3
B45: Disposal of Subsidiary | D45: 1485.4
B46: Reclasified to Right-of-use assets | C46: 3
B47: Foreign currency translation adjustments | C47: -357.4 | D47: 4.5 | E47: -98.7 | F47: -891.8 | G47: -209
B48: Net other intangible assets | C48: =SUM(C39:C47) -> 19857.2 | D48: 20580.6 | E48: =SUM(E39:E47) -> 23282.3 | F48: =SUM(F39:F47) -> 24322.4 | G48: =SUM(G39:G47) -> 23521.3 | H48: =SUM(H39:H47) -> 23752.566 | I48: =SUM(I39:I47) -> 24674.701 | J48: =SUM(J39:J47) -> 26220.862 | K48: =SUM(K39:K47) -> 28352.374 | L48: =SUM(L39:L47) -> 31053.681 | ... Q48: =SUM(Q39:Q47) -> 53805.558
...

Sheet Income Statement
B6: Income Statement
B8: Particulars | C8: 2020 | D8: =C8+1 -> 2021 | E8: =D8+1 -> 2022 | F8: =E8+1 -> 2023 | G8: =F8+1 -> 2024 | H8: =G8+1 -> 2025 | I8: =H8+1 -> 2026 | J8: =I8+1 -> 2027 | K8: =J8+1 -> 2028 | ... Q8: =P8+1 -> 2034
B10: Revenue | C10: ='Revenue Build_up'!C10 -> 230985.1 | D10: ='Revenue Build_up'!D10 -> 247746.2 | E10: ='Revenue Build_up'!E10 -> 234554.9 | F10: ='Revenue Build_up'!F10 -> 248553.8 | G10: ='Revenue Build_up'!G10 -> 290018.7 | H10: ='Revenue Build_up'!H10 -> 311990.27 | I10: ='Revenue Build_up'!I10 -> 337003.68 | J10: ='Revenue Build_up'!J10 -> 365623.11 | ... Q10: ='Revenue Build_up'!Q10 -> 746951.69
B11: COGS | C11: =-'Cost Build_Up'!C12 -> -97352.3 | D11: =-'Cost Build_Up'!D12 -> -99024.7 | E11: =-'Cost Build_Up'!E12 -> -101402.8 | F11: =-'Cost Build_Up'!F12 -> -112932.6 | G11: =-'Cost Build_Up'!G12 -> -126029 | H11: =-'Cost Build_Up'!H12 -> -133681.69 | I11: =-'Cost Build_Up'!I12 -> -144399.44 | J11: =-'Cost Build_Up'!J12 -> -156662.3 | ... Q11: =-'Cost Build_Up'!Q12 -> -320054.09
B12: Gross Profit | C12: =SUM(C10:C11) -> 133632.8 | D12: =SUM(D10:D11) -> 148721.5 | E12: =SUM(E10:E11) -> 133152.1 | F12: =SUM(F10:F11) -> 135621.2 | G12: =SUM(G10:G11) -> 163989.7 | H12: =SUM(H10:H11) -> 178308.58 | I12: =SUM(I10:I11) -> 192604.24 | J12: =SUM(J10:J11) -> 208960.81 | ... Q12: =SUM(Q10:Q11) -> 426897.6
B13: Gross Margin | C13: =C12/C10 -> 0.57853429 | D13: =D12/D10 -> 0.6002978 | E13: =E12/E10 -> 0.56767989 | F13: =F12/F10 -> 0.54564123 | G13: =G12/G10 -> 0.56544526 | H13: =H12/H10 -> 0.57151969 | I13: =I12/I10 -> 0.57151969 | J13: =J12/J10 -> 0.57151969 | ... Q13: =Q12/Q10 -> 0.57151969
B15: Employee Expenses | C15: =-'Cost Build_Up'!C18 -> -32191.8 | D15: =-'Cost Build_Up'!D18 -> -35350.2 | E15: =-'Cost Build_Up'!E18 -> -34509.2 | F15: =-'Cost Build_Up'!F18 -> -35222.5 | G15: =-'Cost Build_Up'!G18 -> -39229.4 | H15: =-'Cost Build_Up'!H18 -> -44062.744 | I15: =-'Cost Build_Up'!I18 -> -47595.417 | J15: =-'Cost Build_Up'!J18 -> -51637.372 | ... Q15: =-'Cost Build_Up'!Q18 -> -105492.85
B16: S&G expenses | C16: =-'Cost Build_Up'!C21 -> -52797.9 | D16: =-'Cost Build_Up'!D21 -> -60037.3 | E16: =-'Cost Build_Up'!E21 -> -54775.2 | F16: =-'Cost Build_Up'!F21 -> -63212.3 | G16: =-'Cost Build_Up'!G21 -> -66330.3 | H16: =-'Cost Build_Up'!H21 -> -74095.821 | I16: =-'Cost Build_Up'!I21 -> -80036.356 | J16: =-'Cost Build_Up'!J21 -> -86833.3 | ... Q16: =-'Cost Build_Up'!Q21 -> -177396.55
B18: EBITDA | C18: =C12+SUM(C15:C16) -> 48643.1 | D18: =D12+SUM(D15:D16) -> 53334 | E18: =E12+SUM(E15:E16) -> 43867.7 | F18: =F12+SUM(F15:F16) -> 37186.4 | G18: =G12+SUM(G15:G16) -> 58430 | H18: =H12+SUM(H15:H16) -> 60150.019 | I18: =I12+SUM(I15:I16) -> 64972.467 | J18: =J12+SUM(J15:J16) -> 70490.138 | ... Q18: =Q12+SUM(Q15:Q16) -> 144008.2
B19: EBITDA Margin | C19: =C18/C10 -> 0.21058977 | D19: =D18/D10 -> 0.21527676 | E19: =E18/E10 -> 0.1870253 | F19: =F18/F10 -> 0.14961107 | G19: =G18/G10 -> 0.20146977 | H19: =H18/H10 -> 0.19279453 | I19: =I18/I10 -> 0.19279453 | J19: =J18/J10 -> 0.19279453 | ... Q19: =Q18/Q10 -> 0.19279453
B21: D&A | C21: =FAS!C94 -> -9667.1 | D21: =FAS!D94 -> -10553.9 | E21: =FAS!E94 -> -11265.2 | F21: =FAS!F94 -> -12445.8 | G21: =FAS!G94 -> -15216.6 | H21: =FAS!H94 -> -18929.396 | I21: =FAS!I94 -> -19688.906 | J21: =FAS!J94 -> -20646.868 | ... Q21: =FAS!Q94 -> -32449.596
B23: EBIT | C23: =SUM(C18,C21) -> 38976 | D23: =SUM(D18,D21) -> 42780.1 | E23: =SUM(E18,E21) -> 32602.5 | F23: =SUM(F18,F21) -> 24740.6 | G23: =SUM(G18,G21) -> 43213.4 | H23: =SUM(H18,H21) -> 41220.622 | I23: =SUM(I18,I21) -> 45283.561 | J23: =SUM(J18,J21) -> 49843.271 | ... Q23: =SUM(Q18,Q21) -> 111558.61
B24: EBIT Margin | C24: =C23/C10 -> 0.16873816 | D24: =D23/D10 -> 0.17267712 | E24: =E23/E10 -> 0.13899731 | F24: =F23/F10 -> 0.099538209 | G24: =G23/G10 -> 0.14900212 | H24: =H23/H10 -> 0.1321215 | I24: =I23/I10 -> 0.13437112 | J24: =J23/J10 -> 0.13632418 | ... Q24: =Q23/Q10 -> 0.14935184
B26: Interest Cost | C26: =-'P&L'!C18 -> -3051.3 | D26: =-'P&L'!D18 -> -744.9 | E26: =-'P&L'!E18 -> -486.4 | F26: =-'P&L'!F18 -> -1404.8 | G26: =-'P&L'!G18 -> -2897.1 | H26: =-'Debt Schedules'!H14 -> -2054.544 | I26: =-'Debt Schedules'!I14 -> -1335.3664 | J26: =-'Debt Schedules'!J14 -> -1445.7211 | K26: =-'Debt Schedules'!K14 -> -1572.3186 | L26: =-'Debt Schedules'!L14 -> -1718.2613 | M26: =-'Debt Schedules'!M14 -> -1887.3076 | N26: =-'Debt Schedules'!N14 -> -2084.0167 | O26: =-'Debt Schedules'!O14 -> -2313.9249 | ... Q26: =-'Debt Schedules'!Q14 -> -2901.7168
B27: Other Income | C27: ='P&L'!C11 -> 1918.7 | D27: ='P&L'!D11 -> 3808.5 | E27: ='P&L'!E11 -> 3203.5 | F27: ='P&L'!F11 -> 2905.9 | G27: ='P&L'!G11 -> 5573.8 | H27: ='Cost Build_Up'!H27 -> 4258.4774 | I27: ='Cost Build_Up'!I27 -> 4599.8952 | J27: ='Cost Build_Up'!J27 -> 4990.5331 | K27: ='Cost Build_Up'!K27 -> 5439.7006 | L27: ='Cost Build_Up'!L27 -> 5958.668 | M27: ='Cost Build_Up'!M27 -> 6561.0975 | N27: ='Cost Build_Up'!N27 -> 7263.5701 | O27: ='Cost Build_Up'!O27 -> 8086.231 | ... Q27: ='Cost Build_Up'!Q27 -> 10195.436
B28: Share of loss of joint ventures and associates (net of tax) | C28: ='Cost Build_Up'!C34 -> -151.7 | D28: ='Cost Build_Up'!D34 -> -553.6 | E28: ='Cost Build_Up'!E34 -> -312.5 | F28: ='Cost Build_Up'!F34 -> -116.7 | G28: ='Cost Build_Up'!G34 -> -171.6 | H28: ='Cost Build_Up'!H34 -> -329.76185
B29: Exceptional items | C29: ='Cost Build_Up'!C31 -> 261.3 | D29: ='Cost Build_Up'!D31 -> -28145.8 | E29: ='Cost Build_Up'!E31 -> 1279.7 | F29: ='Cost Build_Up'!F31 -> 0 | G29: ='Cost Build_Up'!G31 -> 1918.6 | H29: ='Cost Build_Up'!H31 -> -6265.0673
B30: EBT | C30: =SUM(C23,C26,C27,C28)-C29 -> 37430.4 | D30: =SUM(D23,D26,D27,D28)-D29 -> 73435.9 | E30: =SUM(E23,E26,E27,E28)-E29 -> 33727.4 | F30: =SUM(F23,F26,F27,F28)-F29 -> 26125 | G30: =SUM(G23,G26,G27,G28)-G29 -> 43799.9 | H30: =SUM(H23,H26,H27,H28)-H29 -> 49359.861 | I30: =SUM(I23,I26,I27,I28)-I29 -> 48548.09 | J30: =SUM(J23,J26,J27,J28)-J29 -> 53388.083 | ... Q30: =SUM(Q23,Q26,Q27,Q28)-Q29 -> 118852.33
B31: EBT Margin | C31: =C30/C10 -> 0.16204682 | D31: =D30/D10 -> 0.29641585 | E31: =E30/E10 -> 0.1437932 | F31: =F30/F10 -> 0.10510803 | G31: =G30/G10 -> 0.1510244 | H31: =H30/H10 -> 0.15820962 | I31: =I30/I10 -> 0.14405804 | J31: =J30/J10 -> 0.14601944 | ... Q31: =Q30/Q10 -> 0.15911648
B32: TAX | C32: ='P&L'!C28 -> -8993.5 | D32: ='P&L'!D28 -> -20097.7 | E32: ='P&L'!E28 -> -7256.3 | F32: ='P&L'!F28 -> -6848.5 | G32: ='P&L'!G28 -> -12110.2 | H32: ='Cost Build_Up'!H37 -> -12514.973 | I32: ='Cost Build_Up'!I37 -> -12309.152 | J32: ='Cost Build_Up'!J37 -> -13536.31 | K32: ='Cost Build_Up'!K37 -> -14937.087 | L32: ='Cost Build_Up'!L37 -> -16555.79 | M32: ='Cost Build_Up'!M37 -> -18444.302 | N32: ='Cost Build_Up'!N37 -> -20664.296 | O32: ='Cost Build_Up'!O37 -> -23289.809 | ... Q32: ='Cost Build_Up'!Q37 -> -30134.477
B33: Net Profit | C33: =SUM(C30:C32) -> 28437.062 | D33: =SUM(D30:D32) -> 53338.496 | E33: =SUM(E30:E32) -> 26471.244 | F33: =SUM(F30:F32) -> 19276.605 | G33: =SUM(G30:G32) -> 31689.851 | H33: =SUM(H30:H32) -> 36845.047 | I33: =SUM(I30:I32) -> 36239.082 | J33: =SUM(J30:J32) -> 39851.919 | ... Q33: =SUM(Q30:Q32) -> 88718.009
B34: Net Profit Margin | C34: =C33/C10 -> 0.12311211 | D34: =D33/D10 -> 0.21529491 | E34: =E33/E10 -> 0.11285735 | F34: =F33/F10 -> 0.077555061 | G34: =G33/G10 -> 0.1092683 | H34: =H33/H10 -> 0.11809678 | I34: =I33/I10 -> 0.1075332 | J34: =J33/J10 -> 0.10899726 | ... Q34: =Q33/Q10 -> 0.11877342
B37: EPS in Rs. | C37: =C33/580.8 -> 48.961884 | D37: =D33/580.8 -> 91.836254 | E37: =E33/580.8 -> 45.57721 | F37: =F33/580.8 -> 33.189747 | G37: =G33/580.8 -> 54.562416 | H37: =H33/580.8 -> 63.438442 | I37: =I33/580.8 -> 62.395114 | J37: =J33/580.8 -> 68.615562 | ... Q37: =Q33/580.8 -> 152.75139
B39: Dividend | C39: =CashFlow!C76 -> -1756.1 | D39: =CashFlow!D76 -> -2343.1 | E39: =CashFlow!E76 -> -2637 | F39: =CashFlow!F76 -> -4395.3 | G39: =CashFlow!G76 -> -2636.4 | H39: =-H40*H33 -> -3806.1397 | I39: =-I40*I33 -> -3743.5428 | J39: =-J40*J33 -> -4116.7533 | K39: =-K40*K33 -> -4542.7657 | L39: =-L40*L33 -> -5035.0547 | M39: =-M40*M33 -> -5609.3999 | N39: =-N40*N33 -> -6284.5569 | O39: =-O40*O33 -> -7083.0428 | ... Q39: =-Q40*Q33 -> -9164.682
B40: Dividend Payout % | C40: =-C39/C33 -> 0.061753918 | D40: =-D39/D33 -> 0.043928872 | E40: =-E39/E33 -> 0.099617533 | F40: =-F39/F33 -> 0.22801214 | G40: =-G39/G33 -> 0.083193828 | H40: =AVERAGE(C40:G40) -> 0.10330126 | I40: =H40 -> 0.10330126 | J40: =I40 -> 0.10330126 | K40: =J40 -> 0.10330126 | L40: =K40 -> 0.10330126 | M40: =L40 -> 0.10330126 | N40: =M40 -> 0.10330126 | O40: =N40 -> 0.10330126 | P40: =O40 -> 0.10330126 | Q40: =P40 -> 0.10330126
B42: Retained Earning | C42: =C33+C39 -> 26680.962 | D42: =D33+D39 -> 50995.396 | E42: =E33+E39 -> 23834.244 | F42: =F33+F39 -> 14881.305 | G42: =G33+G39 -> 29053.451 | H42: =H33+H39 -> 33038.907 | I42: =I33+I39 -> 32495.54 | J42: =J33+J39 -> 35735.165 | ... Q42: =Q33+Q39 -> 79553.327
B43: Retained % | C43: =C42/C33 -> 0.93824608 | D43: =D42/D33 -> 0.95607113 | E43: =E42/E33 -> 0.90038247 | F43: =F42/F33 -> 0.77198786 | G43: =G42/G33 -> 0.91680617 | H43: =H42/H33 -> 0.89669874 | I43: =I42/I33 -> 0.89669874 | J43: =J42/J33 -> 0.89669874 | ... Q43: =Q42/Q33 -> 0.89669874

Sheet CashFlow
B6: CashFlow Statement
B8: Particulars | C8: 2020 | D8: =C8+1 -> 2021 | E8: =D8+1 -> 2022 | F8: =E8+1 -> 2023 | G8: =F8+1 -> 2024 | H8: =G8+1 -> 2025 | I8: =H8+1 -> 2026 | J8: =I8+1 -> 2027 | K8: =J8+1 -> 2028 | ... Q8: =P8+1 -> 2034
B9: CASH FLOW FROM OPERATING ACTIVITIES
B10: Net profit before tax | C10: 37430.4 | D10: 73435.9 | E10: 33727.4 | F10: 26125 | G10: 43799.9 | H10: ='Income Statement'!H30 -> 49359.861 | I10: ='Income Statement'!I30 -> 48548.09 | J10: ='Income Statement'!J30 -> 53388.083 | K10: ='Income Statement'!K30 -> 58912.839 | L10: ='Income Statement'!L30 -> 65297.105 | M10: ='Income Statement'!M30 -> 72745.521 | N10: ='Income Statement'!N30 -> 81501.319 | O10: ='Income Statement'!O30 -> 91856.513 | ... Q10: ='Income Statement'!Q30 -> 118852.33
B11: Adjustment
B12: Depreciation, amortisation and impairment expense | C12: 9667.1 | D12: 10553.9 | E12: 11265.2 | F12: 12445.8 | G12: 15216.6 | H12: =-'Income Statement'!H21 -> 18929.396 | I12: =-'Income Statement'!I21 -> 19688.906 | J12: =-'Income Statement'!J21 -> 20646.868 | K12: =-'Income Statement'!K21 -> 21789.069 | L12: =-'Income Statement'!L21 -> 23108.124 | M12: =-'Income Statement'!M21 -> 24602.27 | N12: =-'Income Statement'!N21 -> 26274.5 | O12: =-'Income Statement'!O21 -> 28131.955 | ... Q12: =-'Income Statement'!Q21 -> 32449.596
B13: Allowance for credit losses on trade receivables and other advances(net) | C13: 615.9 | D13: -291.2 | E13: -61.1 | F13: 524.5 | G13: 232.8
B14: Liabilities no longer required written back (net) | C14: -263.2 | D14: -534 | E14: -137.8 | F14: -130.1 | G14: -100.5
B15: Stock written off | C15: 98.1 | D15: 486.8 | E15: 382.8 | F15: 56.8 | G15: 66.8
B16: Bad debts/advances written of | C16: 69.4
B17: Mark-to-market gain on derivative financial instruments (net) | C17: 22.3 | D17: -198.2 | E17: -320.2 | F17: -191.4 | G17: -27
B18: Unrealised foreign exchange gain (net) | C18: -745.6 | D18: -1089.5 | E18: -251.8
B19: Exchange differences on translation of assets and liabilities (net) | F19: 3104.6 | G19: -511.4
B20: Profit on sale of property, plant and equipment (net) | C20: 370.4 | D20: 1411.2 | E20: 1350.2 | F20: -132.3 | G20: -234.9
B21: Write off of intangible assets under development | D21: 4349.2 | E21: -396.3 | F21: 239.6 | G21: 326.2
B22: Share of loss of joint ventures and associates | C22: 151.7 | D22: 553.6 | E22: 312.5 | F22: 116.7 | G22: 171.5
B23: Gain on sale and lease back transactions | E23: 208.2
B24: Profit on sale of subsidiary and acquisition of non-controlling interest | D24: -32495
B25: Loss on liquidation of Joint venture/subsidiary | E25: 26.5
B26: Profit on sale of current investments | E26: -290.8 | G26: -1
B27: Finance costs | C27: 1416.3 | D27: 595.7 | E27: 368.4 | F27: 1289.5 | G27: 2680.9 | H27: =-'Income Statement'!H26 -> 2054.544 | I27: =-'Income Statement'!I26 -> 1335.3664 | J27: =-'Income Statement'!J26 -> 1445.7211 | K27: =-'Income Statement'!K26 -> 1572.3186 | L27: =-'Income Statement'!L26 -> 1718.2613 | M27: =-'Income Statement'!M26 -> 1887.3076 | N27: =-'Income Statement'!N26 -> 2084.0167 | O27: =-'Income Statement'!O26 -> 2313.9249 | ... Q27: =-'Income Statement'!Q26 -> 2901.7168
B28: Interest income | C28: -209.1 | D28: -223.7 | E28: -316 | F28: -1459 | G28: -2857.6 | H28: =-'Income Statement'!H27 -> -4258.4774 | I28: =-'Income Statement'!I27 -> -4599.8952 | J28: =-'Income Statement'!J27 -> -4990.5331 | K28: =-'Income Statement'!K27 -> -5439.7006 | L28: =-'Income Statement'!L27 -> -5958.668 | M28: =-'Income Statement'!M27 -> -6561.0975 | N28: =-'Income Statement'!N27 -> -7263.5701 | O28: =-'Income Statement'!O27 -> -8086.231 | ... Q28: =-'Income Statement'!Q27 -> -10195.436
B29: Effect of exchange rate changes | C29: -281.6 | D29: 254.8 | E29: 1301.5
B31: Operating profit before working capital changes | C31: =SUM(C10:C29) -> 48342.1 | D31: =SUM(D10:D29) -> 56809.5 | E31: =SUM(E10:E29) -> 47168.7 | F31: =SUM(F10:F29) -> 41989.7 | G31: =SUM(G10:G29) -> 58762.3 | H31: =SUM(H10:H29) -> 66085.324 | I31: =SUM(I10:I29) -> 64972.467 | J31: =SUM(J10:J29) -> 70490.138 | ... Q31: =SUM(Q10:Q29) -> 144008.2
B32: Movements in working capital :
B33: Increase in inventories | C33: -5269.8 | D33: -16217.4 | E33: 14975.2 | F33: -9267 | G33: -13036.8 | H33: =Balance_sheet!G29-Balance_sheet!H29 -> -8310.0969 | I33: =Balance_sheet!H29-Balance_sheet!I29 -> -8529.8706 | J33: =Balance_sheet!I29-Balance_sheet!J29 -> -9759.5683 | K33: =Balance_sheet!J29-Balance_sheet!K29 -> -11221.852 | L33: =Balance_sheet!K29-Balance_sheet!L29 -> -12965.711 | M33: =Balance_sheet!L29-Balance_sheet!M29 -> -15050.901 | N33: =Balance_sheet!M29-Balance_sheet!N29 -> -17550.344 | O33: =Balance_sheet!N29-Balance_sheet!O29 -> -20553.087 | ... Q33: =Balance_sheet!P29-Balance_sheet!Q29 -> -28527.778
B34: Increase in trade receivables | C34: -6561.2 | D34: 7440.4 | E34: -4108.4 | F34: -4321.1 | G34: -2641.9 | H34: =Balance_sheet!G32-Balance_sheet!H32 -> -4562.6025 | I34: =Balance_sheet!H32-Balance_sheet!I32 -> -4227.5587 | J34: =Balance_sheet!I32-Balance_sheet!J32 -> -4837.0192 | K34: =Balance_sheet!J32-Balance_sheet!K32 -> -5561.7534 | L34: =Balance_sheet!K32-Balance_sheet!L32 -> -6426.0418 | M34: =Balance_sheet!L32-Balance_sheet!M32 -> -7459.4995 | N34: =Balance_sheet!M32-Balance_sheet!N32 -> -8698.269 | O34: =Balance_sheet!N32-Balance_sheet!O32 -> -10186.483 | ... Q34: =Balance_sheet!P32-Balance_sheet!Q32 -> -14138.884
B35: Increase in other financial assets | C35: 12697.9 | D35: -84.2 | E35: 140.8 | F35: -2204 | G35: -1729.1 | H35: =SUM(Balance_sheet!G35:G39,Balance_sheet!G31)-SUM(Balance_sheet!H31,Balance_sheet!H35:H39) -> 4603.2997 | I35: =SUM(Balance_sheet!H35:H39,Balance_sheet!H31)-SUM(Balance_sheet!I31,Balance_sheet!I35:I39) -> -2278.5602 | J35: =SUM(Balance_sheet!I35:I39,Balance_sheet!I31)-SUM(Balance_sheet!J31,Balance_sheet!J35:J39) -> -2607.0459 | K35: =SUM(Balance_sheet!J35:J39,Balance_sheet!J31)-SUM(Balance_sheet!K31,Balance_sheet!K35:K39) -> -2997.6616 | L35: =SUM(Balance_sheet!K35:K39,Balance_sheet!K31)-SUM(Balance_sheet!L31,Balance_sheet!L35:L39) -> -3463.4938 | M35: =SUM(Balance_sheet!L35:L39,Balance_sheet!L31)-SUM(Balance_sheet!M31,Balance_sheet!M35:M39) -> -4020.5046 | N35: =SUM(Balance_sheet!M35:M39,Balance_sheet!M31)-SUM(Balance_sheet!N31,Balance_sheet!N35:N39) -> -4688.1738 | O35: =SUM(Balance_sheet!N35:N39,Balance_sheet!N31)-SUM(Balance_sheet!O31,Balance_sheet!O35:O39) -> -5490.2881 | ... Q35: =SUM(Balance_sheet!P35:P39,Balance_sheet!P31)-SUM(Balance_sheet!Q31,Balance_sheet!Q35:Q39) -> -7620.5446
B36: Increase in other current/non current assets | C36: -1277.8 | D36: 179.1 | E36: -34.9 | F36: -3549.6 | G36: -6689.7
B37: (Increase)/decrease in loans | C37: -28 | D37: -39 | E37: 25.5 | F37: 10.4 | G37: -6.9
B38: Increase in trade payables | C38: 2958.7 | D38: 1265.4 | E38: 1106.5 | F38: 7076.5 | G38: 5828.4 | H38: ='Working Capital'!H13-'Working Capital'!G13 -> -4179.8923 | I38: ='Working Capital'!I13-'Working Capital'!H13 -> 3235.9469 | J38: ='Working Capital'!J13-'Working Capital'!I13 -> 3702.453 | K38: ='Working Capital'!K13-'Working Capital'!J13 -> 4257.1943 | L38: ='Working Capital'!L13-'Working Capital'!K13 -> 4918.7561 | M38: ='Working Capital'!M13-'Working Capital'!L13 -> 5709.807 | N38: ='Working Capital'!N13-'Working Capital'!M13 -> 6658.012 | O38: ='Working Capital'!O13-'Working Capital'!N13 -> 7797.152 | ... Q38: ='Working Capital'!Q13-'Working Capital'!P13 -> 10822.482
B39: Increase in provisions | C39: 1010.4 | D39: -1736.1 | E39: 145.2 | F39: 217.5 | G39: 985.5
B40: Decrease in other current/non-current liabilities | C40: -779.2 | D40: -1466.8 | E40: 5573.1 | F40: -1240.5 | G40: -2634.3
B41: Increase in other financial liabilities | C41: 328.1 | D41: -7.9 | E41: -2245 | F41: 2328 | G41: 3174.1 | H41: =SUM(Balance_sheet!H67:H68,Balance_sheet!H72:H75)-SUM(Balance_sheet!G67:G68,Balance_sheet!G72:G75) -> 16473.76 | I41: =SUM(Balance_sheet!I67:I68,Balance_sheet!I72:I75)-SUM(Balance_sheet!H67:H68,Balance_sheet!H72:H75) -> 7530.19 | J41: =SUM(Balance_sheet!J67:J68,Balance_sheet!J72:J75)-SUM(Balance_sheet!I67:I68,Balance_sheet!I72:I75) -> 8615.77 | K41: =SUM(Balance_sheet!K67:K68,Balance_sheet!K72:K75)-SUM(Balance_sheet!J67:J68,Balance_sheet!J72:J75) -> 9906.6773 | L41: =SUM(Balance_sheet!L67:L68,Balance_sheet!L72:L75)-SUM(Balance_sheet!K67:K68,Balance_sheet!K72:K75) -> 11446.161 | M41: =SUM(Balance_sheet!M67:M68,Balance_sheet!M72:M75)-SUM(Balance_sheet!L67:L68,Balance_sheet!L72:L75) -> 13286.971 | N41: =SUM(Balance_sheet!N67:N68,Balance_sheet!N72:N75)-SUM(Balance_sheet!M67:M68,Balance_sheet!M72:M75) -> 15493.485 | O41: =SUM(Balance_sheet!O67:O68,Balance_sheet!O72:O75)-SUM(Balance_sheet!N67:N68,Balance_sheet!N72:N75) -> 18144.314 | ... Q41: =SUM(Balance_sheet!Q67:Q68,Balance_sheet!Q72:Q75)-SUM(Balance_sheet!P67:P68,Balance_sheet!P72:P75) -> 25184.39
B43: Cash generated from operating activities | C43: =SUM(C31:C41) -> 51421.2 | D43: =SUM(D31:D41) -> 46143 | E43: =SUM(E31:E41) -> 62746.7 | F43: =SUM(F31:F41) -> 31039.9 | G43: =SUM(G31:G41) -> 42011.6 | H43: =SUM(H31:H41) -> 70109.792 | I43: =SUM(I31:I41) -> 60702.615 | J43: =SUM(J31:J41) -> 65604.728 | ... Q43: =SUM(Q31:Q41) -> 129727.87
B44: Direct taxes paid (net of refunds) | C44: -7608.4 | D44: -12852.5 | E44: -12581.9 | F44: -7172.4 | G44: -17666.4 | H44: ='Income Statement'!H32 -> -12514.973 | I44: ='Income Statement'!I32 -> -12309.152 | J44: ='Income Statement'!J32 -> -13536.31 | K44: ='Income Statement'!K32 -> -14937.087 | L44: ='Income Statement'!L32 -> -16555.79 | M44: ='Income Statement'!M32 -> -18444.302 | N44: ='Income Statement'!N32 -> -20664.296 | O44: ='Income Statement'!O32 -> -23289.809 | ... Q44: ='Income Statement'!Q32 -> -30134.477
B46: Net cash generated from operating activities | C46: =SUM(C43:C44) -> 43812.8 | D46: =SUM(D43:D44) -> 33290.5 | E46: =SUM(E43:E44) -> 50164.8 | F46: =SUM(F43:F44) -> 23867.5 | G46: =SUM(G43:G44) -> 24345.2 | H46: =SUM(H43:H44) -> 57594.82 | I46: =SUM(I43:I44) -> 48393.463 | J46: =SUM(J43:J44) -> 52068.418 | ... Q46: =SUM(Q43:Q44) -> 99593.392
B48: CASH FLOW FROM INVESTING ACTIVITIES
B49: Purchase of property, plant and equipment, including movement in capital work- in- progress, capital advances and capital creditors | C49: -13827.5 | D49: -14379.4 | E49: -20529.1 | F49: -24038 | G49: -27803.3 | H49: =-(FAS!H100+Balance_sheet!H16-Balance_sheet!G16+Balance_sheet!H17-Balance_sheet!G17) -> -15892.956 | I49: =-(FAS!I100+Balance_sheet!I16-Balance_sheet!H16+Balance_sheet!I17-Balance_sheet!H17) -> -30152.514 | J49: =-(FAS!J100+Balance_sheet!J16-Balance_sheet!I16+Balance_sheet!J17-Balance_sheet!I17) -> -32346.122 | K49: =-(FAS!K100+Balance_sheet!K16-Balance_sheet!J16+Balance_sheet!K17-Balance_sheet!J17) -> -34732.751 | L49: =-(FAS!L100+Balance_sheet!L16-Balance_sheet!K16+Balance_sheet!L17-Balance_sheet!K17) -> -37332.293 | M49: =-(FAS!M100+Balance_sheet!M16-Balance_sheet!L16+Balance_sheet!M17-Balance_sheet!L17) -> -40166.908 | N49: =-(FAS!N100+Balance_sheet!N16-Balance_sheet!M16+Balance_sheet!N17-Balance_sheet!M17) -> -43261.293 | O49: =-(FAS!O100+Balance_sheet!O16-Balance_sheet!N16+Balance_sheet!O17-Balance_sheet!N17) -> -46642.989 | ... Q49: =-(FAS!Q100+Balance_sheet!Q16-Balance_sheet!P16+Balance_sheet!Q17-Balance_sheet!P17) -> -54394.804
B50: Purchase of intangible assets and intangible assets under development | C50: -483.4 | D50: -4358.7 | E50: -6517.3 | F50: -3166 | G50: -7811.7
...

Sheet BalanceSheet Forecast
B6: Balance Sheet Forecast
B8: Particulars | C8: 2020 | D8: =C8+1 -> 2021 | E8: =D8+1 -> 2022 | F8: =E8+1 -> 2023 | G8: =F8+1 -> 2024 | H8: =G8+1 -> 2025 | I8: =H8+1 -> 2026 | J8: =I8+1 -> 2027 | K8: =J8+1 -> 2028 | ... Q8: =P8+1 -> 2034
B10: Non-current assets
B11: Investments | C11: =Balance_sheet!C19 -> 1450.8 | D11: =Balance_sheet!D19 -> 3365.2 | E11: =Balance_sheet!E19 -> 5389.5 | F11: =Balance_sheet!F19 -> 3017.4 | G11: =Balance_sheet!G19 -> 2268.7 | H11: =H12*'Revenue Build_up'!H$10 -> 3918.8579 | I11: =I12*'Revenue Build_up'!I$10 -> 4233.0472 | J11: =J12*'Revenue Build_up'!J$10 -> 4592.5312 | K11: =K12*'Revenue Build_up'!K$10 -> 5005.8769 | L11: =L12*'Revenue Build_up'!L$10 -> 5483.456 | M11: =M12*'Revenue Build_up'!M$10 -> 6037.8409 | N11: =N12*'Revenue Build_up'!N$10 -> 6684.2903 | O11: =O12*'Revenue Build_up'!O$10 -> 7441.3428 | ... Q11: =Q12*'Revenue Build_up'!Q$10 -> 9382.3361
B12: % of Revenue | C12: =C11/'Revenue Build_up'!C$10 -> 0.0062809246 | D12: =D11/'Revenue Build_up'!D$10 -> 0.013583256 | E12: =E11/'Revenue Build_up'!E$10 -> 0.022977563 | F12: =F11/'Revenue Build_up'!F$10 -> 0.012139826 | G12: =G11/'Revenue Build_up'!G$10 -> 0.007822599 | H12: =AVERAGE(C12:G12) -> 0.012560834 | I12: =H12 -> 0.012560834 | J12: =I12 -> 0.012560834 | K12: =J12 -> 0.012560834 | L12: =K12 -> 0.012560834 | M12: =L12 -> 0.012560834 | N12: =M12 -> 0.012560834 | O12: =N12 -> 0.012560834 | P12: =O12 -> 0.012560834 | Q12: =P12 -> 0.012560834
B13: =Balance_sheet!B20 -> Loans | C13: =Balance_sheet!C20 -> 58.4 | D13: =Balance_sheet!D20 -> 72.6 | E13: =Balance_sheet!E20 -> 63.2 | F13: =Balance_sheet!F20 -> 55.7 | G13: =Balance_sheet!G20 -> 58.3 | H13: =H14*'Revenue Build_up'!H$10 -> 77.400816 | I13: =I14*'Revenue Build_up'!I$10 -> 83.606325 | J13: =J14*'Revenue Build_up'!J$10 -> 90.706442 | K13: =K14*'Revenue Build_up'!K$10 -> 98.870376 | L13: =L14*'Revenue Build_up'!L$10 -> 108.30297 | M13: =M14*'Revenue Build_up'!M$10 -> 119.25255 | N13: =N14*'Revenue Build_up'!N$10 -> 132.02049 | O13: =O14*'Revenue Build_up'!O$10 -> 146.97292 | ... Q13: =Q14*'Revenue Build_up'!Q$10 -> 185.30921
B14: % of Revenue | C14: =C13/'Revenue Build_up'!C$10 -> 0.00025283016 | D14: =D13/'Revenue Build_up'!D$10 -> 0.00029304183 | E14: =E13/'Revenue Build_up'!E$10 -> 0.00026944651 | F14: =F13/'Revenue Build_up'!F$10 -> 0.00022409635 | G14: =G13/'Revenue Build_up'!G$10 -> 0.00020102152 | H14: =AVERAGE(C14:G14) -> 0.00024808728 | I14: =H14 -> 0.00024808728 | J14: =I14 -> 0.00024808728 | K14: =J14 -> 0.00024808728 | L14: =K14 -> 0.00024808728 | M14: =L14 -> 0.00024808728 | N14: =M14 -> 0.00024808728 | O14: =N14 -> 0.00024808728 | P14: =O14 -> 0.00024808728 | Q14: =P14 -> 0.00024808728
B15: =Balance_sheet!B21 -> Other financial assets | C15: =Balance_sheet!C21 -> 1170.3 | D15: =Balance_sheet!D21 -> 1433 | E15: =Balance_sheet!E21 -> 1289.2 | F15: =Balance_sheet!F21 -> 1503.7 | G15: =Balance_sheet!G21 -> 3510 | H15: =H16*'Revenue Build_up'!H$10 -> 2152.7041 | I15: =I16*'Revenue Build_up'!I$10 -> 2325.2943 | J15: =J16*'Revenue Build_up'!J$10 -> 2522.7657 | K15: =K16*'Revenue Build_up'!K$10 -> 2749.8245 | L15: =L16*'Revenue Build_up'!L$10 -> 3012.1679 | M15: =M16*'Revenue Build_up'!M$10 -> 3316.7022 | N15: =N16*'Revenue Build_up'!N$10 -> 3671.8093 | O15: =O16*'Revenue Build_up'!O$10 -> 4087.6728 | ... Q15: =Q16*'Revenue Build_up'!Q$10 -> 5153.8977
B16: % of Revenue | C16: =C15/'Revenue Build_up'!C$10 -> 0.0050665606 | D16: =D15/'Revenue Build_up'!D$10 -> 0.0057841452 | E16: =E15/'Revenue Build_up'!E$10 -> 0.0054963678 | F16: =F15/'Revenue Build_up'!F$10 -> 0.0060497969 | G16: =G15/'Revenue Build_up'!G$10 -> 0.012102668 | H16: =AVERAGE(C16:G16) -> 0.0068999077 | I16: =H16 -> 0.0068999077 | J16: =I16 -> 0.0068999077 | K16: =J16 -> 0.0068999077 | L16: =K16 -> 0.0068999077 | M16: =L16 -> 0.0068999077 | N16: =M16 -> 0.0068999077 | O16: =N16 -> 0.0068999077 | P16: =O16 -> 0.0068999077 | Q16: =P16 -> 0.0068999077
B17: =Balance_sheet!B22 -> Deferred tax assets (net | C17: =Balance_sheet!C22 -> 1632 | D17: =Balance_sheet!D22 -> 4526.8 | E17: =Balance_sheet!E22 -> 2885.9 | F17: =Balance_sheet!F22 -> 6774.9 | G17: =Balance_sheet!G22 -> 12126.4 | H17: =H18*'Revenue Build_up'!H$10 -> 6658.5462 | I17: =I18*'Revenue Build_up'!I$10 -> 7192.3864 | J17: =J18*'Revenue Build_up'!J$10 -> 7803.187 | K17: =K18*'Revenue Build_up'!K$10 -> 8505.5042 | L17: =L18*'Revenue Build_up'!L$10 -> 9316.9606 | M17: =M18*'Revenue Build_up'!M$10 -> 10258.918 | N17: =N18*'Revenue Build_up'!N$10 -> 11357.303 | O17: =O18*'Revenue Build_up'!O$10 -> 12643.614 | ... Q17: =Q18*'Revenue Build_up'!Q$10 -> 15941.562
B18: % of Revenue | C18: =C17/'Revenue Build_up'!C$10 -> 0.0070653908 | D18: =D17/'Revenue Build_up'!D$10 -> 0.018271925 | E18: =E17/'Revenue Build_up'!E$10 -> 0.012303729 | F18: =F17/'Revenue Build_up'!F$10 -> 0.027257278 | G18: =G17/'Revenue Build_up'!G$10 -> 0.041812476 | H18: =AVERAGE(C18:G18) -> 0.02134216 | I18: =H18 -> 0.02134216 | J18: =I18 -> 0.02134216 | K18: =J18 -> 0.02134216 | L18: =K18 -> 0.02134216 | M18: =L18 -> 0.02134216 | N18: =M18 -> 0.02134216 | O18: =N18 -> 0.02134216 | P18: =O18 -> 0.02134216 | Q18: =P18 -> 0.02134216
B19: =Balance_sheet!B23 -> Non-current tax assets (net) | C19: =Balance_sheet!C23 -> 845.3 | D19: =Balance_sheet!D23 -> 1282.6 | E19: =Balance_sheet!E23 -> 3189.7 | F19: =Balance_sheet!F23 -> 2885.2 | G19: =Balance_sheet!G23 -> 3832.9 | H19: =H20*'Revenue Build_up'!H$10 -> 2948.9045 | I19: =I20*'Revenue Build_up'!I$10 -> 3185.329 | J19: =J20*'Revenue Build_up'!J$10 -> 3455.8374 | K19: =K20*'Revenue Build_up'!K$10 -> 3766.8762 | L19: =L20*'Revenue Build_up'!L$10 -> 4126.2501 | M19: =M20*'Revenue Build_up'!M$10 -> 4543.4196 | N19: =N20*'Revenue Build_up'!N$10 -> 5029.8669 | O19: =O20*'Revenue Build_up'!O$10 -> 5599.5419 | ... Q19: =Q20*'Revenue Build_up'!Q$10 -> 7060.1214
B20: % of Revenue | C20: =C19/'Revenue Build_up'!C$10 -> 0.0036595434 | D20: =D19/'Revenue Build_up'!D$10 -> 0.0051770723 | E20: =E19/'Revenue Build_up'!E$10 -> 0.013598948 | F20: =F19/'Revenue Build_up'!F$10 -> 0.01160795 | G20: =G19/'Revenue Build_up'!G$10 -> 0.013216044 | H20: =AVERAGE(C20:G20) -> 0.0094519116 | I20: =H20 -> 0.0094519116 | J20: =I20 -> 0.0094519116 | K20: =J20 -> 0.0094519116 | L20: =K20 -> 0.0094519116 | M20: =L20 -> 0.0094519116 | N20: =M20 -> 0.0094519116 | O20: =N20 -> 0.0094519116 | P20: =O20 -> 0.0094519116 | Q20: =P20 -> 0.0094519116
B21: =Balance_sheet!B24 -> Other non-current asset | C21: =Balance_sheet!C24 -> 2075.5 | D21: =Balance_sheet!D24 -> 4326.5 | E21: =Balance_sheet!E24 -> 1586.4 | F21: =Balance_sheet!F24 -> 4169.3 | G21: =Balance_sheet!G24 -> 2299.6 | H21: =H22*'Revenue Build_up'!H$10 -> 3613.8265 | I21: =I22*'Revenue Build_up'!I$10 -> 3903.5603 | J21: =J22*'Revenue Build_up'!J$10 -> 4235.0632 | K21: =K22*'Revenue Build_up'!K$10 -> 4616.2354 | L21: =L22*'Revenue Build_up'!L$10 -> 5056.6412 | M21: =M22*'Revenue Build_up'!M$10 -> 5567.8746 | N21: =N22*'Revenue Build_up'!N$10 -> 6164.0065 | O21: =O22*'Revenue Build_up'!O$10 -> 6862.1324 | ... Q21: =Q22*'Revenue Build_up'!Q$10 -> 8652.0449
B22: % of Revenue | C22: =C21/'Revenue Build_up'!C$10 -> 0.0089854281 | D22: =D21/'Revenue Build_up'!D$10 -> 0.017463436 | E22: =E21/'Revenue Build_up'!E$10 -> 0.0067634486 | F22: =F21/'Revenue Build_up'!F$10 -> 0.016774236 | G22: =G21/'Revenue Build_up'!G$10 -> 0.0079291439 | H22: =AVERAGE(C22:G22) -> 0.011583138 | I22: =H22 -> 0.011583138 | J22: =I22 -> 0.011583138 | K22: =J22 -> 0.011583138 | L22: =K22 -> 0.011583138 | M22: =L22 -> 0.011583138 | N22: =M22 -> 0.011583138 | O22: =N22 -> 0.011583138 | P22: =O22 -> 0.011583138 | Q22: =P22 -> 0.011583138
B25: Current assets
B26: =Balance_sheet!B31 -> Investments | C26: =Balance_sheet!C31 -> 0.2 | D26: =Balance_sheet!D31 -> 1597.9 | E26: =Balance_sheet!E31 -> 3788.5 | F26: =Balance_sheet!F31 -> 1510 | G26: =Balance_sheet!G31 -> 505.8 | H26: =H27*'Revenue Build_up'!H$10 -> 1898.2517 | I26: =I27*'Revenue Build_up'!I$10 -> 2050.4416 | J26: =J27*'Revenue Build_up'!J$10 -> 2224.5716 | K26: =K27*'Revenue Build_up'!K$10 -> 2424.7918 | L26: =L27*'Revenue Build_up'!L$10 -> 2656.1258 | M26: =M27*'Revenue Build_up'!M$10 -> 2924.6638 | N26: =N27*'Revenue Build_up'!N$10 -> 3237.7968 | O26: =O27*'Revenue Build_up'!O$10 -> 3604.5047 | ... Q26: =Q27*'Revenue Build_up'!Q$10 -> 4544.7005
B27: % of Revenue | C27: =C26/'Revenue Build_up'!C$10 -> 8.6585672e-07 | D27: =D26/'Revenue Build_up'!D$10 -> 0.0064497457 | E27: =E26/'Revenue Build_up'!E$10 -> 0.016151869 | F27: =F26/'Revenue Build_up'!F$10 -> 0.0060751435 | G27: =G26/'Revenue Build_up'!G$10 -> 0.0017440255 | H27: =AVERAGE(C27:G27) -> 0.0060843299 | I27: =H27 -> 0.0060843299 | J27: =I27 -> 0.0060843299 | K27: =J27 -> 0.0060843299 | L27: =K27 -> 0.0060843299 | M27: =L27 -> 0.0060843299 | N27: =M27 -> 0.0060843299 | O27: =N27 -> 0.0060843299 | P27: =O27 -> 0.0060843299 | Q27: =P27 -> 0.0060843299
B28: =Balance_sheet!B35 -> Loans | C28: =Balance_sheet!C35 -> 136.8 | D28: =Balance_sheet!D35 -> 143.2 | E28: =Balance_sheet!E35 -> 127.1 | F28: =Balance_sheet!F35 -> 124.3 | G28: =Balance_sheet!G35 -> 128.6 | H28: =H29*'Revenue Build_up'!H$10 -> 165.7072 | I28: =I29*'Revenue Build_up'!I$10 -> 178.99256 | J28: =J29*'Revenue Build_up'!J$10 -> 194.19318 | K28: =K29*'Revenue Build_up'!K$10 -> 211.67132 | L28: =L29*'Revenue Build_up'!L$10 -> 231.86554 | M28: =M29*'Revenue Build_up'!M$10 -> 255.30747 | N28: =N29*'Revenue Build_up'!N$10 -> 282.6423 | O28: =O29*'Revenue Build_up'!O$10 -> 314.65394 | ... Q28: =Q29*'Revenue Build_up'!Q$10 -> 396.72799
B29: % of Revenue | C29: =C28/'Revenue Build_up'!C$10 -> 0.00059224599 | D29: =D28/'Revenue Build_up'!D$10 -> 0.00057801088 | E29: =E28/'Revenue Build_up'!E$10 -> 0.0005418774 | F29: =F28/'Revenue Build_up'!F$10 -> 0.00050009294 | G29: =G28/'Revenue Build_up'!G$10 -> 0.00044341968 | H29: =AVERAGE(C29:G29) -> 0.00053112938 | I29: =H29 -> 0.00053112938 | J29: =I29 -> 0.00053112938 | K29: =J29 -> 0.00053112938 | L29: =K29 -> 0.00053112938 | M29: =L29 -> 0.00053112938 | N29: =M29 -> 0.00053112938 | O29: =N29 -> 0.00053112938 | P29: =O29 -> 0.00053112938 | Q29: =P29 -> 0.00053112938
B30: =Balance_sheet!B36 -> Other financial assets | C30: =Balance_sheet!C36 -> 400.8 | D30: =Balance_sheet!D36 -> 338.7 | E30: =Balance_sheet!E36 -> 709.1 | F30: =Balance_sheet!F36 -> 2903.5 | G30: =Balance_sheet!G36 -> 2631.1 | H30: =H31*'Revenue Build_up'!H$10 -> 1677.2113 | I30: =I31*'Revenue Build_up'!I$10 -> 1811.6795 | J30: =J31*'Revenue Build_up'!J$10 -> 1965.5331 | K30: =K31*'Revenue Build_up'!K$10 -> 2142.4388 | L30: =L31*'Revenue Build_up'!L$10 -> 2346.8353 | M30: =M31*'Revenue Build_up'!M$10 -> 2584.1036 | N30: =N31*'Revenue Build_up'!N$10 -> 2860.774 | O30: =O31*'Revenue Build_up'!O$10 -> 3184.7809 | ... Q30: =Q31*'Revenue Build_up'!Q$10 -> 4015.4963
B31: % of Revenue | C31: =C30/'Revenue Build_up'!C$10 -> 0.0017351769 | D31: =D30/'Revenue Build_up'!D$10 -> 0.0013671249 | E31: =E30/'Revenue Build_up'!E$10 -> 0.0030231728 | F31: =F30/'Revenue Build_up'!F$10 -> 0.011681576 | G31: =G30/'Revenue Build_up'!G$10 -> 0.0090721736 | H31: =AVERAGE(C31:G31) -> 0.0053758448 | I31: =H31 -> 0.0053758448 | J31: =I31 -> 0.0053758448 | K31: =J31 -> 0.0053758448 | L31: =K31 -> 0.0053758448 | M31: =L31 -> 0.0053758448 | N31: =M31 -> 0.0053758448 | O31: =N31 -> 0.0053758448 | P31: =O31 -> 0.0053758448 | Q31: =P31 -> 0.0053758448
B32: =Balance_sheet!B37 -> Current tax assets (net | C32: =Balance_sheet!C37 -> 157.6 | D32: =Balance_sheet!D37 -> 789.8 | E32: =Balance_sheet!E37 -> 2699.9 | F32: =Balance_sheet!F37 -> 756.2 | G32: =Balance_sheet!G37 -> 56.7 | H32: =H33*'Revenue Build_up'!H$10 -> 1161.7817 | I32: =I33*'Revenue Build_up'!I$10 -> 1254.926 | J32: =J33*'Revenue Build_up'!J$10 -> 1361.4984 | K32: =K33*'Revenue Build_up'!K$10 -> 1484.0386 | L32: =L33*'Revenue Build_up'!L$10 -> 1625.6213 | M32: =M33*'Revenue Build_up'!M$10 -> 1789.9738 | N32: =N33*'Revenue Build_up'!N$10 -> 1981.6197 | O32: =O33*'Revenue Build_up'!O$10 -> 2206.055 | ... Q32: =Q33*'Revenue Build_up'!Q$10 -> 2781.4804
B33: % of Revenue | C33: =C32/'Revenue Build_up'!C$10 -> 0.00068229509 | D33: =D32/'Revenue Build_up'!D$10 -> 0.0031879399 | E33: =E32/'Revenue Build_up'!E$10 -> 0.011510738 | F33: =F32/'Revenue Build_up'!F$10 -> 0.0030423997 | G33: =G32/'Revenue Build_up'!G$10 -> 0.00019550463 | H33: =AVERAGE(C33:G33) -> 0.0037237755 | I33: =H33 -> 0.0037237755 | J33: =I33 -> 0.0037237755 | K33: =J33 -> 0.0037237755 | L33: =K33 -> 0.0037237755 | M33: =L33 -> 0.0037237755 | N33: =M33 -> 0.0037237755 | O33: =N33 -> 0.0037237755 | P33: =O33 -> 0.0037237755 | Q33: =P33 -> 0.0037237755
B34: =Balance_sheet!B38 -> Other current assets | C34: =Balance_sheet!C38 -> 14857.9 | D34: =Balance_sheet!D38 -> 14488.1 | E34: =Balance_sheet!E38 -> 15550.1 | F34: =Balance_sheet!F38 -> 18687 | G34: =Balance_sheet!G38 -> 25364.3 | H34: =H35*'Revenue Build_up'!H$10 -> 21947.907 | I34: =I35*'Revenue Build_up'!I$10 -> 23707.552 | J34: =J35*'Revenue Build_up'!J$10 -> 25720.874 | K34: =K35*'Revenue Build_up'!K$10 -> 28035.853 | L34: =L35*'Revenue Build_up'!L$10 -> 30710.576 | M34: =M35*'Revenue Build_up'!M$10 -> 33815.457 | N34: =N35*'Revenue Build_up'!N$10 -> 37435.954 | O34: =O35*'Revenue Build_up'!O$10 -> 41675.893 | ... Q34: =Q35*'Revenue Build_up'!Q$10 -> 52546.596
B35: % of Revenue | C35: =C34/'Revenue Build_up'!C$10 -> 0.064324062 | D35: =D34/'Revenue Build_up'!D$10 -> 0.058479605 | E35: =E34/'Revenue Build_up'!E$10 -> 0.066296206 | F35: =F34/'Revenue Build_up'!F$10 -> 0.075182918 | G35: =G34/'Revenue Build_up'!G$10 -> 0.087457464 | H35: =AVERAGE(C35:G35) -> 0.070348051 | I35: =H35 -> 0.070348051 | J35: =I35 -> 0.070348051 | K35: =J35 -> 0.070348051 | L35: =K35 -> 0.070348051 | M35: =L35 -> 0.070348051 | N35: =M35 -> 0.070348051 | O35: =N35 -> 0.070348051 | P35: =O35 -> 0.070348051 | Q35: =P35 -> 0.070348051
B36: =Balance_sheet!B39 -> Assets held for sale | C36: =Balance_sheet!C39 -> 0 | D36: =Balance_sheet!D39 -> 836.1 | E36: =Balance_sheet!E39 -> 791 | F36: =Balance_sheet!F39 -> 857.6 | G36: =Balance_sheet!G39 -> 4337.1 | H36: =H37*'Revenue Build_up'!H$10 -> 1569.441 | I36: =I37*'Revenue Build_up'!I$10 -> 1695.2688 | J36: =J37*'Revenue Build_up'!J$10 -> 1839.2365 | K36: =K37*'Revenue Build_up'!K$10 -> 2004.775 | L36: =L37*'Revenue Build_up'!L$10 -> 2196.0379 | M36: =M37*'Revenue Build_up'!M$10 -> 2418.0603 | N36: =N37*'Revenue Build_up'!N$10 -> 2676.9532 | O36: =O37*'Revenue Build_up'!O$10 -> 2980.1408 | ... Q36: =Q37*'Revenue Build_up'!Q$10 -> 3757.4781
B37: % of Revenue | C37: =C36/'Revenue Build_up'!C$10 -> 0 | D37: =D36/'Revenue Build_up'!D$10 -> 0.0033748247 | E37: =E36/'Revenue Build_up'!E$10 -> 0.0033723448 | F37: =F36/'Revenue Build_up'!F$10 -> 0.0034503596 | G37: =G36/'Revenue Build_up'!G$10 -> 0.014954553 | H37: =AVERAGE(C37:G37) -> 0.0050304164 | I37: =H37 -> 0.0050304164 | J37: =I37 -> 0.0050304164 | K37: =J37 -> 0.0050304164 | L37: =K37 -> 0.0050304164 | M37: =L37 -> 0.0050304164 | N37: =M37 -> 0.0050304164 | O37: =N37 -> 0.0050304164 | P37: =O37 -> 0.0050304164 | Q37: =P37 -> 0.0050304164
B39: Non-current liabilities
B40: =Balance_sheet!B56 -> Borrowings | C40: =Balance_sheet!C56 -> 0 | D40: =Balance_sheet!D56 -> 1684.9 | E40: =Balance_sheet!E56 -> 2492.1 | F40: =Balance_sheet!F56 -> 6189.6 | G40: =Balance_sheet!G56 -> 21349 | H40: =H41*'Revenue Build_up'!H$10 -> 7234.472 | I40: =I41*'Revenue Build_up'!I$10 -> 7814.4862 | J40: =J41*'Revenue Build_up'!J$10 -> 8478.1175 | K40: =K41*'Revenue Build_up'!K$10 -> 9241.1812 | L40: =L41*'Revenue Build_up'!L$10 -> 10122.824 | M40: =M41*'Revenue Build_up'!M$10 -> 11146.255 | N40: =N41*'Revenue Build_up'!N$10 -> 12339.644 | O40: =O41*'Revenue Build_up'!O$10 -> 13737.213 | ... Q40: =Q41*'Revenue Build_up'!Q$10 -> 17320.415
B41: % of Revenue | C41: =C40/'Revenue Build_up'!C$10 -> 0 | D41: =D40/'Revenue Build_up'!D$10 -> 0.0068009116 | E41: =E40/'Revenue Build_up'!E$10 -> 0.010624805 | F41: =F40/'Revenue Build_up'!F$10 -> 0.024902456 | G41: =G40/'Revenue Build_up'!G$10 -> 0.073612495 | H41: =AVERAGE(C41:G41) -> 0.023188133 | I41: =H41 -> 0.023188133 | J41: =I41 -> 0.023188133 | K41: =J41 -> 0.023188133 | L41: =K41 -> 0.023188133 | M41: =L41 -> 0.023188133 | N41: =M41 -> 0.023188133 | O41: =N41 -> 0.023188133 | P41: =O41 -> 0.023188133 | Q41: =P41 -> 0.023188133
