Workbook

Sheet Assumption
B7: Scenario Manager | E7: Company Name | F7: Happiest Minds Technologies Ltd
B8: Base Case | C8: =IF(B8="Best Case",1,IF(B8="Base Case",2,3)) -> 2 | E8: ISIN Code | F8: INE419U01012
E9: Sector Name | F9: IT-Software
B10: Assumptions | E10: Industry | F10: Computers - Software & Consulting
B11: Transaction Date | C11: 46030 | E11: Exchange Name | F11: BSE: 543227 | NSE: HAPPSTMNDS
B12: Fiscal Year End | C12: 46112 | E12: Website | F12: happiestminds.com
B13: Risk Free Rate | C13: 0.06615 | E13: Company Description | F13: Happiest Minds Technologies Ltd. is a next-generation IT solutions and services company that was founded in 2011. It specializes in infrastructure management and security services, generative artificial intelligence, and product and digital engineering. It operates in the United States, United Kingdom, Canada, Australia, and the Middle East, with its headquarters located in Bengaluru, India. Clientele The company now has 281 active clients as of FY25, up from 206 in FY22. Of these, 85 are listed within the Fortune 2000 and Forbes 200 list of billion-dollar companies. Repeat business accounts for 94% of its revenue. In FY26 and beyond, the business anticipates robust double-digit organic growth.
B14: Addition In FSA | C14: 0.005
B15: Addition In Tax rate / 2 years | C15: 0.005
B16: Addition In Dep | C16: 0.005
B17: Tax Rate | C17: ='Cost Buildup'!G23 -> 0.27714711
B18: EV/EBITDA Multiple | C18: ='Comparable Valuation'!E36 -> 15.505377
B19: Perpetual Growth Rate | C19: 0.06
B20: Discount Rate | C20: ='Comps Beta'!F51 -> 0.12988112
B21: Shares Outstanding(Lakhs) | C21: ='Comparable Valuation'!F31 -> 1523
B22: Current Market Price | C22: 459
B23: Market Cap (Lakhs.) | C23: =C22*C21 -> 699057
B25: Colour Code
B26: Blue colour | C26: Hardcoded Figures
B27: Black colour | C27: Calculated Figures
B28: Green Colour | C28: Link Data figures
B31: Items | C31: Sheet | E31: Reference | F31: Assumptions
B33: Revenue Segment by Geography | C33: Revenue Buildup | D33: B13:Q54 | F33: For the forecasted year, the base growth rate is calculated as the average of the historical years. Best- and worst-case scenarios are set at ±5% around this base. Revenue is segmented across USA, India, Europe, and Other countries. A uniform annual tapering rate ( 14%) is applied across all segments, calibrated such that the highest revenue segment converges to the perpetual growth rate of 6%. This annual tapering also ensures that total company revenue gradually reaches the same perpetual growth rate of 6% over the forecast period.
B35: Revenue of India | C35: Revenue Buildup | D35: B15:Q23 | F35: India revenue growth is based on the average historical growth rate (from 2023-2025) for base case, with ±5% variation for best and Worst cases, and an annual tapering of 14% applied over the forecast period.
B36: Revenue of USA | C36: Revenue Buildup | D36: B26:Q34 | F36: USA revenue growth is based on the average historical growth rate for base case, with ±5% variation for best and Worst cases, and an annual tapering of 14% applied over the forecast period that reached at the perpetual growth rate of 6 %.
B37: Revenue of Europe | C37: Revenue Buildup | D37: B36:Q44 | F37: Europe revenue growth is based on the average historical growth rate(From 2023 to 2025) for base case, with ±5% variation for best and Worst cases, and an annual tapering of 14% applied over the forecast period.
B38: Revenue of Others | C38: Revenue Buildup | D38: B46:Q54 | F38: Historical revenue growth for other countries is highly irregular. therefore, a normalized growth rate of 25% is assumed for the forecast year, with an annual tapering of 14% applied to gradually converge to the perpetual growth rate.
B39: Total Revenue | C39: Revenue Buildup | D39: G6 | F39: The Segment wise total revenue and the total Revenue in Annual Report is differ by 1 in the year 2025, so in this case I take the P&L statement Revenue.
B40: Exceptional Items | C40: Revenue Buildup | D40: B37:Q38 | F40: exceptional Items Taken as a percentage of revenue. For forecasted years (2026–2035), derived from the historical average of 2021–2025.
B41: Other Income | C41: Revenue Buildup | D41: B33:Q34 | F41: Other Income: Taken as a percentage of revenue. For forecasted years (2026–2035), derived from the historical average of 2021–2025.
B43: Other Expenses | C43: Cost Build_up | D43: B15:Q16 | F43: The first five years show actual historical percentages of revenue. For the forecasted period (2026–2035), other expenses are assumed based on the average percentage of revenue from 2021–2025, stabilizing around 17% and increasing proportionally with revenue growth.
B47: Perpetual Growth Rate | C47: Assumptions | D47: C20 | F47: For calculating the Terminal Value in the DCF model, a perpetual growth rate of 6% has been assumed. This is aligned with India’s long-term GDP growth outlook, which is forecasted at approximately 6%
B49: Effective Tax Rate | C49: Cost Build_up | D49: B21:Q22 | F49: Taxes for the historical years are based on actual PBT percentages. For the forecasted years (2026–2035), taxes for projected year taken as the latest year of the tax ( which is 2025 tax rate ), and aslo adding the growing tax rate of 0.5 % every 2 year.
B51: Cash and Cash Equivalent | C51: Historical Balance Sheet | D51: B29:G29 | F51: Cash and cash equivalents have been adjusted by reducing the bank overdraft balances of ₹7,119 in FY2023 and ₹573 in FY2024, as disclosed under the Components of Cash and Cash Equivalents in the Annual Report (page 281), to ensure that the closing cash balance reconciles with the cash flow statement.
... B71: Interest Expenses | C71: Debt Schedules | D71: B14:Q15 | F71: Interest expenses are calculated as a percentage of the average of opening and closing debt for each year. For the forecasted period (FY2026–FY2035), the interest rate is assumed constant, based on the average percentage of debt from the last five years (FY2021–FY2025), reflecting a stable cost of borrowing trend

Sheet Historical P&L
B5: Income Statement
B6: (All amounts in INR Lakhs, unless otherwise stated)
A7: # | B7: Particulars | C7: 2021 | D7: =C7+1 -> 2022 | E7: =D7+1 -> 2023 | F7: =E7+1 -> 2024 | G7: =F7+1 -> 2025
C8: Audited | D8: Audited | E8: Audited | F8: Audited | G8: Audited
B9: income
B10: Revenue from contracts with customers | C10: 77341 | D10: 109365 | E10: 142929 | F10: 162466 | G10: 206084
B11: other income | C11: 2424 | D11: 3710 | E11: 2111 | F11: 8537 | G11: 10138
B12: total income | C12: =SUM(C10:C11) -> 79765 | D12: =SUM(D10:D11) -> 113075 | E12: =SUM(E10:E11) -> 145040 | F12: =SUM(F10:F11) -> 171003 | G12: =SUM(G10:G11) -> 216222
B14: expenses
B15: Employee benefits expense | C15: 45238 | D15: 62000 | E15: 80681 | F15: 101469 | G15: 136534
B16: Depreciation and amortisation | C16: 2274 | D16: 3288 | E16: 4191 | F16: 5829 | G16: 8870
B17: Finance cost | C17: 697 | D17: 995 | E17: 2186 | F17: 4227 | G17: 9948
B18: Other expenses | C18: 12954 | D18: 21598 | E18: 26362 | F18: 26882 | G18: 32518
B19: Impairment loss allowance on trade and unbilled receivables | F19: 530 | G19: 1590
B20: total expenses | C20: =SUM(C15:C19) -> 61163 | D20: =SUM(D15:D19) -> 87881 | E20: =SUM(E15:E19) -> 113420 | F20: =SUM(F15:F19) -> 138937 | G20: =SUM(G15:G19) -> 189460
B22: Profit before exceptional items and tax | C22: =C12-C20 -> 18602 | D22: =D12-D20 -> 25194 | E22: =E12-E20 -> 31620 | F22: =F12-F20 -> 32066 | G22: =G12-G20 -> 26762
B23: Exceptional Items | D23: -609 | E23: -634 | F23: 1402 | G23: -1216
B24: Profit before tax | C24: =SUM(C22:C23) -> 18602 | D24: =SUM(D22:D23) -> 24585 | E24: =SUM(E22:E23) -> 30986 | F24: =SUM(F22:F23) -> 33468 | G24: =SUM(G22:G23) -> 25546
B26: tax expense
B27: Current tax | C27: 3527 | D27: 6266 | E27: 8508 | F27: 9518 | G27: 8443
B28: Adjustment of tax relating to earlier periods | D28: 44
B29: Deferred tax charge/ (credit) | C29: -1171 | D29: 155 | E29: -621 | F29: -889 | G29: -1363
B31: Profit for the year | C31: =C24-SUM(C27:C29) -> 16246 | D31: =D24-SUM(D27:D29) -> 18120 | E31: =E24-SUM(E27:E29) -> 23099 | F31: =F24-SUM(F27:F29) -> 24839 | G31: =G24-SUM(G27:G29) -> 18466

Sheet Historical Balance Sheet
B5: Balance Sheet
B6: (All amounts in INR Lakhs, unless otherwise stated)
A7: # | B7: Particulars | C7: 2021 | D7: =C7+1 -> 2022 | E7: =D7+1 -> 2023 | F7: =E7+1 -> 2024 | G7: =F7+1 -> 2025
C8: Audited | D8: Audited | E8: Audited | F8: Audited | G8: Audited
B9: Assets
B10: Non-current assets
B11: Property, plant and equipment | C11: 69 | D11: 78 | E11: 13278 | F11: 13778 | G11: 14096
B12: Capital work-in-progress | C12: 14 | D12: 0 | E12: 185 | F12: 9 | G12: 0
B13: Goodwill | C13: 7644 | D13: 7896 | E13: 13913 | F13: 14032 | G13: 76230
B14: Other intangible assets | C14: 2966 | D14: 2396 | E14: 10182 | F14: 7786 | G14: 23831
B15: Intangible assets under development | D15: 35 | E15: 81 | F15: 22 | G15: 18
B16: Right-of-use assets | C16: 2150 | D16: 5390 | E16: 5786 | F16: 5698 | G16: 6958
B17: Financial assets
B18: Investments | C18: 0 | D18: 762 | E18: 1296 | F18: 0 | G18: 0
B19: Other financial assets | C19: 2458 | D19: 1827 | E19: 9389 | F19: 2480 | G19: 7358
B20: Income tax assets (net | C20: 1408 | D20: 680 | E20: 1310 | F20: 1529 | G20: 3537
B21: Other assets | C21: 7 | D21: 1 | E21: 119 | F21: 32 | G21: 170
B22: Deferred tax assets (net) | C22: 1026 | D22: 697 | E22: 1246 | F22: 1636 | G22: 3613
B24: Total non-current assets | C24: =SUM(C11:C22) -> 17742 | D24: =SUM(D11:D22) -> 19762 | E24: =SUM(E11:E22) -> 56785 | F24: =SUM(F11:F22) -> 47002 | G24: =SUM(G11:G22) -> 135811
B26: Current assets
B27: Financial assets
B28: Investments | C28: 39148 | D28: 46400 | E28: 0 | F28: 0 | G28: 35039
B29: Trade receivables | C29: 12192 | D29: 16738 | E29: 21319 | F29: 25444 | G29: 35813
B30: Cash and cash equivalents | C30: =CashFlow!C79 -> 8583 | D30: 6729 | E30: -120 | F30: 10897 | G30: 11912
B31: Bank balance other than cash and cash equivalents | C31: 5935 | D31: 10071 | E31: =62184+7119 -> 69303 | F31: =122183+573 -> 122756 | G31: 93911
B32: Loans | C32: 14 | D32: 4 | E32: 64 | F32: 37 | G32: 12
B33: Other financial assets | C33: 6779 | D33: 9405 | E33: 12237 | F33: 13850 | G33: 17726
B34: Other assets | C34: 1802 | D34: 3392 | E34: 4495 | F34: 4793 | G34: 5682
B36: Total current assets | C36: =SUM(C28:C35) -> 74453 | D36: =SUM(D28:D35) -> 92739 | E36: =SUM(E28:E35) -> 107298 | F36: =SUM(F28:F35) -> 177777 | G36: =SUM(G28:G35) -> 200095
B38: Total Assets | C38: =C36+C24 -> 92195 | D38: =D36+D24 -> 112501 | E38: =E36+E24 -> 164083 | F38: =F36+F24 -> 224779 | G38: =G36+G24 -> 335906
B40: Equity and liabilities
B41: Equity
B42: Equity share capital | C42: 2837 | D42: 2854 | E42: 2866 | F42: 2987 | G42: 3001
B43: Other equity | C43: 51762 | D43: 63726 | E43: 81016 | F43: 145037 | G43: 154457
B44: Equity attributable to equity holders of the parent | C44: =SUM(C42:C43) -> 54599 | D44: =SUM(D42:D43) -> 66580 | E44: =SUM(E42:E43) -> 83882 | F44: =SUM(F42:F43) -> 148024 | G44: =SUM(G42:G43) -> 157458
B45: Total equity | C45: =SUM(C44:C44) -> 54599 | D45: =SUM(D44:D44) -> 66580 | E45: =SUM(E44:E44) -> 83882 | F45: =SUM(F44:F44) -> 148024 | G45: =SUM(G44:G44) -> 157458
B47: Liabilities
B48: Non-current liabilities
B49: Financial liabilities
B50: Borrowings | C50: 3661 | D50: 1724 | E50: 11278 | F50: 10445 | G50: 33537
...

Sheet Revenue BuildUp
B5: Revenue Build_Up
B6: (All amounts in INR Lakhs, unless otherwise stated)
A7: # | B7: Particulars | C7: 2021 | D7: =C7+1 -> 2022 | E7: =D7+1 -> 2023 | F7: =E7+1 -> 2024 | G7: =F7+1 -> 2025 | H7: =G7+1 -> 2026 | I7: =H7+1 -> 2027 | J7: =I7+1 -> 2028 | K7: =J7+1 -> 2029 | ... Q7: =P7+1 -> 2035
C8: Audited | D8: Audited | E8: Audited | F8: Audited | G8: Audited | H8: Estimated | I8: Projected | J8: Projected | K8: Projected | L8: Projected | M8: Projected | N8: Projected | O8: Projected | P8: Projected | Q8: Projected
B10: Revenue | C10: ='Historical P&L'!C10 -> 77341 | D10: ='Historical P&L'!D10 -> 109365 | E10: ='Historical P&L'!E10 -> 142929 | F10: ='Historical P&L'!F10 -> 162466 | G10: ='Historical P&L'!G10 -> 206084 | H10: =SUM(H16,H27,H37,H47) -> 251738.78 | I10: =SUM(I16,I27,I37,I47) -> 299960.77 | J10: =SUM(J16,J27,J37,J47) -> 349602.74 | K10: =SUM(K16,K27,K37,K47) -> 399552.8 | L10: =SUM(L16,L27,L37,L47) -> 448807.82 | M10: =SUM(M16,M27,M37,M47) -> 496520.42 | N10: =SUM(N16,N27,N37,N47) -> 542021.63 | O10: =SUM(O16,O27,O37,O47) -> 584823.41 | ... Q10: =SUM(Q16,Q27,Q37,Q47) -> 661200.04
B11: Y-O-Y Growth | D11: =D10/C10-1 -> 0.4140624 | E11: =E10/D10-1 -> 0.30689892 | F11: =F10/E10-1 -> 0.13669024 | G11: =G10/F10-1 -> 0.26847463 | H11: =H10/G10-1 -> 0.22153481 | I11: =I10/H10-1 -> 0.19155565 | J11: =J10/I10-1 -> 0.1654949 | K11: =K10/J10-1 -> 0.14287662 | ... Q11: =Q10/P10-1 -> 0.058586316
B14: Revenue Segment by Geography
B16: India | C16: 10464 | D16: 20594 | E16: 22982 | F16: 26668 | G16: 32033 | H16: =G16*(1+H18) -> 37131.799 | I16: =H16*(1+I18) -> 42214.735 | J16: =I16*(1+J18) -> 47184.447 | K16: =J16*(1+K18) -> 51961.549 | L16: =K16*(1+L18) -> 56485.794 | M16: =L16*(1+M18) -> 60715.418 | N16: =M16*(1+N18) -> 64625.267 | O16: =N16*(1+O18) -> 68204.267 | ... Q16: =P16*(1+Q18) -> 74379.343
D18: =D16/C16-1 -> 0.96808104 | E18: =E16/D16-1 -> 0.1159561 | F18: =F16/E16-1 -> 0.16038639 | G18: =G16/F16-1 -> 0.20117744 | H18: =CHOOSE(Assumption!$C$8,'Revenue BuildUp'!$H$21:$Q$21,'Revenue BuildUp'!$H$22:$Q$22,'Revenue BuildUp'!$H$23:$Q$23) -> 0.15917331 | I18: =CHOOSE(Assumption!$C$8,'Revenue BuildUp'!$H$21:$Q$21,'Revenue BuildUp'!$H$22:$Q$22,'Revenue BuildUp'!$H$23:$Q$23) -> 0.13688905 | J18: =CHOOSE(Assumption!$C$8,'Revenue BuildUp'!$H$21:$Q$21,'Revenue BuildUp'!$H$22:$Q$22,'Revenue BuildUp'!$H$23:$Q$23) -> 0.11772458 | K18: =CHOOSE(Assumption!$C$8,'Revenue BuildUp'!$H$21:$Q$21,'Revenue BuildUp'!$H$22:$Q$22,'Revenue BuildUp'!$H$23:$Q$23) -> 0.10124314 | L18: =CHOOSE(Assumption!$C$8,'Revenue BuildUp'!$H$21:$Q$21,'Revenue BuildUp'!$H$22:$Q$22,'Revenue BuildUp'!$H$23:$Q$23) -> 0.0870691 | M18: =CHOOSE(Assumption!$C$8,'Revenue BuildUp'!$H$21:$Q$21,'Revenue BuildUp'!$H$22:$Q$22,'Revenue BuildUp'!$H$23:$Q$23) -> 0.074879426 | N18: =CHOOSE(Assumption!$C$8,'Revenue BuildUp'!$H$21:$Q$21,'Revenue BuildUp'!$H$22:$Q$22,'Revenue BuildUp'!$H$23:$Q$23) -> 0.064396306 | O18: =CHOOSE(Assumption!$C$8,'Revenue BuildUp'!$H$21:$Q$21,'Revenue BuildUp'!$H$22:$Q$22,'Revenue BuildUp'!$H$23:$Q$23) -> 0.055380824 | ... Q18: =CHOOSE(Assumption!$C$8,'Revenue BuildUp'!$H$21:$Q$21,'Revenue BuildUp'!$H$22:$Q$22,'Revenue BuildUp'!$H$23:$Q$23) -> 0.040959657
B20: Scenarios
B21: Best Case | H21: =H22+5% -> 0.20917331 | I21: =H21*(1-$C$24) -> 0.17988905 | J21: =I21*(1-$C$24) -> 0.15470458 | K21: =J21*(1-$C$24) -> 0.13304594 | L21: =K21*(1-$C$24) -> 0.11441951 | M21: =L21*(1-$C$24) -> 0.098400777 | N21: =M21*(1-$C$24) -> 0.084624668 | O21: =N21*(1-$C$24) -> 0.072777215 | P21: =O21*(1-$C$24) -> 0.062588405 | Q21: =P21*(1-$C$24) -> 0.053826028
B22: Base Case | H22: =AVERAGE(E18:G18) -> 0.15917331 | I22: =H22*(1-$C$24) -> 0.13688905 | J22: =I22*(1-$C$24) -> 0.11772458 | K22: =J22*(1-$C$24) -> 0.10124314 | L22: =K22*(1-$C$24) -> 0.0870691 | M22: =L22*(1-$C$24) -> 0.074879426 | N22: =M22*(1-$C$24) -> 0.064396306 | O22: =N22*(1-$C$24) -> 0.055380824 | P22: =O22*(1-$C$24) -> 0.047627508 | Q22: =P22*(1-$C$24) -> 0.040959657
B23: Worst Case | H23: =H22-5% -> 0.10917331 | I23: =H23*(1-$C$24) -> 0.093889048 | J23: =I23*(1-$C$24) -> 0.080744581 | K23: =J23*(1-$C$24) -> 0.06944034 | L23: =K23*(1-$C$24) -> 0.059718692 | M23: =L23*(1-$C$24) -> 0.051358075 | N23: =M23*(1-$C$24) -> 0.044167945 | O23: =N23*(1-$C$24) -> 0.037984432 | P23: =O23*(1-$C$24) -> 0.032666612 | Q23: =P23*(1-$C$24) -> 0.028093286
B24: Annual Trapering | C24: =C35 -> 0.14
B27: USA | C27: 56517 | D27: 71141 | E27: 97251 | F27: 114289 | G27: 133134 | H27: =G27*(1+H29) -> 165281.09 | I27: =H27*(1+I29) -> 199603.23 | J27: =I27*(1+J29) -> 235249.76 | K27: =J27*(1+K29) -> 271380.54 | L27: =K27*(1+L29) -> 307225.26 | M27: =L27*(1+M29) -> 342123.37 | N27: =M27*(1+N29) -> 375544.89 | O27: =N27*(1+O29) -> 407095.21 | ... Q27: =P27*(1+Q29) -> 463630.59
D29: =D27/C27-1 -> 0.258754 | E29: =E27/D27-1 -> 0.36701761 | F29: =F27/E27-1 -> 0.17519614 | G29: =G27/F27-1 -> 0.16488901 | H29: =CHOOSE(Assumption!$C$8,'Revenue BuildUp'!$H$32:$Q$32,'Revenue BuildUp'!$H$33:$Q$33,'Revenue BuildUp'!$H$34:$Q$34) -> 0.24146419 | I29: =CHOOSE(Assumption!$C$8,'Revenue BuildUp'!$H$32:$Q$32,'Revenue BuildUp'!$H$33:$Q$33,'Revenue BuildUp'!$H$34:$Q$34) -> 0.20765921 | J29: =CHOOSE(Assumption!$C$8,'Revenue BuildUp'!$H$32:$Q$32,'Revenue BuildUp'!$H$33:$Q$33,'Revenue BuildUp'!$H$34:$Q$34) -> 0.17858692 | K29: =CHOOSE(Assumption!$C$8,'Revenue BuildUp'!$H$32:$Q$32,'Revenue BuildUp'!$H$33:$Q$33,'Revenue BuildUp'!$H$34:$Q$34) -> 0.15358475 | L29: =CHOOSE(Assumption!$C$8,'Revenue BuildUp'!$H$32:$Q$32,'Revenue BuildUp'!$H$33:$Q$33,'Revenue BuildUp'!$H$34:$Q$34) -> 0.13208288 | M29: =CHOOSE(Assumption!$C$8,'Revenue BuildUp'!$H$32:$Q$32,'Revenue BuildUp'!$H$33:$Q$33,'Revenue BuildUp'!$H$34:$Q$34) -> 0.11359128 | N29: =CHOOSE(Assumption!$C$8,'Revenue BuildUp'!$H$32:$Q$32,'Revenue BuildUp'!$H$33:$Q$33,'Revenue BuildUp'!$H$34:$Q$34) -> 0.0976885 | O29: =CHOOSE(Assumption!$C$8,'Revenue BuildUp'!$H$32:$Q$32,'Revenue BuildUp'!$H$33:$Q$33,'Revenue BuildUp'!$H$34:$Q$34) -> 0.08401211 | ... Q29: =CHOOSE(Assumption!$C$8,'Revenue BuildUp'!$H$32:$Q$32,'Revenue BuildUp'!$H$33:$Q$33,'Revenue BuildUp'!$H$34:$Q$34) -> 0.062135357
B31: Scenarios
B32: Best Case | H32: =H33+5% -> 0.29146419 | I32: =H32*(1-$C$35) -> 0.25065921 | J32: =I32*(1-$C$35) -> 0.21556692 | K32: =J32*(1-$C$35) -> 0.18538755 | L32: =K32*(1-$C$35) -> 0.15943329 | M32: =L32*(1-$C$35) -> 0.13711263 | N32: =M32*(1-$C$35) -> 0.11791686 | O32: =N32*(1-$C$35) -> 0.1014085 | P32: =O32*(1-$C$35) -> 0.087211311 | Q32: =P32*(1-$C$35) -> 0.075001728
B33: Base Case | H33: =AVERAGE(D29:G29) -> 0.24146419 | I33: =H33*(1-$C$35) -> 0.20765921 | J33: =I33*(1-$C$35) -> 0.17858692 | K33: =J33*(1-$C$35) -> 0.15358475 | L33: =K33*(1-$C$35) -> 0.13208288 | M33: =L33*(1-$C$35) -> 0.11359128 | N33: =M33*(1-$C$35) -> 0.0976885 | O33: =N33*(1-$C$35) -> 0.08401211 | P33: =O33*(1-$C$35) -> 0.072250415 | Q33: =P33*(1-$C$35) -> 0.062135357
B34: Worst Case | H34: =H33-5% -> 0.19146419 | I34: =H34*(1-$C$35) -> 0.16465921 | J34: =I34*(1-$C$35) -> 0.14160692 | K34: =J34*(1-$C$35) -> 0.12178195 | L34: =K34*(1-$C$35) -> 0.10473248 | M34: =L34*(1-$C$35) -> 0.090069929 | N34: =M34*(1-$C$35) -> 0.077460139 | O34: =N34*(1-$C$35) -> 0.066615719 | P34: =O34*(1-$C$35) -> 0.057289519 | Q34: =P34*(1-$C$35) -> 0.049268986
B35: Annual Trapering | C35: 0.14
B37: Europe | C37: 7611 | D37: 11332 | E37: 13811 | F37: 14751 | G37: 16779 | H37: =G37*(1+H39) -> 19152.137 | I37: =H37*(1+I39) -> 21481.69 | J37: =I37*(1+J39) -> 23728.789 | K37: =J37*(1+K39) -> 25863.444 | L37: =K37*(1+L39) -> 27864.397 | M37: =L37*(1+M39) -> 29718.351 | N37: =M37*(1+N39) -> 31418.833 | O37: =N37*(1+O39) -> 32964.928 | ... Q37: =P37*(1+Q39) -> 35610.535
D39: =D37/C37-1 -> 0.48889765 | E39: =E37/D37-1 -> 0.21876103 | F39: =F37/E37-1 -> 0.06806169 | G39: =G37/F37-1 -> 0.1374822 | H39: =CHOOSE(Assumption!$C$8,'Revenue BuildUp'!$H$42:$Q$42,'Revenue BuildUp'!$H$43:$Q$43,'Revenue BuildUp'!$H$44:$Q$44) -> 0.14143498 | I39: =CHOOSE(Assumption!$C$8,'Revenue BuildUp'!$H$42:$Q$42,'Revenue BuildUp'!$H$43:$Q$43,'Revenue BuildUp'!$H$44:$Q$44) -> 0.12163408 | J39: =CHOOSE(Assumption!$C$8,'Revenue BuildUp'!$H$42:$Q$42,'Revenue BuildUp'!$H$43:$Q$43,'Revenue BuildUp'!$H$44:$Q$44) -> 0.10460531 | K39: =CHOOSE(Assumption!$C$8,'Revenue BuildUp'!$H$42:$Q$42,'Revenue BuildUp'!$H$43:$Q$43,'Revenue BuildUp'!$H$44:$Q$44) -> 0.089960565 | L39: =CHOOSE(Assumption!$C$8,'Revenue BuildUp'!$H$42:$Q$42,'Revenue BuildUp'!$H$43:$Q$43,'Revenue BuildUp'!$H$44:$Q$44) -> 0.077366085 | M39: =CHOOSE(Assumption!$C$8,'Revenue BuildUp'!$H$42:$Q$42,'Revenue BuildUp'!$H$43:$Q$43,'Revenue BuildUp'!$H$44:$Q$44) -> 0.066534834 | N39: =CHOOSE(Assumption!$C$8,'Revenue BuildUp'!$H$42:$Q$42,'Revenue BuildUp'!$H$43:$Q$43,'Revenue BuildUp'!$H$44:$Q$44) -> 0.057219957 | O39: =CHOOSE(Assumption!$C$8,'Revenue BuildUp'!$H$42:$Q$42,'Revenue BuildUp'!$H$43:$Q$43,'Revenue BuildUp'!$H$44:$Q$44) -> 0.049209163 | ... Q39: =CHOOSE(Assumption!$C$8,'Revenue BuildUp'!$H$42:$Q$42,'Revenue BuildUp'!$H$43:$Q$43,'Revenue BuildUp'!$H$44:$Q$44) -> 0.036395097
B41: Scenarios
B42: Best Case | H42: =H43+5% -> 0.19143498 | I42: =H42*(1-$C$45) -> 0.16463408 | J42: =I42*(1-$C$45) -> 0.14158531 | K42: =J42*(1-$C$45) -> 0.12176336 | L42: =K42*(1-$C$45) -> 0.10471649 | M42: =L42*(1-$C$45) -> 0.090056184 | N42: =M42*(1-$C$45) -> 0.077448319 | O42: =N42*(1-$C$45) -> 0.066605554 | P42: =O42*(1-$C$45) -> 0.057280776 | Q42: =P42*(1-$C$45) -> 0.049261468
B43: Base Case | H43: =AVERAGE(E39:G39) -> 0.14143498 | I43: =H43*(1-$C$45) -> 0.12163408 | J43: =I43*(1-$C$45) -> 0.10460531 | K43: =J43*(1-$C$45) -> 0.089960565 | L43: =K43*(1-$C$45) -> 0.077366085 | M43: =L43*(1-$C$45) -> 0.066534834 | N43: =M43*(1-$C$45) -> 0.057219957 | O43: =N43*(1-$C$45) -> 0.049209163 | P43: =O43*(1-$C$45) -> 0.04231988 | Q43: =P43*(1-$C$45) -> 0.036395097
B44: Worst Case | H44: =H43-5% -> 0.091434975 | I44: =H44*(1-$C$45) -> 0.078634079 | J44: =I44*(1-$C$45) -> 0.067625308 | K44: =J44*(1-$C$45) -> 0.058157765 | L44: =K44*(1-$C$45) -> 0.050015677 | M44: =L44*(1-$C$45) -> 0.043013483 | N44: =M44*(1-$C$45) -> 0.036991595 | O44: =N44*(1-$C$45) -> 0.031812772 | P44: =O44*(1-$C$45) -> 0.027358984 | Q44: =P44*(1-$C$45) -> 0.023528726
B45: Annual Trapering | C45: =C35 -> 0.14
B47: Others | C47: 2749 | D47: 6298 | E47: 8885 | F47: 6758 | G47: 24139 | H47: =G47*(1+H49) -> 30173.75 | I47: =H47*(1+I49) -> 36661.106 | J47: =I47*(1+J49) -> 43439.745 | K47: =J47*(1+K49) -> 50347.272 | L47: =K47*(1+L49) -> 57232.365 | M47: =L47*(1+M49) -> 63963.277 | N47: =M47*(1+N49) -> 70432.639 | O47: =N47*(1+O49) -> 76559.007 | ... Q47: =P47*(1+Q49) -> 87579.573
D49: =D47/C47-1 -> 1.2910149 | E49: =E47/D47-1 -> 0.41076532 | F49: =F47/E47-1 -> -0.23939223 | G49: =G47/F47-1 -> 2.5719148 | H49: =CHOOSE(Assumption!$C$8,'Revenue BuildUp'!$H$52:$Q$52,'Revenue BuildUp'!$H$53:$Q$53,'Revenue BuildUp'!$H$54:$Q$54) -> 0.25 | I49: =CHOOSE(Assumption!$C$8,'Revenue BuildUp'!$H$52:$Q$52,'Revenue BuildUp'!$H$53:$Q$53,'Revenue BuildUp'!$H$54:$Q$54) -> 0.215 | J49: =CHOOSE(Assumption!$C$8,'Revenue BuildUp'!$H$52:$Q$52,'Revenue BuildUp'!$H$53:$Q$53,'Revenue BuildUp'!$H$54:$Q$54) -> 0.1849 | K49: =CHOOSE(Assumption!$C$8,'Revenue BuildUp'!$H$52:$Q$52,'Revenue BuildUp'!$H$53:$Q$53,'Revenue BuildUp'!$H$54:$Q$54) -> 0.159014 | L49: =CHOOSE(Assumption!$C$8,'Revenue BuildUp'!$H$52:$Q$52,'Revenue BuildUp'!$H$53:$Q$53,'Revenue BuildUp'!$H$54:$Q$54) -> 0.13675204 | M49: =CHOOSE(Assumption!$C$8,'Revenue BuildUp'!$H$52:$Q$52,'Revenue BuildUp'!$H$53:$Q$53,'Revenue BuildUp'!$H$54:$Q$54) -> 0.11760675 | N49: =CHOOSE(Assumption!$C$8,'Revenue BuildUp'!$H$52:$Q$52,'Revenue BuildUp'!$H$53:$Q$53,'Revenue BuildUp'!$H$54:$Q$54) -> 0.10114181 | O49: =CHOOSE(Assumption!$C$8,'Revenue BuildUp'!$H$52:$Q$52,'Revenue BuildUp'!$H$53:$Q$53,'Revenue BuildUp'!$H$54:$Q$54) -> 0.086981956 | ... Q49: =CHOOSE(Assumption!$C$8,'Revenue BuildUp'!$H$52:$Q$52,'Revenue BuildUp'!$H$53:$Q$53,'Revenue BuildUp'!$H$54:$Q$54) -> 0.064331854
B51: Scenarios
B52: Best Case | H52: =H53+5% -> 0.3 | I52: =H52*(1-$C$55) -> 0.258 | J52: =I52*(1-$C$55) -> 0.22188 | K52: =J52*(1-$C$55) -> 0.1908168 | L52: =K52*(1-$C$55) -> 0.16410245 | M52: =L52*(1-$C$55) -> 0.14112811 | N52: =M52*(1-$C$55) -> 0.12137017 | O52: =N52*(1-$C$55) -> 0.10437835 | P52: =O52*(1-$C$55) -> 0.089765378 | Q52: =P52*(1-$C$55) -> 0.077198225
B53: Base Case | H53: 0.25 | I53: =H53*(1-$C$55) -> 0.215 | J53: =I53*(1-$C$55) -> 0.1849 | K53: =J53*(1-$C$55) -> 0.159014 | L53: =K53*(1-$C$55) -> 0.13675204 | M53: =L53*(1-$C$55) -> 0.11760675 | N53: =M53*(1-$C$55) -> 0.10114181 | O53: =N53*(1-$C$55) -> 0.086981956 | P53: =O53*(1-$C$55) -> 0.074804482 | Q53: =P53*(1-$C$55) -> 0.064331854
B54: Worst Case | H54: =H53-5% -> 0.2 | I54: =H54*(1-$C$55) -> 0.172 | J54: =I54*(1-$C$55) -> 0.14792 | K54: =J54*(1-$C$55) -> 0.1272112 | L54: =K54*(1-$C$55) -> 0.10940163 | M54: =L54*(1-$C$55) -> 0.094085404 | N54: =M54*(1-$C$55) -> 0.080913447 | O54: =N54*(1-$C$55) -> 0.069585564 | P54: =O54*(1-$C$55) -> 0.059843585 | Q54: =P54*(1-$C$55) -> 0.051465483
B55: Annual Trapering | C55: =C35 -> 0.14
B58: Other income | C58: ='Historical P&L'!C11 -> 2424 | D58: ='Historical P&L'!D11 -> 3710 | E58: ='Historical P&L'!E11 -> 2111 | F58: ='Historical P&L'!F11 -> 8537 | G58: ='Historical P&L'!G11 -> 10138 | H58: =H59*H10 -> 9151.9283 | I58: =I59*I10 -> 10905.032 | J58: =J59*J10 -> 12709.759 | K58: =K59*K10 -> 14525.686 | L58: =L59*L10 -> 16316.346 | M58: =M59*M10 -> 18050.931 | N58: =N59*N10 -> 19705.121 | O58: =O59*O10 -> 21261.174 | ... Q58: =Q59*Q10 -> 24037.835
B59: % of Revenue | C59: =C58/C10 -> 0.03134172 | D59: =D58/D10 -> 0.033923102 | E59: =E58/E10 -> 0.014769571 | F59: =F58/F10 -> 0.052546379 | G59: =G58/G10 -> 0.049193533 | H59: =AVERAGE(C59:G59) -> 0.036354861 | I59: =H59 -> 0.036354861 | J59: =I59 -> 0.036354861 | K59: =J59 -> 0.036354861 | L59: =K59 -> 0.036354861 | M59: =L59 -> 0.036354861 | N59: =M59 -> 0.036354861 | O59: =N59 -> 0.036354861 | P59: =O59 -> 0.036354861 | Q59: =P59 -> 0.036354861
B62: Exceptional Items | C62: ='Historical P&L'!C23 -> 0 | D62: ='Historical P&L'!D23 -> -609 | E62: ='Historical P&L'!E23 -> -634 | F62: ='Historical P&L'!F23 -> 1402 | G62: ='Historical P&L'!G23 -> -1216 | H62: =H63*H10 -> -366.29436 | I62: =I63*I10 -> -436.46011 | J62: =J63*J10 -> -508.69203 | K62: =K63*K10 -> -581.37223 | L62: =L63*L10 -> -653.0411 | M62: =M63*M10 -> -722.46567 | N62: =N63*N10 -> -788.67254 | O62: =O63*O10 -> -850.95159 | ... Q62: =Q63*Q10 -> -962.08396
B63: % of Revenue | C63: =C62/C10 -> 0 | D63: =D62/D10 -> -0.0055685091 | E63: =E62/E10 -> -0.0044357688 | F63: =F62/F10 -> 0.0086294979 | G63: =G62/G10 -> -0.0059005066 | H63: =AVERAGE(C63:G63) -> -0.0014550573 | I63: =H63 -> -0.0014550573 | J63: =I63 -> -0.0014550573 | K63: =J63 -> -0.0014550573 | L63: =K63 -> -0.0014550573 | M63: =L63 -> -0.0014550573 | N63: =M63 -> -0.0014550573 | O63: =N63 -> -0.0014550573 | P63: =O63 -> -0.0014550573 | Q63: =P63 -> -0.0014550573

Sheet Common Size Statement
B6: Common Size Statement
B7: (All amounts in INR Lakhs, unless otherwise stated)
B8: Particulars | C8: 2021 | D8: =C8+1 -> 2022 | E8: =D8+1 -> 2023 | F8: =E8+1 -> 2024 | G8: =F8+1 -> 2025 | H8: =G8+1 -> 2026 | I8: =H8+1 -> 2027 | J8: =I8+1 -> 2028 | K8: =J8+1 -> 2029 | ... Q8: =P8+1 -> 2035
C9: Audited | D9: Audited | E9: Audited | F9: Audited | G9: Audited | H9: Estimated | I9: Projected | J9: Projected | K9: Projected | L9: Projected | M9: Projected | N9: Projected | O9: Projected | P9: Projected | Q9: Projected
B11: Revenue | C11: ='Profit & Loss Statement'!C9/'Profit & Loss Statement'!C$9 -> 1 | D11: ='Profit & Loss Statement'!D9/'Profit & Loss Statement'!D$9 -> 1 | E11: ='Profit & Loss Statement'!E9/'Profit & Loss Statement'!E$9 -> 1 | F11: ='Profit & Loss Statement'!F9/'Profit & Loss Statement'!F$9 -> 1 | G11: ='Profit & Loss Statement'!G9/'Profit & Loss Statement'!G$9 -> 1 | H11: ='Profit & Loss Statement'!H9/'Profit & Loss Statement'!H$9 -> 1 | I11: ='Profit & Loss Statement'!I9/'Profit & Loss Statement'!I$9 -> 1 | J11: ='Profit & Loss Statement'!J9/'Profit & Loss Statement'!J$9 -> 1 | ... Q11: ='Profit & Loss Statement'!Q9/'Profit & Loss Statement'!Q$9 -> 1
B13: Expenses
B14: Employee Expenses | C14: ='Profit & Loss Statement'!C14/'Profit & Loss Statement'!C10 -> 0.58491615 | D14: ='Profit & Loss Statement'!D14/'Profit & Loss Statement'!D10 -> 0.56690897 | E14: ='Profit & Loss Statement'!E14/'Profit & Loss Statement'!E10 -> 0.56448307 | F14: ='Profit & Loss Statement'!F14/'Profit & Loss Statement'!F10 -> 0.62455529 | G14: ='Profit & Loss Statement'!G14/'Profit & Loss Statement'!G10 -> 0.66251626 | H14: ='Profit & Loss Statement'!H14/'Profit & Loss Statement'!H10 -> 0.60067595 | I14: ='Profit & Loss Statement'!I14/'Profit & Loss Statement'!I10 -> 0.60067595 | J14: ='Profit & Loss Statement'!J14/'Profit & Loss Statement'!J10 -> 0.60067595 | ... Q14: ='Profit & Loss Statement'!Q14/'Profit & Loss Statement'!Q10 -> 0.60067595
B15: Other expenses | C15: ='Profit & Loss Statement'!C15/'Profit & Loss Statement'!C$9 -> 0.16749202 | D15: ='Profit & Loss Statement'!D15/'Profit & Loss Statement'!D$9 -> 0.19748548 | E15: ='Profit & Loss Statement'!E15/'Profit & Loss Statement'!E$9 -> 0.18444123 | F15: ='Profit & Loss Statement'!F15/'Profit & Loss Statement'!F$9 -> 0.16546231 | G15: ='Profit & Loss Statement'!G15/'Profit & Loss Statement'!G$9 -> 0.15779003 | H15: ='Profit & Loss Statement'!H15/'Profit & Loss Statement'!H$9 -> 0.17453421 | I15: ='Profit & Loss Statement'!I15/'Profit & Loss Statement'!I$9 -> 0.17453421 | J15: ='Profit & Loss Statement'!J15/'Profit & Loss Statement'!J$9 -> 0.17453421 | ... Q15: ='Profit & Loss Statement'!Q15/'Profit & Loss Statement'!Q$9 -> 0.17453421
B16: Impairment loss allowance on trade and unbilled receivables | C16: ='Profit & Loss Statement'!C16/'Profit & Loss Statement'!C$9 -> 0 | D16: ='Profit & Loss Statement'!D16/'Profit & Loss Statement'!D$9 -> 0 | E16: ='Profit & Loss Statement'!E16/'Profit & Loss Statement'!E$9 -> 0 | F16: ='Profit & Loss Statement'!F16/'Profit & Loss Statement'!F$9 -> 0.003262221 | G16: ='Profit & Loss Statement'!G16/'Profit & Loss Statement'!G$9 -> 0.0077153006 | H16: ='Profit & Loss Statement'!H16/'Profit & Loss Statement'!H$9 -> 0.0021955043 | I16: ='Profit & Loss Statement'!I16/'Profit & Loss Statement'!I$9 -> 0.0021955043 | J16: ='Profit & Loss Statement'!J16/'Profit & Loss Statement'!J$9 -> 0.0021955043 | ... Q16: ='Profit & Loss Statement'!Q16/'Profit & Loss Statement'!Q$9 -> 0.0021955043
B17: Total Expenses | C17: ='Profit & Loss Statement'!C17/'Profit & Loss Statement'!C$9 -> 0.75240817 | D17: ='Profit & Loss Statement'!D17/'Profit & Loss Statement'!D$9 -> 0.76439446 | E17: ='Profit & Loss Statement'!E17/'Profit & Loss Statement'!E$9 -> 0.74892429 | F17: ='Profit & Loss Statement'!F17/'Profit & Loss Statement'!F$9 -> 0.79327982 | G17: ='Profit & Loss Statement'!G17/'Profit & Loss Statement'!G$9 -> 0.82802158 | H17: ='Profit & Loss Statement'!H17/'Profit & Loss Statement'!H$9 -> 0.77740566 | I17: ='Profit & Loss Statement'!I17/'Profit & Loss Statement'!I$9 -> 0.77740566 | J17: ='Profit & Loss Statement'!J17/'Profit & Loss Statement'!J$9 -> 0.77740566 | ... Q17: ='Profit & Loss Statement'!Q17/'Profit & Loss Statement'!Q$9 -> 0.77740566
B19: EBITDA | C19: ='Profit & Loss Statement'!C19/'Profit & Loss Statement'!C$9 -> 0.24759183 | D19: ='Profit & Loss Statement'!D19/'Profit & Loss Statement'!D$9 -> 0.23560554 | E19: ='Profit & Loss Statement'!E19/'Profit & Loss Statement'!E$9 -> 0.25107571 | F19: ='Profit & Loss Statement'!F19/'Profit & Loss Statement'!F$9 -> 0.20672018 | G19: ='Profit & Loss Statement'!G19/'Profit & Loss Statement'!G$9 -> 0.17197842 | H19: ='Profit & Loss Statement'!H19/'Profit & Loss Statement'!H$9 -> 0.22259434 | I19: ='Profit & Loss Statement'!I19/'Profit & Loss Statement'!I$9 -> 0.22259434 | J19: ='Profit & Loss Statement'!J19/'Profit & Loss Statement'!J$9 -> 0.22259434 | ... Q19: ='Profit & Loss Statement'!Q19/'Profit & Loss Statement'!Q$9 -> 0.22259434
B21: D&A | C21: ='Profit & Loss Statement'!C21/'Profit & Loss Statement'!C$9 -> 0.029402258 | D21: ='Profit & Loss Statement'!D21/'Profit & Loss Statement'!D$9 -> 0.030064463 | E21: ='Profit & Loss Statement'!E21/'Profit & Loss Statement'!E$9 -> 0.029322251 | F21: ='Profit & Loss Statement'!F21/'Profit & Loss Statement'!F$9 -> 0.035878276 | G21: ='Profit & Loss Statement'!G21/'Profit & Loss Statement'!G$9 -> 0.043040702 | H21: ='Profit & Loss Statement'!H21/'Profit & Loss Statement'!H$9 -> 0.019346245 | I21: ='Profit & Loss Statement'!I21/'Profit & Loss Statement'!I$9 -> 0.016317304 | J21: ='Profit & Loss Statement'!J21/'Profit & Loss Statement'!J$9 -> 0.014070324 | ... Q21: ='Profit & Loss Statement'!Q21/'Profit & Loss Statement'!Q$9 -> 0.0077038618
B23: EBIT | C23: ='Profit & Loss Statement'!C23/'Profit & Loss Statement'!C$9 -> 0.21818958 | D23: ='Profit & Loss Statement'!D23/'Profit & Loss Statement'!D$9 -> 0.20554108 | E23: ='Profit & Loss Statement'!E23/'Profit & Loss Statement'!E$9 -> 0.22175346 | F23: ='Profit & Loss Statement'!F23/'Profit & Loss Statement'!F$9 -> 0.1708419 | G23: ='Profit & Loss Statement'!G23/'Profit & Loss Statement'!G$9 -> 0.12893771 | H23: ='Profit & Loss Statement'!H23/'Profit & Loss Statement'!H$9 -> 0.20324809 | I23: ='Profit & Loss Statement'!I23/'Profit & Loss Statement'!I$9 -> 0.20627703 | J23: ='Profit & Loss Statement'!J23/'Profit & Loss Statement'!J$9 -> 0.20852401 | ... Q23: ='Profit & Loss Statement'!Q23/'Profit & Loss Statement'!Q$9 -> 0.21489047
B25: Finance Cost | C25: ='Profit & Loss Statement'!C25/'Profit & Loss Statement'!C$9 -> 0.0090120376 | D25: ='Profit & Loss Statement'!D25/'Profit & Loss Statement'!D$9 -> 0.0090979747 | E25: ='Profit & Loss Statement'!E25/'Profit & Loss Statement'!E$9 -> 0.015294307 | F25: ='Profit & Loss Statement'!F25/'Profit & Loss Statement'!F$9 -> 0.026017751 | G25: ='Profit & Loss Statement'!G25/'Profit & Loss Statement'!G$9 -> 0.048271579 | H25: ='Profit & Loss Statement'!H25/'Profit & Loss Statement'!H$9 -> 0.02807352 | I25: ='Profit & Loss Statement'!I25/'Profit & Loss Statement'!I$9 -> 0.021552733 | J25: ='Profit & Loss Statement'!J25/'Profit & Loss Statement'!J$9 -> 0.021772634 | ... Q25: ='Profit & Loss Statement'!Q25/'Profit & Loss Statement'!Q$9 -> 0.022788041
B26: Other Income | C26: ='Profit & Loss Statement'!C26/'Profit & Loss Statement'!C$9 -> 0.03134172 | D26: ='Profit & Loss Statement'!D26/'Profit & Loss Statement'!D$9 -> 0.033923102 | E26: ='Profit & Loss Statement'!E26/'Profit & Loss Statement'!E$9 -> 0.014769571 | F26: ='Profit & Loss Statement'!F26/'Profit & Loss Statement'!F$9 -> 0.052546379 | G26: ='Profit & Loss Statement'!G26/'Profit & Loss Statement'!G$9 -> 0.049193533 | H26: ='Profit & Loss Statement'!H26/'Profit & Loss Statement'!H$9 -> 0.036354861 | I26: ='Profit & Loss Statement'!I26/'Profit & Loss Statement'!I$9 -> 0.036354861 | J26: ='Profit & Loss Statement'!J26/'Profit & Loss Statement'!J$9 -> 0.036354861 | ... Q26: ='Profit & Loss Statement'!Q26/'Profit & Loss Statement'!Q$9 -> 0.036354861
B27: Exceptional Items | C27: ='Profit & Loss Statement'!C27/'Profit & Loss Statement'!C$9 -> 0 | D27: ='Profit & Loss Statement'!D27/'Profit & Loss Statement'!D$9 -> -0.0055685091 | E27: ='Profit & Loss Statement'!E27/'Profit & Loss Statement'!E$9 -> -0.0044357688 | F27: ='Profit & Loss Statement'!F27/'Profit & Loss Statement'!F$9 -> 0.0086294979 | G27: ='Profit & Loss Statement'!G27/'Profit & Loss Statement'!G$9 -> -0.0059005066 | H27: ='Profit & Loss Statement'!H27/'Profit & Loss Statement'!H$9 -> -0.0014550573 | I27: ='Profit & Loss Statement'!I27/'Profit & Loss Statement'!I$9 -> -0.0014550573 | J27: ='Profit & Loss Statement'!J27/'Profit & Loss Statement'!J$9 -> -0.0014550573 | ... Q27: ='Profit & Loss Statement'!Q27/'Profit & Loss Statement'!Q$9 -> -0.0014550573
B28: EBT | C28: ='Profit & Loss Statement'!C28/'Profit & Loss Statement'!C$9 -> 0.24051926 | D28: ='Profit & Loss Statement'!D28/'Profit & Loss Statement'!D$9 -> 0.2247977 | E28: ='Profit & Loss Statement'!E28/'Profit & Loss Statement'!E$9 -> 0.21679295 | F28: ='Profit & Loss Statement'!F28/'Profit & Loss Statement'!F$9 -> 0.20600002 | G28: ='Profit & Loss Statement'!G28/'Profit & Loss Statement'!G$9 -> 0.12395916 | H28: ='Profit & Loss Statement'!H28/'Profit & Loss Statement'!H$9 -> 0.21007437 | I28: ='Profit & Loss Statement'!I28/'Profit & Loss Statement'!I$9 -> 0.2196241 | J28: ='Profit & Loss Statement'!J28/'Profit & Loss Statement'!J$9 -> 0.22165118 | ... Q28: ='Profit & Loss Statement'!Q28/'Profit & Loss Statement'!Q$9 -> 0.22700224
B30: Taxes | C30: ='Profit & Loss Statement'!C30/'Profit & Loss Statement'!C$9 -> 0.030462497 | D30: ='Profit & Loss Statement'!D30/'Profit & Loss Statement'!D$9 -> 0.059113976 | E30: ='Profit & Loss Statement'!E30/'Profit & Loss Statement'!E$9 -> 0.055181244 | F30: ='Profit & Loss Statement'!F30/'Profit & Loss Statement'!F$9 -> 0.053112651 | G30: ='Profit & Loss Statement'!G30/'Profit & Loss Statement'!G$9 -> 0.034354923 | H30: ='Profit & Loss Statement'!H30/'Profit & Loss Statement'!H$9 -> 0.059271877 | I30: ='Profit & Loss Statement'!I30/'Profit & Loss Statement'!I$9 -> 0.061966305 | J30: ='Profit & Loss Statement'!J30/'Profit & Loss Statement'!J$9 -> 0.063646495 | ... Q30: ='Profit & Loss Statement'!Q30/'Profit & Loss Statement'!Q$9 -> 0.068100671
B32: Net Profit | C32: ='Profit & Loss Statement'!C32/'Profit & Loss Statement'!C$9 -> 0.21005676 | D32: ='Profit & Loss Statement'!D32/'Profit & Loss Statement'!D$9 -> 0.16568372 | E32: ='Profit & Loss Statement'!E32/'Profit & Loss Statement'!E$9 -> 0.16161171 | F32: ='Profit & Loss Statement'!F32/'Profit & Loss Statement'!F$9 -> 0.15288737 | G32: ='Profit & Loss Statement'!G32/'Profit & Loss Statement'!G$9 -> 0.089604239 | H32: ='Profit & Loss Statement'!H32/'Profit & Loss Statement'!H$9 -> 0.1508025 | I32: ='Profit & Loss Statement'!I32/'Profit & Loss Statement'!I$9 -> 0.1576578 | J32: ='Profit & Loss Statement'!J32/'Profit & Loss Statement'!J$9 -> 0.15800469 | ... Q32: ='Profit & Loss Statement'!Q32/'Profit & Loss Statement'!Q$9 -> 0.15890157
B34: Balance Sheet
B35: Non-current assets
B36: Property, plant and equipment | C36: ='Balance sheet'!C11/'Balance sheet'!C$34 -> 0.056391344 | D36: ='Balance sheet'!D11/'Balance sheet'!D$34 -> 0.070212709 | E36: ='Balance sheet'!E11/'Balance sheet'!E$34 -> 0.17986019 | F36: ='Balance sheet'!F11/'Balance sheet'!F$34 -> 0.12142149 | G36: ='Balance sheet'!G11/'Balance sheet'!G$34 -> 0.13367728 | H36: ='Balance sheet'!H11/'Balance sheet'!H$34 -> 0.14436122 | I36: ='Balance sheet'!I11/'Balance sheet'!I$34 -> 0.1273141 | J36: ='Balance sheet'!J11/'Balance sheet'!J$34 -> 0.11314868 | ... Q36: ='Balance sheet'!Q11/'Balance sheet'!Q$34 -> 0.062906062
B37: Goodwill | C37: ='Balance sheet'!C12/'Balance sheet'!C$34 -> 0.082911221 | D37: ='Balance sheet'!D12/'Balance sheet'!D$34 -> 0.070186043 | E37: ='Balance sheet'!E12/'Balance sheet'!E$34 -> 0.084792453 | F37: ='Balance sheet'!F12/'Balance sheet'!F$34 -> 0.06242576 | G37: ='Balance sheet'!G12/'Balance sheet'!G$34 -> 0.22693849 | H37: ='Balance sheet'!H12/'Balance sheet'!H$34 -> 0.2359752 | I37: ='Balance sheet'!I12/'Balance sheet'!I$34 -> 0.20038628 | J37: ='Balance sheet'!J12/'Balance sheet'!J$34 -> 0.17181312 | ... Q37: ='Balance sheet'!Q12/'Balance sheet'!Q$34 -> 0.076130184
B38: Financial assets
B39: Investments | C39: ='Balance sheet'!C14/'Balance sheet'!C$34 -> 0 | D39: ='Balance sheet'!D14/'Balance sheet'!D$34 -> 0.0067732731 | E39: ='Balance sheet'!E14/'Balance sheet'!E$34 -> 0.0078984416 | F39: ='Balance sheet'!F14/'Balance sheet'!F$34 -> 0 | G39: ='Balance sheet'!G14/'Balance sheet'!G$34 -> 0 | H39: ='Balance sheet'!H14/'Balance sheet'!H$34 -> 0.0024991235 | I39: ='Balance sheet'!I14/'Balance sheet'!I$34 -> 0.002528737 | J39: ='Balance sheet'!J14/'Balance sheet'!J$34 -> 0.0025269834 | ... Q39: ='Balance sheet'!Q14/'Balance sheet'!Q$34 -> 0.0021176831
B40: Other financial assets | C40: ='Balance sheet'!C15/'Balance sheet'!C$34 -> 0.026660882 | D40: ='Balance sheet'!D15/'Balance sheet'!D$34 -> 0.016239856 | E40: ='Balance sheet'!E15/'Balance sheet'!E$34 -> 0.057221041 | F40: ='Balance sheet'!F15/'Balance sheet'!F$34 -> 0.011033059 | G40: ='Balance sheet'!G15/'Balance sheet'!G$34 -> 0.021904938 | H40: ='Balance sheet'!H15/'Balance sheet'!H$34 -> 0.025738731 | I40: ='Balance sheet'!I15/'Balance sheet'!I$34 -> 0.026043724 | J40: ='Balance sheet'!J15/'Balance sheet'!J$34 -> 0.026025664 | ... Q40: ='Balance sheet'!Q15/'Balance sheet'!Q$34 -> 0.021810238
B41: Income tax assets (net | C41: ='Balance sheet'!C16/'Balance sheet'!C$34 -> 0.015271978 | D41: ='Balance sheet'!D16/'Balance sheet'!D$34 -> 0.0060443907 | E41: ='Balance sheet'!E16/'Balance sheet'!E$34 -> 0.0079837643 | F41: ='Balance sheet'!F16/'Balance sheet'!F$34 -> 0.0068022369 | G41: ='Balance sheet'!G16/'Balance sheet'!G$34 -> 0.010529732 | H41: ='Balance sheet'!H16/'Balance sheet'!H$34 -> 0.0093765909 | I41: ='Balance sheet'!I16/'Balance sheet'!I$34 -> 0.0094876994 | J41: ='Balance sheet'!J16/'Balance sheet'!J$34 -> 0.00948112 | ... Q41: ='Balance sheet'!Q16/'Balance sheet'!Q$34 -> 0.0079454452
B42: Other assets | C42: ='Balance sheet'!C17/'Balance sheet'!C$34 -> 7.5926026e-05 | D42: ='Balance sheet'!D17/'Balance sheet'!D$34 -> 8.8888099e-06 | E42: ='Balance sheet'!E17/'Balance sheet'!E$34 -> 0.00072524271 | F42: ='Balance sheet'!F17/'Balance sheet'!F$34 -> 0.00014236205 | G42: ='Balance sheet'!G17/'Balance sheet'!G$34 -> 0.00050609397 | H42: ='Balance sheet'!H17/'Balance sheet'!H$34 -> 0.00030455672 | I42: ='Balance sheet'!I17/'Balance sheet'!I$34 -> 0.00030816559 | J42: ='Balance sheet'!J17/'Balance sheet'!J$34 -> 0.00030795188 | ... Q42: ='Balance sheet'!Q17/'Balance sheet'!Q$34 -> 0.00025807234
B43: Deferred tax assets (net) | C43: ='Balance sheet'!C18/'Balance sheet'!C$34 -> 0.011128586 | D43: ='Balance sheet'!D18/'Balance sheet'!D$34 -> 0.0061955005 | E43: ='Balance sheet'!E18/'Balance sheet'!E$34 -> 0.0075937178 | F43: ='Balance sheet'!F18/'Balance sheet'!F$34 -> 0.00727826 | G43: ='Balance sheet'!G18/'Balance sheet'!G$34 -> 0.010755985 | H43: ='Balance sheet'!H18/'Balance sheet'!H$34 -> 0.0087213586 | I43: ='Balance sheet'!I18/'Balance sheet'!I$34 -> 0.0088247029 | J43: ='Balance sheet'!J18/'Balance sheet'!J$34 -> 0.0088185833 | ... Q43: ='Balance sheet'!Q18/'Balance sheet'!Q$34 -> 0.0073902207
B45: Total non-current assets | C45: ='Balance sheet'!C20/'Balance sheet'!C$34 -> 0.19243994 | D45: ='Balance sheet'!D20/'Balance sheet'!D$34 -> 0.17566066 | E45: ='Balance sheet'!E20/'Balance sheet'!E$34 -> 0.34607485 | F45: ='Balance sheet'!F20/'Balance sheet'!F$34 -> 0.20910316 | G45: ='Balance sheet'!G20/'Balance sheet'!G$34 -> 0.40431252 | H45: ='Balance sheet'!H20/'Balance sheet'!H$34 -> 0.42697678 | I45: ='Balance sheet'!I20/'Balance sheet'!I$34 -> 0.37489341 | J45: ='Balance sheet'!J20/'Balance sheet'!J$34 -> 0.3321221 | ... Q45: ='Balance sheet'!Q20/'Balance sheet'!Q$34 -> 0.17855791
B47: Current assets
B48: Financial assets
B49: Investments | C49: ='Balance sheet'!C24/'Balance sheet'!C$34 -> 0.42462173 | D49: ='Balance sheet'!D24/'Balance sheet'!D$34 -> 0.41244078 | E49: ='Balance sheet'!E24/'Balance sheet'!E$34 -> 0 | F49: ='Balance sheet'!F24/'Balance sheet'!F$34 -> 0 | G49: ='Balance sheet'!G24/'Balance sheet'!G$34 -> 0.10431192 | H49: ='Balance sheet'!H24/'Balance sheet'!H$34 -> 0.28585463 | I49: ='Balance sheet'!I24/'Balance sheet'!I$34 -> 0.28924189 | J49: ='Balance sheet'!J24/'Balance sheet'!J$34 -> 0.28904131 | ... Q49: ='Balance sheet'!Q24/'Balance sheet'!Q$34 -> 0.24222474
B50: Trade receivables | C50: ='Balance sheet'!C25/'Balance sheet'!C$34 -> 0.13224144 | D50: ='Balance sheet'!D25/'Balance sheet'!D$34 -> 0.1487809 | E50: ='Balance sheet'!E25/'Balance sheet'!E$34 -> 0.12992815 | F50: ='Balance sheet'!F25/'Balance sheet'!F$34 -> 0.11319563 | G50: ='Balance sheet'!G25/'Balance sheet'!G$34 -> 0.10661614 | H50: ='Balance sheet'!H25/'Balance sheet'!H$34 -> 0.12316195 | I50: ='Balance sheet'!I25/'Balance sheet'!I$34 -> 0.12462137 | J50: ='Balance sheet'!J25/'Balance sheet'!J$34 -> 0.12453495 | ... Q50: ='Balance sheet'!Q25/'Balance sheet'!Q$34 -> 0.10436379
B51: Cash and cash equivalents | C51: ='Balance sheet'!C26/'Balance sheet'!C$34 -> 0.093096155 | D51: ='Balance sheet'!D26/'Balance sheet'!D$34 -> 0.059812802 | E51: ='Balance sheet'!E26/'Balance sheet'!E$34 -> -0.00073133719 | F51: ='Balance sheet'!F26/'Balance sheet'!F$34 -> 0.048478728 | G51: ='Balance sheet'!G26/'Balance sheet'!G$34 -> 0.035462302 | H51: ='Balance sheet'!H26/'Balance sheet'!H$34 -> 0.074497051 | I51: ='Balance sheet'!I26/'Balance sheet'!I$34 -> 0.12067311 | J51: ='Balance sheet'!J26/'Balance sheet'!J$34 -> 0.16379422 | ... Q51: ='Balance sheet'!Q26/'Balance sheet'!Q$34 -> 0.3990058
B52: Bank balance other than cash and cash equivalents | C52: ='Balance sheet'!C27/'Balance sheet'!C$34 -> 0.064374424 | D52: ='Balance sheet'!D27/'Balance sheet'!D$34 -> 0.089519204 | E52: ='Balance sheet'!E27/'Balance sheet'!E$34 -> 0.42236551 | F52: ='Balance sheet'!F27/'Balance sheet'!F$34 -> 0.54611863 | G52: ='Balance sheet'!G27/'Balance sheet'!G$34 -> 0.27957524 | H52: ='Balance sheet'!H27/'Balance sheet'!H$34 -> 0 | I52: ='Balance sheet'!I27/'Balance sheet'!I$34 -> 0 | J52: ='Balance sheet'!J27/'Balance sheet'!J$34 -> 0 | ... Q52: ='Balance sheet'!Q27/'Balance sheet'!Q$34 -> 0
B53: Loans | C53: ='Balance sheet'!C28/'Balance sheet'!C$34 -> 0.00015185205 | D53: ='Balance sheet'!D28/'Balance sheet'!D$34 -> 3.555524e-05 | E53: ='Balance sheet'!E28/'Balance sheet'!E$34 -> 0.0003900465 | F53: ='Balance sheet'!F28/'Balance sheet'!F$34 -> 0.00016460612 | G53: ='Balance sheet'!G28/'Balance sheet'!G$34 -> 3.572428e-05 | H53: ='Balance sheet'!H28/'Balance sheet'!H$34 -> 0.00014827021 | I53: ='Balance sheet'!I28/'Balance sheet'!I$34 -> 0.00015002715 | J53: ='Balance sheet'!J28/'Balance sheet'!J$34 -> 0.00014992311 | ... Q53: ='Balance sheet'!Q28/'Balance sheet'!Q$34 -> 0.00012563978
B54: Other financial assets | C54: ='Balance sheet'!C29/'Balance sheet'!C$34 -> 0.073528933 | D54: ='Balance sheet'!D29/'Balance sheet'!D$34 -> 0.083599257 | E54: ='Balance sheet'!E29/'Balance sheet'!E$34 -> 0.07457811 | F54: ='Balance sheet'!F29/'Balance sheet'!F$34 -> 0.061616076 | G54: ='Balance sheet'!G29/'Balance sheet'!G$34 -> 0.052770716 | H54: ='Balance sheet'!H29/'Balance sheet'!H$34 -> 0.067099483 | I54: ='Balance sheet'!I29/'Balance sheet'!I$34 -> 0.067894583 | J54: ='Balance sheet'!J29/'Balance sheet'!J$34 -> 0.0678475 | ... Q54: ='Balance sheet'!Q29/'Balance sheet'!Q$34 -> 0.056858113
B55: Other assets | C55: ='Balance sheet'!C30/'Balance sheet'!C$34 -> 0.019545528 | D55: ='Balance sheet'!D30/'Balance sheet'!D$34 -> 0.030150843 | E55: ='Balance sheet'!E30/'Balance sheet'!E$34 -> 0.027394672 | F55: ='Balance sheet'!F30/'Balance sheet'!F$34 -> 0.021323166 | G55: ='Balance sheet'!G30/'Balance sheet'!G$34 -> 0.016915447 | H55: ='Balance sheet'!H30/'Balance sheet'!H$34 -> 0.022261827 | I55: ='Balance sheet'!I30/'Balance sheet'!I$34 -> 0.02252562 | J55: ='Balance sheet'!J30/'Balance sheet'!J$34 -> 0.022509999 | ... Q55: ='Balance sheet'!Q30/'Balance sheet'!Q$34 -> 0.018864012
B57: Total current assets | C57: ='Balance sheet'!C32/'Balance sheet'!C$34 -> 0.80756006 | D57: ='Balance sheet'!D32/'Balance sheet'!D$34 -> 0.82433934 | E57: ='Balance sheet'!E32/'Balance sheet'!E$34 -> 0.65392515 | F57: ='Balance sheet'!F32/'Balance sheet'!F$34 -> 0.79089684 | G57: ='Balance sheet'!G32/'Balance sheet'!G$34 -> 0.59568748 | H57: ='Balance sheet'!H32/'Balance sheet'!H$34 -> 0.57302322 | I57: ='Balance sheet'!I32/'Balance sheet'!I$34 -> 0.62510659 | J57: ='Balance sheet'!J32/'Balance sheet'!J$34 -> 0.6678779 | ... Q57: ='Balance sheet'!Q32/'Balance sheet'!Q$34 -> 0.82144209
...

Sheet Cost Buildup
B5: Cost Build_Up
B6: (All amounts in INR Lakhs, unless otherwise stated)
A7: # | B7: Particulars | C7: 2021 | D7: =C7+1 -> 2022 | E7: =D7+1 -> 2023 | F7: =E7+1 -> 2024 | G7: =F7+1 -> 2025 | H7: =G7+1 -> 2026 | I7: =H7+1 -> 2027 | J7: =I7+1 -> 2028 | K7: =J7+1 -> 2029 | ... Q7: =P7+1 -> 2035
C8: Audited | D8: Audited | E8: Audited | F8: Audited | G8: Audited | H8: Estimated | I8: Projected | J8: Projected | K8: Projected | L8: Projected | M8: Projected | N8: Projected | O8: Projected | P8: Projected | Q8: Projected
B10: Revenue | C10: ='Revenue BuildUp'!C10 -> 77341 | D10: ='Revenue BuildUp'!D10 -> 109365 | E10: ='Revenue BuildUp'!E10 -> 142929 | F10: ='Revenue BuildUp'!F10 -> 162466 | G10: ='Revenue BuildUp'!G10 -> 206084 | H10: ='Revenue BuildUp'!H10 -> 251738.78 | I10: ='Revenue BuildUp'!I10 -> 299960.77 | J10: ='Revenue BuildUp'!J10 -> 349602.74 | ... Q10: ='Revenue BuildUp'!Q10 -> 661200.04
B13: Employee benefits expense | C13: ='Historical P&L'!C15 -> 45238 | D13: ='Historical P&L'!D15 -> 62000 | E13: ='Historical P&L'!E15 -> 80681 | F13: ='Historical P&L'!F15 -> 101469 | G13: ='Historical P&L'!G15 -> 136534 | H13: =H14*H10 -> 151213.43 | I13: =I14*I10 -> 180179.22 | J13: =J14*J10 -> 209997.96 | K13: =K14*K10 -> 240001.76 | L13: =L14*L10 -> 269588.06 | M13: =M14*M10 -> 298247.87 | N13: =N14*N10 -> 325579.35 | O13: =O14*O10 -> 351289.36 | ... Q13: =Q14*Q10 -> 397166.96
B14: % of Revenue | C14: =C13/C10 -> 0.58491615 | D14: =D13/D10 -> 0.56690897 | E14: =E13/E10 -> 0.56448307 | F14: =F13/F10 -> 0.62455529 | G14: =G13/G10 -> 0.66251626 | H14: =AVERAGE(C14:G14) -> 0.60067595 | I14: =H14 -> 0.60067595 | J14: =I14 -> 0.60067595 | K14: =J14 -> 0.60067595 | L14: =K14 -> 0.60067595 | M14: =L14 -> 0.60067595 | N14: =M14 -> 0.60067595 | O14: =N14 -> 0.60067595 | P14: =O14 -> 0.60067595 | Q14: =P14 -> 0.60067595
B16: Other expenses | C16: ='Historical P&L'!C18 -> 12954 | D16: ='Historical P&L'!D18 -> 21598 | E16: ='Historical P&L'!E18 -> 26362 | F16: ='Historical P&L'!F18 -> 26882 | G16: ='Historical P&L'!G18 -> 32518 | H16: =H17*H10 -> 43937.03 | I16: =I17*I10 -> 52353.416 | J16: =J17*J10 -> 61017.639 | K16: =K17*K10 -> 69735.634 | L16: =L17*L10 -> 78332.319 | M16: =M17*M10 -> 86659.8 | N16: =N17*N10 -> 94601.318 | O16: =O17*O10 -> 102071.69 | ... Q16: =Q17*Q10 -> 115402.03
B17: % of Revenue | C17: =C16/C10 -> 0.16749202 | D17: =D16/D10 -> 0.19748548 | E17: =E16/E10 -> 0.18444123 | F17: =F16/F10 -> 0.16546231 | G17: =G16/G10 -> 0.15779003 | H17: =AVERAGE(C17:G17) -> 0.17453421 | I17: =H17 -> 0.17453421 | J17: =I17 -> 0.17453421 | K17: =J17 -> 0.17453421 | L17: =K17 -> 0.17453421 | M17: =L17 -> 0.17453421 | N17: =M17 -> 0.17453421 | O17: =N17 -> 0.17453421 | P17: =O17 -> 0.17453421 | Q17: =P17 -> 0.17453421
B19: Impairment loss allowance on trade and unbilled receivables | C19: ='Historical P&L'!C19 -> 0 | D19: ='Historical P&L'!D19 -> 0 | E19: ='Historical P&L'!E19 -> 0 | F19: ='Historical P&L'!F19 -> 530 | G19: ='Historical P&L'!G19 -> 1590 | H19: =H20*H10 -> 552.69358 | I19: =I20*I10 -> 658.56516 | J19: =J20*J10 -> 767.55433 | K19: =K20*K10 -> 877.2199 | L19: =L20*L10 -> 985.3595 | M19: =M20*M10 -> 1090.1127 | N19: =N20*N10 -> 1190.0108 | O19: =O20*O10 -> 1283.9823 | ... Q19: =Q20*Q10 -> 1451.6675
B20: % of Revenue | C20: =C19/C10 -> 0 | D20: =D19/D10 -> 0 | E20: =E19/E10 -> 0 | F20: =F19/F10 -> 0.003262221 | G20: =G19/G10 -> 0.0077153006 | H20: =AVERAGE(C20:G20) -> 0.0021955043 | I20: =H20 -> 0.0021955043 | J20: =I20 -> 0.0021955043 | K20: =J20 -> 0.0021955043 | L20: =K20 -> 0.0021955043 | M20: =L20 -> 0.0021955043 | N20: =M20 -> 0.0021955043 | O20: =N20 -> 0.0021955043 | P20: =O20 -> 0.0021955043 | Q20: =P20 -> 0.0021955043
B22: Taxes | C22: ='Historical P&L'!C27+'Historical P&L'!C28+'Historical P&L'!C29 -> 2356 | D22: ='Historical P&L'!D27+'Historical P&L'!D28+'Historical P&L'!D29 -> 6465 | E22: ='Historical P&L'!E27+'Historical P&L'!E28+'Historical P&L'!E29 -> 7887 | F22: ='Historical P&L'!F27+'Historical P&L'!F28+'Historical P&L'!F29 -> 8629 | G22: ='Historical P&L'!G27+'Historical P&L'!G28+'Historical P&L'!G29 -> 7080 | H22: =H23*'Profit & Loss Statement'!H28 -> 14921.03 | I22: =I23*'Profit & Loss Statement'!I28 -> 18587.46 | J22: =J23*'Profit & Loss Statement'!J28 -> 22250.989 | K22: =K23*'Profit & Loss Statement'!K28 -> 25602.055 | L22: =L23*'Profit & Loss Statement'!L28 -> 29406.275 | M22: =M23*'Profit & Loss Statement'!M28 -> 32656.288 | N22: =N23*'Profit & Loss Statement'!N28 -> 36364.659 | O22: =O23*'Profit & Loss Statement'!O28 -> 39324.647 | ... Q22: =Q23*'Profit & Loss Statement'!Q28 -> 45028.166
B23: % of EBT | C23: =C22/'Historical P&L'!C24 -> 0.12665305 | D23: =D22/'Historical P&L'!D24 -> 0.26296522 | E23: =E22/'Historical P&L'!E24 -> 0.25453431 | F23: =F22/'Historical P&L'!F24 -> 0.25782837 | G23: =G22/'Historical P&L'!G24 -> 0.27714711 | H23: =G23+Assumption!C15 -> 0.28214711 | I23: =H23 -> 0.28214711 | J23: =I23+Assumption!C15 -> 0.28714711 | K23: =J23 -> 0.28714711 | L23: =K23+Assumption!C15 -> 0.29214711 | M23: =L23 -> 0.29214711 | N23: =M23+Assumption!C15 -> 0.29714711 | O23: =N23 -> 0.29714711 | P23: 0.3 | Q23: =P23 -> 0.3

Sheet FAS
B7: Fixed Assets Schedules
B8: (All amounts in INR Lakhs, unless otherwise stated)
A9: # | B9: Particulars | C9: 2021 | D9: =C9+1 -> 2022 | E9: =D9+1 -> 2023 | F9: =E9+1 -> 2024 | G9: =F9+1 -> 2025 | H9: =G9+1 -> 2026 | I9: =H9+1 -> 2027 | J9: =I9+1 -> 2028 | K9: =J9+1 -> 2029 | ... Q9: =P9+1 -> 2035
C10: Audited | D10: Audited | E10: Audited | F10: Audited | G10: Audited | H10: Estimated | I10: Projected | J10: Projected | K10: Projected | L10: Projected | M10: Projected | N10: Projected | O10: Projected | P10: Projected | Q10: Projected
A11: # | B11: Property, plant and equipment
B13: Land
B14: Opening Gross Block | C14: 0 | D14: =C21 -> 0 | E14: =D21 -> 0 | F14: =E21 -> 4423 | G14: =F21 -> 4423 | H14: =G21 -> 4423 | I14: =H21 -> 5307.6 | J14: =I21 -> 6196.623 | K14: =J21 -> 7090.0911 | ... Q14: =P21 -> 12545.5
B15: Acquisition of subsidiary | C15: 0 | D15: 0 | E15: 0 | F15: 0 | G15: 0 | H15: 0 | I15: 0 | J15: 0 | K15: 0 | L15: 0 | M15: 0 | N15: 0 | O15: 0 | P15: 0 | Q15: 0
B16: Additions | C16: 0 | D16: 0 | E16: 4423 | F16: 0 | G16: 0 | H16: =AVERAGE(C16:G16) -> 884.6 | I16: =H16*(1+Assumption!$C$14) -> 889.023 | J16: =I16*(1+Assumption!$C$14) -> 893.46811 | K16: =J16*(1+Assumption!$C$14) -> 897.93546 | L16: =K16*(1+Assumption!$C$14) -> 902.42513 | M16: =L16*(1+Assumption!$C$14) -> 906.93726 | N16: =M16*(1+Assumption!$C$14) -> 911.47194 | O16: =N16*(1+Assumption!$C$14) -> 916.0293 | P16: =O16*(1+Assumption!$C$14) -> 920.60945 | Q16: =P16*(1+Assumption!$C$14) -> 925.2125
B17: Transfers from CWIP | C17: 0 | D17: 0 | E17: 0 | F17: 0 | G17: 0 | H17: 0 | I17: 0 | J17: 0 | K17: 0 | L17: 0 | M17: 0 | N17: 0 | O17: 0 | P17: 0 | Q17: 0
B18: Disposals | C18: 0 | D18: 0 | E18: 0 | F18: 0 | G18: 0 | H18: 0 | I18: 0 | J18: 0 | K18: 0 | L18: 0 | M18: 0 | N18: 0 | O18: 0 | P18: 0 | Q18: 0
B19: Deletion on liquidation of subsidiary | C19: 0 | D19: 0 | E19: 0 | F19: 0 | G19: 0 | H19: 0 | I19: 0 | J19: 0 | K19: 0 | L19: 0 | M19: 0 | N19: 0 | O19: 0 | P19: 0 | Q19: 0
B20: Exchange difference | C20: 0 | D20: 0 | E20: 0 | F20: 0 | G20: 0 | H20: 0 | I20: 0 | J20: 0 | K20: 0 | L20: 0 | M20: 0 | N20: 0 | O20: 0 | P20: 0 | Q20: 0
B21: Closing Gross Block | C21: =SUM(C14:C19) -> 0 | D21: =SUM(D14:D19) -> 0 | E21: =SUM(E14:E19) -> 4423 | F21: =SUM(F14:F19) -> 4423 | G21: =SUM(G14:G19) -> 4423 | H21: =SUM(H14:H19) -> 5307.6 | I21: =SUM(I14:I19) -> 6196.623 | J21: =SUM(J14:J19) -> 7090.0911 | ... Q21: =SUM(Q14:Q19) -> 13470.712
B22: Accumulated Dep | C22: 0 | D22: 0 | E22: 0 | F22: 0 | G22: 0 | H22: 0 | I22: 0 | J22: 0 | K22: 0 | L22: 0 | M22: 0 | N22: 0 | O22: 0 | P22: 0 | Q22: 0
B23: charge for the year | C23: 0 | D23: 0 | E23: 0 | F23: 0 | G23: 0 | H23: 0 | I23: 0 | J23: 0 | K23: 0 | L23: 0 | M23: 0 | N23: 0 | O23: 0 | P23: 0 | Q23: 0
B24: Disposals | C24: 0 | D24: 0 | E24: 0 | F24: 0 | G24: 0 | H24: 0 | I24: 0 | J24: 0 | K24: 0 | L24: 0 | M24: 0 | N24: 0 | O24: 0 | P24: 0 | Q24: 0
B25: Exchange difference | C25: 0 | D25: 0 | E25: 0 | F25: 0 | G25: 0 | H25: 0 | I25: 0 | J25: 0 | K25: 0 | L25: 0 | M25: 0 | N25: 0 | O25: 0 | P25: 0 | Q25: 0
B26: Deletion on liquidation of subsidiary | C26: 0 | D26: 0 | E26: 0 | F26: 0 | G26: 0 | H26: 0 | I26: 0 | J26: 0 | K26: 0 | L26: 0 | M26: 0 | N26: 0 | O26: 0 | P26: 0 | Q26: 0
B27: Total | C27: 0 | D27: 0 | E27: =SUM(E22:E26) -> 0 | F27: =SUM(F22:F26) -> 0 | G27: =SUM(G22:G26) -> 0 | H27: =SUM(H22:H26) -> 0 | I27: =SUM(I22:I26) -> 0 | J27: =SUM(J22:J26) -> 0 | K27: =SUM(K22:K26) -> 0 | L27: =SUM(L22:L26) -> 0 | ... Q27: =SUM(Q22:Q26) -> 0
B29: Net Block | C29: 0 | D29: 0 | E29: =E21-E27 -> 4423 | F29: =F21-F27 -> 4423 | G29: =G21-G27 -> 4423 | H29: =H21-H27 -> 5307.6 | I29: =I21-I27 -> 6196.623 | J29: =J21-J27 -> 7090.0911 | K29: =K21-K27 -> 7988.0266 | L29: =L21-L27 -> 8890.4517 | ... Q29: =Q21-Q27 -> 13470.712
B32: Building
B33: Opening Gross Block | C33: 0 | D33: 0 | E33: 0 | F33: =E40 -> 8354 | G33: =F40 -> 8486 | H33: =G40 -> 8486 | I33: =H40 -> 10156.8 | J33: =I40 -> 11835.954 | K33: =J40 -> 13523.504 | L33: =K40 -> 15219.491 | M33: =L40 -> 16923.959 | ... Q33: =P40 -> 23827.479
B34: Acquisition of subsidiary | C34: 0 | D34: 0 | E34: 0 | F34: 0 | G34: 0 | H34: 0 | I34: 0 | J34: 0 | K34: 0 | L34: 0 | M34: 0 | N34: 0 | O34: 0 | P34: 0 | Q34: 0
B35: Additions | C35: 0 | D35: 0 | E35: 8354 | F35: 0 | G35: 0 | H35: =AVERAGE(C35:G35) -> 1670.8 | I35: =H35*(1+Assumption!$C$14) -> 1679.154 | J35: =I35*(1+Assumption!$C$14) -> 1687.5498 | K35: =J35*(1+Assumption!$C$14) -> 1695.9875 | L35: =K35*(1+Assumption!$C$14) -> 1704.4675 | M35: =L35*(1+Assumption!$C$14) -> 1712.9898 | N35: =M35*(1+Assumption!$C$14) -> 1721.5547 | O35: =N35*(1+Assumption!$C$14) -> 1730.1625 | P35: =O35*(1+Assumption!$C$14) -> 1738.8133 | Q35: =P35*(1+Assumption!$C$14) -> 1747.5074
B36: Transfers from CWIP | C36: 0 | D36: 0 | E36: 0 | F36: 132 | G36: 0 | H36: 0 | I36: 0 | J36: 0 | K36: 0 | L36: 0 | M36: 0 | N36: 0 | O36: 0 | P36: 0 | Q36: 0
B37: Disposals | C37: 0 | D37: 0 | E37: 0 | F37: 0 | G37: 0 | H37: 0 | I37: 0 | J37: 0 | K37: 0 | L37: 0 | M37: 0 | N37: 0 | O37: 0 | P37: 0 | Q37: 0
B38: Deletion on liquidation of subsidiary | C38: 0 | D38: 0 | E38: 0 | F38: 0 | G38: 0 | H38: 0 | I38: 0 | J38: 0 | K38: 0 | L38: 0 | M38: 0 | N38: 0 | O38: 0 | P38: 0 | Q38: 0
B39: Exchange difference | C39: 0 | D39: 0 | E39: 0 | F39: 0 | G39: 0 | H39: 0 | I39: 0 | J39: 0 | K39: 0 | L39: 0 | M39: 0 | N39: 0 | O39: 0 | P39: 0 | Q39: 0
B40: Closing Gross Block | C40: 0 | D40: 0 | E40: =SUM(E33:E38) -> 8354 | F40: =SUM(F33:F38) -> 8486 | G40: =SUM(G33:G38) -> 8486 | H40: =SUM(H33:H38) -> 10156.8 | I40: =SUM(I33:I38) -> 11835.954 | J40: =SUM(J33:J38) -> 13523.504 | K40: =SUM(K33:K38) -> 15219.491 | L40: =SUM(L33:L38) -> 16923.959 | ... Q40: =SUM(Q33:Q38) -> 25574.987
B41: Accumulated Dep | C41: 0 | D41: 0 | E41: 0 | F41: =E46 -> 119 | G41: =F46 -> 287 | H41: =G46 -> 476 | I41: =H46 -> 571.2 | J41: =I46 -> 666.876 | K41: =J46 -> 763.03038 | L41: =K46 -> 859.66553 | M41: =L46 -> 956.78386 | ... Q41: =P46 -> 1350.1374
B42: charge for the year | C42: 0 | D42: 0 | E42: 119 | F42: 168 | G42: 189 | H42: =AVERAGE(C42:G42) -> 95.2 | I42: =H42*(1+Assumption!$C$16) -> 95.676 | J42: =I42*(1+Assumption!$C$16) -> 96.15438 | K42: =J42*(1+Assumption!$C$16) -> 96.635152 | L42: =K42*(1+Assumption!$C$16) -> 97.118328 | M42: =L42*(1+Assumption!$C$16) -> 97.603919 | N42: =M42*(1+Assumption!$C$16) -> 98.091939 | O42: =N42*(1+Assumption!$C$16) -> 98.582399 | P42: =O42*(1+Assumption!$C$16) -> 99.075311 | Q42: =P42*(1+Assumption!$C$16) -> 99.570687
B43: Disposals | C43: 0 | D43: 0 | E43: 0 | F43: 0 | G43: 0 | H43: 0 | I43: 0 | J43: 0 | K43: 0 | L43: 0 | M43: 0 | N43: 0 | O43: 0 | P43: 0 | Q43: 0
B44: Exchange difference | C44: 0 | D44: 0 | E44: 0 | F44: 0 | G44: 0 | H44: 0 | I44: 0 | J44: 0 | K44: 0 | L44: 0 | M44: 0 | N44: 0 | O44: 0 | P44: 0 | Q44: 0
B45: Deletion on liquidation of subsidiary | C45: 0 | D45: 0 | E45: 0 | F45: 0 | G45: 0 | H45: 0 | I45: 0 | J45: 0 | K45: 0 | L45: 0 | M45: 0 | N45: 0 | O45: 0 | P45: 0 | Q45: 0
B46: Total | E46: =SUM(E41:E45) -> 119 | F46: =SUM(F41:F45) -> 287 | G46: =SUM(G41:G45) -> 476 | H46: =SUM(H41:H45) -> 571.2 | I46: =SUM(I41:I45) -> 666.876 | J46: =SUM(J41:J45) -> 763.03038 | K46: =SUM(K41:K45) -> 859.66553 | L46: =SUM(L41:L45) -> 956.78386 | ... Q46: =SUM(Q41:Q45) -> 1449.7081
B48: Net Block | E48: =E40-E46 -> 8235 | F48: =F40-F46 -> 8199 | G48: =G40-G46 -> 8010 | H48: =H40-H46 -> 9585.6 | I48: =I40-I46 -> 11169.078 | J48: =J40-J46 -> 12760.473 | K48: =K40-K46 -> 14359.826 | L48: =L40-L46 -> 15967.175 | ... Q48: =Q40-Q46 -> 24125.278
B51: computer Systems
