Workbook

Sheet Assumption
B8: Scenario
B9: Base | C9: =IF(B9="Best",1,IF(B9="Base",2,3)) -> 2
B12: Assumptions
B13: Transaction Date | C13: 45883
B14: Fiscal Year End | C14: 46112
B15: Risk Free Rate | C15: 0.06463
B16: Tax Rate | C16: 0.22228215
B17: EV/EBITDA Multiple | C17: ='Comps Valuation'!E36 -> 37.419896
B18: Perpetual Growth Rate | C18: 0.05
B19: Discount Rate | C19: =WACC!C52 -> 0.080628449
B20: Shares Outstanding(Cr.) | C20: 129.78
B21: Current market price | C21: 711
B22: Market Cap (Cr.) | C22: =C21*C20 -> 92273.58
B24: Color Code
B25: Blue color | C25: Hardcoded Figures
B26: Black color | C26: Calculated/Formula Figures
B27: Green color | C27: Linked sheet

Sheet Income Statement
B6: Income Statement
B7: All Figure In INR Cr.
B8: Particular | C8: 2021 | D8: =C8+1 -> 2022 | E8: =D8+1 -> 2023 | F8: =E8+1 -> 2024 | G8: =F8+1 -> 2025
B9: Income
B10: Revenue from operations | C10: 8048 | D10: 9512 | E10: 9764 | F10: 9653 | G10: 10831
B11: Other income | C11: 94 | D11: 98 | E11: 144 | F11: 142 | G11: 208
B12: Total Income | C12: =SUM(C10:C11) -> 8142 | D12: =SUM(D10:D11) -> 9610 | E12: =SUM(E10:E11) -> 9908 | F12: =SUM(F10:F11) -> 9795 | G12: =SUM(G10:G11) -> 11039
B13: Expenses
B14: Cost of materials consumed | C14: 3884 | D14: 5061 | E14: 4649 | F14: 3941 | G14: 4572
B15: Purchases of stock-in-trade | C15: 339 | D15: 491 | E15: 541 | F15: 752 | G15: 960
B16: Changes in inventories of finished goods, stock-in-trade and work-in progress | C16: 47 | D16: -116 | E16: 161 | F16: 55 | G16: -144
B17: Employee benefit expense | C17: 570 | D17: 586 | E17: 653 | F17: 743 | G17: 831
B18: Finance costs | C18: 34 | D18: 39 | E18: 56 | F18: 73 | G18: 53
B19: Depreciation and amortization expense | C19: 139 | D19: 139 | E19: 155 | F19: 158 | G19: 178
B20: Other expenses | C20: 1617 | D20: 1809 | E20: 1950 | F20: 2136 | G20: 2473
B21: Total expenses | C21: =SUM(C14:C20) -> 6630 | D21: =SUM(D14:D20) -> 8009 | E21: =SUM(E14:E20) -> 8165 | F21: =SUM(F14:F20) -> 7858 | G21: =SUM(G14:G20) -> 8923
B22: Profit before exceptional items and tax | C22: =C12-C21 -> 1512 | D22: =D12-D21 -> 1601 | E22: =E12-E21 -> 1743 | F22: =F12-F21 -> 1937 | G22: =G12-G21 -> 2116
B23: Share of net gain/(loss) of joint ventures | C23: -2
B24: Profit before exceptional items and tax | C24: =C22+C23 -> 1510 | D24: =D22+D23 -> 1601 | E24: =E22+E23 -> 1743 | F24: =F22+F23 -> 1937 | G24: =G22+G23 -> 2116
B25: Exceptional items | C25: 13
B26: Profit before tax | C26: =C24+C25 -> 1523 | D26: =D24+D25 -> 1601 | E26: =E24+E25 -> 1743 | F26: =F24+F25 -> 1937 | G26: =G24+G25 -> 2116
B27: Income tax expense
B28: Tax expense for the current year | C28: 324 | D28: 346 | E28: 421 | F28: 435 | G28: 458
B29: Profit for the year (A) | C29: =C26-C28 -> 1199 | D29: =D26-D28 -> 1255 | E29: =E26-E28 -> 1322 | F29: =F26-F28 -> 1502 | G29: =G26-G28 -> 1658

Sheet P&L Statement 
B6: Income Statement
B7: All Figure In INR Cr.
B8: Particulars | C8: 2021 | D8: =C8+1 -> 2022 | E8: =D8+1 -> 2023 | F8: =E8+1 -> 2024 | G8: =F8+1 -> 2025 | H8: =G8+1 -> 2026 | I8: =H8+1 -> 2027 | J8: =I8+1 -> 2028 | K8: =J8+1 -> 2029 | ... Q8: =P8+1 -> 2035
B10: Revenue | C10: ='Revenue BuildUp'!C11 -> 8048 | D10: ='Revenue BuildUp'!D11 -> 9512 | E10: ='Revenue BuildUp'!E11 -> 9764 | F10: ='Revenue BuildUp'!F11 -> 9653 | G10: ='Revenue BuildUp'!G11 -> 10831 | H10: ='Revenue BuildUp'!H11 -> 11829.458 | I10: ='Revenue BuildUp'!I11 -> 12984.788 | J10: ='Revenue BuildUp'!J11 -> 14334.34 | ... Q10: ='Revenue BuildUp'!Q11 -> 35620.804
B11: COGS | C11: =-'Cost BuildUp'!C13 -> -4270 | D11: =-'Cost BuildUp'!D13 -> -5436 | E11: =-'Cost BuildUp'!E13 -> -5351 | F11: =-'Cost BuildUp'!F13 -> -4748 | G11: =-'Cost BuildUp'!G13 -> -5388 | H11: =-'Cost BuildUp'!H13 -> -6244.576 | I11: =-'Cost BuildUp'!I13 -> -6854.4558 | J11: =-'Cost BuildUp'!J13 -> -7566.8621 | ... Q11: =-'Cost BuildUp'!Q13 -> -18803.636
B12: Gross Profit | C12: =SUM(C10:C11) -> 3778 | D12: =SUM(D10:D11) -> 4076 | E12: =SUM(E10:E11) -> 4413 | F12: =SUM(F10:F11) -> 4905 | G12: =SUM(G10:G11) -> 5443 | H12: =SUM(H10:H11) -> 5584.8819 | I12: =SUM(I10:I11) -> 6130.3324 | J12: =SUM(J10:J11) -> 6767.4782 | ... Q12: =SUM(Q10:Q11) -> 16817.168
B13: Gross Margin | C13: =C12/C10 -> 0.4694334 | D13: =D12/D10 -> 0.42851135 | E13: =E12/E10 -> 0.45196641 | F13: =F12/F10 -> 0.50813219 | G13: =G12/G10 -> 0.50253901 | H13: =H12/H10 -> 0.47211647 | I13: =I12/I10 -> 0.47211647 | J13: =J12/J10 -> 0.47211647 | ... Q13: =Q12/Q10 -> 0.47211647
B15: Salaries & Benefits | C15: =-'Cost BuildUp'!C26 -> -570 | D15: =-'Cost BuildUp'!D26 -> -586 | E15: =-'Cost BuildUp'!E26 -> -653 | F15: =-'Cost BuildUp'!F26 -> -743 | G15: =-'Cost BuildUp'!G26 -> -831 | H15: =-'Cost BuildUp'!H26 -> -835.17126 | I15: =-'Cost BuildUp'!I26 -> -916.73871 | J15: =-'Cost BuildUp'!J26 -> -1012.0184 | ... Q15: =-'Cost BuildUp'!Q26 -> -2514.8635
B16: S&G Expenses | C16: =-'Cost BuildUp'!C29 -> -1617 | D16: =-'Cost BuildUp'!D29 -> -1809 | E16: =-'Cost BuildUp'!E29 -> -1950 | F16: =-'Cost BuildUp'!F29 -> -2136 | G16: =-'Cost BuildUp'!G29 -> -2473 | H16: =-'Cost BuildUp'!H29 -> -2461.5162 | I16: =-'Cost BuildUp'!I29 -> -2701.9215 | J16: =-'Cost BuildUp'!J29 -> -2982.7411 | ... Q16: =-'Cost BuildUp'!Q29 -> -7412.1051
B18: EBITDA | C18: =SUM(C12,C15:C16) -> 1591 | D18: =SUM(D12,D15:D16) -> 1681 | E18: =SUM(E12,E15:E16) -> 1810 | F18: =SUM(F12,F15:F16) -> 2026 | G18: =SUM(G12,G15:G16) -> 2139 | H18: =SUM(H12,H15:H16) -> 2288.1945 | I18: =SUM(I12,I15:I16) -> 2511.6722 | J18: =SUM(J12,J15:J16) -> 2772.7186 | ... Q18: =SUM(Q12,Q15:Q16) -> 6890.1996
B19: EBITDA Margin | C19: =C18/C10 -> 0.19768887 | D19: =D18/D10 -> 0.17672414 | E19: =E18/E10 -> 0.18537485 | F19: =F18/F10 -> 0.20988294 | G19: =G18/G10 -> 0.19748869 | H19: =H18/H10 -> 0.1934319 | I19: =I18/I10 -> 0.1934319 | J19: =J18/J10 -> 0.1934319 | ... Q19: =Q18/Q10 -> 0.1934319
B21: Dep & Amortization | C21: =-'Income Statement'!C19 -> -139 | D21: =-'Income Statement'!D19 -> -139 | E21: =-'Income Statement'!E19 -> -155 | F21: =-'Income Statement'!F19 -> -158 | G21: =-'Income Statement'!G19 -> -178 | H21: =-'FAS Seechules'!H86 -> -160.8108 | I21: =-'FAS Seechules'!I86 -> -195.72191 | J21: =-'FAS Seechules'!J86 -> -238.54858 | K21: =-'FAS Seechules'!K86 -> -291.16514 | L21: =-'FAS Seechules'!L86 -> -355.90783 | M21: =-'FAS Seechules'!M86 -> -435.69258 | N21: =-'FAS Seechules'!N86 -> -534.1636 | O21: =-'FAS Seechules'!O86 -> -655.88117 | ... Q21: =-'FAS Seechules'!Q86 -> -993.36431
B23: EBIT | C23: =SUM(C18,C21) -> 1452 | D23: =SUM(D18,D21) -> 1542 | E23: =SUM(E18,E21) -> 1655 | F23: =SUM(F18,F21) -> 1868 | G23: =SUM(G18,G21) -> 1961 | H23: =SUM(H18,H21) -> 2127.3837 | I23: =SUM(I18,I21) -> 2315.9503 | J23: =SUM(J18,J21) -> 2534.17 | ... Q23: =SUM(Q18,Q21) -> 5896.8353
B24: EBIT Margin | C24: =C23/C10 -> 0.1804175 | D24: =D23/D10 -> 0.16211102 | E24: =E23/E10 -> 0.1695002 | F24: =F23/F10 -> 0.19351497 | G24: =G23/G10 -> 0.18105438 | H24: =H23/H10 -> 0.1798378 | I24: =I23/I10 -> 0.17835873 | J24: =J23/J10 -> 0.17679014 | ... Q24: =Q23/Q10 -> 0.1655447
B26: Interest Cost | C26: =-'Income Statement'!C18 -> -34 | D26: =-'Income Statement'!D18 -> -39 | E26: =-'Income Statement'!E18 -> -56 | F26: =-'Income Statement'!F18 -> -73 | G26: =-'Income Statement'!G18 -> -53 | H26: =-'Debt Schedules'!H14 -> -63.701955 | I26: =-'Debt Schedules'!I14 -> -69.958187 | J26: =-'Debt Schedules'!J14 -> -77.272682 | K26: =-'Debt Schedules'!K14 -> -85.907524 | L26: =-'Debt Schedules'!L14 -> -96.20011 | M26: =-'Debt Schedules'!M14 -> -108.58572 | N26: =-'Debt Schedules'!N14 -> -123.62692 | O26: =-'Debt Schedules'!O14 -> -142.05187 | ... Q26: =-'Debt Schedules'!Q14 -> -175.12579
B27: Other Income | C27: ='Revenue BuildUp'!C63 -> 94 | D27: ='Revenue BuildUp'!D63 -> 98 | E27: ='Revenue BuildUp'!E63 -> 144 | F27: ='Revenue BuildUp'!F63 -> 142 | G27: ='Revenue BuildUp'!G63 -> 208 | H27: ='Revenue BuildUp'!H63 -> 167.13921 | I27: ='Revenue BuildUp'!I63 -> 183.46295 | J27: ='Revenue BuildUp'!J63 -> 202.53087 | ... Q27: ='Revenue BuildUp'!Q63 -> 503.28875
B29: Profit before share of profit/ (loss) of associates and tax | C29: =SUM(C23,C26,C27) -> 1512 | D29: =SUM(D23,D26,D27) -> 1601 | E29: =SUM(E23,E26,E27) -> 1743 | F29: =SUM(F23,F26,F27) -> 1937 | G29: =SUM(G23,G26,G27) -> 2116 | H29: =SUM(H23,H26,H27) -> 2230.8209 | I29: =SUM(I23,I26,I27) -> 2429.455 | J29: =SUM(J23,J26,J27) -> 2659.4282 | ... Q29: =SUM(Q23,Q26,Q27) -> 6224.9982
B31: Share in profit/(loss) of associates (net of tax) | C31: ='Income Statement'!C23 -> -2 | D31: ='Income Statement'!D23 -> 0 | E31: ='Income Statement'!E23 -> 0 | F31: ='Income Statement'!F23 -> 0 | G31: ='Income Statement'!G23 -> 0 | H31: ='Income Statement'!H23 -> 0 | I31: ='Income Statement'!I23 -> 0 | J31: ='Income Statement'!J23 -> 0 | ... Q31: ='Income Statement'!Q23 -> 0
B32: Exceptional item | C32: ='Income Statement'!C25 -> 13 | D32: ='Income Statement'!D25 -> 0 | E32: ='Income Statement'!E25 -> 0 | F32: ='Income Statement'!F25 -> 0 | G32: ='Income Statement'!G25 -> 0 | H32: ='Income Statement'!H25 -> 0 | I32: ='Income Statement'!I25 -> 0 | J32: ='Income Statement'!J25 -> 0 | ... Q32: ='Income Statement'!Q25 -> 0
B34: EBT | C34: =SUM(C29:C33) -> 1523 | D34: =SUM(D29:D33) -> 1601 | E34: =SUM(E29:E33) -> 1743 | F34: =SUM(F29:F33) -> 1937 | G34: =SUM(G29:G33) -> 2116 | H34: =SUM(H29:H33) -> 2230.8209 | I34: =SUM(I29:I33) -> 2429.455 | J34: =SUM(J29:J33) -> 2659.4282 | ... Q34: =SUM(Q29:Q33) -> 6224.9982
B35: EBT Margin | C35: =C34/C10 -> 0.18923956 | D35: =D34/D10 -> 0.16831371 | E35: =E34/E10 -> 0.1785129 | F35: =F34/F10 -> 0.20066301 | G35: =G34/G10 -> 0.19536516 | H35: =H34/H10 -> 0.18858184 | I35: =I34/I10 -> 0.18710009 | J35: =J34/J10 -> 0.18552847 | ... Q35: =Q34/Q10 -> 0.17475738
B37: Tax | C37: ='Income Statement'!C28 -> 324 | D37: ='Income Statement'!D28 -> 346 | E37: ='Income Statement'!E28 -> 421 | F37: ='Income Statement'!F28 -> 435 | G37: ='Income Statement'!G28 -> 458 | H37: =H34*'Revenue BuildUp'!H67 -> 495.87166 | I37: =I34*'Revenue BuildUp'!I67 -> 540.02448 | J37: =J34*'Revenue BuildUp'!J67 -> 591.14342 | K37: =K34*'Revenue BuildUp'!K67 -> 650.9658 | L37: =L34*'Revenue BuildUp'!L67 -> 721.74464 | M37: =M34*'Revenue BuildUp'!M67 -> 806.40772 | N37: =N34*'Revenue BuildUp'!N67 -> 908.76586 | O37: =O34*'Revenue BuildUp'!O67 -> 1033.7857 | ... Q37: =Q34*'Revenue BuildUp'!Q67 -> 1383.706
B39: Net Profit | C39: =C34-C37 -> 1199 | D39: =D34-D37 -> 1255 | E39: =E34-E37 -> 1322 | F39: =F34-F37 -> 1502 | G39: =G34-G37 -> 1658 | H39: =H34-H37 -> 1734.9493 | I39: =I34-I37 -> 1889.4306 | J39: =J34-J37 -> 2068.2848 | ... Q39: =Q34-Q37 -> 4841.2923
B40: Net Profit Margin | C40: =C39/C10 -> 0.14898111 | D40: =D39/D10 -> 0.1319386 | E40: =E39/E10 -> 0.13539533 | F40: =F39/F10 -> 0.1555993 | G40: =G39/G10 -> 0.15307912 | H40: =H39/H10 -> 0.14666346 | I40: =I39/I10 -> 0.14551108 | J40: =J39/J10 -> 0.1442888 | ... Q40: =Q39/Q10 -> 0.13591193
B42: EPS in Rs. | C42: =C39/129 -> 9.2945736 | D42: =D39/129 -> 9.7286822 | E42: =E39/129 -> 10.248062 | F42: =F39/129 -> 11.643411 | G42: =G39/129 -> 12.852713 | H42: =H39/129 -> 13.449219 | I42: =I39/129 -> 14.646749 | J42: =J39/129 -> 16.033216 | ... Q42: =Q39/129 -> 37.529397
B44: Dividend | C44: ='Cash Flow '!C64 -> -968 | D44: ='Cash Flow '!D64 -> -1195 | E44: ='Cash Flow '!E64 -> -582 | F44: ='Cash Flow '!F64 -> -1229 | G44: ='Cash Flow '!G64 -> -453 | H44: =H45*-H39 -> -1142.0254 | I44: =I45*-I39 -> -1243.7123 | J44: =J45*-J39 -> -1361.4426 | K44: =K45*-K39 -> -1499.2175 | L44: =L45*-L39 -> -1662.2259 | M44: =M45*-M39 -> -1857.2106 | N44: =N45*-N39 -> -2092.9483 | O44: =O45*-O39 -> -2380.8773 | ... Q44: =Q45*-Q39 -> -3186.7669
B45: Dividend Payout % | C45: =-C44/C39 -> 0.80733945 | D45: =-D44/D39 -> 0.95219124 | E45: =-E44/E39 -> 0.44024206 | F45: =-F44/F39 -> 0.81824234 | G45: =-G44/G39 -> 0.27322075 | H45: =AVERAGE(C45:G45) -> 0.65824717 | I45: =H45 -> 0.65824717 | J45: =I45 -> 0.65824717 | K45: =J45 -> 0.65824717 | L45: =K45 -> 0.65824717 | M45: =L45 -> 0.65824717 | N45: =M45 -> 0.65824717 | O45: =N45 -> 0.65824717 | P45: =O45 -> 0.65824717 | Q45: =P45 -> 0.65824717
B47: Retained Earning | C47: =C39+C44 -> 231 | D47: =D39+D44 -> 60 | E47: =E39+E44 -> 740 | F47: =F39+F44 -> 273 | G47: =G39+G44 -> 1205 | H47: =H39+H44 -> 592.92382 | I47: =I39+I44 -> 645.71825 | J47: =J39+J44 -> 706.8422 | ... Q47: =Q39+Q44 -> 1654.5253
B48: Retained % | C48: =C47/C39 -> 0.19266055 | D48: =D47/D39 -> 0.047808765 | E48: =E47/E39 -> 0.55975794 | F48: =F47/F39 -> 0.18175766 | G48: =G47/G39 -> 0.72677925 | H48: =H47/H39 -> 0.34175283 | I48: =I47/I39 -> 0.34175283 | J48: =J47/J39 -> 0.34175283 | ... Q48: =Q47/Q39 -> 0.34175283

Sheet Balance Sheet
B4: Balance Sheet
B5: All Figure In INR Cr.
B6: Particulars | C6: 2021 | D6: =C6+1 -> 2022 | E6: =D6+1 -> 2023 | F6: =E6+1 -> 2024 | G6: =F6+1 -> 2025 | H6: =G6+1 -> 2026 | I6: =H6+1 -> 2027 | J6: =I6+1 -> 2028 | K6: =J6+1 -> 2029 | ... Q6: =P6+1 -> 2035
B7: Master Check | C7: =IF(SUM(C75:Q75)=0,"OK","Error") -> OK
B8: Balance Sheet
B9: ASSETS
B10: Non-current assets
B11: Property, plant and equipment | C11: 572 | D11: 600 | E11: 633 | F11: 700 | G11: 710 | H11: ='FAS Seechules'!H26 -> 740.95968 | I11: ='FAS Seechules'!I26 -> 767.18738 | J11: ='FAS Seechules'!J26 -> 786.72483 | K11: ='FAS Seechules'!K26 -> 797.14068 | L11: ='FAS Seechules'!L26 -> 795.43184 | M11: ='FAS Seechules'!M26 -> 777.90554 | N11: ='FAS Seechules'!N26 -> 740.03844 | O11: ='FAS Seechules'!O26 -> 676.3083 | ... Q11: ='FAS Seechules'!Q26 -> 442.93257
B12: Capital work-in-progress | C12: 24 | D12: 39 | E12: 67 | F12: 44 | G12: 40 | H12: ='FAS Seechules'!H89 -> 44.8 | I12: ='FAS Seechules'!I89 -> 50.56 | J12: ='FAS Seechules'!J89 -> 57.472 | K12: ='FAS Seechules'!K89 -> 65.7664 | L12: ='FAS Seechules'!L89 -> 75.71968 | M12: ='FAS Seechules'!M89 -> 87.663616 | N12: ='FAS Seechules'!N89 -> 101.99634 | O12: ='FAS Seechules'!O89 -> 119.19561 | ... Q12: ='FAS Seechules'!Q89 -> 164.60167
B13: Right of use assets | C13: 180 | D13: 178 | E13: 175 | F13: 209 | G13: 230 | H13: ='FAS Seechules'!H45 -> 277.32026 | I13: ='FAS Seechules'!I45 -> 333.81101 | J13: ='FAS Seechules'!J45 -> 401.06465 | K13: ='FAS Seechules'!K45 -> 480.8859 | L13: ='FAS Seechules'!L45 -> 575.2953 | M13: ='FAS Seechules'!M45 -> 686.52019 | N13: ='FAS Seechules'!N45 -> 816.96639 | O13: ='FAS Seechules'!O45 -> 969.16144 | ... Q13: ='FAS Seechules'!Q45 -> 1348.8659
B14: Investment properties | C14: 17 | D14: 22 | E14: 16 | F14: 15 | G14: 15 | H14: =G14 -> 15 | I14: =H14 -> 15 | J14: =I14 -> 15 | K14: =J14 -> 15 | L14: =K14 -> 15 | M14: =L14 -> 15 | N14: =M14 -> 15 | O14: =N14 -> 15 | ... Q14: =P14 -> 15
B15: Goodwill | C15: 613 | D15: 654 | E15: 862 | F15: 863 | G15: 857 | H15: =G15 -> 857 | I15: =H15 -> 857 | J15: =I15 -> 857 | K15: =J15 -> 857 | L15: =K15 -> 857 | M15: =L15 -> 857 | N15: =M15 -> 857 | O15: =N15 -> 857 | ... Q15: =P15 -> 857
B16: Other intangible assets | C16: 230 | D16: 306 | E16: 560 | F16: 937 | G16: 946 | H16: ='FAS Seechules'!H64 -> 952.82962 | I16: ='FAS Seechules'!I64 -> 956.60695 | J16: ='FAS Seechules'!J64 -> 956.45323 | K16: ='FAS Seechules'!K64 -> 951.2629 | L16: ='FAS Seechules'!L64 -> 939.64554 | M16: ='FAS Seechules'!M64 -> 919.85295 | N16: ='FAS Seechules'!N64 -> 889.68762 | O16: ='FAS Seechules'!O64 -> 846.38768 | ... Q16: ='FAS Seechules'!Q64 -> 705.61158
B17: Financial assets
B18: (i) Investments | C18: 226 | D18: 187 | E18: 518 | F18: 343 | G18: 215 | H18: ='B_Sheet Forecast'!H9 -> 369.49629 | I18: ='B_Sheet Forecast'!I9 -> 405.58334 | J18: ='B_Sheet Forecast'!J9 -> 447.73696 | K18: ='B_Sheet Forecast'!K9 -> 497.45485 | L18: ='B_Sheet Forecast'!L9 -> 556.66468 | M18: ='B_Sheet Forecast'!M9 -> 627.85287 | N18: ='B_Sheet Forecast'!N9 -> 714.23248 | O18: ='B_Sheet Forecast'!O9 -> 819.9618 | ... Q18: ='B_Sheet Forecast'!Q9 -> 1112.6254
B19: (ii) Loans | C19: 4 | D19: 4 | E19: 4 | F19: 4 | G19: 6 | H19: ='B_Sheet Forecast'!H11 -> 5.431027 | I19: ='B_Sheet Forecast'!I11 -> 5.9614511 | J19: ='B_Sheet Forecast'!J11 -> 6.5810445 | K19: ='B_Sheet Forecast'!K11 -> 7.311821 | L19: ='B_Sheet Forecast'!L11 -> 8.1821143 | M19: ='B_Sheet Forecast'!M11 -> 9.2284713 | N19: ='B_Sheet Forecast'!N11 -> 10.498119 | O19: ='B_Sheet Forecast'!O11 -> 12.052177 | ... Q19: ='B_Sheet Forecast'!Q11 -> 16.353881
B20: (iii) Other financial assets | C20: 41 | D20: 17 | E20: 32 | F20: 100 | G20: 22 | H20: ='B_Sheet Forecast'!H13 -> 53.350087 | I20: ='B_Sheet Forecast'!I13 -> 58.560551 | J20: ='B_Sheet Forecast'!J13 -> 64.646944 | K20: ='B_Sheet Forecast'!K13 -> 71.825511 | L20: ='B_Sheet Forecast'!L13 -> 80.37458 | M20: ='B_Sheet Forecast'!M13 -> 90.653158 | N20: ='B_Sheet Forecast'!N13 -> 103.12516 | O20: ='B_Sheet Forecast'!O13 -> 118.391 | ... Q20: ='B_Sheet Forecast'!Q13 -> 160.64751
B21: Deferred tax assets (net) | C21: 186 | D21: 187 | E21: 146 | F21: 68 | G21: 57 | H21: ='B_Sheet Forecast'!H15 -> 165.68507 | I21: ='B_Sheet Forecast'!I15 -> 181.86679 | J21: ='B_Sheet Forecast'!J15 -> 200.76881 | K21: ='B_Sheet Forecast'!K15 -> 223.06271 | L21: ='B_Sheet Forecast'!L15 -> 249.61286 | M21: ='B_Sheet Forecast'!M15 -> 281.53422 | N21: ='B_Sheet Forecast'!N15 -> 320.26752 | O21: ='B_Sheet Forecast'!O15 -> 367.67739 | ... Q21: ='B_Sheet Forecast'!Q15 -> 498.91005
B22: Non current tax assets (net) | C22: 55 | D22: 57 | E22: 67 | F22: 95 | G22: 108 | H22: ='B_Sheet Forecast'!H17 -> 93.455667 | I22: ='B_Sheet Forecast'!I17 -> 102.58306 | J22: ='B_Sheet Forecast'!J17 -> 113.24486 | K22: ='B_Sheet Forecast'!K17 -> 125.81987 | L22: ='B_Sheet Forecast'!L17 -> 140.79565 | M22: ='B_Sheet Forecast'!M17 -> 158.80108 | N22: ='B_Sheet Forecast'!N17 -> 180.64883 | O22: ='B_Sheet Forecast'!O17 -> 207.39066 | ... Q22: ='B_Sheet Forecast'!Q17 -> 281.41323
B23: Other non-current assets | C23: 26 | D23: 30 | E23: 46 | F23: 40 | G23: 49 | H23: ='B_Sheet Forecast'!H19 -> 46.758421 | I23: ='B_Sheet Forecast'!I19 -> 51.325107 | J23: ='B_Sheet Forecast'!J19 -> 56.659496 | K23: ='B_Sheet Forecast'!K19 -> 62.951115 | L23: ='B_Sheet Forecast'!L19 -> 70.443905 | M23: ='B_Sheet Forecast'!M19 -> 79.452514 | N23: ='B_Sheet Forecast'!N19 -> 90.383541 | O23: ='B_Sheet Forecast'!O19 -> 103.76321 | ... Q23: ='B_Sheet Forecast'!Q19 -> 140.79872
B24: Total non-current assets | C24: =SUM(C11:C23) -> 2174 | D24: =SUM(D11:D23) -> 2281 | E24: =SUM(E11:E23) -> 3126 | F24: =SUM(F11:F23) -> 3418 | G24: =SUM(G11:G23) -> 3255 | H24: =SUM(H11:H23) -> 3622.0861 | I24: =SUM(I11:I23) -> 3786.0456 | J24: =SUM(J11:J23) -> 3963.3528 | ... Q24: =SUM(Q11:Q23) -> 5744.7605
B25: Current assets
B26: Inventories | C26: 1126 | D26: 1412 | E26: 1225 | F26: 1336 | G26: 1235 | H26: ='Working Capital'!H12 -> 1577.3473 | I26: ='Working Capital'!I12 -> 1731.3998 | J26: ='Working Capital'!J12 -> 1911.3499 | K26: ='Working Capital'!K12 -> 2123.5912 | L26: ='Working Capital'!L12 -> 2376.3528 | M26: ='Working Capital'!M12 -> 2680.249 | N26: ='Working Capital'!N12 -> 3048.996 | O26: ='Working Capital'!O12 -> 3500.3452 | ... Q26: ='Working Capital'!Q12 -> 4749.7003
B27: Financial assets
B28: (i) Investments | C28: 628 | D28: 641 | E28: 578 | F28: 259 | G28: 1375 | H28: ='B_Sheet Forecast'!H24 -> 847.93289 | I28: ='B_Sheet Forecast'!I24 -> 930.7467 | J28: ='B_Sheet Forecast'!J24 -> 1027.4823 | K28: ='B_Sheet Forecast'!K24 -> 1141.5766 | L28: ='B_Sheet Forecast'!L24 -> 1277.4534 | M28: ='B_Sheet Forecast'!M24 -> 1440.8185 | N28: ='B_Sheet Forecast'!N24 -> 1639.0454 | O28: ='B_Sheet Forecast'!O24 -> 1881.6768 | ... Q28: ='B_Sheet Forecast'!Q24 -> 2553.2912
B29: (ii) Trade receivables | C29: 388 | D29: 652 | E29: 1015 | F29: 1069 | G29: 1271 | H29: ='Working Capital'!H13 -> 1061.8125 | I29: ='Working Capital'!I13 -> 1165.515 | J29: ='Working Capital'!J13 -> 1286.6508 | K29: ='Working Capital'!K13 -> 1429.5239 | L29: ='Working Capital'!L13 -> 1599.6738 | M29: ='Working Capital'!M13 -> 1804.2456 | N29: ='Working Capital'!N13 -> 2052.4725 | O29: ='Working Capital'!O13 -> 2356.3043 | ... Q29: ='Working Capital'!Q13 -> 3197.3244
B30: (iii) Cash and cash equivalents | C30: 109 | D30: 276 | E30: 207 | F30: 228 | G30: 321 | H30: ='Cash Flow '!H70 -> 587.50131 | I30: ='Cash Flow '!I70 -> 1050.3777 | J30: ='Cash Flow '!J70 -> 1557.8561 | K30: ='Cash Flow '!K70 -> 2118.0857 | L30: ='Cash Flow '!L70 -> 2741.4249 | M30: ='Cash Flow '!M70 -> 3441.1158 | N30: ='Cash Flow '!N70 -> 4234.1683 | O30: ='Cash Flow '!O70 -> 5142.5199 | ... Q30: ='Cash Flow '!Q70 -> 7431.8919
B31: (iv) Bank balances other than (iii) above | C31: 835 | D31: 303 | E31: 549 | F31: 715 | G31: 456 | H31: 456 | I31: 456 | J31: 456 | K31: 456 | L31: 456 | M31: 456 | N31: 456 | O31: 456 | P31: 456 | Q31: 456
B32: (v) Loans | C32: 6 | D32: 5 | E32: 4 | F32: 6 | G32: 7 | H32: ='B_Sheet Forecast'!H26 -> 6.9763241 | I32: ='B_Sheet Forecast'!I26 -> 7.6576705 | J32: ='B_Sheet Forecast'!J26 -> 8.4535576 | K32: ='B_Sheet Forecast'!K26 -> 9.3922629 | L32: ='B_Sheet Forecast'!L26 -> 10.510182 | M32: ='B_Sheet Forecast'!M26 -> 11.85426 | N32: ='B_Sheet Forecast'!N26 -> 13.485162 | O32: ='B_Sheet Forecast'!O26 -> 15.481399 | ... Q32: ='B_Sheet Forecast'!Q26 -> 21.007072
B33: (vi) Other financial assets | C33: 5 | D33: 2 | E33: 4 | F33: 5 | G33: 3 | H33: ='B_Sheet Forecast'!H28 -> 4.8173283 | I33: ='B_Sheet Forecast'!I28 -> 5.2878152 | J33: ='B_Sheet Forecast'!J28 -> 5.8373954 | K33: ='B_Sheet Forecast'!K28 -> 6.4855952 | L33: ='B_Sheet Forecast'!L28 -> 7.2575465 | M33: ='B_Sheet Forecast'!M28 -> 8.1856666 | N33: ='B_Sheet Forecast'!N28 -> 9.3118455 | O33: ='B_Sheet Forecast'!O28 -> 10.690297 | ... Q33: ='B_Sheet Forecast'!Q28 -> 14.505915
B34: Current tax asset (net) | C34: 1 | D34: 1 | E34: 2 | F34: 2 | G34: 2 | H34: ='B_Sheet Forecast'!H30 -> 1.9543768 | I34: ='B_Sheet Forecast'!I30 -> 2.145252 | J34: ='B_Sheet Forecast'!J30 -> 2.3682152 | K34: ='B_Sheet Forecast'!K30 -> 2.6311881 | L34: ='B_Sheet Forecast'!L30 -> 2.9443666 | M34: ='B_Sheet Forecast'!M30 -> 3.3209023 | N34: ='B_Sheet Forecast'!N30 -> 3.77779 | O34: ='B_Sheet Forecast'!O30 -> 4.3370241 | ... Q34: ='B_Sheet Forecast'!Q30 -> 5.8850095
B35: Other current assets | C35: 224 | D35: 213 | E35: 229 | F35: 378 | G35: 413 | H35: ='B_Sheet Forecast'!H32 -> 357.17717 | I35: ='B_Sheet Forecast'!I32 -> 392.06106 | J35: ='B_Sheet Forecast'!J32 -> 432.80927 | K35: ='B_Sheet Forecast'!K32 -> 480.86955 | L35: ='B_Sheet Forecast'!L32 -> 538.1053 | M35: ='B_Sheet Forecast'!M32 -> 606.92006 | N35: ='B_Sheet Forecast'!N32 -> 690.41975 | O35: ='B_Sheet Forecast'!O32 -> 792.62402 | ... Q35: ='B_Sheet Forecast'!Q32 -> 1075.5301
B36: Assets classified as held for sale | C36: 14 | D36: 0 | E36: 7 | F36: 5 | H36: ='B_Sheet Forecast'!H34 -> 7.0372394 | I36: ='B_Sheet Forecast'!I34 -> 7.7245352 | J36: ='B_Sheet Forecast'!J34 -> 8.5273718 | K36: ='B_Sheet Forecast'!K34 -> 9.4742736 | L36: ='B_Sheet Forecast'!L34 -> 10.601954 | M36: ='B_Sheet Forecast'!M34 -> 11.957768 | N36: ='B_Sheet Forecast'!N34 -> 13.602911 | O36: ='B_Sheet Forecast'!O34 -> 15.616578 | ... Q36: ='B_Sheet Forecast'!Q34 -> 21.1905
B37: Total current assets | C37: =SUM(C26:C36) -> 3336 | D37: =SUM(D26:D36) -> 3505 | E37: =SUM(E26:E36) -> 3820 | F37: =SUM(F26:F36) -> 4003 | G37: =SUM(G26:G36) -> 5083 | H37: =SUM(H26:H36) -> 4908.5564 | I37: =SUM(I26:I36) -> 5748.9155 | J37: =SUM(J26:J36) -> 6697.335 | ... Q37: =SUM(Q26:Q36) -> 19526.326
B38: Total assets | C38: =C24+C37 -> 5510 | D38: =D24+D37 -> 5786 | E38: =E24+E37 -> 6946 | F38: =F24+F37 -> 7421 | G38: =G24+G37 -> 8338 | H38: =H24+H37 -> 8530.6426 | I38: =I24+I37 -> 9534.9612 | J38: =J24+J37 -> 10660.688 | ... Q38: =Q24+Q37 -> 25271.087
B39: EQUITY AND LIABILITIES
B40: Equity
B41: Equity share capital | C41: 129 | D41: 129 | E41: 129 | F41: 129 | G41: 129 | H41: =G41 -> 129 | I41: =H41 -> 129 | J41: =I41 -> 129 | K41: =J41 -> 129 | L41: =K41 -> 129 | M41: =L41 -> 129 | N41: =M41 -> 129 | O41: =N41 -> 129 | ... Q41: =P41 -> 129
B42: Other equity
B43: Reserves and surplus | C43: 3111 | D43: 3189 | E43: 3674 | F43: 3782 | G43: 3997 | H43: =G43+'P&L Statement '!H39+'P&L Statement '!H44 -> 4589.9238 | I43: =H43+'P&L Statement '!I39+'P&L Statement '!I44 -> 5235.6421 | J43: =I43+'P&L Statement '!J39+'P&L Statement '!J44 -> 5942.4843 | K43: =J43+'P&L Statement '!K39+'P&L Statement '!K44 -> 6720.8573 | L43: =K43+'P&L Statement '!L39+'P&L Statement '!L44 -> 7583.862 | M43: =L43+'P&L Statement '!M39+'P&L Statement '!M44 -> 8548.1001 | N43: =M43+'P&L Statement '!N39+'P&L Statement '!N44 -> 9634.7299 | O43: =N43+'P&L Statement '!O39+'P&L Statement '!O44 -> 10870.849 | ... Q43: =P43+'P&L Statement '!Q39+'P&L Statement '!Q44 -> 13945.826
...

Sheet Common Size Statement
B4: Common Size Statement
B5: All Figure In INR Cr.
B6: Particulars | C6: 2021 | D6: =C6+1 -> 2022 | E6: =D6+1 -> 2023 | F6: =E6+1 -> 2024 | G6: =F6+1 -> 2025 | H6: =G6+1 -> 2026 | I6: =H6+1 -> 2027 | J6: =I6+1 -> 2028 | K6: =J6+1 -> 2029 | ... Q6: =P6+1 -> 2035
B7: Income Statement
B8: Revenue | C8: ='P&L Statement '!C10/'P&L Statement '!C$10 -> 1 | D8: ='P&L Statement '!D10/'P&L Statement '!D$10 -> 1 | E8: ='P&L Statement '!E10/'P&L Statement '!E$10 -> 1 | F8: ='P&L Statement '!F10/'P&L Statement '!F$10 -> 1 | G8: ='P&L Statement '!G10/'P&L Statement '!G$10 -> 1 | H8: ='P&L Statement '!H10/'P&L Statement '!H$10 -> 1 | I8: ='P&L Statement '!I10/'P&L Statement '!I$10 -> 1 | J8: ='P&L Statement '!J10/'P&L Statement '!J$10 -> 1 | ... Q8: ='P&L Statement '!Q10/'P&L Statement '!Q$10 -> 1
B9: COGS | C9: =-'P&L Statement '!C11/'P&L Statement '!C$10 -> 0.5305666 | D9: =-'P&L Statement '!D11/'P&L Statement '!D$10 -> 0.57148865 | E9: =-'P&L Statement '!E11/'P&L Statement '!E$10 -> 0.54803359 | F9: =-'P&L Statement '!F11/'P&L Statement '!F$10 -> 0.49186781 | G9: =-'P&L Statement '!G11/'P&L Statement '!G$10 -> 0.49746099 | H9: =-'P&L Statement '!H11/'P&L Statement '!H$10 -> 0.52788353 | I9: =-'P&L Statement '!I11/'P&L Statement '!I$10 -> 0.52788353 | J9: =-'P&L Statement '!J11/'P&L Statement '!J$10 -> 0.52788353 | ... Q9: =-'P&L Statement '!Q11/'P&L Statement '!Q$10 -> 0.52788353
B10: Gross Profit | C10: ='P&L Statement '!C12/'P&L Statement '!C$10 -> 0.4694334 | D10: ='P&L Statement '!D12/'P&L Statement '!D$10 -> 0.42851135 | E10: ='P&L Statement '!E12/'P&L Statement '!E$10 -> 0.45196641 | F10: ='P&L Statement '!F12/'P&L Statement '!F$10 -> 0.50813219 | G10: ='P&L Statement '!G12/'P&L Statement '!G$10 -> 0.50253901 | H10: ='P&L Statement '!H12/'P&L Statement '!H$10 -> 0.47211647 | I10: ='P&L Statement '!I12/'P&L Statement '!I$10 -> 0.47211647 | J10: ='P&L Statement '!J12/'P&L Statement '!J$10 -> 0.47211647 | ... Q10: ='P&L Statement '!Q12/'P&L Statement '!Q$10 -> 0.47211647
B12: Salaries & Benefits | C12: =-'P&L Statement '!C15/'P&L Statement '!C$10 -> 0.07082505 | D12: =-'P&L Statement '!D15/'P&L Statement '!D$10 -> 0.061606392 | E12: =-'P&L Statement '!E15/'P&L Statement '!E$10 -> 0.066878329 | F12: =-'P&L Statement '!F15/'P&L Statement '!F$10 -> 0.07697089 | G12: =-'P&L Statement '!G15/'P&L Statement '!G$10 -> 0.076724218 | H12: =-'P&L Statement '!H15/'P&L Statement '!H$10 -> 0.070600976 | I12: =-'P&L Statement '!I15/'P&L Statement '!I$10 -> 0.070600976 | J12: =-'P&L Statement '!J15/'P&L Statement '!J$10 -> 0.070600976 | ... Q12: =-'P&L Statement '!Q15/'P&L Statement '!Q$10 -> 0.070600976
B13: S&G Expenses | C13: =-'P&L Statement '!C16/'P&L Statement '!C$10 -> 0.20091948 | D13: =-'P&L Statement '!D16/'P&L Statement '!D$10 -> 0.19018082 | E13: =-'P&L Statement '!E16/'P&L Statement '!E$10 -> 0.19971323 | F13: =-'P&L Statement '!F16/'P&L Statement '!F$10 -> 0.22127836 | G13: =-'P&L Statement '!G16/'P&L Statement '!G$10 -> 0.2283261 | H13: =-'P&L Statement '!H16/'P&L Statement '!H$10 -> 0.2080836 | I13: =-'P&L Statement '!I16/'P&L Statement '!I$10 -> 0.2080836 | J13: =-'P&L Statement '!J16/'P&L Statement '!J$10 -> 0.2080836 | ... Q13: =-'P&L Statement '!Q16/'P&L Statement '!Q$10 -> 0.2080836
B15: EBITDA | C15: ='P&L Statement '!C18/'P&L Statement '!C$10 -> 0.19768887 | D15: ='P&L Statement '!D18/'P&L Statement '!D$10 -> 0.17672414 | E15: ='P&L Statement '!E18/'P&L Statement '!E$10 -> 0.18537485 | F15: ='P&L Statement '!F18/'P&L Statement '!F$10 -> 0.20988294 | G15: ='P&L Statement '!G18/'P&L Statement '!G$10 -> 0.19748869 | H15: ='P&L Statement '!H18/'P&L Statement '!H$10 -> 0.1934319 | I15: ='P&L Statement '!I18/'P&L Statement '!I$10 -> 0.1934319 | J15: ='P&L Statement '!J18/'P&L Statement '!J$10 -> 0.1934319 | ... Q15: ='P&L Statement '!Q18/'P&L Statement '!Q$10 -> 0.1934319
B16: Dep & Amortization | C16: =-'P&L Statement '!C21/'P&L Statement '!C$10 -> 0.017271372 | D16: =-'P&L Statement '!D21/'P&L Statement '!D$10 -> 0.01461312 | E16: =-'P&L Statement '!E21/'P&L Statement '!E$10 -> 0.015874642 | F16: =-'P&L Statement '!F21/'P&L Statement '!F$10 -> 0.016367969 | G16: =-'P&L Statement '!G21/'P&L Statement '!G$10 -> 0.016434309 | H16: =-'P&L Statement '!H21/'P&L Statement '!H$10 -> 0.013594097 | I16: =-'P&L Statement '!I21/'P&L Statement '!I$10 -> 0.015073169 | J16: =-'P&L Statement '!J21/'P&L Statement '!J$10 -> 0.016641755 | ... Q16: =-'P&L Statement '!Q21/'P&L Statement '!Q$10 -> 0.027887195
B18: EBIT | C18: ='P&L Statement '!C23/'P&L Statement '!C$10 -> 0.1804175 | D18: ='P&L Statement '!D23/'P&L Statement '!D$10 -> 0.16211102 | E18: ='P&L Statement '!E23/'P&L Statement '!E$10 -> 0.1695002 | F18: ='P&L Statement '!F23/'P&L Statement '!F$10 -> 0.19351497 | G18: ='P&L Statement '!G23/'P&L Statement '!G$10 -> 0.18105438 | H18: ='P&L Statement '!H23/'P&L Statement '!H$10 -> 0.1798378 | I18: ='P&L Statement '!I23/'P&L Statement '!I$10 -> 0.17835873 | J18: ='P&L Statement '!J23/'P&L Statement '!J$10 -> 0.17679014 | ... Q18: ='P&L Statement '!Q23/'P&L Statement '!Q$10 -> 0.1655447
B20: Interest Cost | C20: =-'P&L Statement '!C26/'P&L Statement '!C$10 -> 0.0042246521 | D20: =-'P&L Statement '!D26/'P&L Statement '!D$10 -> 0.0041000841 | E20: =-'P&L Statement '!E26/'P&L Statement '!E$10 -> 0.0057353544 | F20: =-'P&L Statement '!F26/'P&L Statement '!F$10 -> 0.0075624158 | G20: =-'P&L Statement '!G26/'P&L Statement '!G$10 -> 0.0048933616 | H20: =-'P&L Statement '!H26/'P&L Statement '!H$10 -> 0.0053850274 | I20: =-'P&L Statement '!I26/'P&L Statement '!I$10 -> 0.0053877034 | J20: =-'P&L Statement '!J26/'P&L Statement '!J$10 -> 0.0053907386 | ... Q20: =-'P&L Statement '!Q26/'P&L Statement '!Q$10 -> 0.0049163909
B21: Other Income | C21: ='P&L Statement '!C27/'P&L Statement '!C$10 -> 0.01167992 | D21: ='P&L Statement '!D27/'P&L Statement '!D$10 -> 0.010302775 | E21: ='P&L Statement '!E27/'P&L Statement '!E$10 -> 0.014748054 | F21: ='P&L Statement '!F27/'P&L Statement '!F$10 -> 0.014710453 | G21: ='P&L Statement '!G27/'P&L Statement '!G$10 -> 0.019204136 | H21: ='P&L Statement '!H27/'P&L Statement '!H$10 -> 0.014129068 | I21: ='P&L Statement '!I27/'P&L Statement '!I$10 -> 0.014129068 | J21: ='P&L Statement '!J27/'P&L Statement '!J$10 -> 0.014129068 | ... Q21: ='P&L Statement '!Q27/'P&L Statement '!Q$10 -> 0.014129068
B23: Profit before share of profit/ (loss) of associates and tax | C23: ='P&L Statement '!C29/'P&L Statement '!C$10 -> 0.18787276 | D23: ='P&L Statement '!D29/'P&L Statement '!D$10 -> 0.16831371 | E23: ='P&L Statement '!E29/'P&L Statement '!E$10 -> 0.1785129 | F23: ='P&L Statement '!F29/'P&L Statement '!F$10 -> 0.20066301 | G23: ='P&L Statement '!G29/'P&L Statement '!G$10 -> 0.19536516 | H23: ='P&L Statement '!H29/'P&L Statement '!H$10 -> 0.18858184 | I23: ='P&L Statement '!I29/'P&L Statement '!I$10 -> 0.18710009 | J23: ='P&L Statement '!J29/'P&L Statement '!J$10 -> 0.18552847 | ... Q23: ='P&L Statement '!Q29/'P&L Statement '!Q$10 -> 0.17475738
B24: Share in profit/(loss) of associates (net of tax) | C24: ='P&L Statement '!C31/'P&L Statement '!C$10 -> -0.00024850895 | D24: ='P&L Statement '!D31/'P&L Statement '!D$10 -> 0 | E24: ='P&L Statement '!E31/'P&L Statement '!E$10 -> 0 | F24: ='P&L Statement '!F31/'P&L Statement '!F$10 -> 0 | G24: ='P&L Statement '!G31/'P&L Statement '!G$10 -> 0 | H24: ='P&L Statement '!H31/'P&L Statement '!H$10 -> 0 | I24: ='P&L Statement '!I31/'P&L Statement '!I$10 -> 0 | J24: ='P&L Statement '!J31/'P&L Statement '!J$10 -> 0 | ... Q24: ='P&L Statement '!Q31/'P&L Statement '!Q$10 -> 0
B25: Exceptional item | C25: ='P&L Statement '!C32/'P&L Statement '!C$10 -> 0.0016153082 | D25: ='P&L Statement '!D32/'P&L Statement '!D$10 -> 0 | E25: ='P&L Statement '!E32/'P&L Statement '!E$10 -> 0 | F25: ='P&L Statement '!F32/'P&L Statement '!F$10 -> 0 | G25: ='P&L Statement '!G32/'P&L Statement '!G$10 -> 0 | H25: ='P&L Statement '!H32/'P&L Statement '!H$10 -> 0 | I25: ='P&L Statement '!I32/'P&L Statement '!I$10 -> 0 | J25: ='P&L Statement '!J32/'P&L Statement '!J$10 -> 0 | ... Q25: ='P&L Statement '!Q32/'P&L Statement '!Q$10 -> 0
B27: EBT | C27: ='P&L Statement '!C34/'P&L Statement '!C$10 -> 0.18923956 | D27: ='P&L Statement '!D34/'P&L Statement '!D$10 -> 0.16831371 | E27: ='P&L Statement '!E34/'P&L Statement '!E$10 -> 0.1785129 | F27: ='P&L Statement '!F34/'P&L Statement '!F$10 -> 0.20066301 | G27: ='P&L Statement '!G34/'P&L Statement '!G$10 -> 0.19536516 | H27: ='P&L Statement '!H34/'P&L Statement '!H$10 -> 0.18858184 | I27: ='P&L Statement '!I34/'P&L Statement '!I$10 -> 0.18710009 | J27: ='P&L Statement '!J34/'P&L Statement '!J$10 -> 0.18552847 | ... Q27: ='P&L Statement '!Q34/'P&L Statement '!Q$10 -> 0.17475738
B29: Tax | C29: ='P&L Statement '!C37/'P&L Statement '!C$10 -> 0.040258449 | D29: ='P&L Statement '!D37/'P&L Statement '!D$10 -> 0.036375105 | E29: ='P&L Statement '!E37/'P&L Statement '!E$10 -> 0.043117575 | F29: ='P&L Statement '!F37/'P&L Statement '!F$10 -> 0.045063711 | G29: ='P&L Statement '!G37/'P&L Statement '!G$10 -> 0.042286031 | H29: ='P&L Statement '!H37/'P&L Statement '!H$10 -> 0.041918376 | I29: ='P&L Statement '!I37/'P&L Statement '!I$10 -> 0.04158901 | J29: ='P&L Statement '!J37/'P&L Statement '!J$10 -> 0.041239667 | ... Q29: ='P&L Statement '!Q37/'P&L Statement '!Q$10 -> 0.038845445
B31: Net Profit | C31: ='P&L Statement '!C39/'P&L Statement '!C$10 -> 0.14898111 | D31: ='P&L Statement '!D39/'P&L Statement '!D$10 -> 0.1319386 | E31: ='P&L Statement '!E39/'P&L Statement '!E$10 -> 0.13539533 | F31: ='P&L Statement '!F39/'P&L Statement '!F$10 -> 0.1555993 | G31: ='P&L Statement '!G39/'P&L Statement '!G$10 -> 0.15307912 | H31: ='P&L Statement '!H39/'P&L Statement '!H$10 -> 0.14666346 | I31: ='P&L Statement '!I39/'P&L Statement '!I$10 -> 0.14551108 | J31: ='P&L Statement '!J39/'P&L Statement '!J$10 -> 0.1442888 | ... Q31: ='P&L Statement '!Q39/'P&L Statement '!Q$10 -> 0.13591193
B33: Balance Sheet
B34: ASSETS
B35: Non-current assets
B36: Property, plant and equipment | C36: ='Balance Sheet'!C11/'Balance Sheet'!C$38 -> 0.10381125 | D36: ='Balance Sheet'!D11/'Balance Sheet'!D$38 -> 0.10369858 | E36: ='Balance Sheet'!E11/'Balance Sheet'!E$38 -> 0.091131587 | F36: ='Balance Sheet'!F11/'Balance Sheet'!F$38 -> 0.09432691 | G36: ='Balance Sheet'!G11/'Balance Sheet'!G$38 -> 0.085152315 | H36: ='Balance Sheet'!H11/'Balance Sheet'!H$38 -> 0.086858602 | I36: ='Balance Sheet'!I11/'Balance Sheet'!I$38 -> 0.080460462 | J36: ='Balance Sheet'!J11/'Balance Sheet'!J$38 -> 0.073796817 | ... Q36: ='Balance Sheet'!Q11/'Balance Sheet'!Q$38 -> 0.017527246
B37: Capital work-in-progress | C37: ='Balance Sheet'!C12/'Balance Sheet'!C$38 -> 0.0043557169 | D37: ='Balance Sheet'!D12/'Balance Sheet'!D$38 -> 0.0067404079 | E37: ='Balance Sheet'!E12/'Balance Sheet'!E$38 -> 0.0096458393 | F37: ='Balance Sheet'!F12/'Balance Sheet'!F$38 -> 0.0059291201 | G37: ='Balance Sheet'!G12/'Balance Sheet'!G$38 -> 0.0047973135 | H37: ='Balance Sheet'!H12/'Balance Sheet'!H$38 -> 0.005251656 | I37: ='Balance Sheet'!I12/'Balance Sheet'!I$38 -> 0.0053025911 | J37: ='Balance Sheet'!J12/'Balance Sheet'!J$38 -> 0.0053910218 | ... Q37: ='Balance Sheet'!Q12/'Balance Sheet'!Q$38 -> 0.0065134387
B38: Right of use assets | C38: ='Balance Sheet'!C13/'Balance Sheet'!C$38 -> 0.032667877 | D38: ='Balance Sheet'!D13/'Balance Sheet'!D$38 -> 0.030763913 | E38: ='Balance Sheet'!E13/'Balance Sheet'!E$38 -> 0.025194356 | F38: ='Balance Sheet'!F13/'Balance Sheet'!F$38 -> 0.02816332 | G38: ='Balance Sheet'!G13/'Balance Sheet'!G$38 -> 0.027584553 | H38: ='Balance Sheet'!H13/'Balance Sheet'!H$38 -> 0.032508719 | I38: ='Balance Sheet'!I13/'Balance Sheet'!I$38 -> 0.035009163 | J38: ='Balance Sheet'!J13/'Balance Sheet'!J$38 -> 0.037620898 | ... Q38: ='Balance Sheet'!Q13/'Balance Sheet'!Q$38 -> 0.053375858
B39: Investment properties | C39: ='Balance Sheet'!C14/'Balance Sheet'!C$38 -> 0.0030852995 | D39: ='Balance Sheet'!D14/'Balance Sheet'!D$38 -> 0.0038022814 | E39: ='Balance Sheet'!E14/'Balance Sheet'!E$38 -> 0.002303484 | F39: ='Balance Sheet'!F14/'Balance Sheet'!F$38 -> 0.0020212909 | G39: ='Balance Sheet'!G14/'Balance Sheet'!G$38 -> 0.0017989926 | H39: ='Balance Sheet'!H14/'Balance Sheet'!H$38 -> 0.001758367 | I39: ='Balance Sheet'!I14/'Balance Sheet'!I$38 -> 0.001573158 | J39: ='Balance Sheet'!J14/'Balance Sheet'!J$38 -> 0.0014070387 | ... Q39: ='Balance Sheet'!Q14/'Balance Sheet'!Q$38 -> 0.00059356371
B40: Goodwill | C40: ='Balance Sheet'!C15/'Balance Sheet'!C$38 -> 0.11125227 | D40: ='Balance Sheet'!D15/'Balance Sheet'!D$38 -> 0.11303146 | E40: ='Balance Sheet'!E15/'Balance Sheet'!E$38 -> 0.1241002 | F40: ='Balance Sheet'!F15/'Balance Sheet'!F$38 -> 0.1162916 | G40: ='Balance Sheet'!G15/'Balance Sheet'!G$38 -> 0.10278244 | H40: ='Balance Sheet'!H15/'Balance Sheet'!H$38 -> 0.10046137 | I40: ='Balance Sheet'!I15/'Balance Sheet'!I$38 -> 0.089879758 | J40: ='Balance Sheet'!J15/'Balance Sheet'!J$38 -> 0.080388809 | ... Q40: ='Balance Sheet'!Q15/'Balance Sheet'!Q$38 -> 0.033912273
B41: Other intangible assets | C41: ='Balance Sheet'!C16/'Balance Sheet'!C$38 -> 0.041742287 | D41: ='Balance Sheet'!D16/'Balance Sheet'!D$38 -> 0.052886277 | E41: ='Balance Sheet'!E16/'Balance Sheet'!E$38 -> 0.080621941 | F41: ='Balance Sheet'!F16/'Balance Sheet'!F$38 -> 0.12626331 | G41: ='Balance Sheet'!G16/'Balance Sheet'!G$38 -> 0.11345646 | H41: ='Balance Sheet'!H16/'Balance Sheet'!H$38 -> 0.11169494 | I41: ='Balance Sheet'!I16/'Balance Sheet'!I$38 -> 0.10032625 | J41: ='Balance Sheet'!J16/'Balance Sheet'!J$38 -> 0.089717778 | ... Q41: ='Balance Sheet'!Q16/'Balance Sheet'!Q$38 -> 0.027921695
B42: Financial assets
B43: (i) Investments | C43: ='Balance Sheet'!C18/'Balance Sheet'!C$38 -> 0.041016334 | D43: ='Balance Sheet'!D18/'Balance Sheet'!D$38 -> 0.032319392 | E43: ='Balance Sheet'!E18/'Balance Sheet'!E$38 -> 0.074575295 | F43: ='Balance Sheet'!F18/'Balance Sheet'!F$38 -> 0.046220186 | G43: ='Balance Sheet'!G18/'Balance Sheet'!G$38 -> 0.02578556 | H43: ='Balance Sheet'!H18/'Balance Sheet'!H$38 -> 0.043314004 | I43: ='Balance Sheet'!I18/'Balance Sheet'!I$38 -> 0.042536444 | J43: ='Balance Sheet'!J18/'Balance Sheet'!J$38 -> 0.041998881 | ... Q43: ='Balance Sheet'!Q18/'Balance Sheet'!Q$38 -> 0.044027602
B44: (ii) Loans | C44: ='Balance Sheet'!C19/'Balance Sheet'!C$38 -> 0.00072595281 | D44: ='Balance Sheet'!D19/'Balance Sheet'!D$38 -> 0.00069132389 | E44: ='Balance Sheet'!E19/'Balance Sheet'!E$38 -> 0.000575871 | F44: ='Balance Sheet'!F19/'Balance Sheet'!F$38 -> 0.00053901091 | G44: ='Balance Sheet'!G19/'Balance Sheet'!G$38 -> 0.00071959703 | H44: ='Balance Sheet'!H19/'Balance Sheet'!H$38 -> 0.00063664922 | I44: ='Balance Sheet'!I19/'Balance Sheet'!I$38 -> 0.00062522028 | J44: ='Balance Sheet'!J19/'Balance Sheet'!J$38 -> 0.00061731894 | ... Q44: ='Balance Sheet'!Q19/'Balance Sheet'!Q$38 -> 0.00064713801
B45: (iii) Other financial assets | C45: ='Balance Sheet'!C20/'Balance Sheet'!C$38 -> 0.0074410163 | D45: ='Balance Sheet'!D20/'Balance Sheet'!D$38 -> 0.0029381265 | E45: ='Balance Sheet'!E20/'Balance Sheet'!E$38 -> 0.004606968 | F45: ='Balance Sheet'!F20/'Balance Sheet'!F$38 -> 0.013475273 | G45: ='Balance Sheet'!G20/'Balance Sheet'!G$38 -> 0.0026385224 | H45: ='Balance Sheet'!H20/'Balance Sheet'!H$38 -> 0.0062539353 | I45: ='Balance Sheet'!I20/'Balance Sheet'!I$38 -> 0.0061416665 | J45: ='Balance Sheet'!J20/'Balance Sheet'!J$38 -> 0.00606405 | ... Q45: ='Balance Sheet'!Q20/'Balance Sheet'!Q$38 -> 0.0063569688
B46: Deferred tax assets (net) | C46: ='Balance Sheet'!C21/'Balance Sheet'!C$38 -> 0.033756806 | D46: ='Balance Sheet'!D21/'Balance Sheet'!D$38 -> 0.032319392 | E46: ='Balance Sheet'!E21/'Balance Sheet'!E$38 -> 0.021019292 | F46: ='Balance Sheet'!F21/'Balance Sheet'!F$38 -> 0.0091631856 | G46: ='Balance Sheet'!G21/'Balance Sheet'!G$38 -> 0.0068361717 | H46: ='Balance Sheet'!H21/'Balance Sheet'!H$38 -> 0.019422344 | I46: ='Balance Sheet'!I21/'Balance Sheet'!I$38 -> 0.019073679 | J46: ='Balance Sheet'!J21/'Balance Sheet'!J$38 -> 0.018832632 | ... Q46: ='Balance Sheet'!Q21/'Balance Sheet'!Q$38 -> 0.019742326
B47: Non current tax assets (net) | C47: ='Balance Sheet'!C22/'Balance Sheet'!C$38 -> 0.0099818512 | D47: ='Balance Sheet'!D22/'Balance Sheet'!D$38 -> 0.0098513654 | E47: ='Balance Sheet'!E22/'Balance Sheet'!E$38 -> 0.0096458393 | F47: ='Balance Sheet'!F22/'Balance Sheet'!F$38 -> 0.012801509 | G47: ='Balance Sheet'!G22/'Balance Sheet'!G$38 -> 0.012952746 | H47: ='Balance Sheet'!H22/'Balance Sheet'!H$38 -> 0.01095529 | I47: ='Balance Sheet'!I22/'Balance Sheet'!I$38 -> 0.010758624 | J47: ='Balance Sheet'!J22/'Balance Sheet'!J$38 -> 0.01062266 | ... Q47: ='Balance Sheet'!Q22/'Balance Sheet'!Q$38 -> 0.011135779
B48: Other non-current assets | C48: ='Balance Sheet'!C23/'Balance Sheet'!C$38 -> 0.0047186933 | D48: ='Balance Sheet'!D23/'Balance Sheet'!D$38 -> 0.0051849291 | E48: ='Balance Sheet'!E23/'Balance Sheet'!E$38 -> 0.0066225166 | F48: ='Balance Sheet'!F23/'Balance Sheet'!F$38 -> 0.0053901091 | G48: ='Balance Sheet'!G23/'Balance Sheet'!G$38 -> 0.005876709 | H48: ='Balance Sheet'!H23/'Balance Sheet'!H$38 -> 0.0054812308 | I48: ='Balance Sheet'!I23/'Balance Sheet'!I$38 -> 0.0053828333 | J48: ='Balance Sheet'!J23/'Balance Sheet'!J$38 -> 0.0053148068 | ... Q48: ='Balance Sheet'!Q23/'Balance Sheet'!Q$38 -> 0.005571534
B49: Total non-current assets | C49: ='Balance Sheet'!C24/'Balance Sheet'!C$38 -> 0.39455535 | D49: ='Balance Sheet'!D24/'Balance Sheet'!D$38 -> 0.39422745 | E49: ='Balance Sheet'!E24/'Balance Sheet'!E$38 -> 0.45004319 | F49: ='Balance Sheet'!F24/'Balance Sheet'!F$38 -> 0.46058483 | G49: ='Balance Sheet'!G24/'Balance Sheet'!G$38 -> 0.39038139 | H49: ='Balance Sheet'!H24/'Balance Sheet'!H$38 -> 0.4245971 | I49: ='Balance Sheet'!I24/'Balance Sheet'!I$38 -> 0.39706985 | J49: ='Balance Sheet'!J24/'Balance Sheet'!J$38 -> 0.37177271 | ... Q49: ='Balance Sheet'!Q24/'Balance Sheet'!Q$38 -> 0.22732542
B50: Current assets
B51: Inventories | C51: ='Balance Sheet'!C26/'Balance Sheet'!C$38 -> 0.20435572 | D51: ='Balance Sheet'!D26/'Balance Sheet'!D$38 -> 0.24403733 | E51: ='Balance Sheet'!E26/'Balance Sheet'!E$38 -> 0.1763605 | F51: ='Balance Sheet'!F26/'Balance Sheet'!F$38 -> 0.18002965 | G51: ='Balance Sheet'!G26/'Balance Sheet'!G$38 -> 0.14811705 | H51: ='Balance Sheet'!H26/'Balance Sheet'!H$38 -> 0.18490369 | I51: ='Balance Sheet'!I26/'Balance Sheet'!I$38 -> 0.18158436 | J51: ='Balance Sheet'!J26/'Balance Sheet'!J$38 -> 0.17928955 | ... Q51: ='Balance Sheet'!Q26/'Balance Sheet'!Q$38 -> 0.18794998
B52: Financial assets
...

Sheet Cash Flow 
B4: CashFlow Statement
B5: All Figure In INR Cr.
B6: Particulars | C6: 2021 | D6: =C6+1 -> 2022 | E6: =D6+1 -> 2023 | F6: =E6+1 -> 2024 | G6: =F6+1 -> 2025 | H6: =G6+1 -> 2026 | I6: =H6+1 -> 2027 | J6: =I6+1 -> 2028 | K6: =J6+1 -> 2029 | ... Q6: =P6+1 -> 2035
B8: CASH FLOW FROM OPERATING ACTIVITIES
B9: PROFIT BEFORE INCOME TAX | C9: 1523 | D9: 1601 | E9: 1743 | F9: 1937 | G9: 2116 | H9: ='P&L Statement '!H34 -> 2230.8209 | I9: ='P&L Statement '!I34 -> 2429.455 | J9: ='P&L Statement '!J34 -> 2659.4282 | K9: ='P&L Statement '!K34 -> 2928.5564 | L9: ='P&L Statement '!L34 -> 3246.9753 | M9: ='P&L Statement '!M34 -> 3627.8565 | N9: ='P&L Statement '!N34 -> 4088.3439 | O9: ='P&L Statement '!O34 -> 4650.7816 | ... Q9: ='P&L Statement '!Q34 -> 6224.9982
B10: Adjustments for:
B11: Depreciation and amortization expense/impairment | C11: 139 | D11: 139 | E11: 155 | F11: 158 | G11: 178 | H11: =-'P&L Statement '!H21 -> 160.8108 | I11: =-'P&L Statement '!I21 -> 195.72191 | J11: =-'P&L Statement '!J21 -> 238.54858 | K11: =-'P&L Statement '!K21 -> 291.16514 | L11: =-'P&L Statement '!L21 -> 355.90783 | M11: =-'P&L Statement '!M21 -> 435.69258 | N11: =-'P&L Statement '!N21 -> 534.1636 | O11: =-'P&L Statement '!O21 -> 655.88117 | ... Q11: =-'P&L Statement '!Q21 -> 993.36431
B12: Share of net loss /(gain) of joint ventures accounted for using the equity method | C12: 2 | D12: 0 | E12: 0 | F12: 0 | G12: 0 | H12: 0 | I12: 0 | J12: 0 | K12: 0 | L12: 0 | M12: 0 | N12: 0 | O12: 0 | P12: 0 | Q12: 0
B13: Finance costs | C13: 34 | D13: 39 | E13: 56 | F13: 73 | G13: 53 | H13: =-'P&L Statement '!H26 -> 63.701955 | I13: =-'P&L Statement '!I26 -> 69.958187 | J13: =-'P&L Statement '!J26 -> 77.272682 | K13: =-'P&L Statement '!K26 -> 85.907524 | L13: =-'P&L Statement '!L26 -> 96.20011 | M13: =-'P&L Statement '!M26 -> 108.58572 | N13: =-'P&L Statement '!N26 -> 123.62692 | O13: =-'P&L Statement '!O26 -> 142.05187 | ... Q13: =-'P&L Statement '!Q26 -> 175.12579
B14: Interest income from financial assets | C14: -59 | D14: -59 | E14: -49 | F14: -77 | G14: -77 | H14: 0 | I14: 0 | J14: 0 | K14: 0 | L14: 0 | M14: 0 | N14: 0 | O14: 0 | P14: 0 | Q14: 0
B15: (Gain)/ Loss on disposal of property, plant and equipment (NET) | C15: 0 | D15: 0 | E15: -28 | F15: -15 | G15: -20 | H15: 0 | I15: 0 | J15: 0 | K15: 0 | L15: 0 | M15: 0 | N15: 0 | O15: 0 | P15: 0 | Q15: 0
B16: Net fair value changes financial assets (including net gain on sale) | C16: -21 | D16: -29 | E16: -50 | F16: -73 | G16: -76 | H16: 0 | I16: 0 | J16: 0 | K16: 0 | L16: 0 | M16: 0 | N16: 0 | O16: 0 | P16: 0 | Q16: 0
B17: Employees stock option charge | C17: 9 | D17: 10 | E17: 19 | F17: 35 | G17: 43 | H17: 0 | I17: 0 | J17: 0 | K17: 0 | L17: 0 | M17: 0 | N17: 0 | O17: 0 | P17: 0 | Q17: 0
B18: Impairment of Non-current assets and Inventory (refer note 39) | C18: 51 | D18: 0 | E18: 0 | F18: 0 | G18: 0 | H18: 0 | I18: 0 | J18: 0 | K18: 0 | L18: 0 | M18: 0 | N18: 0 | O18: 0 | P18: 0 | Q18: 0
B19: Fair valuation gain on existing stake of Joint venture (refer note 42)/FA and Invstmnt | C19: -64 | D19: 0 | E19: 0 | F19: 0 | G19: 0 | H19: 0 | I19: 0 | J19: 0 | K19: 0 | L19: 0 | M19: 0 | N19: 0 | O19: 0 | P19: 0 | Q19: 0
B20: Bad debt written off and Provision for doubtful debts | C20: 3 | D20: 8 | E20: 1 | F20: 2 | G20: 2 | H20: 0 | I20: 0 | J20: 0 | K20: 0 | L20: 0 | M20: 0 | N20: 0 | O20: 0 | P20: 0 | Q20: 0
B21: Stock appreciation rights expense charge
B22: Sum of Adjustments | C22: =SUM(C11:C21) -> 94 | D22: =SUM(D11:D21) -> 108 | E22: =SUM(E11:E21) -> 104 | F22: =SUM(F11:F21) -> 103 | G22: =SUM(G11:G21) -> 103 | H22: =SUM(H11:H21) -> 224.51275 | I22: =SUM(I11:I21) -> 265.6801 | J22: =SUM(J11:J21) -> 315.82126 | ... Q22: =SUM(Q11:Q21) -> 1168.4901
B23: Sub total of Adjustment | C23: =SUM(C22,C9) -> 1617 | D23: =SUM(D22,D9) -> 1709 | E23: =SUM(E22,E9) -> 1847 | F23: =SUM(F22,F9) -> 2040 | G23: =SUM(G22,G9) -> 2219 | H23: =SUM(H22,H9) -> 2455.3337 | I23: =SUM(I22,I9) -> 2695.1351 | J23: =SUM(J22,J9) -> 2975.2495 | ... Q23: =SUM(Q22,Q9) -> 7393.4883
B24: Change in operating assets and liabilities:
B25: (Increase) / Decrease in inventories | C25: 251 | D25: -286 | E25: 191 | F25: -101 | G25: 101 | H25: ='Balance Sheet'!G26-'Balance Sheet'!H26 -> -342.34732 | I25: ='Balance Sheet'!H26-'Balance Sheet'!I26 -> -154.05247 | J25: ='Balance Sheet'!I26-'Balance Sheet'!J26 -> -179.95013 | K25: ='Balance Sheet'!J26-'Balance Sheet'!K26 -> -212.24133 | L25: ='Balance Sheet'!K26-'Balance Sheet'!L26 -> -252.76156 | M25: ='Balance Sheet'!L26-'Balance Sheet'!M26 -> -303.89618 | N25: ='Balance Sheet'!M26-'Balance Sheet'!N26 -> -368.74698 | O25: ='Balance Sheet'!N26-'Balance Sheet'!O26 -> -451.34923 | ... Q25: ='Balance Sheet'!P26-'Balance Sheet'!Q26 -> -692.40043
B26: (Increase) in trade receivables/decrease | C26: 147 | D26: -272 | E26: -360 | F26: -52 | G26: -205 | H26: ='Balance Sheet'!G29-'Balance Sheet'!H29 -> 209.18749 | I26: ='Balance Sheet'!H29-'Balance Sheet'!I29 -> -103.70248 | J26: ='Balance Sheet'!I29-'Balance Sheet'!J29 -> -121.13584 | K26: ='Balance Sheet'!J29-'Balance Sheet'!K29 -> -142.8731 | L26: ='Balance Sheet'!K29-'Balance Sheet'!L29 -> -170.14983 | M26: ='Balance Sheet'!L29-'Balance Sheet'!M29 -> -204.57179 | N26: ='Balance Sheet'!M29-'Balance Sheet'!N29 -> -248.22698 | O26: ='Balance Sheet'!N29-'Balance Sheet'!O29 -> -303.83179 | ... Q26: ='Balance Sheet'!P29-'Balance Sheet'!Q29 -> -466.09863
B27: (Increase) / Decrease in other financials assets | C27: -4 | D27: 3 | E27: 13 | F27: -4 | G27: 3 | H27: ='Balance Sheet'!G33-'Balance Sheet'!H33 -> -1.8173283 | I27: ='Balance Sheet'!H33-'Balance Sheet'!I33 -> -0.47048693 | J27: ='Balance Sheet'!I33-'Balance Sheet'!J33 -> -0.54958019 | K27: ='Balance Sheet'!J33-'Balance Sheet'!K33 -> -0.64819977 | L27: ='Balance Sheet'!K33-'Balance Sheet'!L33 -> -0.77195135 | M27: ='Balance Sheet'!L33-'Balance Sheet'!M33 -> -0.92812005 | N27: ='Balance Sheet'!M33-'Balance Sheet'!N33 -> -1.1261789 | O27: ='Balance Sheet'!N33-'Balance Sheet'!O33 -> -1.3784519 | ... Q27: ='Balance Sheet'!P33-'Balance Sheet'!Q33 -> -2.114639
B28: (Increase) in other non-current assets/decrease | C28: 2 | D28: 0 | E28: -4 | F28: -6 | G28: 2 | H28: =SUM('Balance Sheet'!G28,'Balance Sheet'!G34,'Balance Sheet'!G36)-SUM('Balance Sheet'!H28,'Balance Sheet'!H34,'Balance Sheet'!H36) -> 520.0755 | I28: =SUM('Balance Sheet'!H28,'Balance Sheet'!H34,'Balance Sheet'!H36)-SUM('Balance Sheet'!I28,'Balance Sheet'!I34,'Balance Sheet'!I36) -> -83.691988 | J28: =SUM('Balance Sheet'!I28,'Balance Sheet'!I34,'Balance Sheet'!I36)-SUM('Balance Sheet'!J28,'Balance Sheet'!J34,'Balance Sheet'!J36) -> -97.761395 | K28: =SUM('Balance Sheet'!J28,'Balance Sheet'!J34,'Balance Sheet'!J36)-SUM('Balance Sheet'!K28,'Balance Sheet'!K34,'Balance Sheet'!K36) -> -115.30422 | L28: =SUM('Balance Sheet'!K28,'Balance Sheet'!K34,'Balance Sheet'!K36)-SUM('Balance Sheet'!L28,'Balance Sheet'!L34,'Balance Sheet'!L36) -> -137.31761 | M28: =SUM('Balance Sheet'!L28,'Balance Sheet'!L34,'Balance Sheet'!L36)-SUM('Balance Sheet'!M28,'Balance Sheet'!M34,'Balance Sheet'!M36) -> -165.09749 | N28: =SUM('Balance Sheet'!M28,'Balance Sheet'!M34,'Balance Sheet'!M36)-SUM('Balance Sheet'!N28,'Balance Sheet'!N34,'Balance Sheet'!N36) -> -200.32895 | O28: =SUM('Balance Sheet'!N28,'Balance Sheet'!N34,'Balance Sheet'!N36)-SUM('Balance Sheet'!O28,'Balance Sheet'!O34,'Balance Sheet'!O36) -> -245.20421 | ... Q28: =SUM('Balance Sheet'!P28,'Balance Sheet'!P34,'Balance Sheet'!P36)-SUM('Balance Sheet'!Q28,'Balance Sheet'!Q34,'Balance Sheet'!Q36) -> -376.15995
B29: (Increase) in other current assets/decrease | C29: 83 | D29: 11 | E29: -13 | F29: -145 | G29: -33 | H29: ='Balance Sheet'!G35-'Balance Sheet'!H35 -> 55.822835 | I29: ='Balance Sheet'!H35-'Balance Sheet'!I35 -> -34.883898 | J29: ='Balance Sheet'!I35-'Balance Sheet'!J35 -> -40.748208 | K29: ='Balance Sheet'!J35-'Balance Sheet'!K35 -> -48.060282 | L29: ='Balance Sheet'!K35-'Balance Sheet'!L35 -> -57.235749 | M29: ='Balance Sheet'!L35-'Balance Sheet'!M35 -> -68.814759 | N29: ='Balance Sheet'!M35-'Balance Sheet'!N35 -> -83.499684 | O29: ='Balance Sheet'!N35-'Balance Sheet'!O35 -> -102.20427 | ... Q29: ='Balance Sheet'!P35-'Balance Sheet'!Q35 -> -156.78831
B30: (Increase) / Decrease in loans and other assets | C30: -60 | D30: 1 | E30: 1 | F30: 9 | G30: -3 | H30: ='Balance Sheet'!G32-'Balance Sheet'!H32 -> 0.023675914 | I30: ='Balance Sheet'!H32-'Balance Sheet'!I32 -> -0.6813464 | J30: ='Balance Sheet'!I32-'Balance Sheet'!J32 -> -0.79588712 | K30: ='Balance Sheet'!J32-'Balance Sheet'!K32 -> -0.93870531 | L30: ='Balance Sheet'!K32-'Balance Sheet'!L32 -> -1.117919 | M30: ='Balance Sheet'!L32-'Balance Sheet'!M32 -> -1.3440783 | N30: ='Balance Sheet'!M32-'Balance Sheet'!N32 -> -1.6309017 | O30: ='Balance Sheet'!N32-'Balance Sheet'!O32 -> -1.9962366 | ... Q30: ='Balance Sheet'!P32-'Balance Sheet'!Q32 -> -3.0623628
B31: (Decrease)/ Increase in provisions | C31: -39 | D31: 1 | E31: 26 | F31: -40 | G31: 14 | H31: ='Balance Sheet'!H68-'Balance Sheet'!G68 -> 7.0670904 | I31: ='Balance Sheet'!I68-'Balance Sheet'!H68 -> 2.7411873 | J31: ='Balance Sheet'!J68-'Balance Sheet'!I68 -> 3.2020066 | K31: ='Balance Sheet'!K68-'Balance Sheet'!J68 -> 3.7765916 | L31: ='Balance Sheet'!L68-'Balance Sheet'!K68 -> 4.4976026 | M31: ='Balance Sheet'!M68-'Balance Sheet'!L68 -> 5.4074847 | N31: ='Balance Sheet'!N68-'Balance Sheet'!M68 -> 6.5614306 | O31: ='Balance Sheet'!O68-'Balance Sheet'!N68 -> 8.0312429 | ... Q31: ='Balance Sheet'!Q68-'Balance Sheet'!P68 -> 12.320473
B32: Increase in employee benefit obligations/(decrease) | C32: 26 | D32: -7 | E32: 5 | F32: 5 | G32: 21 | H32: ='Balance Sheet'!H69-'Balance Sheet'!G69 -> 4.2377846 | I32: ='Balance Sheet'!I69-'Balance Sheet'!H69 -> 9.3991144 | J32: ='Balance Sheet'!J69-'Balance Sheet'!I69 -> 10.979194 | K32: ='Balance Sheet'!K69-'Balance Sheet'!J69 -> 12.949358 | L32: ='Balance Sheet'!L69-'Balance Sheet'!K69 -> 15.421595 | M32: ='Balance Sheet'!M69-'Balance Sheet'!L69 -> 18.541443 | N32: ='Balance Sheet'!N69-'Balance Sheet'!M69 -> 22.498148 | O32: ='Balance Sheet'!O69-'Balance Sheet'!N69 -> 27.537911 | ... Q32: ='Balance Sheet'!Q69-'Balance Sheet'!P69 -> 42.245029
B33: (Decrease) in other current liabilities/increase | C33: 77 | D33: -3 | E33: -9 | F33: -7 | G33: 21 | H33: ='Balance Sheet'!H67-'Balance Sheet'!G67 -> 63.057958 | I33: ='Balance Sheet'!I67-'Balance Sheet'!H67 -> 28.816992 | J33: ='Balance Sheet'!J67-'Balance Sheet'!I67 -> 33.661399 | K33: ='Balance Sheet'!K67-'Balance Sheet'!J67 -> 39.701778 | L33: ='Balance Sheet'!L67-'Balance Sheet'!K67 -> 47.281475 | M33: ='Balance Sheet'!M67-'Balance Sheet'!L67 -> 56.846698 | N33: ='Balance Sheet'!N67-'Balance Sheet'!M67 -> 68.977663 | O33: ='Balance Sheet'!O67-'Balance Sheet'!N67 -> 84.429205 | ... Q33: ='Balance Sheet'!Q67-'Balance Sheet'!P67 -> 129.52015
B34: Increase in trade payables/(decrease) | C34: 184 | D34: 210 | E34: 99 | F34: 106 | G34: -218 | H34: ='Working Capital'!H14-'Working Capital'!G14 -> 348.16045 | I34: ='Working Capital'!I14-'Working Capital'!H14 -> 167.1214 | J34: ='Working Capital'!J14-'Working Capital'!I14 -> 195.21607 | K34: ='Working Capital'!K14-'Working Capital'!J14 -> 230.24667 | L34: ='Working Capital'!L14-'Working Capital'!K14 -> 274.2044 | M34: ='Working Capital'!M14-'Working Capital'!L14 -> 329.67699 | N34: ='Working Capital'!N14-'Working Capital'!M14 -> 400.02937 | O34: ='Working Capital'!O14-'Working Capital'!N14 -> 489.63911 | ... Q34: ='Working Capital'!Q14-'Working Capital'!P14 -> 751.13972
B35: Increase / (Decrease) in other financial liabilities | C35: 8 | D35: 0 | E35: -8 | F35: 9 | G35: 4 | H35: =SUM('Balance Sheet'!H61,'Balance Sheet'!H62,'Balance Sheet'!H66,'Balance Sheet'!H70)-SUM('Balance Sheet'!G61:G62,'Balance Sheet'!G66,'Balance Sheet'!G70) -> -24.646275 | I35: =SUM('Balance Sheet'!I61,'Balance Sheet'!I62,'Balance Sheet'!I66,'Balance Sheet'!I70)-SUM('Balance Sheet'!H61:H62,'Balance Sheet'!H66,'Balance Sheet'!H70) -> 71.135054 | J35: =SUM('Balance Sheet'!J61,'Balance Sheet'!J62,'Balance Sheet'!J66,'Balance Sheet'!J70)-SUM('Balance Sheet'!I61:I62,'Balance Sheet'!I66,'Balance Sheet'!I70) -> 83.093524 | K35: =SUM('Balance Sheet'!K61,'Balance Sheet'!K62,'Balance Sheet'!K66,'Balance Sheet'!K70)-SUM('Balance Sheet'!J61:J62,'Balance Sheet'!J66,'Balance Sheet'!J70) -> 98.004264 | L35: =SUM('Balance Sheet'!L61,'Balance Sheet'!L62,'Balance Sheet'!L66,'Balance Sheet'!L70)-SUM('Balance Sheet'!K61:K62,'Balance Sheet'!K66,'Balance Sheet'!K70) -> 116.71483 | M35: =SUM('Balance Sheet'!M61,'Balance Sheet'!M62,'Balance Sheet'!M66,'Balance Sheet'!M70)-SUM('Balance Sheet'!L61:L62,'Balance Sheet'!L66,'Balance Sheet'!L70) -> 140.32668 | N35: =SUM('Balance Sheet'!N61,'Balance Sheet'!N62,'Balance Sheet'!N66,'Balance Sheet'!N70)-SUM('Balance Sheet'!M61:M62,'Balance Sheet'!M66,'Balance Sheet'!M70) -> 170.2721 | O35: =SUM('Balance Sheet'!O61,'Balance Sheet'!O62,'Balance Sheet'!O66,'Balance Sheet'!O70)-SUM('Balance Sheet'!N61:N62,'Balance Sheet'!N66,'Balance Sheet'!N70) -> 208.4144 | ... Q35: =SUM('Balance Sheet'!Q61,'Balance Sheet'!Q62,'Balance Sheet'!Q66,'Balance Sheet'!Q70)-SUM('Balance Sheet'!P61:P62,'Balance Sheet'!P66,'Balance Sheet'!P70) -> 319.72187
B36: Changes in working capital | C36: =SUM(C25:C35) -> 675 | D36: =SUM(D25:D35) -> -342 | E36: =SUM(E25:E35) -> -59 | F36: =SUM(F25:F35) -> -226 | G36: =SUM(G25:G35) -> -293 | H36: =SUM(H25:H35) -> 838.82186 | I36: =SUM(I25:I35) -> -98.268924 | J36: =SUM(J25:J35) -> -114.78885 | ... Q36: =SUM(Q25:Q35) -> -441.67709
B37: Cash generated from operations | C37: =C23+C36 -> 2292 | D37: =D23+D36 -> 1367 | E37: =E23+E36 -> 1788 | F37: =F23+F36 -> 1814 | G37: =G23+G36 -> 1926 | H37: =H23+H36 -> 3294.1555 | I37: =I23+I36 -> 2596.8662 | J37: =J23+J36 -> 2860.4606 | ... Q37: =Q23+Q36 -> 6951.8112
B38: Income taxes paid (net of refunds) | C38: -285 | D38: -351 | E38: -369 | F38: -378 | G38: -484 | H38: =-'P&L Statement '!H37 -> -495.87166 | I38: =-'P&L Statement '!I37 -> -540.02448 | J38: =-'P&L Statement '!J37 -> -591.14342 | K38: =-'P&L Statement '!K37 -> -650.9658 | L38: =-'P&L Statement '!L37 -> -721.74464 | M38: =-'P&L Statement '!M37 -> -806.40772 | N38: =-'P&L Statement '!N37 -> -908.76586 | O38: =-'P&L Statement '!O37 -> -1033.7857 | ... Q38: =-'P&L Statement '!Q37 -> -1383.706
B39: Net cash generated from operating activities (A) | C39: =SUM(C37:C38) -> 2007 | D39: =SUM(D37:D38) -> 1016 | E39: =SUM(E37:E38) -> 1419 | F39: =SUM(F37:F38) -> 1436 | G39: =SUM(G37:G38) -> 1442 | H39: =SUM(H37:H38) -> 2798.2839 | I39: =SUM(I37:I38) -> 2056.8417 | J39: =SUM(J37:J38) -> 2269.3172 | ... Q39: =SUM(Q37:Q38) -> 5568.1053
B41: CASH FLOW FROM INVESTING ACTIVITIES
B42: Payment for property, plant and equipment and intangible assets | C42: -142 | D42: -132 | E42: -182 | F42: -153 | G42: -161 | H42: =-'FAS Seechules'!H92 -> -250.72036 | I42: =-'FAS Seechules'!I92 -> -287.97769 | J42: =-'FAS Seechules'!J92 -> -332.09794 | K42: =-'FAS Seechules'!K92 -> -384.5063 | L42: =-'FAS Seechules'!L92 -> -446.94432 | M42: =-'FAS Seechules'!M92 -> -521.54252 | N42: =-'FAS Seechules'!N92 -> -610.91009 | O42: =-'FAS Seechules'!O92 -> -718.2454 | ... Q42: =-'FAS Seechules'!Q92 -> -1003.4095
B43: Acquisition of subsidiary under business combination net of cash (refer note 42) | C43: -132 | D43: -55 | E43: -277 | F43: -103 | G43: 0 | H43: 0 | I43: 0 | J43: 0 | K43: 0 | L43: 0 | M43: 0 | N43: 0 | O43: 0 | P43: 0 | Q43: 0
B44: Proceeds from sale of property, plant and equipment | C44: 5 | D44: 3 | E44: 25 | F44: 18 | G44: 39 | H44: 0 | I44: 0 | J44: 0 | K44: 0 | L44: 0 | M44: 0 | N44: 0 | O44: 0 | P44: 0 | Q44: 0
B45: Purchase of non current investments | C45: 0 | D45: 0 | E45: 0 | F45: 0 | G45: -46 | H45: ='Balance Sheet'!G18-'Balance Sheet'!H18 -> -154.49629 | I45: ='Balance Sheet'!H18-'Balance Sheet'!I18 -> -36.087052 | J45: ='Balance Sheet'!I18-'Balance Sheet'!J18 -> -42.153623 | K45: ='Balance Sheet'!J18-'Balance Sheet'!K18 -> -49.717892 | L45: ='Balance Sheet'!K18-'Balance Sheet'!L18 -> -59.209824 | M45: ='Balance Sheet'!L18-'Balance Sheet'!M18 -> -71.188196 | N45: ='Balance Sheet'!M18-'Balance Sheet'!N18 -> -86.379607 | O45: ='Balance Sheet'!N18-'Balance Sheet'!O18 -> -105.72932 | ... Q45: ='Balance Sheet'!P18-'Balance Sheet'!Q18 -> -162.19598
...

Sheet B_Sheet Forecast
B4: Balance Sheet Forecast
B5: All Figure In INR Cr.
B6: Particulars | C6: 2021 | D6: =C6+1 -> 2022 | E6: =D6+1 -> 2023 | F6: =E6+1 -> 2024 | G6: =F6+1 -> 2025 | H6: =G6+1 -> 2026 | I6: =H6+1 -> 2027 | J6: =I6+1 -> 2028 | K6: =J6+1 -> 2029 | ... Q6: =P6+1 -> 2035
B7: Non-current assets
