Workbook

Sheet Assumption
B8: Scenario Manager | E8: Company Name | F8: Paradeep Phosphates Ltd
B9: Best Case | C9: =IF(B9="Best Case",1,IF(B9="Base Case",2,3)) -> 1 | E9: ISIN Code | F9: INE088F01024
E10: Sector Name | F10: Fertilizers
E11: Industry | F11: Fertilizers & Agrochemicals
E12: Exchange Name | F12: NSE: PARADEEP / BSE: 543530
B13: Assumptions | E13: Website | F13: www.paradeepphosphates.com
B14: Addition In FAS | C14: 0.005 | E14: Company Description | F14: Incorporated in 1981, Paradeep Phosphates Limited is a manufacturer of non-urea fertilizers and India’s second largest private sector phosphatic company. The company is engaged in manufacturing, trading, distribution, and sales of a variety of complex fertilizers such as DAP, three grades of Nitrogen-Phosphorus-Potassium (namely NPK-10, NPK-12, and NP-20), Zypmite, Phospho-gypsum, and Hydroflorosilicic Acid. The company serves over 9 Million farmers across 15 states in India. Its network includes 22 regional offices, 529 stock points, over 5,000 dealers, and 75,000 retailers
B15: Annual growth Tapering | C15: ='Revenue BuildUp'!C23 -> 0.2
B16: Risk Free Rate | C16: 0.06519
B17: Tax Rate | C17: ='cost Build_up'!$G$35 -> 0.29058993
B18: EV/EBITDA Multiple | C18: ='Comps Valuation'!E34 -> 12.828106
B19: Perpetual Growth Rate | C19: 0.05
B20: Discount Rate | C20: =WACC!C28 -> 0.08201757
B21: Shares Outstanding(Lakhs) | C21: ='Balance Sheet'!F39/Assumption!C22 -> 8147.786
B22: Face Value | C22: 10
B23: Current Market Price | C23: 220.13
B24: Market Cap (Lakhs) | C24: =C23*C21 -> 1793572.1

Sheet Income statement
B6: Historical Income Statement
B8: Particulars | C8: 2021 | D8: =C8+1 -> 2022 | E8: =D8+1 -> 2023 | F8: =E8+1 -> 2024
B9: Revenue
B10: Revenue from Operations | C10: 516473.35 | D10: 785871.92 | E10: 1334072.2 | F10: 1157512
B11: Other income | C11: 1920.6 | D11: 3926.99 | E11: 9107 | F11: 6883.51
B12: Total Income | C12: =SUM(C10:C11) -> 518393.95 | D12: =SUM(D10:D11) -> 789798.91 | E12: =SUM(E10:E11) -> 1343179.2 | F12: =SUM(F10:F11) -> 1164395.5
B13: Expenses
B14: Cost of materials consumed | C14: 226512.43 | D14: 524622.29 | E14: 1043969.5 | F14: 760903.84
B15: Purchase of stock-in-trade | C15: 138020.07 | D15: 142828.18 | E15: 18226.12 | F15: 105508.61
B16: Changes in Inventories of Finished Goods, Work-in-progress and Stock-in-Trade | C16: 22583.41 | D16: -39324.17 | E16: -877.73 | F16: 33431.87
B17: Employee Benefits Expenses | C17: 13919 | D17: 13850.44 | E17: 21320.25 | F17: 22978.77
B18: Finance cost | C18: 11142.53 | D18: 8554.14 | E18: 29124.25 | F18: 36602.7
B19: Depreciation and Amortisation Expenses | C19: 8332.81 | D19: 9045.72 | E19: 17515.31 | F19: 21067.03
B20: Other Expenses | C20: 61213.9 | D20: 76784.2 | E20: 171335.01 | F20: 169885.95
B21: Total Expenses | C21: =SUM(C14:C20) -> 481724.15 | D21: =SUM(D14:D20) -> 736360.8 | E21: =SUM(E14:E20) -> 1300612.7 | F21: =SUM(F14:F20) -> 1150378.8
B23: Profit before share of equity accounted investee and tax | C23: =C12-C21 -> 36669.8 | D23: =D12-D21 -> 53438.11 | E23: =E12-E21 -> 42566.46 | F23: =F12-F21 -> 14016.72
B24: Share of net profit/(loss) of associate accounted for using the equity method | C24: -19.5 | D24: 61.12 | E24: 50.52 | F24: 66.7
B26: Profit before tax | C26: =SUM(C23:C24) -> 36650.3 | D26: =SUM(D23:D24) -> 53499.23 | E26: =SUM(E23:E24) -> 42616.98 | F26: =SUM(F23:F24) -> 14083.42
B27: Tax expenses | C27: 14323.48 | D27: 13653.91 | E27: 12197.72 | F27: 4092.5
B28: Profit for the year | C28: =C26-C27 -> 22326.82 | D28: =D26-D27 -> 39845.32 | E28: =E26-E27 -> 30419.26 | F28: =F26-F27 -> 9990.92
B31: Earnings per equity share
B32: Basic | C32: 3.88 | D32: 6.91 | E32: 3.9 | F32: 1.22
B33: Diluted | C33: 3.88 | D33: 6.91 | E33: 3.9 | F33: 1.22

Sheet Balance Sheet
B6: Historical BalanceSheet
B8: Particulars | C8: 2021 | D8: =C8+1 -> 2022 | E8: =D8+1 -> 2023 | F8: =E8+1 -> 2024
B10: Assets
B11: Non-Current Assets
B12: Property Plant and Equipment | C12: 122510.42 | D12: 125973.84 | E12: 279571.01 | F12: 335317.89
B13: Capital Work-in-Progress | C13: 22005.97 | D13: 33629.46 | E13: 69686.32 | F13: 37219.28
B14: Right of use Assets | C14: 0 | D14: 0 | E14: 1619.27 | F14: 1790.53
B15: Goodwill | C15: 0 | D15: 0 | E15: 5806.94 | F15: 5806.94
B16: Intangible Assets | C16: 110.55 | D16: 86.23 | E16: 177.84 | F16: 184.5
B17: Equity accounted investment | C17: 278.52 | D17: 289.43 | E17: 315.29 | F17: 324.63
C18: 0 | D18: 0 | E18: 0 | F18: 0
B19: Other income tax assets | C19: 1246.99 | D19: 1236.5 | E19: 1106.62 | F19: 5950.43
B20: Other Non-Current Assets | C20: 2321.36 | D20: 118276.53 | E20: 5900.04 | F20: 3828.56
B22: Total Non-Current Assets | C22: =SUM(C12:C21) -> 148473.81 | D22: =SUM(D12:D21) -> 279491.99 | E22: =SUM(E12:E21) -> 364183.33 | F22: =SUM(F12:F21) -> 390422.76
B24: Current Assets:
B25: Inventories | C25: 89905.36 | D25: 229322.24 | E25: 223767.72 | F25: 183082.95
B26: Investments | C26: 12204 | D26: 55036.14 | E26: 0 | F26: 0
B27: Trade Receivables | C27: 115559.36 | D27: 90247.54 | E27: 368973.75 | F27: 272047.93
B28: Cash and Cash Equivalents | C28: 9152.45 | D28: 53784.1 | E28: 4303.42 | F28: 9071.79
B29: Bank Balances | C29: 167.32 | D29: 5987.37 | E29: 6681.98 | F29: 2730.57
B30: Others Current Financial Assets | C30: 19591.9 | D30: 33844.36 | E30: 33718.27 | F30: 50419.05
B31: Other Current Assets | C31: 47238.04 | D31: 45080.39 | E31: 64048.36 | F31: 58314.22
B32: Assets classified as held for sale | C32: 24.32 | D32: 23.96 | E32: 23.26 | F32: 23.26
B33: Total Current Assets | C33: =SUM(C25:C32) -> 293842.75 | D33: =SUM(D25:D32) -> 513326.1 | E33: =SUM(E25:E32) -> 701516.76 | F33: =SUM(F25:F32) -> 575689.77
B35: TOTAL ASSETS | C35: =C33+C22 -> 442316.56 | D35: =D33+D22 -> 792818.09 | E35: =E33+E22 -> 1065700.1 | F35: =F33+F22 -> 966112.53
B37: EQUITY AND LIABILITIES
B38: EQUITY
B39: Equity Share Capital | C39: 57545 | D39: 57545 | E39: 81449.76 | F39: 81477.86
B40: Other Equity | C40: 125205.97 | D40: 164954.74 | E40: 269020.47 | F40: 274962.15
B42: Total Equity | C42: =SUM(C39:C40) -> 182750.97 | D42: =SUM(D39:D40) -> 222499.74 | E42: =SUM(E39:E40) -> 350470.23 | F42: =SUM(F39:F40) -> 356440.01
B44: LIABILITIES
B45: Non-Current Liabilities:
B46: Financial Liabilities
B47: (i) Borrowings | C47: 11341.13 | D47: 52817.08 | E47: 61188.79 | F47: 67650.58
B48: (ii) Lease Liabilities | C48: 0 | D48: 0 | E48: 1603.78 | F48: 1722.29
B49: Other financial liabilities | C49: 10.05 | D49: 286.71 | E49: 180.42 | F49: 0
B50: Provisions | C50: 1974.99 | D50: 2654.83 | E50: 2379.21 | F50: 2621.4
B51: Deferred Tax Liabilities (Net) | C51: 9301.23 | D51: 9218.11 | E51: 10778.02 | F51: 15085.16
B52: Total Non-Current Liabilities | C52: =SUM(C47:C51) -> 22627.4 | D52: =SUM(D47:D51) -> 64976.73 | E52: =SUM(E47:E51) -> 76130.22 | F52: =SUM(F47:F51) -> 87079.43
B54: Current Liabilities:
...

Sheet Revenue BuildUp
B6: Revenue Build_up
B8: Particulars | C8: 2021 | D8: =C8+1 -> 2022 | E8: =D8+1 -> 2023 | F8: =E8+1 -> 2024 | G8: =F8+1 -> 2025 | H8: =G8+1 -> 2026 | I8: =H8+1 -> 2027 | J8: =I8+1 -> 2028 | K8: =J8+1 -> 2029
B10: Revenue | C10: ='Income statement'!C10 -> 516473.35 | D10: ='Income statement'!D10 -> 785871.92 | E10: ='Income statement'!E10 -> 1334072.2 | F10: ='Income statement'!F10 -> 1157512 | G10: =F10*(1+G11) -> 1750480.1 | H10: =G10*(1+H11) -> 2467866.2 | I10: =H10*(1+I11) -> 3276975.9 | J10: =I10*(1+J11) -> 4136482.1 | K10: =J10*(1+K11) -> 5004436.6
B11: Growth Rate | D11: =D10/C10-1 -> 0.52161175 | E11: =E10/D10-1 -> 0.69756948 | F11: =F10/E10-1 -> -0.13234682 | G11: =CHOOSE(Assumption!$C$9,'Revenue BuildUp'!G20:K20,'Revenue BuildUp'!G21:K21,'Revenue BuildUp'!G22:K22) -> 0.51227814 | H11: =CHOOSE(Assumption!$C$9,'Revenue BuildUp'!H20:L20,'Revenue BuildUp'!H21:L21,'Revenue BuildUp'!H22:L22) -> 0.40982251 | I11: =CHOOSE(Assumption!$C$9,'Revenue BuildUp'!I20:M20,'Revenue BuildUp'!I21:M21,'Revenue BuildUp'!I22:M22) -> 0.32785801 | J11: =CHOOSE(Assumption!$C$9,'Revenue BuildUp'!J20:N20,'Revenue BuildUp'!J21:N21,'Revenue BuildUp'!J22:N22) -> 0.26228641 | K11: =CHOOSE(Assumption!$C$9,'Revenue BuildUp'!K20:O20,'Revenue BuildUp'!K21:O21,'Revenue BuildUp'!K22:O22) -> 0.20982913
B13: Other Income | C13: ='Income statement'!C11 -> 1920.6 | D13: ='Income statement'!D11 -> 3926.99 | E13: ='Income statement'!E11 -> 9107 | F13: ='Income statement'!F11 -> 6883.51 | G13: =G10*G14 -> 9403.9942 | H13: =H10*H14 -> 13257.963 | I13: =I10*I14 -> 17604.692 | J13: =J10*J14 -> 22222.163 | K13: =K10*K14 -> 26885.021
B14: % of Revenue | C14: =C13/C10 -> 0.0037186817 | D14: =D13/D10 -> 0.0049969848 | E14: =E13/E10 -> 0.0068264672 | F14: =F13/F10 -> 0.0059468153 | G14: =AVERAGE(C14:F14) -> 0.0053722372 | H14: =G14 -> 0.0053722372 | I14: =H14 -> 0.0053722372 | J14: =I14 -> 0.0053722372 | K14: =J14 -> 0.0053722372
B16: Share of net profit/(loss) of associate accounted for using the equity method | C16: ='Income statement'!C24 -> -19.5 | D16: ='Income statement'!D24 -> 61.12 | E16: ='Income statement'!E24 -> 50.52 | F16: ='Income statement'!F24 -> 66.7 | G16: =G17*G10 -> 59.301903 | H16: =H17*H10 -> 83.605158 | I16: =I17*I10 -> 111.01578 | J16: =J17*J10 -> 140.13371 | K16: =K17*K10 -> 169.53784
B17: % of Revenue | C17: =C16/C10 -> -3.7756062e-05 | D17: =D16/D10 -> 7.7773488e-05 | E17: =E16/E10 -> 3.7869015e-05 | F17: =F16/F10 -> 5.7623594e-05 | G17: =AVERAGE(C17:F17) -> 3.3877509e-05 | H17: =G17 -> 3.3877509e-05 | I17: =H17 -> 3.3877509e-05 | J17: =I17 -> 3.3877509e-05 | K17: =J17 -> 3.3877509e-05
B19: Scenario | C19: Growth
B20: Best Case | C20: =C21+15% -> 0.51227814 | G20: =C20 -> 0.51227814 | H20: =G20*(1-$C$23) -> 0.40982251 | I20: =H20*(1-$C$23) -> 0.32785801 | J20: =I20*(1-$C$23) -> 0.26228641 | K20: =J20*(1-$C$23) -> 0.20982913
B21: Base Case | C21: =AVERAGE(D11:F11) -> 0.36227814 | G21: =C21 -> 0.36227814 | H21: =G21*(1-$C$23) -> 0.28982251 | I21: =H21*(1-$C$23) -> 0.23185801 | J21: =I21*(1-$C$23) -> 0.18548641 | K21: =J21*(1-$C$23) -> 0.14838913
B22: Worst Case | C22: =C21-15% -> 0.21227814 | G22: =C22 -> 0.21227814 | H22: =G22*(1-$C$23) -> 0.16982251 | I22: =H22*(1-$C$23) -> 0.13585801 | J22: =I22*(1-$C$23) -> 0.10868641 | K22: =J22*(1-$C$23) -> 0.086949126
B23: Annual growth Tapering | C23: 0.2

Sheet cost Build_up
B6: Cost Build_up
B8: Particulars | C8: 2021 | D8: =C8+1 -> 2022 | E8: =D8+1 -> 2023 | F8: =E8+1 -> 2024 | G8: =F8+1 -> 2025 | H8: =G8+1 -> 2026 | I8: =H8+1 -> 2027 | J8: =I8+1 -> 2028 | K8: =J8+1 -> 2029
B10: Revenue | C10: ='Revenue BuildUp'!C10 -> 516473.35 | D10: ='Revenue BuildUp'!D10 -> 785871.92 | E10: ='Revenue BuildUp'!E10 -> 1334072.2 | F10: ='Revenue BuildUp'!F10 -> 1157512 | G10: ='Revenue BuildUp'!G10 -> 1750480.1 | H10: ='Revenue BuildUp'!H10 -> 2467866.2 | I10: ='Revenue BuildUp'!I10 -> 3276975.9 | J10: ='Revenue BuildUp'!J10 -> 4136482.1 | K10: ='Revenue BuildUp'!K10 -> 5004436.6
B12: Cost of materials consumed | C12: ='Income statement'!C14 -> 226512.43 | D12: ='Income statement'!D14 -> 524622.29 | E12: ='Income statement'!E14 -> 1043969.5 | F12: ='Income statement'!F14 -> 760903.84 | G12: =G10*G13 -> 1114201.3 | H12: =H10*H13 -> 1570826.1 | I12: =I10*I13 -> 2085834 | J12: =J10*J13 -> 2632919.9 | K12: =K10*K13 -> 3185383.2
B13: % of Revenue | C13: =C12/C10 -> 0.43857525 | D13: =D12/D10 -> 0.66756717 | E13: =E12/E10 -> 0.7825435 | F13: =F12/F10 -> 0.65736152 | G13: =AVERAGE(C13:F13) -> 0.63651186 | H13: =G13 -> 0.63651186 | I13: =H13 -> 0.63651186 | J13: =I13 -> 0.63651186 | K13: =J13 -> 0.63651186
B15: Purchases of stock-in-trade | C15: ='Income statement'!C15 -> 138020.07 | D15: ='Income statement'!D15 -> 142828.18 | E15: ='Income statement'!E15 -> 18226.12 | F15: ='Income statement'!F15 -> 105508.61 | G15: =G16*G10 -> 242351.2 | H15: =H16*H10 -> 341672.18 | I15: =I16*I10 -> 453692.14 | J15: =J16*J10 -> 572689.43 | K15: =K16*K10 -> 692856.35
B16: % of Revenue | C16: =C15/C10 -> 0.26723561 | D16: =D15/D10 -> 0.18174486 | E16: =E15/E10 -> 0.013662019 | F16: =F15/F10 -> 0.091151203 | G16: =AVERAGE($C$16:$F$16) -> 0.13844842 | H16: =AVERAGE($C$16:$F$16) -> 0.13844842 | I16: =AVERAGE($C$16:$F$16) -> 0.13844842 | J16: =AVERAGE($C$16:$F$16) -> 0.13844842 | K16: =AVERAGE($C$16:$F$16) -> 0.13844842
B18: Changes in inventories of finished goods, work-in-progress and stock in-trade | C18: ='Income statement'!C16 -> 22583.41 | D18: ='Income statement'!D16 -> -39324.17 | E18: ='Income statement'!E16 -> -877.73 | F18: ='Income statement'!F16 -> 33431.87 | G18: =G19*G10 -> 9589.0751 | H18: =H19*H10 -> 13518.894 | I18: =I19*I10 -> 17951.172 | J18: =J19*J10 -> 22659.52 | K18: =K19*K10 -> 27414.147
B19: % of Revenue | C19: =C18/C10 -> 0.043726186 | D19: =D18/D10 -> -0.050038905 | E19: =E18/E10 -> -0.00065793291 | F19: =F18/F10 -> 0.028882526 | G19: =AVERAGE($C$19:$F$19) -> 0.0054779688 | H19: =AVERAGE($C$19:$F$19) -> 0.0054779688 | I19: =AVERAGE($C$19:$F$19) -> 0.0054779688 | J19: =AVERAGE($C$19:$F$19) -> 0.0054779688 | K19: =AVERAGE($C$19:$F$19) -> 0.0054779688
B21: COGS | C21: =C18+C15+C12 -> 387115.91 | D21: =D18+D15+D12 -> 628126.3 | E21: =E18+E15+E12 -> 1061317.9 | F21: =F18+F15+F12 -> 899844.32 | G21: =G18+G15+G12 -> 1366141.6 | H21: =H18+H15+H12 -> 1926017.2 | I21: =I18+I15+I12 -> 2557477.3 | J21: =J18+J15+J12 -> 3228268.9 | K21: =K18+K15+K12 -> 3905653.7
B22: % of Revenue | C22: =C21/C10 -> 0.74953705 | D22: =D21/D10 -> 0.79927312 | E22: =E21/E10 -> 0.79554759 | F22: =F21/F10 -> 0.77739525 | G22: =G21/G10 -> 0.78043825 | H22: =H21/H10 -> 0.78043825 | I22: =I21/I10 -> 0.78043825 | J22: =J21/J10 -> 0.78043825 | K22: =K21/K10 -> 0.78043825
B24: Gross Profit Margin | C24: =(C10-C21)/C10 -> 0.25046295 | D24: =(D10-D21)/D10 -> 0.20072688 | E24: =(E10-E21)/E10 -> 0.20445241 | F24: =(F10-F21)/F10 -> 0.22260475 | G24: =(G10-G21)/G10 -> 0.21956175 | H24: =(H10-H21)/H10 -> 0.21956175 | I24: =(I10-I21)/I10 -> 0.21956175 | J24: =(J10-J21)/J10 -> 0.21956175 | K24: =(K10-K21)/K10 -> 0.21956175
B26: Employee benefits expense | C26: ='Income statement'!C17 -> 13919 | D26: ='Income statement'!D17 -> 13850.44 | E26: ='Income statement'!E17 -> 21320.25 | F26: ='Income statement'!F17 -> 22978.77 | G26: =G27*G10 -> 35187.965 | H26: =H27*H10 -> 49608.785 | I26: =I27*I10 -> 65873.422 | J26: =J27*J10 -> 83151.125 | K26: =K27*K10 -> 100598.65
B27: % of Revenue | C27: =C26/C10 -> 0.026950084 | D27: =D26/D10 -> 0.017624297 | E27: =E26/E10 -> 0.015981332 | F27: =F26/F10 -> 0.019851864 | G27: =AVERAGE($C$27:$F$27) -> 0.020101894 | H27: =AVERAGE($C$27:$F$27) -> 0.020101894 | I27: =AVERAGE($C$27:$F$27) -> 0.020101894 | J27: =AVERAGE($C$27:$F$27) -> 0.020101894 | K27: =AVERAGE($C$27:$F$27) -> 0.020101894
B29: Other expenses | C29: ='Income statement'!C20 -> 61213.9 | D29: ='Income statement'!D20 -> 76784.2 | E29: ='Income statement'!E20 -> 171335.01 | F29: ='Income statement'!F20 -> 169885.95 | G29: =G30*G10 -> 215058.25 | H29: =H30*H10 -> 303193.96 | I29: =I30*I10 -> 402598.52 | J29: =J30*J10 -> 508194.64 | K29: =K30*K10 -> 614828.68
B30: % of Revenue | C30: =C29/C10 -> 0.11852286 | D30: =D29/D10 -> 0.097705743 | E30: =E29/E10 -> 0.12843009 | F30: =F29/F10 -> 0.1467682 | G30: =AVERAGE($C$30:$F$30) -> 0.12285672 | H30: =AVERAGE($C$30:$F$30) -> 0.12285672 | I30: =AVERAGE($C$30:$F$30) -> 0.12285672 | J30: =AVERAGE($C$30:$F$30) -> 0.12285672 | K30: =AVERAGE($C$30:$F$30) -> 0.12285672
B32: Opex | C32: =C29+C26 -> 75132.9 | D32: =D29+D26 -> 90634.64 | E32: =E29+E26 -> 192655.26 | F32: =F29+F26 -> 192864.72 | G32: =G29+G26 -> 250246.21 | H32: =H29+H26 -> 352802.74 | I32: =I29+I26 -> 468471.95 | J32: =J29+J26 -> 591345.77 | K32: =K29+K26 -> 715427.33
B33: % of Revenue | C33: =C32/C10 -> 0.14547295 | D33: =D32/D10 -> 0.11533004 | E33: =E32/E10 -> 0.14441142 | F33: =F32/F10 -> 0.16662006 | G33: =G32/G10 -> 0.14295862 | H33: =H32/H10 -> 0.14295862 | I33: =I32/I10 -> 0.14295862 | J33: =J32/J10 -> 0.14295862 | K33: =K32/K10 -> 0.14295862
B35: Effective Tax Rate | C35: ='Income statement'!C27/'Income statement'!C26 -> 0.39081481 | D35: ='Income statement'!D27/'Income statement'!D26 -> 0.25521694 | E35: ='Income statement'!E27/'Income statement'!E26 -> 0.28621737 | F35: ='Income statement'!F27/'Income statement'!F26 -> 0.29058993 | G35: =F35 -> 0.29058993 | H35: =G35 -> 0.29058993 | I35: =H35 -> 0.29058993 | J35: =I35 -> 0.29058993 | K35: =J35 -> 0.29058993

Sheet Working Capital
B6: Working Capital
B8: Particulars | C8: 2021 | D8: =C8+1 -> 2022 | E8: =D8+1 -> 2023 | F8: =E8+1 -> 2024 | G8: =F8+1 -> 2025 | H8: =G8+1 -> 2026 | I8: =H8+1 -> 2027 | J8: =I8+1 -> 2028 | K8: =J8+1 -> 2029
B9: Days of operation | C9: 365 | D9: =C9 -> 365 | E9: =D9 -> 365 | F9: =E9 -> 365 | G9: =F9 -> 365 | H9: =G9 -> 365 | I9: =H9 -> 365 | J9: =I9 -> 365 | K9: =J9 -> 365
B11: Inventores | C11: ='Balance Sheet'!C25 -> 89905.36 | D11: ='Balance Sheet'!D25 -> 229322.24 | E11: ='Balance Sheet'!E25 -> 223767.72 | F11: ='Balance Sheet'!F25 -> 183082.95 | G11: =G18*'cost Build_up'!G21/'Working Capital'!G9 -> 345508.68 | H11: =H18*'cost Build_up'!H21/'Working Capital'!H9 -> 487105.92 | I11: =I18*'cost Build_up'!I21/'Working Capital'!I9 -> 646807.5 | J11: =J18*'cost Build_up'!J21/'Working Capital'!J9 -> 816456.31 | K11: =K18*'cost Build_up'!K21/'Working Capital'!K9 -> 987772.62
B12: Recievables | C12: ='Balance Sheet'!C27 -> 115559.36 | D12: ='Balance Sheet'!D27 -> 90247.54 | E12: ='Balance Sheet'!E27 -> 368973.75 | F12: ='Balance Sheet'!F27 -> 272047.93 | G12: =G19*'cost Build_up'!G10/'Working Capital'!G9 -> 372060.02 | H12: =H19*'cost Build_up'!H10/'Working Capital'!H9 -> 524538.6 | I12: =I19*'cost Build_up'!I10/'Working Capital'!I9 -> 696512.78 | J12: =J19*'cost Build_up'!J10/'Working Capital'!J9 -> 879198.61 | K12: =K19*'cost Build_up'!K10/'Working Capital'!K9 -> 1063680.1
B13: Trade payables | C13: =SUM('Balance Sheet'!C59:C60) -> 93953.17 | D13: =SUM('Balance Sheet'!D59:D60) -> 227339.87 | E13: =SUM('Balance Sheet'!E59:E60) -> 191247.67 | F13: =SUM('Balance Sheet'!F59:F60) -> 148811.73 | G13: =G20*'cost Build_up'!G21/'Working Capital'!G9 -> 324529.32 | H13: =H20*'cost Build_up'!H21/'Working Capital'!H9 -> 457528.75 | I13: =I20*'cost Build_up'!I21/'Working Capital'!I9 -> 607533.21 | J13: =J20*'cost Build_up'!J21/'Working Capital'!J9 -> 766880.92 | K13: =K20*'cost Build_up'!K21/'Working Capital'!K9 -> 927794.87
B14: Net Working Capital | C14: =C11+C12-C13 -> 111511.55 | D14: =D11+D12-D13 -> 92229.91 | E14: =E11+E12-E13 -> 401493.8 | F14: =F11+F12-F13 -> 306319.15 | G14: =G11+G12-G13 -> 393039.38 | H14: =H11+H12-H13 -> 554115.77 | I14: =I11+I12-I13 -> 735787.06 | J14: =J11+J12-J13 -> 928774.01 | K14: =K11+K12-K13 -> 1123657.8
B17: KPI
B18: DIO | C18: =C11/'cost Build_up'!C21*'Working Capital'!C9 -> 84.769072 | D18: =D11/'cost Build_up'!D21*'Working Capital'!D9 -> 133.25762 | E18: =E11/'cost Build_up'!E21*'Working Capital'!E9 -> 76.956411 | F18: =F11/'cost Build_up'!F21*'Working Capital'!F9 -> 74.263153 | G18: =AVERAGE(C18:F18) -> 92.311565 | H18: =G18 -> 92.311565 | I18: =H18 -> 92.311565 | J18: =I18 -> 92.311565 | K18: =J18 -> 92.311565
B19: DSO | C19: =C12/'cost Build_up'!C10*'Working Capital'!C9 -> 81.667653 | D19: =D12/'cost Build_up'!D10*'Working Capital'!D9 -> 41.915675 | E19: =E12/'cost Build_up'!E10*'Working Capital'!E9 -> 100.95062 | F19: =F12/'cost Build_up'!F10*'Working Capital'!F9 -> 85.785284 | G19: =AVERAGE(C19:F19) -> 77.579809 | H19: =G19 -> 77.579809 | I19: =H19 -> 77.579809 | J19: =I19 -> 77.579809 | K19: =J19 -> 77.579809
B20: DPO | C20: =C13/'cost Build_up'!C21*'Working Capital'!C9 -> 88.585631 | D20: =D13/'cost Build_up'!D21*'Working Capital'!D9 -> 132.10568 | E20: =E13/'cost Build_up'!E21*'Working Capital'!E9 -> 65.772375 | F20: =F13/'cost Build_up'!F21*'Working Capital'!F9 -> 60.361865 | G20: =AVERAGE(C20:F20) -> 86.706388 | H20: =G20 -> 86.706388 | I20: =H20 -> 86.706388 | J20: =I20 -> 86.706388 | K20: =J20 -> 86.706388
B21: Net Trade Cycle | C21: =C18+C19-C20 -> 77.851094 | D21: =D18+D19-D20 -> 43.067617 | E21: =E18+E19-E20 -> 112.13466 | F21: =F18+F19-F20 -> 99.686573 | G21: =G18+G19-G20 -> 83.184986 | H21: =H18+H19-H20 -> 83.184986 | I21: =I18+I19-I20 -> 83.184986 | J21: =J18+J19-J20 -> 83.184986 | K21: =K18+K19-K20 -> 83.184986

Sheet Debt Schedules
B6: Debt Schedules
B8: Particulars | C8: 2021 | D8: =C8+1 -> 2022 | E8: =D8+1 -> 2023 | F8: =E8+1 -> 2024 | G8: =F8+1 -> 2025 | H8: =G8+1 -> 2026 | I8: =H8+1 -> 2027 | J8: =I8+1 -> 2028 | K8: =J8+1 -> 2029
B10: Opening Balance | D10: =C12 -> 125117.25 | E10: =D12 -> 295429.57 | F10: =E12 -> 464791.42 | G10: =F12 -> 401370.72 | H10: =G12 -> 574740.54 | I10: =H12 -> 810282.15 | J10: =I12 -> 1075939.6 | K10: =J12 -> 1358144
B11: New Issuance/ Repayment | D11: =D12-D10 -> 170312.32 | E11: =E12-E10 -> 169361.85 | F11: =F12-F10 -> -63420.7 | G11: =G12-G10 -> 173369.82 | H11: =H12-H10 -> 235541.61 | I11: =I12-I10 -> 265657.49 | J11: =J12-J10 -> 282204.34 | K11: =K12-K10 -> 284978.17
B12: Closing Balance | C12: =SUM('Balance Sheet'!C47:C48,'Balance Sheet'!C56:C57) -> 125117.25 | D12: =SUM('Balance Sheet'!D47:D48,'Balance Sheet'!D56:D57) -> 295429.57 | E12: =SUM('Balance Sheet'!E47:E48,'Balance Sheet'!E56:E57) -> 464791.42 | F12: =SUM('Balance Sheet'!F47:F48,'Balance Sheet'!F56:F57) -> 401370.72 | G12: =SUM('B_Sheet '!G29,'B_Sheet '!G31,'B_Sheet '!G41,'B_Sheet '!G43) -> 574740.54 | H12: =SUM('B_Sheet '!H29,'B_Sheet '!H31,'B_Sheet '!H41,'B_Sheet '!H43) -> 810282.15 | I12: =SUM('B_Sheet '!I29,'B_Sheet '!I31,'B_Sheet '!I41,'B_Sheet '!I43) -> 1075939.6 | J12: =SUM('B_Sheet '!J29,'B_Sheet '!J31,'B_Sheet '!J41,'B_Sheet '!J43) -> 1358144 | K12: =SUM('B_Sheet '!K29,'B_Sheet '!K31,'B_Sheet '!K41,'B_Sheet '!K43) -> 1643122.2
B13: Interest rate | C13: =C14/C12 -> 0.089056705 | D13: =D14/D12 -> 0.028954921 | E13: =E14/E12 -> 0.062660903 | F13: =F14/F12 -> 0.091194246 | G13: =AVERAGE(C13:F13) -> 0.067966694 | H13: =G13 -> 0.067966694 | I13: =H13 -> 0.067966694 | J13: =I13 -> 0.067966694 | K13: =J13 -> 0.067966694
B14: Interest Expense | C14: ='Income statement'!C18 -> 11142.53 | D14: ='Income statement'!D18 -> 8554.14 | E14: ='Income statement'!E18 -> 29124.25 | F14: ='Income statement'!F18 -> 36602.7 | G14: =G13*G12 -> 39063.214 | H14: =H13*H12 -> 55072.199 | I14: =I13*I12 -> 73128.06 | J14: =J13*J12 -> 92308.556 | K14: =K13*K12 -> 111677.58

Sheet CashFlow 
B6: CashFlow Statement
B8: Particulars | C8: 2021 | D8: =C8+1 -> 2022 | E8: =D8+1 -> 2023 | F8: =E8+1 -> 2024 | G8: =F8+1 -> 2025 | H8: =G8+1 -> 2026 | I8: =H8+1 -> 2027 | J8: =I8+1 -> 2028 | K8: =J8+1 -> 2029
B10: Cash Flow from Operating Activities:
B11: Profit before tax | C11: 36650.3 | D11: 53499.23 | E11: 42616.98 | F11: 14083.42 | G11: ='P&L Statement'!G28 -> 79252.793 | H11: ='P&L Statement'!H28 -> 118551.87 | I11: ='P&L Statement'!I28 -> 163562.79 | J11: ='P&L Statement'!J28 -> 211800.66 | K11: ='P&L Statement'!K28 -> 260744.85
B12: Adjustments for:
B13: Depreciation | C13: 8332.81 | D13: 9045.72 | E13: 17515.31 | F13: 21067.03 | G13: =-'P&L Statement'!G19 -> 25239.542 | H13: =-'P&L Statement'!H19 -> 28763.777 | I13: =-'P&L Statement'!I19 -> 32051.471 | J13: =-'P&L Statement'!J19 -> 35120.568 | K13: =-'P&L Statement'!K19 -> 37987.636
B14: Finance Cost | C14: 10158.34 | D14: 6151.37 | E14: 25151.99 | F14: 32128.33 | G14: =-'P&L Statement'!G24 -> 39063.214 | H14: =-'P&L Statement'!H24 -> 55072.199 | I14: =-'P&L Statement'!I24 -> 73128.06 | J14: =-'P&L Statement'!J24 -> 92308.556 | K14: =-'P&L Statement'!K24 -> 111677.58
B15: Interest income | C15: -55.86 | D15: -299.99 | E15: -986.5 | F15: -625.86 | G15: 0 | H15: 0 | I15: 0 | J15: 0 | K15: 0
B16: Profit on sale of current investments | C16: -23.43 | D16: -635.85 | E16: -93.36 | F16: -111.58 | G16: 0 | H16: 0 | I16: 0 | J16: 0 | K16: 0
B17: Gain on fair valuation of investments measured at fair value through profit or loss | C17: -3.99 | D17: -38.13 | G17: 0 | H17: 0 | I17: 0 | J17: 0 | K17: 0
B18: Loss on sale / discard of property,plant and equipment (net) | C18: 689.9 | D18: 1289.42 | E18: 1511.9 | F18: 2431.13 | G18: 0 | H18: 0 | I18: 0 | J18: 0 | K18: 0
B19: Loss allowance | C19: 764.91 | D19: 2095.78 | E19: 1239.9 | F19: 797.88 | G19: 0 | H19: 0 | I19: 0 | J19: 0 | K19: 0
B20: Bad debts, claims and advances written off | D20: 10.23 | E20: 68.73 | F20: 33.76 | G20: 0 | H20: 0 | I20: 0 | J20: 0 | K20: 0
B21: Unspent liabilities/provision no longer required written back | C21: -359.88 | D21: -1727.47 | E21: -6883.44 | F21: -3850.13 | G21: 0 | H21: 0 | I21: 0 | J21: 0 | K21: 0
B22: Foreign exchange fluctuation loss unrealised (net) | C22: 2400.17 | D22: 3922.46 | E22: 2586.92 | F22: 180.32 | G22: 0 | H22: 0 | I22: 0 | J22: 0 | K22: 0
B23: Share of profit from associate | C23: 19.5 | D23: -61.12 | E23: -50.52 | F23: -66.7 | G23: =-'Revenue BuildUp'!G16 -> -59.301903 | H23: =-'Revenue BuildUp'!H16 -> -83.605158 | I23: =-'Revenue BuildUp'!I16 -> -111.01578 | J23: =-'Revenue BuildUp'!J16 -> -140.13371 | K23: =-'Revenue BuildUp'!K16 -> -169.53784
B24: Operating Profit before Working Capital Changes | C24: =SUM(C11:C23) -> 58572.77 | D24: =SUM(D11:D23) -> 73251.65 | E24: =SUM(E11:E23) -> 82677.91 | F24: =SUM(F11:F23) -> 66067.6 | G24: =SUM(G11:G23) -> 143496.25 | H24: =SUM(H11:H23) -> 202304.24 | I24: =SUM(I11:I23) -> 268631.31 | J24: =SUM(J11:J23) -> 339089.65 | K24: =SUM(K11:K23) -> 410240.53
B26: Adjustments for:
B27: (Increase)/Decrease in Inventories | C27: 17948.45 | D27: -139416.88 | E27: 14748.72 | F27: 40684.77 | G27: =Balance_Sheet!F25-Balance_Sheet!G25 -> -162425.73 | H27: =Balance_Sheet!G25-Balance_Sheet!H25 -> -141597.24 | I27: =Balance_Sheet!H25-Balance_Sheet!I25 -> -159701.58 | J27: =Balance_Sheet!I25-Balance_Sheet!J25 -> -169648.81 | K27: =Balance_Sheet!J25-Balance_Sheet!K25 -> -171316.31
B28: Increase in trade receivables | C28: 98565.79 | D28: -10627.34 | E28: -242375.3 | F28: 96429.76 | G28: =Balance_Sheet!F27-Balance_Sheet!G27 -> -100012.09 | H28: =Balance_Sheet!G27-Balance_Sheet!H27 -> -152478.57 | I28: =Balance_Sheet!H27-Balance_Sheet!I27 -> -171974.18 | J28: =Balance_Sheet!I27-Balance_Sheet!J27 -> -182685.83 | K28: =Balance_Sheet!J27-Balance_Sheet!K27 -> -184481.48
B29: Increase in financial and other assets | C29: -33083.24 | D29: -51707.35 | E29: -4033.41 | F29: -10696.24 | G29: =SUM(Balance_Sheet!F30:F32)-SUM(Balance_Sheet!G30:G32) -> -65049.838 | H29: =SUM(Balance_Sheet!G30:G32)-SUM(Balance_Sheet!H30:H32) -> -71229.762 | I29: =SUM(Balance_Sheet!H30:H32)-SUM(Balance_Sheet!I30:I32) -> -80337.058 | J29: =SUM(Balance_Sheet!I30:I32)-SUM(Balance_Sheet!J30:J32) -> -85340.965 | K29: =SUM(Balance_Sheet!J30:J32)-SUM(Balance_Sheet!K30:K32) -> -86179.792
B30: (Decrease)/increase in trade payables and other current liabilities | C30: 15688.45 | D30: 132807.79 | E30: -74426.45 | F30: -41241.6 | G30: =SUM(Balance_Sheet!G56:G62,Balance_Sheet!G64)-SUM(Balance_Sheet!F56:F62,Balance_Sheet!F64) -> 356478.31 | H30: =SUM(Balance_Sheet!H56:H62,Balance_Sheet!H64)-SUM(Balance_Sheet!G56:G62,Balance_Sheet!G64) -> 357277.73 | I30: =SUM(Balance_Sheet!I56:I62,Balance_Sheet!I64)-SUM(Balance_Sheet!H56:H62,Balance_Sheet!H64) -> 402958.55 | J30: =SUM(Balance_Sheet!J56:J62,Balance_Sheet!J64)-SUM(Balance_Sheet!I56:I62,Balance_Sheet!I64) -> 428057.39 | K30: =SUM(Balance_Sheet!K56:K62,Balance_Sheet!K64)-SUM(Balance_Sheet!J56:J62,Balance_Sheet!J64) -> 432264.82
B31: Decrease in provisions | C31: 135.21 | D31: -143.48 | E31: -523.43 | F31: -1732.2 | G31: =Balance_Sheet!G63-Balance_Sheet!F63 -> 9646.0062 | H31: =Balance_Sheet!H63-Balance_Sheet!G63 -> 6938.6665 | I31: =Balance_Sheet!I63-Balance_Sheet!H63 -> 7825.8306 | J31: =Balance_Sheet!J63-Balance_Sheet!I63 -> 8313.2735 | K31: =Balance_Sheet!K63-Balance_Sheet!J63 -> 8394.9857
B32: Cash Generated from Operations | C32: =C24+SUM(C27:C31) -> 157827.43 | D32: =D24+SUM(D27:D31) -> 4164.39 | E32: =E24+SUM(E27:E31) -> -223931.96 | F32: =F24+SUM(F27:F31) -> 149512.09 | G32: =G24+SUM(G27:G31) -> 182132.9 | H32: =H24+SUM(H27:H31) -> 201215.07 | I32: =I24+SUM(I27:I31) -> 267402.87 | J32: =J24+SUM(J27:J31) -> 337784.7 | K32: =K24+SUM(K27:K31) -> 408922.76
B33: Direct Taxes Paid | C33: -7712.66 | D33: -8552.21 | E33: -13735.33 | F33: -5836.25 | G33: =-'P&L Statement'!G31 -> -23030.064 | H33: =-'P&L Statement'!H31 -> -34449.979 | I33: =-'P&L Statement'!I31 -> -47529.699 | J33: =-'P&L Statement'!J31 -> -61547.137 | K33: =-'P&L Statement'!K31 -> -75769.828
B35: Net Cash Flow from Operating Activities (A) | C35: =SUM(C32:C33) -> 150114.77 | D35: =SUM(D32:D33) -> -4387.82 | E35: =SUM(E32:E33) -> -237667.29 | F35: =SUM(F32:F33) -> 143675.84 | G35: =SUM(G32:G33) -> 159102.83 | H35: =SUM(H32:H33) -> 166765.09 | I35: =SUM(I32:I33) -> 219873.17 | J35: =SUM(J32:J33) -> 276237.56 | K35: =SUM(K32:K33) -> 333152.93
B37: Cash Flow from Investing Activities:
B38: Proceeds from sale of property, plant and equipment | C38: 11.04 | D38: 38.4 | E38: 37.73 | F38: 38.78 | G38: 0 | H38: 0 | I38: 0 | J38: 0 | K38: 0
B39: Acquisition of property, plant and equipment, including capital work in progress, capital advances and capital creditors | C39: -16883.28 | D39: -62022.19 | E39: -43618.36 | F39: -41150.29 | G39: =-FAS!G75 -> -75720.75 | H39: =-FAS!H75 -> -76099.354 | I39: =-FAS!I75 -> -76479.85 | J39: =-FAS!J75 -> -76862.25 | K39: =-FAS!K75 -> -77246.561
B40: Purchase of business | C40: 0 | D40: 0 | E40: -53700 | F40: 0 | G40: 0 | H40: 0 | I40: 0 | J40: 0
B41: Investments in current investments - mutual funds | C41: -76004 | D41: -537889.63 | E41: -440021.35 | F41: -126805.24 | G41: =SUM(Balance_Sheet!F19:F20)-SUM(Balance_Sheet!G19:G20) -> -65792.044 | H41: =SUM(Balance_Sheet!G19:G20)-SUM(Balance_Sheet!H19:H20) -> -30970.711 | I41: =SUM(Balance_Sheet!H19:H20)-SUM(Balance_Sheet!I19:I20) -> -34930.564 | J41: =SUM(Balance_Sheet!I19:I20)-SUM(Balance_Sheet!J19:J20) -> -37106.264 | K41: =SUM(Balance_Sheet!J19:J20)-SUM(Balance_Sheet!K19:K20) -> -37470.986
B42: Proceeds from sale of current investments - mutual fund | C42: 63827.42 | D42: 495731.47 | E42: 495150.85 | F42: 126916.82 | G42: 0 | H42: 0 | I42: 0 | J42: 0 | K42: 0
B43: Investment in Joint Venture | C43: 0 | D43: 0 | E43: 0 | F43: 0 | G43: 0 | H43: 0 | I43: 0 | J43: 0 | K43: 0
B44: Interest received | C44: 58.52 | D44: 326.12 | E44: 891.16 | F44: 372.52 | G44: 0 | H44: 0 | I44: 0 | J44: 0 | K44: 0
B45: Investment in deposits with maturity of more than three months | C45: 57.87 | D45: -6062.09 | E45: -610.42 | F45: 3941.87 | G45: =Balance_Sheet!F29-Balance_Sheet!G29 -> 2730.57 | H45: =Balance_Sheet!G29-Balance_Sheet!H29 -> 0 | I45: =Balance_Sheet!H29-Balance_Sheet!I29 -> 0 | J45: =Balance_Sheet!I29-Balance_Sheet!J29 -> 0 | K45: =Balance_Sheet!J29-Balance_Sheet!K29 -> 0
B48: Net Cash Flow from Investing Activities (B) | C48: =SUM(C38:C45) -> -28932.43 | D48: =SUM(D38:D45) -> -109877.92 | E48: =SUM(E38:E45) -> -41870.39 | F48: =SUM(F38:F45) -> -36685.54 | G48: =SUM(G38:G45) -> -138782.22 | H48: =SUM(H38:H45) -> -107070.06 | I48: =SUM(I38:I45) -> -111410.41 | J48: =SUM(J38:J45) -> -113968.51 | K48: =SUM(K38:K45) -> -114717.55
B50: Cash Flow from Financing Activities:
B51: Proceeds from issue of share capital | C51: 0 | D51: 0 | E51: 97506.79 | F51: 303.53 | G51: 0 | H51: 0 | I51: 0 | J51: 0 | K51: 0
B52: Proceeds from non-current borrowings | C52: 6878.77 | D52: 57247.95 | E52: 43921.48 | F52: 46105.98 | G52: =SUM(Balance_Sheet!G47:G51)-SUM(Balance_Sheet!F47:F51) -> 26171.511 | H52: =SUM(Balance_Sheet!H47:H51)-SUM(Balance_Sheet!G47:G51) -> 46412.785 | I52: =SUM(Balance_Sheet!I47:I51)-SUM(Balance_Sheet!H47:H51) -> 52347.031 | J52: =SUM(Balance_Sheet!J47:J51)-SUM(Balance_Sheet!I47:I51) -> 55607.54 | K52: =SUM(Balance_Sheet!K47:K51)-SUM(Balance_Sheet!J47:J51) -> 56154.113
B53: Repayment of non-current borrowings | C53: -9878.77 | D53: -6611.19 | E53: -18217.42 | F53: -37308.27 | G53: 0 | H53: 0 | I53: 0 | J53: 0 | K53: 0
...

Sheet CommonSize Statement
B6: Common Size Statement
B8: Particulars | C8: 2021 | D8: =C8+1 -> 2022 | E8: =D8+1 -> 2023 | F8: =E8+1 -> 2024 | G8: =F8+1 -> 2025 | H8: =G8+1 -> 2026 | I8: =H8+1 -> 2027 | J8: =I8+1 -> 2028 | K8: =J8+1 -> 2029
B9: Income Statement
B10: Revenue | C10: ='P&L Statement'!C9/'P&L Statement'!C$9 -> 1 | D10: ='P&L Statement'!D9/'P&L Statement'!D$9 -> 1 | E10: ='P&L Statement'!E9/'P&L Statement'!E$9 -> 1 | F10: ='P&L Statement'!F9/'P&L Statement'!F$9 -> 1 | G10: ='P&L Statement'!G9/'P&L Statement'!G$9 -> 1 | H10: ='P&L Statement'!H9/'P&L Statement'!H$9 -> 1 | I10: ='P&L Statement'!I9/'P&L Statement'!I$9 -> 1 | J10: ='P&L Statement'!J9/'P&L Statement'!J$9 -> 1 | K10: ='P&L Statement'!K9/'P&L Statement'!K$9 -> 1
B11: COGS | C11: =-'P&L Statement'!C10/'P&L Statement'!C$9 -> 0.74953705 | D11: =-'P&L Statement'!D10/'P&L Statement'!D$9 -> 0.79927312 | E11: =-'P&L Statement'!E10/'P&L Statement'!E$9 -> 0.79554759 | F11: =-'P&L Statement'!F10/'P&L Statement'!F$9 -> 0.77739525 | G11: =-'P&L Statement'!G10/'P&L Statement'!G$9 -> 0.78043825 | H11: =-'P&L Statement'!H10/'P&L Statement'!H$9 -> 0.78043825 | I11: =-'P&L Statement'!I10/'P&L Statement'!I$9 -> 0.78043825 | J11: =-'P&L Statement'!J10/'P&L Statement'!J$9 -> 0.78043825 | K11: =-'P&L Statement'!K10/'P&L Statement'!K$9 -> 0.78043825
B12: Gross Profit | C12: ='P&L Statement'!C11/'P&L Statement'!C$9 -> 0.25046295 | D12: ='P&L Statement'!D11/'P&L Statement'!D$9 -> 0.20072688 | E12: ='P&L Statement'!E11/'P&L Statement'!E$9 -> 0.20445241 | F12: ='P&L Statement'!F11/'P&L Statement'!F$9 -> 0.22260475 | G12: ='P&L Statement'!G11/'P&L Statement'!G$9 -> 0.21956175 | H12: ='P&L Statement'!H11/'P&L Statement'!H$9 -> 0.21956175 | I12: ='P&L Statement'!I11/'P&L Statement'!I$9 -> 0.21956175 | J12: ='P&L Statement'!J11/'P&L Statement'!J$9 -> 0.21956175 | K12: ='P&L Statement'!K11/'P&L Statement'!K$9 -> 0.21956175
B14: Salaries & Benefits | C14: =-'P&L Statement'!C14/'P&L Statement'!C$9 -> 0.026950084 | D14: =-'P&L Statement'!D14/'P&L Statement'!D$9 -> 0.017624297 | E14: =-'P&L Statement'!E14/'P&L Statement'!E$9 -> 0.015981332 | F14: =-'P&L Statement'!F14/'P&L Statement'!F$9 -> 0.019851864 | G14: =-'P&L Statement'!G14/'P&L Statement'!G$9 -> 0.020101894 | H14: =-'P&L Statement'!H14/'P&L Statement'!H$9 -> 0.020101894 | I14: =-'P&L Statement'!I14/'P&L Statement'!I$9 -> 0.020101894 | J14: =-'P&L Statement'!J14/'P&L Statement'!J$9 -> 0.020101894 | K14: =-'P&L Statement'!K14/'P&L Statement'!K$9 -> 0.020101894
B15: S&G Expenses | C15: =-'P&L Statement'!C15/'P&L Statement'!C$9 -> 0.11852286 | D15: =-'P&L Statement'!D15/'P&L Statement'!D$9 -> 0.097705743 | E15: =-'P&L Statement'!E15/'P&L Statement'!E$9 -> 0.12843009 | F15: =-'P&L Statement'!F15/'P&L Statement'!F$9 -> 0.1467682 | G15: =-'P&L Statement'!G15/'P&L Statement'!G$9 -> 0.12285672 | H15: =-'P&L Statement'!H15/'P&L Statement'!H$9 -> 0.12285672 | I15: =-'P&L Statement'!I15/'P&L Statement'!I$9 -> 0.12285672 | J15: =-'P&L Statement'!J15/'P&L Statement'!J$9 -> 0.12285672 | K15: =-'P&L Statement'!K15/'P&L Statement'!K$9 -> 0.12285672
B16: EBITDA | C16: ='P&L Statement'!C16/'P&L Statement'!C$9 -> 0.10499001 | D16: ='P&L Statement'!D16/'P&L Statement'!D$9 -> 0.085396842 | E16: ='P&L Statement'!E16/'P&L Statement'!E$9 -> 0.060040994 | F16: ='P&L Statement'!F16/'P&L Statement'!F$9 -> 0.055984682 | G16: ='P&L Statement'!G16/'P&L Statement'!G$9 -> 0.076603131 | H16: ='P&L Statement'!H16/'P&L Statement'!H$9 -> 0.076603131 | I16: ='P&L Statement'!I16/'P&L Statement'!I$9 -> 0.076603131 | J16: ='P&L Statement'!J16/'P&L Statement'!J$9 -> 0.076603131 | K16: ='P&L Statement'!K16/'P&L Statement'!K$9 -> 0.076603131
B18: Dep & Amo | C18: =-'P&L Statement'!C19/'P&L Statement'!C$9 -> 0.016134056 | D18: =-'P&L Statement'!D19/'P&L Statement'!D$9 -> 0.011510425 | E18: =-'P&L Statement'!E19/'P&L Statement'!E$9 -> 0.013129207 | F18: =-'P&L Statement'!F19/'P&L Statement'!F$9 -> 0.01820027 | G18: =-'P&L Statement'!G19/'P&L Statement'!G$9 -> 0.01441864 | H18: =-'P&L Statement'!H19/'P&L Statement'!H$9 -> 0.011655323 | I18: =-'P&L Statement'!I19/'P&L Statement'!I$9 -> 0.0097808077 | J18: =-'P&L Statement'!J19/'P&L Statement'!J$9 -> 0.0084904434 | K18: =-'P&L Statement'!K19/'P&L Statement'!K$9 -> 0.0075907918
B20: EBIT | C20: ='P&L Statement'!C21/'P&L Statement'!C$9 -> 0.08885595 | D20: ='P&L Statement'!D21/'P&L Statement'!D$9 -> 0.073886417 | E20: ='P&L Statement'!E21/'P&L Statement'!E$9 -> 0.046911787 | F20: ='P&L Statement'!F21/'P&L Statement'!F$9 -> 0.037784412 | G20: ='P&L Statement'!G21/'P&L Statement'!G$9 -> 0.062184491 | H20: ='P&L Statement'!H21/'P&L Statement'!H$9 -> 0.064947808 | I20: ='P&L Statement'!I21/'P&L Statement'!I$9 -> 0.066822323 | J20: ='P&L Statement'!J21/'P&L Statement'!J$9 -> 0.068112687 | K20: ='P&L Statement'!K21/'P&L Statement'!K$9 -> 0.069012339
B22: Interest Cost | C22: =-'P&L Statement'!C24/'P&L Statement'!C$9 -> 0.021574259 | D22: =-'P&L Statement'!D24/'P&L Statement'!D$9 -> 0.010884903 | E22: =-'P&L Statement'!E24/'P&L Statement'!E$9 -> 0.02183109 | F22: =-'P&L Statement'!F24/'P&L Statement'!F$9 -> 0.031621876 | G22: =-'P&L Statement'!G24/'P&L Statement'!G$9 -> 0.022315715 | H22: =-'P&L Statement'!H24/'P&L Statement'!H$9 -> 0.022315715 | I22: =-'P&L Statement'!I24/'P&L Statement'!I$9 -> 0.022315715 | J22: =-'P&L Statement'!J24/'P&L Statement'!J$9 -> 0.022315715 | K22: =-'P&L Statement'!K24/'P&L Statement'!K$9 -> 0.022315715
B23: Other Income | C23: ='P&L Statement'!C25/'P&L Statement'!C$9 -> 0.0037186817 | D23: ='P&L Statement'!D25/'P&L Statement'!D$9 -> 0.0049969848 | E23: ='P&L Statement'!E25/'P&L Statement'!E$9 -> 0.0068264672 | F23: ='P&L Statement'!F25/'P&L Statement'!F$9 -> 0.0059468153 | G23: ='P&L Statement'!G25/'P&L Statement'!G$9 -> 0.0053722372 | H23: ='P&L Statement'!H25/'P&L Statement'!H$9 -> 0.0053722372 | I23: ='P&L Statement'!I25/'P&L Statement'!I$9 -> 0.0053722372 | J23: ='P&L Statement'!J25/'P&L Statement'!J$9 -> 0.0053722372 | K23: ='P&L Statement'!K25/'P&L Statement'!K$9 -> 0.0053722372
B24: Share of net profit/(loss) of associate accounted for using the equity method | C24: ='P&L Statement'!C26/'P&L Statement'!C$9 -> -3.7756062e-05 | D24: ='P&L Statement'!D26/'P&L Statement'!D$9 -> 7.7773488e-05 | E24: ='P&L Statement'!E26/'P&L Statement'!E$9 -> 3.7869015e-05 | F24: ='P&L Statement'!F26/'P&L Statement'!F$9 -> 5.7623594e-05 | G24: ='P&L Statement'!G26/'P&L Statement'!G$9 -> 3.3877509e-05 | H24: ='P&L Statement'!H26/'P&L Statement'!H$9 -> 3.3877509e-05 | I24: ='P&L Statement'!I26/'P&L Statement'!I$9 -> 3.3877509e-05 | J24: ='P&L Statement'!J26/'P&L Statement'!J$9 -> 3.3877509e-05 | K24: ='P&L Statement'!K26/'P&L Statement'!K$9 -> 3.3877509e-05
B26: EBT | C26: ='P&L Statement'!C28/'P&L Statement'!C$9 -> 0.070962616 | D26: ='P&L Statement'!D28/'P&L Statement'!D$9 -> 0.068076271 | E26: ='P&L Statement'!E28/'P&L Statement'!E$9 -> 0.031945033 | F26: ='P&L Statement'!F28/'P&L Statement'!F$9 -> 0.012166976 | G26: ='P&L Statement'!G28/'P&L Statement'!G$9 -> 0.045274891 | H26: ='P&L Statement'!H28/'P&L Statement'!H$9 -> 0.048038208 | I26: ='P&L Statement'!I28/'P&L Statement'!I$9 -> 0.049912723 | J26: ='P&L Statement'!J28/'P&L Statement'!J$9 -> 0.051203087 | K26: ='P&L Statement'!K28/'P&L Statement'!K$9 -> 0.052102739
B28: Tax | C28: ='P&L Statement'!C31/'P&L Statement'!C$9 -> 0.027733241 | D28: ='P&L Statement'!D31/'P&L Statement'!D$9 -> 0.017374218 | E28: ='P&L Statement'!E31/'P&L Statement'!E$9 -> 0.0091432234 | F28: ='P&L Statement'!F31/'P&L Statement'!F$9 -> 0.0035356006 | G28: ='P&L Statement'!G31/'P&L Statement'!G$9 -> 0.013156427 | H28: ='P&L Statement'!H31/'P&L Statement'!H$9 -> 0.013959419 | I28: ='P&L Statement'!I31/'P&L Statement'!I$9 -> 0.014504135 | J28: ='P&L Statement'!J31/'P&L Statement'!J$9 -> 0.014879101 | K28: ='P&L Statement'!K31/'P&L Statement'!K$9 -> 0.015140531
B30: Net Profit | C30: ='P&L Statement'!C33/'P&L Statement'!C$9 -> 0.043229375 | D30: ='P&L Statement'!D33/'P&L Statement'!D$9 -> 0.050702053 | E30: ='P&L Statement'!E33/'P&L Statement'!E$9 -> 0.02280181 | F30: ='P&L Statement'!F33/'P&L Statement'!F$9 -> 0.008631375 | G30: ='P&L Statement'!G33/'P&L Statement'!G$9 -> 0.032118463 | H30: ='P&L Statement'!H33/'P&L Statement'!H$9 -> 0.034078788 | I30: ='P&L Statement'!I33/'P&L Statement'!I$9 -> 0.035408588 | J30: ='P&L Statement'!J33/'P&L Statement'!J$9 -> 0.036323986 | K30: ='P&L Statement'!K33/'P&L Statement'!K$9 -> 0.036962208
B33: Balance Sheet
B34: Assets
B35: Non-Current Assets
B36: Property Plant and Equipment | C36: =Balance_Sheet!C12/Balance_Sheet!C$35 -> 0.27697453 | D36: =Balance_Sheet!D12/Balance_Sheet!D$35 -> 0.15889375 | E36: =Balance_Sheet!E12/Balance_Sheet!E$35 -> 0.26233554 | F36: =Balance_Sheet!F12/Balance_Sheet!F$35 -> 0.34707954 | G36: =Balance_Sheet!G12/Balance_Sheet!G$35 -> 0.27142543 | H36: =Balance_Sheet!H12/Balance_Sheet!H$35 -> 0.22498613 | I36: =Balance_Sheet!I12/Balance_Sheet!I$35 -> 0.18981729 | J36: =Balance_Sheet!J12/Balance_Sheet!J$35 -> 0.16371279 | K36: =Balance_Sheet!K12/Balance_Sheet!K$35 -> 0.14434763
B37: Capital Work-in-Progress | C37: =Balance_Sheet!C13/Balance_Sheet!C$35 -> 0.04975163 | D37: =Balance_Sheet!D13/Balance_Sheet!D$35 -> 0.042417624 | E37: =Balance_Sheet!E13/Balance_Sheet!E$35 -> 0.065390179 | F37: =Balance_Sheet!F13/Balance_Sheet!F$35 -> 0.038524788 | G37: =Balance_Sheet!G13/Balance_Sheet!G$35 -> 0.028723957 | H37: =Balance_Sheet!H13/Balance_Sheet!H$35 -> 0.023078563 | I37: =Balance_Sheet!I13/Balance_Sheet!I$35 -> 0.01909423 | J37: =Balance_Sheet!J13/Balance_Sheet!J$35 -> 0.016287217 | K37: =Balance_Sheet!K13/Balance_Sheet!K$35 -> 0.014293196
B38: Right of use Assets | C38: =Balance_Sheet!C14/Balance_Sheet!C$35 -> 0 | D38: =Balance_Sheet!D14/Balance_Sheet!D$35 -> 0 | E38: =Balance_Sheet!E14/Balance_Sheet!E$35 -> 0.0015194425 | F38: =Balance_Sheet!F14/Balance_Sheet!F$35 -> 0.0018533348 | G38: =Balance_Sheet!G14/Balance_Sheet!G$35 -> 0.0013778846 | H38: =Balance_Sheet!H14/Balance_Sheet!H$35 -> 0.0010945347 | I38: =Balance_Sheet!I14/Balance_Sheet!I$35 -> 0.000890029 | J38: =Balance_Sheet!J14/Balance_Sheet!J$35 -> 0.00074305812 | K38: =Balance_Sheet!K14/Balance_Sheet!K$35 -> 0.00063636297
B39: Goodwill | C39: =Balance_Sheet!C15/Balance_Sheet!C$35 -> 0 | D39: =Balance_Sheet!D15/Balance_Sheet!D$35 -> 0 | E39: =Balance_Sheet!E15/Balance_Sheet!E$35 -> 0.0054489439 | F39: =Balance_Sheet!F15/Balance_Sheet!F$35 -> 0.0060106249 | G39: =Balance_Sheet!G15/Balance_Sheet!G$35 -> 0.004121786 | H39: =Balance_Sheet!H15/Balance_Sheet!H$35 -> 0.0030644853 | I39: =Balance_Sheet!I15/Balance_Sheet!I$35 -> 0.0023584922 | J39: =Balance_Sheet!J15/Balance_Sheet!J$35 -> 0.0018799279 | K39: =Balance_Sheet!K15/Balance_Sheet!K$35 -> 0.0015478238
B40: Intangible Assets | C40: =Balance_Sheet!C16/Balance_Sheet!C$35 -> 0.00024993412 | D40: =Balance_Sheet!D16/Balance_Sheet!D$35 -> 0.00010876392 | E40: =Balance_Sheet!E16/Balance_Sheet!E$35 -> 0.00016687622 | F40: =Balance_Sheet!F16/Balance_Sheet!F$35 -> 0.00019097154 | G40: =Balance_Sheet!G16/Balance_Sheet!G$35 -> 0.00013451864 | H40: =Balance_Sheet!H16/Balance_Sheet!H$35 -> 0.00010204451 | I40: =Balance_Sheet!I16/Balance_Sheet!I$35 -> 7.9764433e-05 | J40: =Balance_Sheet!J16/Balance_Sheet!J$35 -> 6.4369939e-05 | K40: =Balance_Sheet!K16/Balance_Sheet!K$35 -> 5.3539502e-05
B41: Equity accounted investment | C41: =Balance_Sheet!C17/Balance_Sheet!C$35 -> 0.00062968477 | D41: =Balance_Sheet!D17/Balance_Sheet!D$35 -> 0.00036506483 | E41: =Balance_Sheet!E17/Balance_Sheet!E$35 -> 0.00029585247 | F41: =Balance_Sheet!F17/Balance_Sheet!F$35 -> 0.00033601676 | G41: =Balance_Sheet!G17/Balance_Sheet!G$35 -> 0.00023042349 | H41: =Balance_Sheet!H17/Balance_Sheet!H$35 -> 0.00017131637 | I41: =Balance_Sheet!I17/Balance_Sheet!I$35 -> 0.00013184867 | J41: =Balance_Sheet!J17/Balance_Sheet!J$35 -> 0.00010509511 | K41: =Balance_Sheet!K17/Balance_Sheet!K$35 -> 8.6529227e-05
B43: Other income tax assets | C43: =Balance_Sheet!C19/Balance_Sheet!C$35 -> 0.0028192252 | D43: =Balance_Sheet!D19/Balance_Sheet!D$35 -> 0.0015596264 | E43: =Balance_Sheet!E19/Balance_Sheet!E$35 -> 0.0010383972 | F43: =Balance_Sheet!F19/Balance_Sheet!F$35 -> 0.0061591479 | G43: =Balance_Sheet!G19/Balance_Sheet!G$35 -> 0.0030932133 | H43: =Balance_Sheet!H19/Balance_Sheet!H$35 -> 0.0032422493 | I43: =Balance_Sheet!I19/Balance_Sheet!I$35 -> 0.0033134081 | J43: =Balance_Sheet!J19/Balance_Sheet!J$35 -> 0.0033338004 | K43: =Balance_Sheet!K19/Balance_Sheet!K$35 -> 0.0033208094
B44: Other Non-Current Assets | C44: =Balance_Sheet!C20/Balance_Sheet!C$35 -> 0.005248187 | D44: =Balance_Sheet!D20/Balance_Sheet!D$35 -> 0.14918495 | E44: =Balance_Sheet!E20/Balance_Sheet!E$35 -> 0.0055363043 | F44: =Balance_Sheet!F20/Balance_Sheet!F$35 -> 0.003962851 | G44: =Balance_Sheet!G20/Balance_Sheet!G$35 -> 0.050547367 | H44: =Balance_Sheet!H20/Balance_Sheet!H$35 -> 0.052982822 | I44: =Balance_Sheet!I20/Balance_Sheet!I$35 -> 0.054145655 | J44: =Balance_Sheet!J20/Balance_Sheet!J$35 -> 0.054478892 | K44: =Balance_Sheet!K20/Balance_Sheet!K$35 -> 0.054266602
B46: Total Non-Current Assets | C46: =Balance_Sheet!C22/Balance_Sheet!C$35 -> 0.33567319 | D46: =Balance_Sheet!D22/Balance_Sheet!D$35 -> 0.35252978 | E46: =Balance_Sheet!E22/Balance_Sheet!E$35 -> 0.34173154 | F46: =Balance_Sheet!F22/Balance_Sheet!F$35 -> 0.40411727 | G46: =Balance_Sheet!G22/Balance_Sheet!G$35 -> 0.35965458 | H46: =Balance_Sheet!H22/Balance_Sheet!H$35 -> 0.30872214 | I46: =Balance_Sheet!I22/Balance_Sheet!I$35 -> 0.26983072 | J46: =Balance_Sheet!J22/Balance_Sheet!J$35 -> 0.24060515 | K46: =Balance_Sheet!K22/Balance_Sheet!K$35 -> 0.21855249
B48: Current Assets:
B49: Inventories | C49: =Balance_Sheet!C25/Balance_Sheet!C$35 -> 0.20326022 | D49: =Balance_Sheet!D25/Balance_Sheet!D$35 -> 0.2892495 | E49: =Balance_Sheet!E25/Balance_Sheet!E$35 -> 0.20997251 | F49: =Balance_Sheet!F25/Balance_Sheet!F$35 -> 0.18950479 | G49: =Balance_Sheet!G25/Balance_Sheet!G$35 -> 0.24524325 | H49: =Balance_Sheet!H25/Balance_Sheet!H$35 -> 0.25705947 | I49: =Balance_Sheet!I25/Balance_Sheet!I$35 -> 0.26270125 | J49: =Balance_Sheet!J25/Balance_Sheet!J$35 -> 0.26431803 | K49: =Balance_Sheet!K25/Balance_Sheet!K$35 -> 0.26328805
B50: Investments | C50: =Balance_Sheet!C26/Balance_Sheet!C$35 -> 0.027591099 | D50: =Balance_Sheet!D26/Balance_Sheet!D$35 -> 0.069418371 | E50: =Balance_Sheet!E26/Balance_Sheet!E$35 -> 0 | F50: =Balance_Sheet!F26/Balance_Sheet!F$35 -> 0 | G50: =Balance_Sheet!G26/Balance_Sheet!G$35 -> 0 | H50: =Balance_Sheet!H26/Balance_Sheet!H$35 -> 0 | I50: =Balance_Sheet!I26/Balance_Sheet!I$35 -> 0 | J50: =Balance_Sheet!J26/Balance_Sheet!J$35 -> 0 | K50: =Balance_Sheet!K26/Balance_Sheet!K$35 -> 0
B51: Trade Receivables | C51: =Balance_Sheet!C27/Balance_Sheet!C$35 -> 0.2612594 | D51: =Balance_Sheet!D27/Balance_Sheet!D$35 -> 0.11383133 | E51: =Balance_Sheet!E27/Balance_Sheet!E$35 -> 0.34622663 | F51: =Balance_Sheet!F27/Balance_Sheet!F$35 -> 0.28159031 | G51: =Balance_Sheet!G27/Balance_Sheet!G$35 -> 0.26408949 | H51: =Balance_Sheet!H27/Balance_Sheet!H$35 -> 0.27681375 | I51: =Balance_Sheet!I27/Balance_Sheet!I$35 -> 0.28288908 | J51: =Balance_Sheet!J27/Balance_Sheet!J$35 -> 0.28463011 | K51: =Balance_Sheet!K27/Balance_Sheet!K$35 -> 0.28352098
B52: Cash and Cash Equivalents | C52: =Balance_Sheet!C28/Balance_Sheet!C$35 -> 0.020692081 | D52: =Balance_Sheet!D28/Balance_Sheet!D$35 -> 0.067839143 | E52: =Balance_Sheet!E28/Balance_Sheet!E$35 -> 0.0040381155 | F52: =Balance_Sheet!F28/Balance_Sheet!F$35 -> 0.0093899931 | G52: =Balance_Sheet!G28/Balance_Sheet!G$35 -> 0.0076443207 | H52: =Balance_Sheet!H28/Balance_Sheet!H$35 -> 0.028092185 | I52: =Balance_Sheet!I28/Balance_Sheet!I$35 -> 0.052428437 | J52: =Balance_Sheet!J28/Balance_Sheet!J$35 -> 0.077482877 | K52: =Balance_Sheet!K28/Balance_Sheet!K$35 -> 0.10219277
B53: Bank Balances | C53: =Balance_Sheet!C29/Balance_Sheet!C$35 -> 0.00037828111 | D53: =Balance_Sheet!D29/Balance_Sheet!D$35 -> 0.0075520098 | E53: =Balance_Sheet!E29/Balance_Sheet!E$35 -> 0.0062700379 | F53: =Balance_Sheet!F29/Balance_Sheet!F$35 -> 0.0028263478 | G53: =Balance_Sheet!G29/Balance_Sheet!G$35 -> 0 | H53: =Balance_Sheet!H29/Balance_Sheet!H$35 -> 0 | I53: =Balance_Sheet!I29/Balance_Sheet!I$35 -> 0 | J53: =Balance_Sheet!J29/Balance_Sheet!J$35 -> 0 | K53: =Balance_Sheet!K29/Balance_Sheet!K$35 -> 0
B54: Others Current Financial Assets | C54: =Balance_Sheet!C30/Balance_Sheet!C$35 -> 0.044293842 | D54: =Balance_Sheet!D30/Balance_Sheet!D$35 -> 0.042688683 | E54: =Balance_Sheet!E30/Balance_Sheet!E$35 -> 0.031639549 | F54: =Balance_Sheet!F30/Balance_Sheet!F$35 -> 0.052187554 | G54: =Balance_Sheet!G30/Balance_Sheet!G$35 -> 0.046541699 | H54: =Balance_Sheet!H30/Balance_Sheet!H$35 -> 0.048784154 | I54: =Balance_Sheet!I30/Balance_Sheet!I$35 -> 0.049854838 | J54: =Balance_Sheet!J30/Balance_Sheet!J$35 -> 0.050161667 | K54: =Balance_Sheet!K30/Balance_Sheet!K$35 -> 0.0499662
B55: Other Current Assets | C55: =Balance_Sheet!C31/Balance_Sheet!C$35 -> 0.10679691 | D55: =Balance_Sheet!D31/Balance_Sheet!D$35 -> 0.05686095 | E55: =Balance_Sheet!E31/Balance_Sheet!E$35 -> 0.060099798 | F55: =Balance_Sheet!F31/Balance_Sheet!F$35 -> 0.060359656 | G55: =Balance_Sheet!G31/Balance_Sheet!G$35 -> 0.076790905 | H55: =Balance_Sheet!H31/Balance_Sheet!H$35 -> 0.080490816 | I55: =Balance_Sheet!I31/Balance_Sheet!I$35 -> 0.082257377 | J55: =Balance_Sheet!J31/Balance_Sheet!J$35 -> 0.082763626 | K55: =Balance_Sheet!K31/Balance_Sheet!K$35 -> 0.082441117
B56: Assets classified as held for sale | C56: =Balance_Sheet!C32/Balance_Sheet!C$35 -> 5.4983245e-05 | D56: =Balance_Sheet!D32/Balance_Sheet!D$35 -> 3.0221308e-05 | E56: =Balance_Sheet!E32/Balance_Sheet!E$35 -> 2.1826028e-05 | F56: =Balance_Sheet!F32/Balance_Sheet!F$35 -> 2.407587e-05 | G56: =Balance_Sheet!G32/Balance_Sheet!G$35 -> 3.5755075e-05 | H56: =Balance_Sheet!H32/Balance_Sheet!H$35 -> 3.7477812e-05 | I56: =Balance_Sheet!I32/Balance_Sheet!I$35 -> 3.8300351e-05 | J56: =Balance_Sheet!J32/Balance_Sheet!J$35 -> 3.8536069e-05 | K56: =Balance_Sheet!K32/Balance_Sheet!K$35 -> 3.8385904e-05
B57: Total Current Assets | C57: =Balance_Sheet!C33/Balance_Sheet!C$35 -> 0.66432681 | D57: =Balance_Sheet!D33/Balance_Sheet!D$35 -> 0.64747022 | E57: =Balance_Sheet!E33/Balance_Sheet!E$35 -> 0.65826846 | F57: =Balance_Sheet!F33/Balance_Sheet!F$35 -> 0.59588273 | G57: =Balance_Sheet!G33/Balance_Sheet!G$35 -> 0.64034542 | H57: =Balance_Sheet!H33/Balance_Sheet!H$35 -> 0.69127786 | I57: =Balance_Sheet!I33/Balance_Sheet!I$35 -> 0.73016928 | J57: =Balance_Sheet!J33/Balance_Sheet!J$35 -> 0.75939485 | K57: =Balance_Sheet!K33/Balance_Sheet!K$35 -> 0.78144751
B59: TOTAL ASSETS | C59: =Balance_Sheet!C35/Balance_Sheet!C$35 -> 1 | D59: =Balance_Sheet!D35/Balance_Sheet!D$35 -> 1 | E59: =Balance_Sheet!E35/Balance_Sheet!E$35 -> 1 | F59: =Balance_Sheet!F35/Balance_Sheet!F$35 -> 1 | G59: =Balance_Sheet!G35/Balance_Sheet!G$35 -> 1 | H59: =Balance_Sheet!H35/Balance_Sheet!H$35 -> 1 | I59: =Balance_Sheet!I35/Balance_Sheet!I$35 -> 1 | J59: =Balance_Sheet!J35/Balance_Sheet!J$35 -> 1 | K59: =Balance_Sheet!K35/Balance_Sheet!K$35 -> 1
...

Sheet B_Sheet 
B6: Balance Sheet Forecasting
B8: Particulars | C8: 2021 | D8: =C8+1 -> 2022 | E8: =D8+1 -> 2023 | F8: =E8+1 -> 2024 | G8: =F8+1 -> 2025 | H8: =G8+1 -> 2026 | I8: =H8+1 -> 2027 | J8: =I8+1 -> 2028 | K8: =J8+1 -> 2029
B10: Non-Current Assets
B11: Other income tax assets | C11: ='Balance Sheet'!C19 -> 1246.99 | D11: ='Balance Sheet'!D19 -> 1236.5 | E11: ='Balance Sheet'!E19 -> 1106.62 | F11: ='Balance Sheet'!F19 -> 5950.43 | G11: =G12*'Revenue BuildUp'!G$10 -> 4357.8448 | H11: =H12*'Revenue BuildUp'!H$10 -> 6143.7877 | I11: =I12*'Revenue BuildUp'!I$10 -> 8158.0777 | J11: =J12*'Revenue BuildUp'!J$10 -> 10297.831 | K11: =K12*'Revenue BuildUp'!K$10 -> 12458.615
B12: % of Revenue | C12: =C11/'Revenue BuildUp'!C$10 -> 0.0024144324 | D12: =D11/'Revenue BuildUp'!D$10 -> 0.0015734116 | E12: =E11/'Revenue BuildUp'!E$10 -> 0.00082950534 | F12: =F11/'Revenue BuildUp'!F$10 -> 0.0051407071 | G12: =AVERAGE($C$12:$F$12) -> 0.0024895141 | H12: =AVERAGE($C$12:$F$12) -> 0.0024895141 | I12: =AVERAGE($C$12:$F$12) -> 0.0024895141 | J12: =AVERAGE($C$12:$F$12) -> 0.0024895141 | K12: =AVERAGE($C$12:$F$12) -> 0.0024895141
B13: Other Non-Current Assets | C13: ='Balance Sheet'!C20 -> 2321.36 | D13: ='Balance Sheet'!D20 -> 118276.53 | E13: ='Balance Sheet'!E20 -> 5900.04 | F13: ='Balance Sheet'!F20 -> 3828.56 | G13: =G14*'Revenue BuildUp'!G$10 -> 71213.189 | H13: =H14*'Revenue BuildUp'!H$10 -> 100397.96 | I13: =I14*'Revenue BuildUp'!I$10 -> 133314.23 | J13: =J14*'Revenue BuildUp'!J$10 -> 168280.74 | K13: =K14*'Revenue BuildUp'!K$10 -> 203590.94
B14: % of Revenue | C14: =C13/'Revenue BuildUp'!C$10 -> 0.0044946366 | D14: =D13/'Revenue BuildUp'!D$10 -> 0.15050357 | E14: =E13/'Revenue BuildUp'!E$10 -> 0.0044225793 | F14: =F13/'Revenue BuildUp'!F$10 -> 0.003307577 | G14: =AVERAGE(C14:F14) -> 0.040682091 | H14: =G14 -> 0.040682091 | I14: =H14 -> 0.040682091 | J14: =I14 -> 0.040682091 | K14: =J14 -> 0.040682091
B17: Current Assets:
B18: Investments | C18: ='Balance Sheet'!C26 -> 12204 | D18: ='Balance Sheet'!D26 -> 55036.14 | E18: ='Balance Sheet'!E26 -> 0 | F18: ='Balance Sheet'!F26 -> 0 | G18: =G19*'Revenue BuildUp'!G$10 -> 0 | H18: =H19*'Revenue BuildUp'!H$10 -> 0 | I18: =I19*'Revenue BuildUp'!I$10 -> 0 | J18: =J19*'Revenue BuildUp'!J$10 -> 0 | K18: =K19*'Revenue BuildUp'!K$10 -> 0
B19: % of Revenue | C19: =C18/'Revenue BuildUp'!C$10 -> 0.023629486 | D19: =D18/'Revenue BuildUp'!D$10 -> 0.070031946 | E19: =E18/'Revenue BuildUp'!E$10 -> 0 | F19: =F18/'Revenue BuildUp'!F$10 -> 0 | G19: =F19 -> 0 | H19: =G19 -> 0 | I19: =H19 -> 0 | J19: =I19 -> 0 | K19: =J19 -> 0
B20: Others Current Financial Assets | C20: ='Balance Sheet'!C30 -> 19591.9 | D20: ='Balance Sheet'!D30 -> 33844.36 | E20: ='Balance Sheet'!E30 -> 33718.27 | F20: ='Balance Sheet'!F30 -> 50419.05 | G20: =G21*'Revenue BuildUp'!G$10 -> 65569.841 | H20: =H21*'Revenue BuildUp'!H$10 -> 92441.838 | I20: =I21*'Revenue BuildUp'!I$10 -> 122749.64 | J20: =J21*'Revenue BuildUp'!J$10 -> 154945.2 | K20: =K21*'Revenue BuildUp'!K$10 -> 187457.21
B21: % of Revenue | C21: =C20/'Revenue BuildUp'!C$10 -> 0.037934 | D21: =D20/'Revenue BuildUp'!D$10 -> 0.043066 | E21: =E20/'Revenue BuildUp'!E$10 -> 0.025274697 | F21: =F20/'Revenue BuildUp'!F$10 -> 0.043558124 | G21: =AVERAGE(C21:F21) -> 0.037458205 | H21: =G21 -> 0.037458205 | I21: =H21 -> 0.037458205 | J21: =I21 -> 0.037458205 | K21: =J21 -> 0.037458205
B22: Other Current Assets | C22: ='Balance Sheet'!C31 -> 47238.04 | D22: ='Balance Sheet'!D31 -> 45080.39 | E22: ='Balance Sheet'!E31 -> 64048.36 | F22: ='Balance Sheet'!F31 -> 58314.22 | G22: =G23*'Revenue BuildUp'!G$10 -> 108186.15 | H22: =H23*'Revenue BuildUp'!H$10 -> 152523.27 | I22: =I23*'Revenue BuildUp'!I$10 -> 202529.25 | J22: =J23*'Revenue BuildUp'!J$10 -> 255649.92 | K22: =K23*'Revenue BuildUp'!K$10 -> 309292.72
B23: % of Revenue | C23: =C22/'Revenue BuildUp'!C$10 -> 0.091462686 | D23: =D22/'Revenue BuildUp'!D$10 -> 0.057363533 | E23: =E22/'Revenue BuildUp'!E$10 -> 0.048009666 | F23: =F22/'Revenue BuildUp'!F$10 -> 0.050378934 | G23: =AVERAGE(C23:F23) -> 0.061803705 | H23: =G23 -> 0.061803705 | I23: =H23 -> 0.061803705 | J23: =I23 -> 0.061803705 | K23: =J23 -> 0.061803705
B24: Assets classified as held for sale | C24: ='Balance Sheet'!C32 -> 24.32 | D24: ='Balance Sheet'!D32 -> 23.96 | E24: ='Balance Sheet'!E32 -> 23.26 | F24: ='Balance Sheet'!F32 -> 23.26 | G24: =G25*'Revenue BuildUp'!G$10 -> 50.373205 | H24: =H25*'Revenue BuildUp'!H$10 -> 71.017278 | I24: =I25*'Revenue BuildUp'!I$10 -> 94.300862 | J24: =J25*'Revenue BuildUp'!J$10 -> 119.0347 | K24: =K25*'Revenue BuildUp'!K$10 -> 144.01164
B25: % of Revenue | C25: =C24/'Revenue BuildUp'!C$10 -> 4.7088586e-05 | D25: =D24/'Revenue BuildUp'!D$10 -> 3.0488429e-05 | E25: =E24/'Revenue BuildUp'!E$10 -> 1.7435338e-05 | F25: =F24/'Revenue BuildUp'!F$10 -> 2.0094824e-05 | G25: =AVERAGE(C25:F25) -> 2.8776794e-05 | H25: =G25 -> 2.8776794e-05 | I25: =H25 -> 2.8776794e-05 | J25: =I25 -> 2.8776794e-05 | K25: =J25 -> 2.8776794e-05
B27: LIABILITIES
B28: Non-Current Liabilities:
B29: (i) Borrowings | C29: ='Balance Sheet'!C47 -> 11341.13 | D29: ='Balance Sheet'!D47 -> 52817.08 | E29: ='Balance Sheet'!E47 -> 61188.79 | F29: ='Balance Sheet'!F47 -> 67650.58 | G29: =G30*'Revenue BuildUp'!G$10 -> 84669.864 | H29: =H30*'Revenue BuildUp'!H$10 -> 119369.48 | I29: =I30*'Revenue BuildUp'!I$10 -> 158505.72 | J29: =J30*'Revenue BuildUp'!J$10 -> 200079.62 | K29: =K30*'Revenue BuildUp'!K$10 -> 242062.15
B30: % of Revenue | C30: =C29/'Revenue BuildUp'!C$10 -> 0.02195879 | D30: =D29/'Revenue BuildUp'!D$10 -> 0.067208254 | E30: =E29/'Revenue BuildUp'!E$10 -> 0.045866176 | F30: =F29/'Revenue BuildUp'!F$10 -> 0.058444821 | G30: =AVERAGE(C30:F30) -> 0.04836951 | H30: =G30 -> 0.04836951 | I30: =H30 -> 0.04836951 | J30: =I30 -> 0.04836951 | K30: =J30 -> 0.04836951
B31: (ii) Lease Liabilities | C31: ='Balance Sheet'!C48 -> 0 | D31: ='Balance Sheet'!D48 -> 0 | E31: ='Balance Sheet'!E48 -> 1603.78 | F31: ='Balance Sheet'!F48 -> 1722.29 | G31: =G32*'Revenue BuildUp'!G$10 -> 1177.2385 | H31: =H32*'Revenue BuildUp'!H$10 -> 1659.6974 | I31: =I32*'Revenue BuildUp'!I$10 -> 2203.8424 | J31: =J32*'Revenue BuildUp'!J$10 -> 2781.8804 | K31: =K32*'Revenue BuildUp'!K$10 -> 3365.5999
B32: % of Revenue | C32: =C31/'Revenue BuildUp'!C$10 -> 0 | D32: =D31/'Revenue BuildUp'!D$10 -> 0 | E32: =E31/'Revenue BuildUp'!E$10 -> 0.0012021688 | F32: =F31/'Revenue BuildUp'!F$10 -> 0.0014879241 | G32: =AVERAGE(C32:F32) -> 0.00067252324 | H32: =G32 -> 0.00067252324 | I32: =H32 -> 0.00067252324 | J32: =I32 -> 0.00067252324 | K32: =J32 -> 0.00067252324
B33: Other financial liabilities | C33: ='Balance Sheet'!C49 -> 10.05 | D33: ='Balance Sheet'!D49 -> 286.71 | E33: ='Balance Sheet'!E49 -> 180.42 | F33: ='Balance Sheet'!F49 -> 0 | G33: =G34*'Revenue BuildUp'!G$10 -> 227.35646 | H33: =H34*'Revenue BuildUp'!H$10 -> 320.53226 | I33: =I34*'Revenue BuildUp'!I$10 -> 425.62133 | J33: =J34*'Revenue BuildUp'!J$10 -> 537.25601 | K33: =K34*'Revenue BuildUp'!K$10 -> 649.98797
B34: % of Revenue | C34: =C33/'Revenue BuildUp'!C$10 -> 1.9458894e-05 | D34: =D33/'Revenue BuildUp'!D$10 -> 0.00036483044 | E34: =E33/'Revenue BuildUp'!E$10 -> 0.00013524006 | F34: =F33/'Revenue BuildUp'!F$10 -> 0 | G34: =AVERAGE(C34:F34) -> 0.00012988235 | H34: =G34 -> 0.00012988235 | I34: =H34 -> 0.00012988235 | J34: =I34 -> 0.00012988235 | K34: =J34 -> 0.00012988235
B35: Provisions | C35: ='Balance Sheet'!C50 -> 1974.99 | D35: ='Balance Sheet'!D50 -> 2654.83 | E35: ='Balance Sheet'!E50 -> 2379.21 | F35: ='Balance Sheet'!F50 -> 2621.4 | G35: =G36*'Revenue BuildUp'!G$10 -> 4923.3534 | H35: =H36*'Revenue BuildUp'!H$10 -> 6941.0545 | I35: =I36*'Revenue BuildUp'!I$10 -> 9216.7348 | J35: =J36*'Revenue BuildUp'!J$10 -> 11634.159 | K35: =K36*'Revenue BuildUp'!K$10 -> 14075.345
B36: % of Revenue | C36: =C35/'Revenue BuildUp'!C$10 -> 0.0038239921 | D36: =D35/'Revenue BuildUp'!D$10 -> 0.0033781968 | E36: =E35/'Revenue BuildUp'!E$10 -> 0.0017834192 | F36: =F35/'Revenue BuildUp'!F$10 -> 0.002264685 | G36: =AVERAGE(C36:F36) -> 0.0028125733 | H36: =G36 -> 0.0028125733 | I36: =H36 -> 0.0028125733 | J36: =I36 -> 0.0028125733 | K36: =J36 -> 0.0028125733
B37: Deferred Tax Liabilities (Net) | C37: ='Balance Sheet'!C51 -> 9301.23 | D37: ='Balance Sheet'!D51 -> 9218.11 | E37: ='Balance Sheet'!E51 -> 10778.02 | F37: ='Balance Sheet'!F51 -> 15085.16 | G37: =G38*'Revenue BuildUp'!G$10 -> 22253.129 | H37: =H38*'Revenue BuildUp'!H$10 -> 31372.962 | I37: =I38*'Revenue BuildUp'!I$10 -> 41658.838 | J37: =J38*'Revenue BuildUp'!J$10 -> 52585.385 | K37: =K38*'Revenue BuildUp'!K$10 -> 63619.331
B38: % of Revenue | C38: =C37/'Revenue BuildUp'!C$10 -> 0.018009119 | D38: =D37/'Revenue BuildUp'!D$10 -> 0.011729787 | E38: =E37/'Revenue BuildUp'!E$10 -> 0.0080790381 | F38: =F37/'Revenue BuildUp'!F$10 -> 0.013032401 | G38: =AVERAGE(C38:F38) -> 0.012712586 | H38: =G38 -> 0.012712586 | I38: =H38 -> 0.012712586 | J38: =I38 -> 0.012712586 | K38: =J38 -> 0.012712586
B40: Current Liabilities:
