Workbook

Sheet SBI
D13: NSE : | E13: SBIN
D14: BSE : | E14: 500112
B16: Detailed DCF Financial Analysis
J20: - Dhiraj Mehta

Sheet Assumptions
B1: State Bank of India
B2: BSE: 500112 | NSE: SBIN
C3: 10000
B9: Scenario Manager | E9: Company Name | F9: State Bank of India
B10: Base Case | C10: =IF(B10="Best Case",1,IF(B10="Base Case",2,3)) -> 2 | E10: ISIN Code | F10: INE062A01020
E11: Sector Name | F11: Financial Services
B12: Assumptions | E12: Industry | F12: Banks
B13: Transaction Date | C13: 46063 | E13: Exchange Name | F13: BSE: 500112 | NSE: SBIN
B14: Fiscal Year End | C14: 46112 | E14: Website | F14: sbi.co.in
B15: Risk Free Rate | C15: 0.06715 | E15: Company Description | F15: The State Bank of India (SBI) is the nation's largest bank, boasting a distinguished heritage that spans more than 200 years. Under the current leadership of Chairman Challa Sreenivasulu Setty, the institution continues to pursue its vision of being the "bank of choice for a transforming India" for its customer base of over 52 crores. The bank maintains an unrivalled physical and digital reach, operating 22,937 domestic branches and 63,791 ATMs. Globally, it acts as India’s partner with 244 overseas offices across 29 countries. Its digital transformation is led by the YONO app, which has 8.77 crore registered users, and the bank now processes approximately 220 million financial UPI transactions every day.
B16: Addition In FSA | C16: 0.005
B17: Addition In Dep | C17: 0.005
B18: Tax Rate | C18: =Cost_BuildUp!G22 -> 0.30327525
B19: EV/EBITDA Multiple | C19: ='Comparable Valuation'!E35 -> 17.648039
B20: Perpetual Growth Rate | C20: 0.04
B21: Discount Rate | C21: ='DCF Analysis'!C43 -> 0.1030778
B22: Shares Outstanding(Cr) | C22: ='Comparable Valuation'!F30 -> 923.06
B23: Current Market Price | C23: ='Comparable Valuation'!E30 -> 1144.1
B24: Market Cap (Cr.) | C24: =C23*C22 -> 1056072.9
B26: Colour Code
B27: Blue colour | C27: Hardcoded Figures
B28: Black colour | C28: Calculated Figures
B29: Green Colour | C29: Link Data figures from Different Sheets
B30: Purple Colour | C30: Link Data figures in same sheet
B32: Items | C32: Sheet | E32: Reference | F32: Assumptions
B33: Treasury | C33: Revenue_Build_Up | E33: B31:Q37 | F33: Treasury revenues are forecast using the average growth rate (10.10%) of the last five years as the base case. The best and worst cases are derived by applying a ±5% variation to the base growth rate. A 12% annual tapering is applied from 2026 to 2035 to ensure revenues converge toward a sustainable perpetual growth rate.
B36: Corporate/Wholesale | C36: Revenue_Build_Up | E36: B39:Q45 | F36: Corporate/Wholesale revenues are forecast as 14 % for the base , This avlue is given by the SBI Management for the future year, ±5% adjustments for best and worst cases. A 12% annual tapering is applied from 2026 to 2035 to ensure revenues converge toward a sustainable perpetual growth rate.
B39: Digital Banking | C39: Revenue_Build_Up | E39: B56:Q62 | F39: To forecast the business segment "digital banking", CAGR was used as a reference for future years' projections for the Base scenario. +5% and -5% were calculated for the best and worst case scenarios, respectively. Additionally, a 12% annual tapering rate is applied.
B42: Other Retail Banking | C42: Revenue_Build_Up | E42: B47:Q54 | F42: Retail revenue is projected based on IBEF forecasts for housing, auto, and credit cards, with an initial growth rate of 13%, . grow by 13% in the base case scenario, with ±5% variations for best and worst scenarios. Given the segment’s large contribution, a 12% annual Tapering rate is applied to gradually moderate growth and align it with a perpetual growth rate of ~4%, ensuring consistency and sustainability across all segments.
B45: Insurance Business | C45: Revenue_Build_Up | E45: B64:Q70 | F45: Insurance Business are projected using the historical five-year average growth rate as the base case, with ±5% adjustments applied for best and worst scenarios. A 12% annual tapering is applied from 2026 to 2035 to ensure revenues converge toward a sustainable perpetual growth rate.
B48: Other Banking Operations | C48: Revenue_Build_Up | E48: B72:Q78 | F48: Other Banking Operations are projected using the historical five-year Min growth rate as the base case, with ±5% adjustments applied for best and worst scenarios. A 12% annual tapering is applied from 2026 to 2035 to ensure revenues converge toward a sustainable perpetual growth rate.
B51: Unalloacated Revenue | C51: Revenue_Build_Up | E51: B14:Q20 | F51: Unallocated income is projected based on a minimum inflation rate of 3% growth rate as the base case, with ±2% adjustments applied for best and worst scenarios. A 12% annual tapering is applied from 2026 to 2035 to ensure revenues converge toward a sustainable perpetual growth rate.
B54: Inter Segment Revenue | C54: Revenue_Build_Up | E54: B22:Q28 | F54: Inter segment Revenue are projected using the historical year average growth rate of year 2022 and 2025 only (other years growth rate is outlier) for base case, with ±5% adjustments applied for best and worst scenarios. A 12% annual tapering is applied from 2026 to 2035 to ensure revenues converge toward a sustainable perpetual growth rate.
B57: Share of earnings in Associates | C57: Revenue_Build_Up | E57: B80:Q81 | F57: The "Share of Earnings in Associates" estimate is based on the average percentage of income/revenue from prior years.
B60: Minority Expense | C60: Revenue_Build_Up | E60: B83:Q84 | F60: The "Minority Expense" estimate is based on the average percentage of income/revenue from prior years.
B64: Interest of Deposits, Operating Expenses, Provisions & Contingencies | C64: Cost_Build_Up | E64: B12:Q19 | F64: Interest on deposits, operating expenses, and provisions and contingencies have been analysed by calculating the average percentage of these expenses relative to income/revenue.
... B90: Riskfree Rate | C90: Assumptions | E90: C15 | F90: The risk-free rate is based on the 10-year Indian government bond yield, reflecting long-term returns with minimal default risk.

Sheet P&L_Input
B1: State Bank of India
B2: BSE: 500112 | NSE: SBIN
C3: 10000
B4: (INR in Crores)
B5: Income Statement
B7: Particular | C7: 2021 | D7: =C7+1 -> 2022 | E7: =D7+1 -> 2023 | F7: =E7+1 -> 2024 | G7: =F7+1 -> 2025
B8: INCOME
B9: Interest earned | C9: 278115.48 | D9: 289972.69 | E9: 350844.58 | F9: 439188.51 | G9: 490937.79
B10: Other Income | C10: 107222.41 | D10: 117000.4 | E10: 122533.56 | F10: 155386.39 | G10: 172405.53
B11: Total Income | C11: =SUM(C9:C10) -> 385337.89 | D11: =SUM(D9:D10) -> 406973.09 | E11: =SUM(E9:E10) -> 473378.14 | F11: =SUM(F9:F10) -> 594574.9 | G11: =SUM(G9:G10) -> 663343.32
G12: =G10/'Revenue_Build Up'!G10 -> 0.25990393
B13: EXPENDITURE
B14: Interest on Deposit | C14: 143060.45 | D14: 141765.28 | E14: 163518.78 | F14: 223278.71 | G14: 259228.12
B15: Operating expenses | C15: 142899.04 | D15: 161647.85 | E15: 168795.17 | F15: 200776.45 | G15: 198820.6
B16: Provisions and contingencies | C16: 54618.409 | D16: 40059.148 | E16: 37024.409 | F16: 30806.757 | G16: 46809.309
B17: Total | C17: =SUM(C14:C16) -> 340577.89 | D17: =SUM(D14:D16) -> 343472.28 | E17: =SUM(E14:E16) -> 369338.36 | F17: =SUM(F14:F16) -> 454861.92 | G17: =SUM(G14:G16) -> 504858.03
B19: EBITDA | C19: =C11-C17 -> 44759.997 | D19: =D11-D17 -> 63500.806 | E19: =E11-E17 -> 104039.78 | F19: =F11-F17 -> 139712.99 | G19: =G11-G17 -> 158485.29
B21: Depreciation & Amortization Expenses | C21: 3711.0636 | D21: 3691.27 | E21: 3695.5986 | F21: 3849.1245 | G21: 3991.4767
B23: EBIT | C23: =C19-C21 -> 41048.934 | D23: =D19-D21 -> 59809.536 | E23: =E19-E21 -> 100344.19 | F23: =F19-F21 -> 135863.86 | G23: =G19-G21 -> 154493.82
B25: Interest on Borrowings | C25: 12949.721 | D25: 14429.061 | E25: 26462.034 | F25: 36457.335 | G25: 41715.216
B26: Add: Share in Profit/(Loss) of Associates | C26: -391.9045 | D26: 827.0133 | E26: 1191.4521 | F26: 1405.1543 | G26: 1505.4709
B27: Less: Minority Interest | C27: 1482.3573 | D27: 1809.3049 | E27: 2101.7092 | F27: 2458.7491 | G27: 2961.2882
B29: EBT | C29: =C23-C25+C26-C27 -> 26224.951 | D29: =D23-D25+D26-D27 -> 44398.183 | E29: =E23-E25+E26-E27 -> 72971.895 | F29: =F23-F25+F26-F27 -> 98352.934 | G29: =G23-G25+G26-G27 -> 111322.78
B31: Tax Expenses | C31: -3819.4934 | D31: -9024.303 | E31: -17323.722 | F31: -31268.268 | G31: -33761.445
B33: Post Tax Income | C33: =C29+C31 -> 22405.458 | D33: =D29+D31 -> 35373.88 | E33: =E29+E31 -> 55648.173 | F33: =F29+F31 -> 67084.666 | G33: =G29+G31 -> 77561.337

Sheet BS_Input
B1: State Bank of India
B2: BSE: 500112 | NSE: SBIN
C3: 10000
B4: (INR in Crores)
B5: Balance Sheet
B7: Particular | C7: 2021 | D7: =C7+1 -> 2022 | E7: =D7+1 -> 2023 | F7: =E7+1 -> 2024 | G7: =F7+1 -> 2025
B8: CAPITAL AND LIABILITIES
B9: Capital | C9: 892.4612 | D9: 892.4612 | E9: 892.4612 | F9: 892.4612 | G9: 892.462
B10: Reserves & Surplus | C10: 274669.1 | D10: 304695.58 | E10: 358038.86 | F10: 414046.71 | G10: 486144.3
B11: Minority Interest | C11: 9625.9166 | D11: 11207.423 | E11: 12836.619 | F11: 15617.962 | G11: 18025.839
B12: CASA Deposits | C12: 1686779.5 | D12: 1819712 | E12: 1906519.4 | F12: 1982929.8 | G12: 2108936.6 | K12: 10000
B13: Fixed Deposits | C13: 2028551.7 | D13: 2267698.6 | E13: 2562016.1 | F13: 2983607.7 | G13: 3330961.4
B14: Borrowings | C14: 433796.21 | D14: 449159.78 | E14: 521151.95 | F14: 639609.5 | G14: 610857.24
B15: Other Liabilities and Provisions | C15: 411303.62 | D15: 507517.68 | E15: 592962.92 | F15: 697074.68 | G15: 758367.48
B16: TOTAL | C16: =SUM(C9:C15) -> 4845618.5 | D16: =SUM(D9:D15) -> 5360883.5 | E16: =SUM(E9:E15) -> 5954418.3 | F16: =SUM(F9:F15) -> 6733778.8 | G16: =SUM(G9:G15) -> 7314185.3
B18: ASSETS
B19: Cash and Balances with Reserve Bank of India | C19: 213498.62 | D19: 318492.43 | E19: 247321.05 | F19: 225356.34 | G19: 227485.16
B20: Balances with Banks and Money at Call & Short Notice | C20: 134208.42 | D20: 80412.692 | E20: 70990.86 | F20: 101215.97 | G20: 130447.79
B21: Investments | C21: 1595100.3 | D21: 1776489.9 | E21: 1913107.9 | F21: 2110548.2 | G21: 2205601.1
B22: Advances | C22: 2500599 | D22: 2794076 | E22: 3267902.1 | F22: 3784272.7 | G22: 4250830.7
B23: Fixed Assets | C23: 40166.788 | D23: 39510.031 | E23: 44407.381 | F23: 44708.177 | G23: 46337.695
B24: Other Assets | C24: 362045.47 | D24: 351902.48 | E24: 410689.04 | F24: 467677.42 | G24: 453482.86
B25: TOTAL | C25: =SUM(C19:C24) -> 4845618.5 | D25: =SUM(D19:D24) -> 5360883.5 | E25: =SUM(E19:E24) -> 5954418.3 | F25: =SUM(F19:F24) -> 6733778.8 | G25: =SUM(G19:G24) -> 7314185.3
B27: Check | C27: =C25=C16 -> TRUE | D27: =D25=D16 -> TRUE | E27: =E25=E16 -> TRUE | F27: =F25=F16 -> TRUE | G27: =G25=G16 -> TRUE

Sheet Revenue_Build Up
B1: State Bank of India
B2: BSE: 500112 | NSE: SBIN
C3: 10000
B4: (INR in Crores)
B5: Revenue BuildUp
B7: Particular | C7: 2021 | D7: =C7+1 -> 2022 | E7: =D7+1 -> 2023 | F7: =E7+1 -> 2024 | G7: =F7+1 -> 2025 | H7: =G7+1 -> 2026 | I7: =H7+1 -> 2027 | J7: =I7+1 -> 2028 | K7: =J7+1 -> 2029 | ... Q7: =P7+1 -> 2035
C8: Audited | D8: Audited | E8: Audited | F8: Audited | G8: Audited | H8: Forecasted | I8: Forecasted | J8: Forecasted | K8: Forecasted | L8: Forecasted | M8: Forecasted | N8: Forecasted | O8: Forecasted | P8: Forecasted | Q8: Forecasted
B10: Total Income | C10: 385337.89 | D10: 406973.09 | E10: 473378.14 | F10: 594574.9 | G10: 663343.32 | H10: =H14-H22+H31+H39+H48+H56+H64+H72 -> 747480.98 | I10: =I14-I22+I31+I39+I48+I56+I64+I72 -> 831100.29 | J10: =J14-J22+J31+J39+J48+J56+J64+J72 -> 913085.46 | K10: =K14-K22+K31+K39+K48+K56+K64+K72 -> 992499.22 | L10: =L14-L22+L31+L39+L48+L56+L64+L72 -> 1068593 | M10: =M14-M22+M31+M39+M48+M56+M64+M72 -> 1140803.7 | N10: =N14-N22+N31+N39+N48+N56+N64+N72 -> 1208741.4 | O10: =O14-O22+O31+O39+O48+O56+O64+O72 -> 1272170.5 | ... Q10: =Q14-Q22+Q31+Q39+Q48+Q56+Q64+Q72 -> 1385198
B11: Y-O-Y Growth Rate | D11: =D10/C10-1 -> 0.056146047 | E11: =E10/D10-1 -> 0.16316816 | F11: =F10/E10-1 -> 0.25602526 | G11: =G10/F10-1 -> 0.1156598 | H11: =H10/G10-1 -> 0.12683879 | I11: =I10/H10-1 -> 0.11186814 | J11: =J10/I10-1 -> 0.09864654 | K11: =K10/J10-1 -> 0.08697298 | ... Q11: =Q10/P10-1 -> 0.040729599
B14: Unalloacated Revenue | C14: 1651.31 | D14: 3155.89 | E14: 1861.43 | F14: 2261.66 | G14: 1815.45 | H14: =G14*(1+H15) -> 1869.9135 | I14: =H14*(1+I15) -> 1919.2792 | J14: =I14*(1+J15) -> 1963.8679 | K14: =J14*(1+K15) -> 2004.0175 | L14: =K14*(1+L15) -> 2040.0715 | M14: =L14*(1+M15) -> 2072.3699 | N14: =M14*(1+N15) -> 2101.2424 | O14: =N14*(1+O15) -> 2127.0042 | ... Q14: =P14*(1+Q15) -> 2170.3649
B15: Y-O-Y Growth Rate | D15: =IFERROR(D14/C14-1,0) -> 0.91114327 | E15: =IFERROR(E14/D14-1,0) -> -0.41017272 | F15: =IFERROR(F14/E14-1,0) -> 0.21501211 | G15: =IFERROR(G14/F14-1,0) -> -0.19729314 | H15: =CHOOSE(Assumptions!$C$10,'Revenue_Build Up'!$H17:$Q17,'Revenue_Build Up'!$H18:$Q18,'Revenue_Build Up'!$H19:$Q19) -> 0.03 | I15: =CHOOSE(Assumptions!$C$10,'Revenue_Build Up'!$H17:$Q17,'Revenue_Build Up'!$H18:$Q18,'Revenue_Build Up'!$H19:$Q19) -> 0.0264 | J15: =CHOOSE(Assumptions!$C$10,'Revenue_Build Up'!$H17:$Q17,'Revenue_Build Up'!$H18:$Q18,'Revenue_Build Up'!$H19:$Q19) -> 0.023232 | K15: =CHOOSE(Assumptions!$C$10,'Revenue_Build Up'!$H17:$Q17,'Revenue_Build Up'!$H18:$Q18,'Revenue_Build Up'!$H19:$Q19) -> 0.02044416 | L15: =CHOOSE(Assumptions!$C$10,'Revenue_Build Up'!$H17:$Q17,'Revenue_Build Up'!$H18:$Q18,'Revenue_Build Up'!$H19:$Q19) -> 0.017990861 | M15: =CHOOSE(Assumptions!$C$10,'Revenue_Build Up'!$H17:$Q17,'Revenue_Build Up'!$H18:$Q18,'Revenue_Build Up'!$H19:$Q19) -> 0.015831958 | N15: =CHOOSE(Assumptions!$C$10,'Revenue_Build Up'!$H17:$Q17,'Revenue_Build Up'!$H18:$Q18,'Revenue_Build Up'!$H19:$Q19) -> 0.013932123 | O15: =CHOOSE(Assumptions!$C$10,'Revenue_Build Up'!$H17:$Q17,'Revenue_Build Up'!$H18:$Q18,'Revenue_Build Up'!$H19:$Q19) -> 0.012260268 | ... Q15: =CHOOSE(Assumptions!$C$10,'Revenue_Build Up'!$H17:$Q17,'Revenue_Build Up'!$H18:$Q18,'Revenue_Build Up'!$H19:$Q19) -> 0.0094943515
B17: Best Case | H17: =H18+2% -> 0.05 | I17: =H17*(1-$C$20) -> 0.044 | J17: =I17*(1-$C$20) -> 0.03872 | K17: =J17*(1-$C$20) -> 0.0340736 | L17: =K17*(1-$C$20) -> 0.029984768 | M17: =L17*(1-$C$20) -> 0.026386596 | N17: =M17*(1-$C$20) -> 0.023220204 | O17: =N17*(1-$C$20) -> 0.02043378 | P17: =O17*(1-$C$20) -> 0.017981726 | Q17: =P17*(1-$C$20) -> 0.015823919
B18: Base Case | H18: 0.03 | I18: =H18*(1-$C$20) -> 0.0264 | J18: =I18*(1-$C$20) -> 0.023232 | K18: =J18*(1-$C$20) -> 0.02044416 | L18: =K18*(1-$C$20) -> 0.017990861 | M18: =L18*(1-$C$20) -> 0.015831958 | N18: =M18*(1-$C$20) -> 0.013932123 | O18: =N18*(1-$C$20) -> 0.012260268 | P18: =O18*(1-$C$20) -> 0.010789036 | Q18: =P18*(1-$C$20) -> 0.0094943515
B19: Worst Case | H19: =H18-2% -> 0.01 | I19: =H19*(1-$C$20) -> 0.0088 | J19: =I19*(1-$C$20) -> 0.007744 | K19: =J19*(1-$C$20) -> 0.00681472 | L19: =K19*(1-$C$20) -> 0.0059969536 | M19: =L19*(1-$C$20) -> 0.0052773192 | N19: =M19*(1-$C$20) -> 0.0046440409 | O19: =N19*(1-$C$20) -> 0.004086756 | P19: =O19*(1-$C$20) -> 0.0035963452 | Q19: =P19*(1-$C$20) -> 0.0031647838
B20: Annual Tapering Rate | C20: 0.12
B22: Less : Inter Segment Revenue | C22: 3097.34 | D22: 3717.19 | E22: 5566.62 | F22: 7569.44 | G22: 9025.12 | H22: =G22*(1+H23) -> 10796 | I22: =H22*(1+I23) -> 12660.153 | J22: =I22*(1+J23) -> 14583.866 | K22: =J22*(1+K23) -> 16533.965 | L22: =K22*(1+L23) -> 18479.521 | M22: =L22*(1+M23) -> 20393.072 | N22: =M22*(1+N23) -> 22251.368 | O22: =N22*(1+O23) -> 24035.682 | ... Q22: =P22*(1+Q23) -> 27329.694
B23: Y-O-Y Growth Rate | D23: =IFERROR(D22/C22-1,0) -> 0.20012333 | E23: =IFERROR(E22/D22-1,0) -> 0.49753443 | F23: =IFERROR(F22/E22-1,0) -> 0.35979104 | G23: =IFERROR(G22/F22-1,0) -> 0.19231013 | H23: =CHOOSE(Assumptions!$C$10,'Revenue_Build Up'!$H25:$Q25,'Revenue_Build Up'!$H26:$Q26,'Revenue_Build Up'!$H27:$Q27) -> 0.19621673 | I23: =CHOOSE(Assumptions!$C$10,'Revenue_Build Up'!$H25:$Q25,'Revenue_Build Up'!$H26:$Q26,'Revenue_Build Up'!$H27:$Q27) -> 0.17267072 | J23: =CHOOSE(Assumptions!$C$10,'Revenue_Build Up'!$H25:$Q25,'Revenue_Build Up'!$H26:$Q26,'Revenue_Build Up'!$H27:$Q27) -> 0.15195024 | K23: =CHOOSE(Assumptions!$C$10,'Revenue_Build Up'!$H25:$Q25,'Revenue_Build Up'!$H26:$Q26,'Revenue_Build Up'!$H27:$Q27) -> 0.13371621 | L23: =CHOOSE(Assumptions!$C$10,'Revenue_Build Up'!$H25:$Q25,'Revenue_Build Up'!$H26:$Q26,'Revenue_Build Up'!$H27:$Q27) -> 0.11767026 | M23: =CHOOSE(Assumptions!$C$10,'Revenue_Build Up'!$H25:$Q25,'Revenue_Build Up'!$H26:$Q26,'Revenue_Build Up'!$H27:$Q27) -> 0.10354983 | N23: =CHOOSE(Assumptions!$C$10,'Revenue_Build Up'!$H25:$Q25,'Revenue_Build Up'!$H26:$Q26,'Revenue_Build Up'!$H27:$Q27) -> 0.091123852 | O23: =CHOOSE(Assumptions!$C$10,'Revenue_Build Up'!$H25:$Q25,'Revenue_Build Up'!$H26:$Q26,'Revenue_Build Up'!$H27:$Q27) -> 0.08018899 | ... Q23: =CHOOSE(Assumptions!$C$10,'Revenue_Build Up'!$H25:$Q25,'Revenue_Build Up'!$H26:$Q26,'Revenue_Build Up'!$H27:$Q27) -> 0.062098354
B25: Best Case | H25: =H26+5% -> 0.24621673 | I25: =H25*(1-$C$28) -> 0.21667072 | J25: =I25*(1-$C$28) -> 0.19067024 | K25: =J25*(1-$C$28) -> 0.16778981 | L25: =K25*(1-$C$28) -> 0.14765503 | M25: =L25*(1-$C$28) -> 0.12993643 | N25: =M25*(1-$C$28) -> 0.11434406 | O25: =N25*(1-$C$28) -> 0.10062277 | P25: =O25*(1-$C$28) -> 0.088548037 | Q25: =P25*(1-$C$28) -> 0.077922273
B26: Base Case | H26: =AVERAGE(G23,D23) -> 0.19621673 | I26: =H26*(1-$C$28) -> 0.17267072 | J26: =I26*(1-$C$28) -> 0.15195024 | K26: =J26*(1-$C$28) -> 0.13371621 | L26: =K26*(1-$C$28) -> 0.11767026 | M26: =L26*(1-$C$28) -> 0.10354983 | N26: =M26*(1-$C$28) -> 0.091123852 | O26: =N26*(1-$C$28) -> 0.08018899 | P26: =O26*(1-$C$28) -> 0.070566311 | Q26: =P26*(1-$C$28) -> 0.062098354
B27: Worst Case | H27: =H26-5% -> 0.14621673 | I27: =H27*(1-$C$28) -> 0.12867072 | J27: =I27*(1-$C$28) -> 0.11323024 | K27: =J27*(1-$C$28) -> 0.099642608 | L27: =K27*(1-$C$28) -> 0.087685495 | M27: =L27*(1-$C$28) -> 0.077163236 | N27: =M27*(1-$C$28) -> 0.067903648 | O27: =N27*(1-$C$28) -> 0.05975521 | P27: =O27*(1-$C$28) -> 0.052584585 | Q27: =P27*(1-$C$28) -> 0.046274435
B28: Annual Tapering Rate | C28: 0.12
B30: Bussiness Segment
B31: Treasury | C31: 92399.77 | D31: 99649.8 | E31: 101804.55 | F31: 124225.02 | G31: 134627.51 | H31: =G31*(1+H32) -> 148226.79 | I31: =H31*(1+I32) -> 161403.03 | J31: =I31*(1+J32) -> 174028.84 | K31: =J31*(1+K32) -> 186008.69 | L31: =K31*(1+L32) -> 197276.68 | M31: =L31*(1+M32) -> 207793.18 | N31: =M31*(1+N32) -> 217541.04 | O31: =N31*(1+O32) -> 226521.57 | ... Q31: =P31*(1+Q32) -> 242255.39
B32: Y-O-Y Growth Rate | D32: =IFERROR(D31/C31-1,0) -> 0.078463723 | E32: =IFERROR(E31/D31-1,0) -> 0.021623225 | F32: =IFERROR(F31/E31-1,0) -> 0.22023053 | G32: =IFERROR(G31/F31-1,0) -> 0.083739089 | H32: =CHOOSE(Assumptions!$C$10,'Revenue_Build Up'!$H34:$Q34,'Revenue_Build Up'!$H35:$Q35,'Revenue_Build Up'!$H36:$Q36) -> 0.10101414 | I32: =CHOOSE(Assumptions!$C$10,'Revenue_Build Up'!$H34:$Q34,'Revenue_Build Up'!$H35:$Q35,'Revenue_Build Up'!$H36:$Q36) -> 0.088892445 | J32: =CHOOSE(Assumptions!$C$10,'Revenue_Build Up'!$H34:$Q34,'Revenue_Build Up'!$H35:$Q35,'Revenue_Build Up'!$H36:$Q36) -> 0.078225351 | K32: =CHOOSE(Assumptions!$C$10,'Revenue_Build Up'!$H34:$Q34,'Revenue_Build Up'!$H35:$Q35,'Revenue_Build Up'!$H36:$Q36) -> 0.068838309 | L32: =CHOOSE(Assumptions!$C$10,'Revenue_Build Up'!$H34:$Q34,'Revenue_Build Up'!$H35:$Q35,'Revenue_Build Up'!$H36:$Q36) -> 0.060577712 | M32: =CHOOSE(Assumptions!$C$10,'Revenue_Build Up'!$H34:$Q34,'Revenue_Build Up'!$H35:$Q35,'Revenue_Build Up'!$H36:$Q36) -> 0.053308387 | N32: =CHOOSE(Assumptions!$C$10,'Revenue_Build Up'!$H34:$Q34,'Revenue_Build Up'!$H35:$Q35,'Revenue_Build Up'!$H36:$Q36) -> 0.04691138 | O32: =CHOOSE(Assumptions!$C$10,'Revenue_Build Up'!$H34:$Q34,'Revenue_Build Up'!$H35:$Q35,'Revenue_Build Up'!$H36:$Q36) -> 0.041282015 | ... Q32: =CHOOSE(Assumptions!$C$10,'Revenue_Build Up'!$H34:$Q34,'Revenue_Build Up'!$H35:$Q35,'Revenue_Build Up'!$H36:$Q36) -> 0.031968792
B34: Best Case | H34: =H35+5% -> 0.15101414 | I34: =H34*(1-$C$37) -> 0.13289244 | J34: =I34*(1-$C$37) -> 0.11694535 | K34: =J34*(1-$C$37) -> 0.10291191 | L34: =K34*(1-$C$37) -> 0.09056248 | M34: =L34*(1-$C$37) -> 0.079694982 | N34: =M34*(1-$C$37) -> 0.070131585 | O34: =N34*(1-$C$37) -> 0.061715794 | P34: =O34*(1-$C$37) -> 0.054309899 | Q34: =P34*(1-$C$37) -> 0.047792711
B35: Base Case | H35: =AVERAGE(D32:G32) -> 0.10101414 | I35: =H35*(1-$C$37) -> 0.088892445 | J35: =I35*(1-$C$37) -> 0.078225351 | K35: =J35*(1-$C$37) -> 0.068838309 | L35: =K35*(1-$C$37) -> 0.060577712 | M35: =L35*(1-$C$37) -> 0.053308387 | N35: =M35*(1-$C$37) -> 0.04691138 | O35: =N35*(1-$C$37) -> 0.041282015 | P35: =O35*(1-$C$37) -> 0.036328173 | Q35: =P35*(1-$C$37) -> 0.031968792
B36: Worst Case | H36: =H35-5% -> 0.051014142 | I36: =H36*(1-$C$37) -> 0.044892445 | J36: =I36*(1-$C$37) -> 0.039505351 | K36: =J36*(1-$C$37) -> 0.034764709 | L36: =K36*(1-$C$37) -> 0.030592944 | M36: =L36*(1-$C$37) -> 0.026921791 | N36: =M36*(1-$C$37) -> 0.023691176 | O36: =N36*(1-$C$37) -> 0.020848235 | P36: =O36*(1-$C$37) -> 0.018346447 | Q36: =P36*(1-$C$37) -> 0.016144873
B37: Annual Tapering Rate | C37: 0.12
B39: Corporate / Wholesale Banking | C39: 83073.07 | D39: 75675.43 | E39: 100160.24 | F39: 132845.5 | G39: 148999.81 | H39: =G39*(1+H40) -> 169859.78 | I39: =H39*(1+I40) -> 190786.51 | J39: =I39*(1+J40) -> 211470.82 | K39: =J39*(1+K40) -> 231646.42 | L39: =K39*(1+L40) -> 251094.84 | M39: =L39*(1+M40) -> 269646.35 | N39: =M39*(1+N40) -> 287177.83 | O39: =N39*(1+O40) -> 303608.59 | ... Q39: =P39*(1+Q40) -> 333024.2
B40: Y-O-Y Growth Rate | D40: =IFERROR(D39/C39-1,0) -> -0.089049797 | E40: =IFERROR(E39/D39-1,0) -> 0.32355033 | F40: =IFERROR(F39/E39-1,0) -> 0.32632969 | G40: =IFERROR(G39/F39-1,0) -> 0.12160224 | H40: =CHOOSE(Assumptions!$C$10,'Revenue_Build Up'!$H42:$Q42,'Revenue_Build Up'!$H43:$Q43,'Revenue_Build Up'!$H44:$Q44) -> 0.14 | I40: =CHOOSE(Assumptions!$C$10,'Revenue_Build Up'!$H42:$Q42,'Revenue_Build Up'!$H43:$Q43,'Revenue_Build Up'!$H44:$Q44) -> 0.1232 | J40: =CHOOSE(Assumptions!$C$10,'Revenue_Build Up'!$H42:$Q42,'Revenue_Build Up'!$H43:$Q43,'Revenue_Build Up'!$H44:$Q44) -> 0.108416 | K40: =CHOOSE(Assumptions!$C$10,'Revenue_Build Up'!$H42:$Q42,'Revenue_Build Up'!$H43:$Q43,'Revenue_Build Up'!$H44:$Q44) -> 0.09540608 | L40: =CHOOSE(Assumptions!$C$10,'Revenue_Build Up'!$H42:$Q42,'Revenue_Build Up'!$H43:$Q43,'Revenue_Build Up'!$H44:$Q44) -> 0.08395735 | M40: =CHOOSE(Assumptions!$C$10,'Revenue_Build Up'!$H42:$Q42,'Revenue_Build Up'!$H43:$Q43,'Revenue_Build Up'!$H44:$Q44) -> 0.073882468 | N40: =CHOOSE(Assumptions!$C$10,'Revenue_Build Up'!$H42:$Q42,'Revenue_Build Up'!$H43:$Q43,'Revenue_Build Up'!$H44:$Q44) -> 0.065016572 | O40: =CHOOSE(Assumptions!$C$10,'Revenue_Build Up'!$H42:$Q42,'Revenue_Build Up'!$H43:$Q43,'Revenue_Build Up'!$H44:$Q44) -> 0.057214583 | ... Q40: =CHOOSE(Assumptions!$C$10,'Revenue_Build Up'!$H42:$Q42,'Revenue_Build Up'!$H43:$Q43,'Revenue_Build Up'!$H44:$Q44) -> 0.044306973
B42: Best Case | H42: =H43+5% -> 0.19 | I42: =H42*(1-$C$45) -> 0.1672 | J42: =I42*(1-$C$45) -> 0.147136 | K42: =J42*(1-$C$45) -> 0.12947968 | L42: =K42*(1-$C$45) -> 0.11394212 | M42: =L42*(1-$C$45) -> 0.10026906 | N42: =M42*(1-$C$45) -> 0.088236776 | O42: =N42*(1-$C$45) -> 0.077648363 | P42: =O42*(1-$C$45) -> 0.06833056 | Q42: =P42*(1-$C$45) -> 0.060130893
B43: Base Case | H43: 0.14 | I43: =H43*(1-$C$45) -> 0.1232 | J43: =I43*(1-$C$45) -> 0.108416 | K43: =J43*(1-$C$45) -> 0.09540608 | L43: =K43*(1-$C$45) -> 0.08395735 | M43: =L43*(1-$C$45) -> 0.073882468 | N43: =M43*(1-$C$45) -> 0.065016572 | O43: =N43*(1-$C$45) -> 0.057214583 | P43: =O43*(1-$C$45) -> 0.050348833 | Q43: =P43*(1-$C$45) -> 0.044306973
B44: Worst Case | H44: =H43-5% -> 0.09 | I44: =H44*(1-$C$45) -> 0.0792 | J44: =I44*(1-$C$45) -> 0.069696 | K44: =J44*(1-$C$45) -> 0.06133248 | L44: =K44*(1-$C$45) -> 0.053972582 | M44: =L44*(1-$C$45) -> 0.047495873 | N44: =M44*(1-$C$45) -> 0.041796368 | O44: =N44*(1-$C$45) -> 0.036780804 | P44: =O44*(1-$C$45) -> 0.032367107 | Q44: =P44*(1-$C$45) -> 0.028483054
B45: Annual Tapering Rate | C45: 0.12
B47: Retail Banking
B48: Other Retail Banking | C48: 132094.86 | D48: 138896.25 | E48: 163755.15 | F48: 204491.84 | G48: 233942.93 | H48: =G48*(1+H49) -> 264355.51 | I48: =H48*(1+I49) -> 294597.78 | J48: =I48*(1+J49) -> 324255.53 | K48: =J48*(1+K49) -> 352981.77 | L48: =K48*(1+L49) -> 380500.37 | M48: =L48*(1+M49) -> 406604.65 | N48: =M48*(1+N49) -> 431152.4 | O48: =N48*(1+O49) -> 454058.59 | ... Q48: =P48*(1+Q49) -> 494841.31
B49: Y-O-Y Growth Rate | D49: =IFERROR(D48/C48-1,0) -> 0.05148868 | E49: =IFERROR(E48/D48-1,0) -> 0.17897459 | F49: =IFERROR(F48/E48-1,0) -> 0.24876586 | G49: =IFERROR(G48/F48-1,0) -> 0.14402086 | H49: =CHOOSE(Assumptions!$C$10,'Revenue_Build Up'!$H51:$Q51,'Revenue_Build Up'!$H52:$Q52,'Revenue_Build Up'!$H53:$Q53) -> 0.13 | I49: =CHOOSE(Assumptions!$C$10,'Revenue_Build Up'!$H51:$Q51,'Revenue_Build Up'!$H52:$Q52,'Revenue_Build Up'!$H53:$Q53) -> 0.1144 | J49: =CHOOSE(Assumptions!$C$10,'Revenue_Build Up'!$H51:$Q51,'Revenue_Build Up'!$H52:$Q52,'Revenue_Build Up'!$H53:$Q53) -> 0.100672 | K49: =CHOOSE(Assumptions!$C$10,'Revenue_Build Up'!$H51:$Q51,'Revenue_Build Up'!$H52:$Q52,'Revenue_Build Up'!$H53:$Q53) -> 0.08859136 | L49: =CHOOSE(Assumptions!$C$10,'Revenue_Build Up'!$H51:$Q51,'Revenue_Build Up'!$H52:$Q52,'Revenue_Build Up'!$H53:$Q53) -> 0.077960397 | M49: =CHOOSE(Assumptions!$C$10,'Revenue_Build Up'!$H51:$Q51,'Revenue_Build Up'!$H52:$Q52,'Revenue_Build Up'!$H53:$Q53) -> 0.068605149 | N49: =CHOOSE(Assumptions!$C$10,'Revenue_Build Up'!$H51:$Q51,'Revenue_Build Up'!$H52:$Q52,'Revenue_Build Up'!$H53:$Q53) -> 0.060372531 | O49: =CHOOSE(Assumptions!$C$10,'Revenue_Build Up'!$H51:$Q51,'Revenue_Build Up'!$H52:$Q52,'Revenue_Build Up'!$H53:$Q53) -> 0.053127828 | ... Q49: =CHOOSE(Assumptions!$C$10,'Revenue_Build Up'!$H51:$Q51,'Revenue_Build Up'!$H52:$Q52,'Revenue_Build Up'!$H53:$Q53) -> 0.04114219
B51: Best Case | H51: =H52+5% -> 0.18 | I51: =H51*(1-$C$54) -> 0.1584 | J51: =I51*(1-$C$54) -> 0.139392 | K51: =J51*(1-$C$54) -> 0.12266496 | L51: =K51*(1-$C$54) -> 0.10794516 | M51: =L51*(1-$C$54) -> 0.094991745 | N51: =M51*(1-$C$54) -> 0.083592736 | O51: =N51*(1-$C$54) -> 0.073561607 | P51: =O51*(1-$C$54) -> 0.064734214 | Q51: =P51*(1-$C$54) -> 0.056966109
B52: Base Case | H52: 0.13 | I52: =H52*(1-$C$54) -> 0.1144 | J52: =I52*(1-$C$54) -> 0.100672 | K52: =J52*(1-$C$54) -> 0.08859136 | L52: =K52*(1-$C$54) -> 0.077960397 | M52: =L52*(1-$C$54) -> 0.068605149 | N52: =M52*(1-$C$54) -> 0.060372531 | O52: =N52*(1-$C$54) -> 0.053127828 | P52: =O52*(1-$C$54) -> 0.046752488 | Q52: =P52*(1-$C$54) -> 0.04114219
B53: Worst Case | H53: =H52-5% -> 0.08 | I53: =H53*(1-$C$54) -> 0.0704 | J53: =I53*(1-$C$54) -> 0.061952 | K53: =J53*(1-$C$54) -> 0.05451776 | L53: =K53*(1-$C$54) -> 0.047975629 | M53: =L53*(1-$C$54) -> 0.042218553 | N53: =M53*(1-$C$54) -> 0.037152327 | O53: =N53*(1-$C$54) -> 0.032694048 | P53: =O53*(1-$C$54) -> 0.028770762 | Q53: =P53*(1-$C$54) -> 0.025318271
...

Sheet Cost_BuildUp
B1: State Bank of India
B2: BSE: 500112 | NSE: SBIN
C3: 10000
B4: (INR in Crores)
B5: Cost BuildUp
B7: Particular | C7: 2021 | D7: =C7+1 -> 2022 | E7: =D7+1 -> 2023 | F7: =E7+1 -> 2024 | G7: =F7+1 -> 2025 | H7: =G7+1 -> 2026 | I7: =H7+1 -> 2027 | J7: =I7+1 -> 2028 | K7: =J7+1 -> 2029 | ... Q7: =P7+1 -> 2035
C8: Audited | D8: Audited | E8: Audited | F8: Audited | G8: Audited | H8: Forecasted | I8: Forecasted | J8: Forecasted | K8: Forecasted | L8: Forecasted | M8: Forecasted | N8: Forecasted | O8: Forecasted | P8: Forecasted | Q8: Forecasted
B10: Total Income | C10: ='Revenue_Build Up'!C10 -> 385337.89 | D10: ='Revenue_Build Up'!D10 -> 406973.09 | E10: ='Revenue_Build Up'!E10 -> 473378.14 | F10: ='Revenue_Build Up'!F10 -> 594574.9 | G10: ='Revenue_Build Up'!G10 -> 663343.32 | H10: ='Revenue_Build Up'!H10 -> 747480.98 | I10: ='Revenue_Build Up'!I10 -> 831100.29 | J10: ='Revenue_Build Up'!J10 -> 913085.46 | ... Q10: ='Revenue_Build Up'!Q10 -> 1385198
B12: Interest on Deposits | C12: ='P&L_Input'!C14 -> 143060.45 | D12: ='P&L_Input'!D14 -> 141765.28 | E12: ='P&L_Input'!E14 -> 163518.78 | F12: ='P&L_Input'!F14 -> 223278.71 | G12: ='P&L_Input'!G14 -> 259228.12 | H12: =H13*H$10 -> 273779.39 | I12: =I13*I$10 -> 304406.58 | J12: =J13*J$10 -> 334435.24 | K12: =K13*K$10 -> 363522.06 | L12: =L13*L$10 -> 391392.87 | M12: =M13*M$10 -> 417841.45 | N12: =N13*N$10 -> 442724.97 | O12: =O13*O$10 -> 465957.09 | ... Q12: =Q13*Q$10 -> 507355.6
B13: % of Revenue | C13: =C12/C$10 -> 0.37125974 | D13: =D12/D$10 -> 0.34834068 | E13: =E12/E$10 -> 0.34542952 | F13: =F12/F$10 -> 0.37552664 | G13: =G12/G$10 -> 0.39079028 | H13: =AVERAGE($C$13:$G$13) -> 0.36626937 | I13: =AVERAGE($C$13:$G$13) -> 0.36626937 | J13: =AVERAGE($C$13:$G$13) -> 0.36626937 | K13: =AVERAGE($C$13:$G$13) -> 0.36626937 | L13: =AVERAGE($C$13:$G$13) -> 0.36626937 | M13: =AVERAGE($C$13:$G$13) -> 0.36626937 | N13: =AVERAGE($C$13:$G$13) -> 0.36626937 | O13: =AVERAGE($C$13:$G$13) -> 0.36626937 | ... Q13: =AVERAGE($C$13:$G$13) -> 0.36626937
B15: Operating Expenses | C15: ='P&L_Input'!C15 -> 142899.04 | D15: ='P&L_Input'!D15 -> 161647.85 | E15: ='P&L_Input'!E15 -> 168795.17 | F15: ='P&L_Input'!F15 -> 200776.45 | G15: ='P&L_Input'!G15 -> 198820.6 | H15: =H16*H$10 -> 263414.95 | I15: =I16*I$10 -> 292882.69 | J15: =J16*J$10 -> 321774.56 | K15: =K16*K$10 -> 349760.25 | L15: =L16*L$10 -> 376575.95 | M15: =M16*M$10 -> 402023.27 | N15: =N16*N$10 -> 425964.77 | O15: =O16*O$10 -> 448317.4 | ... Q15: =Q16*Q$10 -> 488148.69
B16: % of Revenue | C16: =C15/C$10 -> 0.37084087 | D16: =D15/D$10 -> 0.39719543 | E16: =E15/E$10 -> 0.35657575 | F16: =F15/F$10 -> 0.33768066 | G16: =G15/G$10 -> 0.29972503 | H16: =AVERAGE($C$16:$G$16) -> 0.35240355 | I16: =AVERAGE($C$16:$G$16) -> 0.35240355 | J16: =AVERAGE($C$16:$G$16) -> 0.35240355 | K16: =AVERAGE($C$16:$G$16) -> 0.35240355 | L16: =AVERAGE($C$16:$G$16) -> 0.35240355 | M16: =AVERAGE($C$16:$G$16) -> 0.35240355 | N16: =AVERAGE($C$16:$G$16) -> 0.35240355 | O16: =AVERAGE($C$16:$G$16) -> 0.35240355 | ... Q16: =AVERAGE($C$16:$G$16) -> 0.35240355
B18: Provisions and Contingencies | C18: ='P&L_Input'!C16 -> 54618.409 | D18: ='P&L_Input'!D16 -> 40059.148 | E18: ='P&L_Input'!E16 -> 37024.409 | F18: ='P&L_Input'!F16 -> 30806.757 | G18: ='P&L_Input'!G16 -> 46809.309 | H18: =H19*H$10 -> 65892.77 | I18: =I19*I$10 -> 73264.071 | J18: =J19*J$10 -> 80491.318 | K18: =K19*K$10 -> 87491.888 | L18: =L19*L$10 -> 94199.788 | M18: =M19*M$10 -> 100565.39 | N18: =N19*N$10 -> 106554.31 | O18: =O19*O$10 -> 112145.78 | ... Q18: =Q19*Q$10 -> 122109.5
B19: % of Revenue | C19: =C18/C$10 -> 0.1417416 | D19: =D18/D$10 -> 0.098431934 | E19: =E18/E$10 -> 0.078213178 | F19: =F18/F$10 -> 0.051813079 | G19: =G18/G$10 -> 0.070565736 | H19: =AVERAGE($C$19:$G$19) -> 0.088153105 | I19: =AVERAGE($C$19:$G$19) -> 0.088153105 | J19: =AVERAGE($C$19:$G$19) -> 0.088153105 | K19: =AVERAGE($C$19:$G$19) -> 0.088153105 | L19: =AVERAGE($C$19:$G$19) -> 0.088153105 | M19: =AVERAGE($C$19:$G$19) -> 0.088153105 | N19: =AVERAGE($C$19:$G$19) -> 0.088153105 | O19: =AVERAGE($C$19:$G$19) -> 0.088153105 | ... Q19: =AVERAGE($C$19:$G$19) -> 0.088153105
B21: Tax Expense | C21: ='P&L_Input'!C31 -> -3819.4934 | D21: ='P&L_Input'!D31 -> -9024.303 | E21: ='P&L_Input'!E31 -> -17323.722 | F21: ='P&L_Input'!F31 -> -31268.268 | G21: ='P&L_Input'!G31 -> -33761.445 | H21: =H22*-'Income Statement'!H28 -> -31282.518 | I21: =I22*-'Income Statement'!I28 -> -34025.674 | J21: =J22*-'Income Statement'!J28 -> -37401.596 | K21: =K22*-'Income Statement'!K28 -> -40663.653 | L21: =L22*-'Income Statement'!L28 -> -43782.342 | M21: =M22*-'Income Statement'!M28 -> -46735.82 | N21: =N22*-'Income Statement'!N28 -> -49509.306 | O21: =O22*-'Income Statement'!O28 -> -52094.258 | ... Q21: =Q22*-'Income Statement'!Q28 -> -56689.941
B22: % of EBT | C22: =-C21/'P&L_Input'!C29 -> 0.14564349 | D22: =-D21/'P&L_Input'!D29 -> 0.20325839 | E22: =-E21/'P&L_Input'!E29 -> 0.23740266 | F22: =-F21/'P&L_Input'!F29 -> 0.31791902 | G22: =-G21/'P&L_Input'!G29 -> 0.30327525 | H22: 0.3 | I22: 0.3 | J22: 0.3 | K22: 0.3 | L22: 0.3 | M22: 0.3 | N22: 0.3 | O22: 0.3 | P22: 0.3 | Q22: 0.3

Sheet Debt Schedules
B1: State Bank of India
B2: BSE: 500112 | NSE: SBIN
C3: 10000
B4: (INR in Crores)
B5: Borrowing Schedule
B7: Particular | C7: 2021 | D7: =C7+1 -> 2022 | E7: =D7+1 -> 2023 | F7: =E7+1 -> 2024 | G7: =F7+1 -> 2025 | H7: =G7+1 -> 2026 | I7: =H7+1 -> 2027 | J7: =I7+1 -> 2028 | K7: =J7+1 -> 2029 | ... Q7: =P7+1 -> 2035
C8: Audited | D8: Audited | E8: Audited | F8: Audited | G8: Audited | H8: Forecasted | I8: Forecasted | J8: Forecasted | K8: Forecasted | L8: Forecasted | M8: Forecasted | N8: Forecasted | O8: Forecasted | P8: Forecasted | Q8: Forecasted
B10: Opening Balance | D10: =C12 -> 433796.21 | E10: =D12 -> 449159.78 | F10: =E12 -> 521151.95 | G10: =F12 -> 639609.5 | H10: =G12 -> 610857.24 | I10: =H12 -> 796359.52 | J10: =I12 -> 885446.78 | K10: =J12 -> 972793.04 | ... Q10: =P12 -> 1418022
B11: Addition / Repayment' | D11: =D12-D10 -> 15363.576 | E11: =E12-E10 -> 71992.166 | F11: =F12-F10 -> 118457.55 | G11: =G12-G10 -> -28752.258 | H11: =H12-H10 -> 185502.28 | I11: =I12-I10 -> 89087.256 | J11: =J12-J10 -> 87346.261 | K11: =K12-K10 -> 84606.709 | ... Q11: =Q12-Q10 -> 57755.468
B12: Ending Balance | C12: =BS_Items!C18 -> 433796.21 | D12: =BS_Items!D18 -> 449159.78 | E12: =BS_Items!E18 -> 521151.95 | F12: =BS_Items!F18 -> 639609.5 | G12: =BS_Items!G18 -> 610857.24 | H12: =BS_Items!H18 -> 796359.52 | I12: =BS_Items!I18 -> 885446.78 | J12: =BS_Items!J18 -> 972793.04 | ... Q12: =BS_Items!Q18 -> 1475777.5
B14: Interest on Borrowing | C14: ='P&L_Input'!C25 -> 12949.721 | D14: ='P&L_Input'!D25 -> 14429.061 | E14: ='P&L_Input'!E25 -> 26462.034 | F14: ='P&L_Input'!F25 -> 36457.335 | G14: ='P&L_Input'!G25 -> 41715.216 | H14: =H15*AVERAGE(H12,H10) -> 34704.028 | I14: =I15*AVERAGE(I12,I10) -> 41475.808 | J14: =J15*AVERAGE(J12,J10) -> 45826.917 | K14: =K15*AVERAGE(K12,K10) -> 50067.529 | L14: =L15*AVERAGE(L12,L10) -> 54153.35 | M14: =M15*AVERAGE(M12,M10) -> 58049.917 | N14: =N15*AVERAGE(N12,N10) -> 61732.192 | O14: =O15*AVERAGE(O12,O10) -> 65183.737 | ... Q14: =Q15*AVERAGE(Q12,Q10) -> 71365.337
B15: % of Borrowing | C15: =C14/AVERAGE(C12,C10) -> 0.029852084 | D15: =D14/AVERAGE(D12,D10) -> 0.032683534 | E15: =E14/AVERAGE(E12,E10) -> 0.054543365 | F15: =F14/AVERAGE(F12,F10) -> 0.062816239 | G15: =G14/AVERAGE(G12,G10) -> 0.066719433 | H15: =AVERAGE(C15:G15) -> 0.049322931 | I15: =H15 -> 0.049322931 | J15: =I15 -> 0.049322931 | K15: =J15 -> 0.049322931 | L15: =K15 -> 0.049322931 | M15: =L15 -> 0.049322931 | N15: =M15 -> 0.049322931 | O15: =N15 -> 0.049322931 | P15: =O15 -> 0.049322931 | Q15: =P15 -> 0.049322931

Sheet FAS
B1: State Bank of India
B2: BSE: 500112 | NSE: SBIN
C3: 10000
B4: (INR in Crores)
B5: Fixed Assets Schedules
B7: Particular | C7: 2021 | D7: =C7+1 -> 2022 | E7: =D7+1 -> 2023 | F7: =E7+1 -> 2024 | G7: =F7+1 -> 2025 | H7: =G7+1 -> 2026 | I7: =H7+1 -> 2027 | J7: =I7+1 -> 2028 | K7: =J7+1 -> 2029 | ... Q7: =P7+1 -> 2035
C8: Audited | D8: Audited | E8: Audited | F8: Audited | G8: Audited | H8: Forecasted | I8: Forecasted | J8: Forecasted | K8: Forecasted | L8: Forecasted | M8: Forecasted | N8: Forecasted | O8: Forecasted | P8: Forecasted | Q8: Forecasted
C9: 10000
A11: # | B11: Premises
B12: Opening Gross Block | C12: 31094.355 | D12: =C15 -> 31130.034 | E12: =D15 -> 31336.609 | F12: =E15 -> 35945.976 | G12: =F15 -> 36023.909 | H12: =G15 -> 36413.533 | I12: =H15 -> 37858.756 | J12: =I15 -> 39311.206 | K12: =J15 -> 40770.917 | ... Q12: =P15 -> 49683.74
B13: Additions: | C13: 81.6496 | D13: 226.5368 | E13: 6445.0955 | F13: 82.6219 | G13: 390.212 | H13: =AVERAGE(C13:G13) -> 1445.2232 | I13: =H13*(1+Assumptions!$C$16) -> 1452.4493 | J13: =I13*(1+Assumptions!$C$16) -> 1459.7115 | K13: =J13*(1+Assumptions!$C$16) -> 1467.0101 | L13: =K13*(1+Assumptions!$C$16) -> 1474.3451 | M13: =L13*(1+Assumptions!$C$16) -> 1481.7169 | N13: =M13*(1+Assumptions!$C$16) -> 1489.1254 | O13: =N13*(1+Assumptions!$C$16) -> 1496.5711 | P13: =O13*(1+Assumptions!$C$16) -> 1504.0539 | Q13: =P13*(1+Assumptions!$C$16) -> 1511.5742
B14: Deductions | C14: -45.9707 | D14: -19.9624 | E14: -1835.7277 | F14: -4.6892 | G14: -0.5881
B15: Closing Gross Block | C15: =SUM(C12:C14) -> 31130.034 | D15: =SUM(D12:D14) -> 31336.609 | E15: =SUM(E12:E14) -> 35945.976 | F15: =SUM(F12:F14) -> 36023.909 | G15: =SUM(G12:G14) -> 36413.533 | H15: =SUM(H12:H14) -> 37858.756 | I15: =SUM(I12:I14) -> 39311.206 | J15: =SUM(J12:J14) -> 40770.917 | ... Q15: =SUM(Q12:Q14) -> 51195.314
B16: Depreciation to date | C16: 1893.9793 | D16: 2197.6739 | E16: 2545.9369 | F16: 2885.7395 | G16: 3227.4558 | H16: =AVERAGE(C16:G16) -> 2550.1571 | I16: =H16*(1+Assumptions!$C$17) -> 2562.9079 | J16: =I16*(1+Assumptions!$C$17) -> 2575.7224 | K16: =J16*(1+Assumptions!$C$17) -> 2588.601 | L16: =K16*(1+Assumptions!$C$17) -> 2601.544 | M16: =L16*(1+Assumptions!$C$17) -> 2614.5517 | N16: =M16*(1+Assumptions!$C$17) -> 2627.6245 | O16: =N16*(1+Assumptions!$C$17) -> 2640.7626 | P16: =O16*(1+Assumptions!$C$17) -> 2653.9664 | Q16: =P16*(1+Assumptions!$C$17) -> 2667.2363
B17: Net Block | C17: =C15-C16 -> 29236.055 | D17: =D15-D16 -> 29138.935 | E17: =E15-E16 -> 33400.04 | F17: =F15-F16 -> 33138.17 | G17: =G15-G16 -> 33186.077 | H17: =H15-H16 -> 35308.599 | I17: =I15-I16 -> 36748.298 | J17: =J15-J16 -> 38195.195 | ... Q17: =Q15-Q16 -> 48528.077
B18: Premises under construction | C18: 351.8345 | D18: 252.9655 | E18: 317.546 | F18: 528.4341 | G18: 532.8122 | H18: 0 | I18: 0 | J18: 0 | K18: 0 | L18: 0 | M18: 0 | N18: 0 | O18: 0 | P18: 0 | Q18: 0
A20: # | B20: Other Fixed Assets
B21: Opening Gross Block | C21: 36021.193 | D21: =C24 -> 38991.323 | E21: =D24 -> 41202.178 | F21: =E24 -> 44177.262 | G21: =F24 -> 46975.335 | H21: =G24 -> 51314.365 | I21: =H24 -> 55265.463 | J21: =I24 -> 59236.316 | K21: =J24 -> 63227.024 | ... Q21: =P24 -> 87593.803
B22: Addition | C22: 3753.8335 | D22: 2952.3616 | E22: 3771.9049 | F22: 3832.0094 | G22: 5445.3796 | H22: =AVERAGE(C22:G22) -> 3951.0978 | I22: =H22*(1+Assumptions!$C$16) -> 3970.8533 | J22: =I22*(1+Assumptions!$C$16) -> 3990.7076 | K22: =J22*(1+Assumptions!$C$16) -> 4010.6611 | L22: =K22*(1+Assumptions!$C$16) -> 4030.7144 | M22: =L22*(1+Assumptions!$C$16) -> 4050.868 | N22: =M22*(1+Assumptions!$C$16) -> 4071.1223 | O22: =N22*(1+Assumptions!$C$16) -> 4091.4779 | P22: =O22*(1+Assumptions!$C$16) -> 4111.9353 | Q22: =P22*(1+Assumptions!$C$16) -> 4132.495
B23: Deductions/ Adjustments | C23: -783.7042 | D23: -741.506 | E23: -796.8209 | F23: -1033.9367 | G23: -1106.3492
B24: Closing Gross Block | C24: =SUM(C21:C23) -> 38991.323 | D24: =SUM(D21:D23) -> 41202.178 | E24: =SUM(E21:E23) -> 44177.262 | F24: =SUM(F21:F23) -> 46975.335 | G24: =SUM(G21:G23) -> 51314.365 | H24: =SUM(H21:H23) -> 55265.463 | I24: =SUM(I21:I23) -> 59236.316 | J24: =SUM(J21:J23) -> 63227.024 | ... Q24: =SUM(Q21:Q23) -> 91726.298
B25: Depreciation to date | C25: 28686.495 | D25: 31339.276 | E25: 33883.54 | F25: 36342.875 | G25: 38907.426 | H25: =AVERAGE(C25:G25) -> 33831.923 | I25: =H25*(1+Assumptions!$C$17) -> 34001.082 | J25: =I25*(1+Assumptions!$C$17) -> 34171.088 | K25: =J25*(1+Assumptions!$C$17) -> 34341.943 | L25: =K25*(1+Assumptions!$C$17) -> 34513.653 | M25: =L25*(1+Assumptions!$C$17) -> 34686.221 | N25: =M25*(1+Assumptions!$C$17) -> 34859.652 | O25: =N25*(1+Assumptions!$C$17) -> 35033.95 | P25: =O25*(1+Assumptions!$C$17) -> 35209.12 | Q25: =P25*(1+Assumptions!$C$17) -> 35385.166
B26: Net Block | C26: =C24-C25 -> 10304.827 | D26: =D24-D25 -> 9862.902 | E26: =E24-E25 -> 10293.723 | F26: =F24-F25 -> 10632.46 | G26: =G24-G25 -> 12406.94 | H26: =H24-H25 -> 21433.541 | I26: =I24-I25 -> 25235.234 | J26: =J24-J25 -> 29055.937 | ... Q26: =Q24-Q25 -> 56341.132
A29: # | B29: Leased Assets
B30: Opening Gross Block | C30: 240.3884 | D30: =C33 -> 288.8563 | E30: =D33 -> 397.9402 | F30: =E33 -> 505.9027 | G30: =F33 -> 621.7792 | H30: =G33 -> 393.8593 | I30: =H33 -> 499.2106 | J30: =I33 -> 605.08866 | K30: =J33 -> 711.4961 | ... Q30: =P33 -> 1361.2071
B31: Addition | C31: 74.3419 | D31: 126.3617 | E31: 178.4134 | F31: 136.0071 | G31: 11.6324 | H31: =AVERAGE(C31:G31) -> 105.3513 | I31: =H31*(1+Assumptions!$C$16) -> 105.87806 | J31: =I31*(1+Assumptions!$C$16) -> 106.40745 | K31: =J31*(1+Assumptions!$C$16) -> 106.93948 | L31: =K31*(1+Assumptions!$C$16) -> 107.47418 | M31: =L31*(1+Assumptions!$C$16) -> 108.01155 | N31: =M31*(1+Assumptions!$C$16) -> 108.55161 | O31: =N31*(1+Assumptions!$C$16) -> 109.09437 | P31: =O31*(1+Assumptions!$C$16) -> 109.63984 | Q31: =P31*(1+Assumptions!$C$16) -> 110.18804
B32: Deductions/ Adjustments | C32: -25.874 | D32: -17.2778 | E32: -70.4509 | F32: -20.1306 | G32: -239.5523
B33: Closing Gross Block | C33: =SUM(C30:C32) -> 288.8563 | D33: =SUM(D30:D32) -> 397.9402 | E33: =SUM(E30:E32) -> 505.9027 | F33: =SUM(F30:F32) -> 621.7792 | G33: =SUM(G30:G32) -> 393.8593 | H33: =SUM(H30:H32) -> 499.2106 | I33: =SUM(I30:I32) -> 605.08866 | J33: =SUM(J30:J32) -> 711.4961 | ... Q33: =SUM(Q30:Q32) -> 1471.3952
B34: Depreciation to date | C34: 131.1319 | D34: 170.2788 | E34: 175.8503 | F34: 255.1177 | G34: 223.3958 | H34: =AVERAGE(C34:G34) -> 191.1549 | I34: =H34*(1+Assumptions!$C$17) -> 192.11067 | J34: =I34*(1+Assumptions!$C$17) -> 193.07123 | K34: =J34*(1+Assumptions!$C$17) -> 194.03658 | L34: =K34*(1+Assumptions!$C$17) -> 195.00677 | M34: =L34*(1+Assumptions!$C$17) -> 195.9818 | N34: =M34*(1+Assumptions!$C$17) -> 196.96171 | O34: =N34*(1+Assumptions!$C$17) -> 197.94652 | P34: =O34*(1+Assumptions!$C$17) -> 198.93625 | Q34: =P34*(1+Assumptions!$C$17) -> 199.93093
B35: Net Block | C35: =C33-C34 -> 157.7244 | D35: =D33-D34 -> 227.6614 | E35: =E33-E34 -> 330.0524 | F35: =F33-F34 -> 366.6615 | G35: =G33-G34 -> 170.4635 | H35: =H33-H34 -> 308.0557 | I35: =I33-I34 -> 412.97798 | J35: =J33-J34 -> 518.42488 | ... Q35: =Q33-Q34 -> 1271.4642
A38: # | B38: Fixed Assets
B39: Opening Gross Block | C39: =C30+C21+C12 -> 67355.937 | D39: =D30+D21+D12 -> 70410.213 | E39: =E30+E21+E12 -> 72936.727 | F39: =F30+F21+F12 -> 80629.141 | G39: =G30+G21+G12 -> 83621.023 | H39: =H30+H21+H12 -> 88121.758 | I39: =I30+I21+I12 -> 93623.43 | J39: =J30+J21+J12 -> 99152.611 | ... Q39: =Q30+Q21+Q12 -> 138638.75
B40: Additions: | C40: =C31+C22+C13 -> 3909.825 | D40: =D31+D22+D13 -> 3305.2601 | E40: =E31+E22+E13 -> 10395.414 | F40: =F31+F22+F13 -> 4050.6384 | G40: =G31+G22+G13 -> 5847.224 | H40: =H31+H22+H13 -> 5501.6723 | I40: =I31+I22+I13 -> 5529.1806 | J40: =J31+J22+J13 -> 5556.8265 | ... Q40: =Q31+Q22+Q13 -> 5754.2572
B41: Deductions | C41: =C32+C23+C14 -> -855.5489 | D41: =D32+D23+D14 -> -778.7462 | E41: =E32+E23+E14 -> -2702.9995 | F41: =F32+F23+F14 -> -1058.7565 | G41: =G32+G23+G14 -> -1346.4896 | H41: =H32+H23+H14 -> 0 | I41: =I32+I23+I14 -> 0 | J41: =J32+J23+J14 -> 0 | ... Q41: =Q32+Q23+Q14 -> 0
B42: Closing Gross Block | C42: =SUM(C39:C41) -> 70410.213 | D42: =SUM(D39:D41) -> 72936.727 | E42: =SUM(E39:E41) -> 80629.141 | F42: =SUM(F39:F41) -> 83621.023 | G42: =SUM(G39:G41) -> 88121.758 | H42: =SUM(H39:H41) -> 93623.43 | I42: =SUM(I39:I41) -> 99152.611 | J42: =SUM(J39:J41) -> 104709.44 | ... Q42: =SUM(Q39:Q41) -> 144393.01
B43: Depreciation to date | C43: =C34+C25+C16 -> 30711.606 | D43: =D34+D25+D16 -> 33707.229 | E43: =E34+E25+E16 -> 36605.327 | F43: =F34+F25+F16 -> 39483.733 | G43: =G34+G25+G16 -> 42358.278 | H43: =H34+H25+H16 -> 36573.234 | I43: =I34+I25+I16 -> 36756.101 | J43: =J34+J25+J16 -> 36939.881 | ... Q43: =Q34+Q25+Q16 -> 38252.333
B45: Net Block | C45: =C42-C43 -> 39698.607 | D45: =D42-D43 -> 39229.498 | E45: =E42-E43 -> 44023.815 | F45: =F42-F43 -> 44137.291 | G45: =G42-G43 -> 45763.48 | H45: =H42-H43 -> 57050.196 | I45: =I42-I43 -> 62396.51 | J45: =J42-J43 -> 67769.556 | ... Q45: =Q42-Q43 -> 106140.67
B46: Premises under construction | C46: =C18 -> 351.8345 | D46: =D18 -> 252.9655 | E46: =E18 -> 317.546 | F46: =F18 -> 528.4341 | G46: =G18 -> 532.8122 | H46: =H18 -> 0 | I46: =I18 -> 0 | J46: =J18 -> 0 | ... Q46: =Q18 -> 0
B47: Net Block + Premises Under Construction | C47: =C45+C46 -> 40050.441 | D47: =D45+D46 -> 39482.464 | E47: =E45+E46 -> 44341.361 | F47: =F45+F46 -> 44665.725 | G47: =G45+G46 -> 46296.292 | H47: =H45+H46 -> 57050.196 | I47: =I45+I46 -> 62396.51 | J47: =J45+J46 -> 67769.556 | ... Q47: =Q45+Q46 -> 106140.67
B48: CWIP | C48: 116.3469 | D48: 27.5668 | E48: 66.0204 | F48: 42.4523 | G48: 41.4029 | H48: 0 | I48: 0 | J48: 0 | K48: 0 | L48: 0 | M48: 0 | N48: 0 | O48: 0 | P48: 0 | Q48: 0
...

Sheet Working Capital
B1: State Bank of India
B2: BSE: 500112 | NSE: SBIN
C3: 10000
B4: (INR in Crores)
B5: Change in Working Capital
B7: Particular | C7: 2021 | D7: =C7+1 -> 2022 | E7: =D7+1 -> 2023 | F7: =E7+1 -> 2024 | G7: =F7+1 -> 2025 | H7: =G7+1 -> 2026 | I7: =H7+1 -> 2027 | J7: =I7+1 -> 2028 | K7: =J7+1 -> 2029 | ... Q7: =P7+1 -> 2035
C8: Audited | D8: Audited | E8: Audited | F8: Audited | G8: Audited | H8: Forecasted | I8: Forecasted | J8: Forecasted | K8: Forecasted | L8: Forecasted | M8: Forecasted | N8: Forecasted | O8: Forecasted | P8: Forecasted | Q8: Forecasted
B10: CASA Deposits | D10: ='Balance Sheet'!D18-'Balance Sheet'!C18 -> 132932.47 | E10: ='Balance Sheet'!E18-'Balance Sheet'!D18 -> 86807.464 | F10: ='Balance Sheet'!F18-'Balance Sheet'!E18 -> 76410.384 | G10: ='Balance Sheet'!G18-'Balance Sheet'!F18 -> 126006.76 | H10: ='Balance Sheet'!H18-'Balance Sheet'!G18 -> 789870.05 | I10: ='Balance Sheet'!I18-'Balance Sheet'!H18 -> 324284.1 | J10: ='Balance Sheet'!J18-'Balance Sheet'!I18 -> 317946.75 | K10: ='Balance Sheet'!K18-'Balance Sheet'!J18 -> 307974.58 | ... Q10: ='Balance Sheet'!Q18-'Balance Sheet'!P18 -> 210234.11
B11: Borrowings | D11: ='Balance Sheet'!D20-'Balance Sheet'!C20 -> 15363.576 | E11: ='Balance Sheet'!E20-'Balance Sheet'!D20 -> 71992.166 | F11: ='Balance Sheet'!F20-'Balance Sheet'!E20 -> 118457.55 | G11: ='Balance Sheet'!G20-'Balance Sheet'!F20 -> -28752.258 | H11: ='Balance Sheet'!H20-'Balance Sheet'!G20 -> 185502.28 | I11: ='Balance Sheet'!I20-'Balance Sheet'!H20 -> 89087.256 | J11: ='Balance Sheet'!J20-'Balance Sheet'!I20 -> 87346.261 | K11: ='Balance Sheet'!K20-'Balance Sheet'!J20 -> 84606.709 | ... Q11: ='Balance Sheet'!Q20-'Balance Sheet'!P20 -> 57755.468
B12: Other Liabilities and Provisions | D12: ='Balance Sheet'!D21-'Balance Sheet'!C21 -> 96214.057 | E12: ='Balance Sheet'!E21-'Balance Sheet'!D21 -> 85445.246 | F12: ='Balance Sheet'!F21-'Balance Sheet'!E21 -> 104111.75 | G12: ='Balance Sheet'!G21-'Balance Sheet'!F21 -> 61292.803 | H12: ='Balance Sheet'!H21-'Balance Sheet'!G21 -> 121073.94 | I12: ='Balance Sheet'!I21-'Balance Sheet'!H21 -> 98381.474 | J12: ='Balance Sheet'!J21-'Balance Sheet'!I21 -> 96458.845 | K12: ='Balance Sheet'!K21-'Balance Sheet'!J21 -> 93433.484 | ... Q12: ='Balance Sheet'!Q21-'Balance Sheet'!P21 -> 63780.93
B13: Total | D13: =SUM(D10:D12) -> 244510.1 | E13: =SUM(E10:E12) -> 244244.88 | F13: =SUM(F10:F12) -> 298979.69 | G13: =SUM(G10:G12) -> 158547.31 | H13: =SUM(H10:H12) -> 1096446.3 | I13: =SUM(I10:I12) -> 511752.83 | J13: =SUM(J10:J12) -> 501751.85 | K13: =SUM(K10:K12) -> 486014.77 | ... Q13: =SUM(Q10:Q12) -> 331770.51
B16: Advances | D16: ='Balance Sheet'!C30-'Balance Sheet'!D30 -> -293477.02 | E16: ='Balance Sheet'!D30-'Balance Sheet'!E30 -> -473826.13 | F16: ='Balance Sheet'!E30-'Balance Sheet'!F30 -> -516370.54 | G16: ='Balance Sheet'!F30-'Balance Sheet'!G30 -> -466558.07 | H16: ='Balance Sheet'!G30-'Balance Sheet'!H30 -> -687192.8 | I16: ='Balance Sheet'!H30-'Balance Sheet'!I30 -> -552407.5 | J16: ='Balance Sheet'!I30-'Balance Sheet'!J30 -> -541612.02 | K16: ='Balance Sheet'!J30-'Balance Sheet'!K30 -> -524624.76 | ... Q16: ='Balance Sheet'!P30-'Balance Sheet'!Q30 -> -358127.02
B17: Other Assets | D17: ='Balance Sheet'!C32-'Balance Sheet'!D32 -> 10142.993 | E17: ='Balance Sheet'!D32-'Balance Sheet'!E32 -> -58786.566 | F17: ='Balance Sheet'!E32-'Balance Sheet'!F32 -> -56988.38 | G17: ='Balance Sheet'!F32-'Balance Sheet'!G32 -> 14194.565 | H17: ='Balance Sheet'!G32-'Balance Sheet'!H32 -> -165732.35 | I17: ='Balance Sheet'!H32-'Balance Sheet'!I32 -> -69270.452 | J17: ='Balance Sheet'!I32-'Balance Sheet'!J32 -> -67916.728 | K17: ='Balance Sheet'!J32-'Balance Sheet'!K32 -> -65786.569 | ... Q17: ='Balance Sheet'!P32-'Balance Sheet'!Q32 -> -44908.189
B18: Total | D18: =SUM(D16:D17) -> -283334.02 | E18: =SUM(E15:E17) -> -532612.69 | F18: =SUM(F15:F17) -> -573358.92 | G18: =SUM(G15:G17) -> -452363.5 | H18: =SUM(H15:H17) -> -852925.15 | I18: =SUM(I15:I17) -> -621677.95 | J18: =SUM(J15:J17) -> -609528.75 | K18: =SUM(K15:K17) -> -590411.33 | L18: =SUM(L15:L17) -> -565728.24 | ... Q18: =SUM(Q15:Q17) -> -403035.21
B20: Change in Net Working Capital | D20: =D13+D18 -> -38823.918 | E20: =E13+E18 -> -288367.82 | F20: =F13+F18 -> -274379.23 | G20: =G13+G18 -> -293816.19 | H20: =H13+H18 -> 243521.13 | I20: =I13+I18 -> -109925.12 | J20: =J13+J18 -> -107776.9 | K20: =K13+K18 -> -104396.55 | ... Q20: =Q13+Q18 -> -71264.7

Sheet BS_Items
B1: State Bank of India
B2: BSE: 500112 | NSE: SBIN
C3: 10000
B4: (INR in Crores)
B5: Balance Sheet Forecast
B7: Particular | C7: 2021 | D7: =C7+1 -> 2022 | E7: =D7+1 -> 2023 | F7: =E7+1 -> 2024 | G7: =F7+1 -> 2025 | H7: =G7+1 -> 2026 | I7: =H7+1 -> 2027 | J7: =I7+1 -> 2028 | K7: =J7+1 -> 2029 | ... Q7: =P7+1 -> 2035
C8: Audited | D8: Audited | E8: Audited | F8: Audited | G8: Audited | H8: Forecasted | I8: Forecasted | J8: Forecasted | K8: Forecasted | L8: Forecasted | M8: Forecasted | N8: Forecasted | O8: Forecasted | P8: Forecasted | Q8: Forecasted
B10: Total Income | C10: ='Revenue_Build Up'!C10 -> 385337.89 | D10: ='Revenue_Build Up'!D10 -> 406973.09 | E10: ='Revenue_Build Up'!E10 -> 473378.14 | F10: ='Revenue_Build Up'!F10 -> 594574.9 | G10: ='Revenue_Build Up'!G10 -> 663343.32 | H10: ='Revenue_Build Up'!H10 -> 747480.98 | I10: ='Revenue_Build Up'!I10 -> 831100.29 | J10: ='Revenue_Build Up'!J10 -> 913085.46 | ... Q10: ='Revenue_Build Up'!Q10 -> 1385198
B12: =BS_Input!B12 -> CASA Deposits | C12: =BS_Input!C12 -> 1686779.5 | D12: =BS_Input!D12 -> 1819712 | E12: =BS_Input!E12 -> 1906519.4 | F12: =BS_Input!F12 -> 1982929.8 | G12: =BS_Input!G12 -> 2108936.6 | H12: =H$10*H13 -> 2898806.6 | I12: =I$10*I13 -> 3223090.7 | J12: =J$10*J13 -> 3541037.5 | K12: =K$10*K13 -> 3849012.1 | L12: =L$10*L13 -> 4144111.3 | M12: =M$10*M13 -> 4424151.8 | N12: =N$10*N13 -> 4687621.2 | O12: =O$10*O13 -> 4933605.5 | ... Q12: =Q$10*Q13 -> 5371937.5
B13: =B12&" x of Total Income" -> CASA Deposits x of Total Income | C13: =C12/C$10 -> 4.3774037 | D13: =D12/D$10 -> 4.4713324 | E13: =E12/E$10 -> 4.0274767 | F13: =F12/F$10 -> 3.3350379 | G13: =G12/G$10 -> 3.1792535 | H13: =AVERAGE(C13:G13) -> 3.8781008 | I13: =H13 -> 3.8781008 | J13: =I13 -> 3.8781008 | K13: =J13 -> 3.8781008 | L13: =K13 -> 3.8781008 | M13: =L13 -> 3.8781008 | N13: =M13 -> 3.8781008 | O13: =N13 -> 3.8781008 | P13: =O13 -> 3.8781008 | Q13: =P13 -> 3.8781008
B15: =BS_Input!B13 -> Fixed Deposits | C15: =BS_Input!C13 -> 2028551.7 | D15: =BS_Input!D13 -> 2267698.6 | E15: =BS_Input!E13 -> 2562016.1 | F15: =BS_Input!F13 -> 2983607.7 | G15: =BS_Input!G13 -> 3330961.4 | H15: =H$10*H16 -> 3929982.7 | I15: =I$10*I16 -> 4369622.6 | J15: =J$10*J16 -> 4800670.7 | K15: =K$10*K16 -> 5218199.4 | L15: =L$10*L16 -> 5618272.5 | M15: =M$10*M16 -> 5997930.3 | N15: =N$10*N16 -> 6355122.2 | O15: =O$10*O16 -> 6688609 | ... Q15: =Q$10*Q16 -> 7282866.5
B16: =B15 & " x of Total Inomce" -> Fixed Deposits x of Total Inomce | C16: =C15/C$10 -> 5.2643454 | D16: =D15/D$10 -> 5.5721095 | E16: =E15/E$10 -> 5.4121977 | F16: =F15/F$10 -> 5.0180518 | G16: =G15/G$10 -> 5.0214743 | H16: =AVERAGE(C16:G16) -> 5.2576357 | I16: =H16 -> 5.2576357 | J16: =I16 -> 5.2576357 | K16: =J16 -> 5.2576357 | L16: =K16 -> 5.2576357 | M16: =L16 -> 5.2576357 | N16: =M16 -> 5.2576357 | O16: =N16 -> 5.2576357 | P16: =O16 -> 5.2576357 | Q16: =P16 -> 5.2576357
B18: Borrowings | C18: =BS_Input!C14 -> 433796.21 | D18: =BS_Input!D14 -> 449159.78 | E18: =BS_Input!E14 -> 521151.95 | F18: =BS_Input!F14 -> 639609.5 | G18: =BS_Input!G14 -> 610857.24 | H18: =H$10*H19 -> 796359.52 | I18: =I$10*I19 -> 885446.78 | J18: =J$10*J19 -> 972793.04 | K18: =K$10*K19 -> 1057399.7 | L18: =L$10*L19 -> 1138469.3 | M18: =M$10*M19 -> 1215402 | N18: =N$10*N19 -> 1287782.3 | O18: =O$10*O19 -> 1355359 | ... Q18: =Q$10*Q19 -> 1475777.5
B19: =B18 & " x of Total Inomce" -> Borrowings x of Total Inomce | C19: =C18/C$10 -> 1.1257554 | D19: =D18/D$10 -> 1.1036597 | E19: =E18/E$10 -> 1.100921 | F19: =F18/F$10 -> 1.0757425 | G19: =G18/G$10 -> 0.92087646 | H19: =AVERAGE(C19:G19) -> 1.065391 | I19: =H19 -> 1.065391 | J19: =I19 -> 1.065391 | K19: =J19 -> 1.065391 | L19: =K19 -> 1.065391 | M19: =L19 -> 1.065391 | N19: =M19 -> 1.065391 | O19: =N19 -> 1.065391 | P19: =O19 -> 1.065391 | Q19: =P19 -> 1.065391
B21: Other Liabilities and Provisions | C21: =BS_Input!C15 -> 411303.62 | D21: =BS_Input!D15 -> 507517.68 | E21: =BS_Input!E15 -> 592962.92 | F21: =BS_Input!F15 -> 697074.68 | G21: =BS_Input!G15 -> 758367.48 | H21: =H$10*H22 -> 879441.42 | I21: =I$10*I22 -> 977822.9 | J21: =J$10*J22 -> 1074281.7 | K21: =K$10*K22 -> 1167715.2 | L21: =L$10*L22 -> 1257242.6 | M21: =M$10*M22 -> 1342201.4 | N21: =N$10*N22 -> 1422132.9 | O21: =O$10*O22 -> 1496759.7 | ... Q21: =Q$10*Q22 -> 1629741.1
B22: =B21 & " x of Income" -> Other Liabilities and Provisions x of Income | C22: =C21/C$10 -> 1.0673843 | D22: =D21/D$10 -> 1.2470546 | E22: =E21/E$10 -> 1.25262 | F22: =F21/F$10 -> 1.1723917 | G22: =G21/G$10 -> 1.1432503 | H22: =AVERAGE(C22:G22) -> 1.1765402 | I22: =H22 -> 1.1765402 | J22: =I22 -> 1.1765402 | K22: =J22 -> 1.1765402 | L22: =K22 -> 1.1765402 | M22: =L22 -> 1.1765402 | N22: =M22 -> 1.1765402 | O22: =N22 -> 1.1765402 | P22: =O22 -> 1.1765402 | Q22: =P22 -> 1.1765402
B24: Investments | C24: =BS_Input!C21 -> 1595100.3 | D24: =BS_Input!D21 -> 1776489.9 | E24: =BS_Input!E21 -> 1913107.9 | F24: =BS_Input!F21 -> 2110548.2 | G24: =BS_Input!G21 -> 2205601.1 | H24: =H$10*H25 -> 2903314.9 | I24: =I$10*I25 -> 3228103.3 | J24: =J$10*J25 -> 3546544.5 | K24: =K$10*K25 -> 3854998.1 | L24: =L$10*L25 -> 4150556.2 | M24: =M$10*M25 -> 4431032.3 | N24: =N$10*N25 -> 4694911.4 | O24: =O$10*O25 -> 4941278.2 | ... Q24: =Q$10*Q25 -> 5380292
B25: =B24 & " x of Income" -> Investments x of Income | C25: =C24/C$10 -> 4.1394846 | D25: =D24/D$10 -> 4.3651287 | E25: =E24/E$10 -> 4.0413946 | F25: =F24/F$10 -> 3.5496759 | G25: =G24/G$10 -> 3.3249768 | H25: =AVERAGE(C25:G25) -> 3.8841321 | I25: =H25 -> 3.8841321 | J25: =I25 -> 3.8841321 | K25: =J25 -> 3.8841321 | L25: =K25 -> 3.8841321 | M25: =L25 -> 3.8841321 | N25: =M25 -> 3.8841321 | O25: =N25 -> 3.8841321 | P25: =O25 -> 3.8841321 | Q25: =P25 -> 3.8841321
B27: Advances | C27: =BS_Input!C22 -> 2500599 | D27: =BS_Input!D22 -> 2794076 | E27: =BS_Input!E22 -> 3267902.1 | F27: =BS_Input!F22 -> 3784272.7 | G27: =BS_Input!G22 -> 4250830.7 | H27: =H$10*H28 -> 4938023.5 | I27: =I$10*I28 -> 5490431 | J27: =J$10*J28 -> 6032043.1 | K27: =K$10*K28 -> 6556667.8 | L27: =L$10*L28 -> 7059359.8 | M27: =M$10*M28 -> 7536399.7 | N27: =N$10*N28 -> 7985211.4 | O27: =O$10*O28 -> 8404237.6 | ... Q27: =Q$10*Q28 -> 9150922.1
B28: =B27 & " x of Income" -> Advances x of Income | C28: =C27/C$10 -> 6.489367 | D28: =D27/D$10 -> 6.8655055 | E28: =E27/E$10 -> 6.9033651 | F28: =F27/F$10 -> 6.3646693 | G28: =G27/G$10 -> 6.4081911 | H28: =AVERAGE(C28:G28) -> 6.6062196 | I28: =H28 -> 6.6062196 | J28: =I28 -> 6.6062196 | K28: =J28 -> 6.6062196 | L28: =K28 -> 6.6062196 | M28: =L28 -> 6.6062196 | N28: =M28 -> 6.6062196 | O28: =N28 -> 6.6062196 | P28: =O28 -> 6.6062196 | Q28: =P28 -> 6.6062196
B30: Other Assets | C30: =BS_Input!C24 -> 362045.47 | D30: =BS_Input!D24 -> 351902.48 | E30: =BS_Input!E24 -> 410689.04 | F30: =BS_Input!F24 -> 467677.42 | G30: =BS_Input!G24 -> 453482.86 | H30: =H$10*H31 -> 619215.21 | I30: =I$10*I31 -> 688485.66 | J30: =J$10*J31 -> 756402.39 | K30: =K$10*K31 -> 822188.96 | L30: =L$10*L31 -> 885225.21 | M30: =M$10*M31 -> 945044.77 | N30: =N$10*N31 -> 1001324.6 | O30: =O$10*O31 -> 1053869.4 | ... Q30: =Q$10*Q31 -> 1147501.6
B31: =B30 & " x of Income" -> Other Assets x of Income | C31: =C30/C$10 -> 0.93955326 | D31: =D30/D$10 -> 0.86468242 | E31: =E30/E$10 -> 0.86757078 | F31: =F30/F$10 -> 0.78657444 | G31: =G30/G$10 -> 0.68363221 | H31: =AVERAGE(C31:G31) -> 0.82840262 | I31: =H31 -> 0.82840262 | J31: =I31 -> 0.82840262 | K31: =J31 -> 0.82840262 | L31: =K31 -> 0.82840262 | M31: =L31 -> 0.82840262 | N31: =M31 -> 0.82840262 | O31: =N31 -> 0.82840262 | P31: =O31 -> 0.82840262 | Q31: =P31 -> 0.82840262

Sheet Income Statement
B1: State Bank of India
B2: BSE: 500112 | NSE: SBIN
C3: 10000
B4: (INR in Crores)
B5: Income Statement
B7: Particular | C7: 2021 | D7: =C7+1 -> 2022 | E7: =D7+1 -> 2023 | F7: =E7+1 -> 2024 | G7: =F7+1 -> 2025 | H7: =G7+1 -> 2026 | I7: =H7+1 -> 2027 | J7: =I7+1 -> 2028 | K7: =J7+1 -> 2029 | ... Q7: =P7+1 -> 2035
C8: Audited | D8: Audited | E8: Audited | F8: Audited | G8: Audited | H8: Forecasted | I8: Forecasted | J8: Forecasted | K8: Forecasted | L8: Forecasted | M8: Forecasted | N8: Forecasted | O8: Forecasted | P8: Forecasted | Q8: Forecasted
B10: Total Income | C10: ='Revenue_Build Up'!C10 -> 385337.89 | D10: ='Revenue_Build Up'!D10 -> 406973.09 | E10: ='Revenue_Build Up'!E10 -> 473378.14 | F10: ='Revenue_Build Up'!F10 -> 594574.9 | G10: ='Revenue_Build Up'!G10 -> 663343.32 | H10: ='Revenue_Build Up'!H10 -> 747480.98 | I10: ='Revenue_Build Up'!I10 -> 831100.29 | J10: ='Revenue_Build Up'!J10 -> 913085.46 | ... Q10: ='Revenue_Build Up'!Q10 -> 1385198
B12: EXPENDITURE
B13: Interest on Deposit | C13: =Cost_BuildUp!C12 -> 143060.45 | D13: =Cost_BuildUp!D12 -> 141765.28 | E13: =Cost_BuildUp!E12 -> 163518.78 | F13: =Cost_BuildUp!F12 -> 223278.71 | G13: =Cost_BuildUp!G12 -> 259228.12 | H13: =Cost_BuildUp!H12 -> 273779.39 | I13: =Cost_BuildUp!I12 -> 304406.58 | J13: =Cost_BuildUp!J12 -> 334435.24 | ... Q13: =Cost_BuildUp!Q12 -> 507355.6
B14: Operating expenses | C14: =Cost_BuildUp!C15 -> 142899.04 | D14: =Cost_BuildUp!D15 -> 161647.85 | E14: =Cost_BuildUp!E15 -> 168795.17 | F14: =Cost_BuildUp!F15 -> 200776.45 | G14: =Cost_BuildUp!G15 -> 198820.6 | H14: =Cost_BuildUp!H15 -> 263414.95 | I14: =Cost_BuildUp!I15 -> 292882.69 | J14: =Cost_BuildUp!J15 -> 321774.56 | ... Q14: =Cost_BuildUp!Q15 -> 488148.69
B15: Provisions and contingencies | C15: =Cost_BuildUp!C18 -> 54618.409 | D15: =Cost_BuildUp!D18 -> 40059.148 | E15: =Cost_BuildUp!E18 -> 37024.409 | F15: =Cost_BuildUp!F18 -> 30806.757 | G15: =Cost_BuildUp!G18 -> 46809.309 | H15: =Cost_BuildUp!H18 -> 65892.77 | I15: =Cost_BuildUp!I18 -> 73264.071 | J15: =Cost_BuildUp!J18 -> 80491.318 | ... Q15: =Cost_BuildUp!Q18 -> 122109.5
B16: Total | C16: =SUM(C13:C15) -> 340577.89 | D16: =SUM(D13:D15) -> 343472.28 | E16: =SUM(E13:E15) -> 369338.36 | F16: =SUM(F13:F15) -> 454861.92 | G16: =SUM(G13:G15) -> 504858.03 | H16: =SUM(H13:H15) -> 603087.11 | I16: =SUM(I13:I15) -> 670553.34 | J16: =SUM(J13:J15) -> 736701.11 | ... Q16: =SUM(Q13:Q15) -> 1117613.8
B18: EBITDA | C18: =C10-C16 -> 44759.997 | D18: =D10-D16 -> 63500.806 | E18: =E10-E16 -> 104039.78 | F18: =F10-F16 -> 139712.99 | G18: =G10-G16 -> 158485.29 | H18: =H10-H16 -> 144393.87 | I18: =I10-I16 -> 160546.95 | J18: =J10-J16 -> 176384.35 | ... Q18: =Q10-Q16 -> 267584.2
B20: Depreciation & Amortization Expenses | C20: =FAS!C54 -> 3711.0636 | D20: =FAS!D54 -> 3691.27 | E20: =FAS!E54 -> 3695.5986 | F20: =FAS!F54 -> 3849.1245 | G20: =FAS!G54 -> 3991.4767 | H20: =FAS!H54 -> 3446.3444 | I20: =FAS!I54 -> 3463.5761 | J20: =FAS!J54 -> 3480.894 | ... Q20: =FAS!Q54 -> 3604.5681
B22: EBIT | C22: =C18-C20 -> 41048.934 | D22: =D18-D20 -> 59809.536 | E22: =E18-E20 -> 100344.19 | F22: =F18-F20 -> 135863.86 | G22: =G18-G20 -> 154493.82 | H22: =H18-H20 -> 140947.53 | I22: =I18-I20 -> 157083.37 | J22: =J18-J20 -> 172903.45 | ... Q22: =Q18-Q20 -> 263979.63
