Workbook

Sheet Assumptions
B7: Scenario | E7: Company Name | F7: Vardhman Holdings Ltd
B8: Base Case | C8: =IF(B8="Best Case",1,IF(B8="Base Case",2,3)) -> 2 | E8: ISIN Code | F8: INE701A01023
E9: Sector Name | F9: Investment Company
B10: Assumptions | E10: Industry | F10: Finance
B11: Transaction Date | C11: 45922 | E11: Exchange Name | F11: BSE: 500439 | NSE: VHL
B12: Fiscal Year End | C12: 46112 | E12: Website | F12: vardhman.in
B13: Annual growth Tapering | C13: =Revenue_BuildUp!C33 -> 0.2 | E13: Company Description | F13: VHL is a Non Deposit Taking Systemically Important Non Banking Finance Corporation which is mainly into investment activities. It primarily earns its income from investments. Company’s strategy is to adopt a systematic approach of investment into different asset classes and to keep the portfolio dynamic as per the changing market conditions. Company’s current portfolio consists of investments into debt, equity and real estate. Interest Income from investments ~43%, Dividend Income from investments ~25%, Net gain on trading portfolio ~8%, Receipt against License agreement ~24%, (Company has no debt, it is debt free).
B14: Risk Free Rate | C14: 0.06481
B15: Addition In CAPEX | C15: 0.005
B16: Addition In Tax rate / 2 years | C16: 0.005
B17: Addition In Dep / 3 years | C17: 0.0015
B18: Tax Rate | C18: =Cost_BuildUp!H19 -> 0.05984114
B19: Investment Growth rate / year | C19: 0.03
B20: Investments in associates Growth Rate / year | C20: 0.04
B21: EV/EBITDA Multiple | C21: ='Comps Valuation'!E37 -> 16.309294
B22: Perpetual Growth Rate | C22: 0.06
B23: Discount Rate | C23: =DCF!C43 -> 0.14212865
B24: Shares Outstanding(Lakhs) | C24: ='Comps Data'!D15 -> 31.9
B25: Current Market Price | C25: ='Comps Data'!C15 -> 3810 | E25: Associate Company | F25: a) Vardhman Textiles Limited (VTXL)- Company holds ~28.48% shares of VTXL. It is engaged in manufacturing of texiles. b) Vardhman Spinning and General Mills Limited (VSGM)- Company holds ~50% shares of VSGM. It deals in trading of Cotton and Fibre. In FY23, VSGM has not traded any goods
B26: Market Cap (Cr.) | C26: =C25*C24 -> 121539
B28: Colour Code
B29: Blue colour | C29: Hardcoded Figures
B30: Black colour | C30: Calculated Figures
B31: Green Colour | C31: Link Data figures
B33: Items | C33: Sheet | E33: Reference | F33: Assumptions
B35: Revenue from operation | C35: Revenue Buildup | D35: B28:Q33 | F35: Revenue has been forecasted using the historic average YoY growth of the last 5 years and tapered down to match the perpetual growth rate. Moreover, a Bull and a Bear Case has been calculated as +/-5% of Base Case respectively
B38: Share of Profit of Associates | C38: Revenue Buildup | D38: B22:Q23 | F38: Share of Profit of Associates: Taken as a multiple of revenue. For forecasted years (2026–2035), assumed at 8x revenue, based on the historical average of 2021–2025. (except 2023)
B41: Other Income | C41: Revenue Buildup | D41: B25:Q26 | F41: Other Income: Taken as a percentage of revenue. For forecasted years (2026–2035), assumed at 14% of revenue, derived from the historical average of 2021–2025.
B43: Investments | C43: Investment | D43: B16:Q21 | F43: Investment forecast is based on the historical average growth rate of Investment. For the forecasted period, we assumes a steady and conservative annual investment growth rate of 3% ( every 3 year). This simplified projection supports long-term financial planning by assuming stable, moderate expansion.
B45: Investments in associates accounted for using the equity method | C45: Investment | D45: B9:Q12 | F45: Investment in associates accounted for using the equity method forecast is based on the historical average growth rate of the investment. For the forecasted period, we assumes a steady and conservative annual investment growth rate of 4% ( every 3 year). This simplified projection supports long-term financial planning by assuming stable, moderate expansion.
B48: Other Expenses | C48: Cost Build_up | D48: B19:Q23 | F48: The first five years show actual historical percentages of revenue. For the forecasted period (2026–2035), other expenses are assumed based on the average percentage of revenue from 2021–2025, stabilizing around 24% and increasing proportionally with revenue growth.
B52: Employee benefits expense, | C52: Cost Build_up | D52: B30:Q34 | F52: From 2026 to 2035, the employee benefits expenses are forecasted using the average percentage of revenue from the historical five years (2021–2025), stabilizing at around 6% and reflecting growth in line with business expansion.
B55: Perpetual Growth Rate | C55: Assumptions | D55: C21 | F55: For calculating the Terminal Value in the DCF model, a perpetual growth rate of 6% has been assumed. This is aligned with India’s long-term GDP growth outlook, which is forecasted at approximately 6.4%
B57: Effective Tax Rate | C57: Cost Build_up | D57: B39:Q39 | F57: Taxes for the historical years are based on actual PBT percentages. For the forecasted years (2026–2035), taxes for projected year taken as the latest year of the tax ( which is 2025 tax rate ), and aslo adding the growing tax rate of 0.5 % every 2 year.
B59: Other Receivables , Other Financial assets | C59: Balance_Sheet_Forecast | D59: B11:Q37 | F59: The balances for Other Receivables and Other Financial Assets are forecasted based on their historical relationship to revenue. The specific percentage used for each forecast year is calculated as the average of their historical percentages of revenue.
B61: Current Tax assets (Net), , Other non-financial assets | C61: Balance_Sheet_Forecast | D61: B11:Q37 | F61: The balances for Current Tax Assets (Net), and Other Non-Financial Assets are forecasted based on their historical relationship to revenue. The specific amount for each forecast year is calculated as the average of their historical percentages of revenue.
B63: Other financial liabilities | C63: Balance_Sheet_Forecast | D63: B11:Q37 | F63: The balance for Other Financial Liabilities is forecasted based on its historical relationship to total revenue. The specific amount for each forecast year is calculated as the average of its historical percentage of revenue.
... B84: Net Working Capital | C84: Net Working Capital | D84: B43:Q43 | F84: Net Working Capital Consist Change of the Current portion of Current Assets and Current portion of Current Liabilities , The Current Assets & Current Liabilities are Taken from the annual Report based on their Maturity Paatern ( With in 12 Months) and some portion of Investment of Current Assets Taken as % of the total Investment and for forecasted year taken as the average of that.

Sheet Historical P&L
B6: (All amounts in INR Lakhs, unless otherwise stated)
B7: Particulars | C7: 2021 | D7: =C7+1 -> 2022 | E7: =D7+1 -> 2023 | F7: =E7+1 -> 2024 | G7: =F7+1 -> 2025
B9: Revenue from operations
B10: Interest Income | C10: 779.91 | D10: 393.67 | E10: 335.7 | F10: 102.87 | G10: 119.48
B11: Dividend Income | C11: 6.38 | D11: 263.68 | E11: 192.98 | F11: 229.05 | G11: 225.33
B12: Net gain on fair value changes | C12: 1192.22 | D12: 2651.6 | E12: 59.77 | F12: 1158.21 | G12: 1932.81
B13: Total Revenue from operations | C13: =SUM(C10:C12) -> 1978.51 | D13: =SUM(D10:D12) -> 3308.95 | E13: =SUM(E10:E12) -> 588.45 | F13: =SUM(F10:F12) -> 1490.13 | G13: =SUM(G10:G12) -> 2277.62
B14: Other income | C14: 124.69 | D14: 185.46 | E14: 188.17 | F14: 247.22 | G14: 185.66
B15: Total Income | C15: =SUM(C13:C14) -> 2103.2 | D15: =SUM(D13:D14) -> 3494.41 | E15: =SUM(E13:E14) -> 776.62 | F15: =SUM(F13:F14) -> 1737.35 | G15: =SUM(G13:G14) -> 2463.28
B16: Expenses
B17: Employee benefits expenses | C17: 56.11 | D17: 81.83 | E17: 124.52 | F17: 48.36 | G17: 62.01
B18: Depreciation and amortization expense | C18: 0.88 | D18: 0.77 | E18: 0.72 | F18: 0.72 | G18: 0.72
B19: Other expenses | C19: 170.92 | D19: 225.61 | E19: 312.42 | F19: 385.57 | G19: 556.24
B20: Total Expenses | C20: =SUM(C17:C19) -> 227.91 | D20: =SUM(D17:D19) -> 308.21 | E20: =SUM(E17:E19) -> 437.66 | F20: =SUM(F17:F19) -> 434.65 | G20: =SUM(G17:G19) -> 618.97
B22: Profit before Share of profit of Associates, Exeptional Items and tax | C22: =C15-C20 -> 1875.29 | D22: =D15-D20 -> 3186.2 | E22: =E15-E20 -> 338.96 | F22: =F15-F20 -> 1302.7 | G22: =G15-G20 -> 1844.31
B23: Share of Profit of Associates | C23: 11446.14 | D23: 42760.92 | E23: 22153.14 | F23: 18121.32 | G23: 25453.08
B24: Profit before exceptional Items and Tax | C24: =SUM(C22:C23) -> 13321.43 | D24: =SUM(D22:D23) -> 45947.12 | E24: =SUM(E22:E23) -> 22492.1 | F24: =SUM(F22:F23) -> 19424.02 | G24: =SUM(G22:G23) -> 27297.39
B25: Exeptional Items
B26: Profit before tax | C26: =SUM(C24:C25) -> 13321.43 | D26: =SUM(D24:D25) -> 45947.12 | E26: =SUM(E24:E25) -> 22492.1 | F26: =SUM(F24:F25) -> 19424.02 | G26: =SUM(G24:G25) -> 27297.39
B28: Tax expense :
B29: Current Tax | C29: 365.42 | D29: 2725.35 | E29: 347.67 | F29: 761.19 | G29: 1014.2
B30: Deferred tax | C30: 4.86 | D30: 313.95 | E30: -698.83 | F30: 174.77 | G30: 482.82
B31: Total Tax | C31: =SUM(C29:C30) -> 370.28 | D31: =SUM(D29:D30) -> 3039.3 | E31: =SUM(E29:E30) -> -351.16 | F31: =SUM(F29:F30) -> 935.96 | G31: =SUM(G29:G30) -> 1497.02
B33: Profit for the year | C33: =C26-C31 -> 12951.15 | D33: =D26-D31 -> 42907.82 | E33: =E26-E31 -> 22843.26 | F33: =F26-F31 -> 18488.06 | G33: =G26-G31 -> 25800.37

Sheet Historical B_Sheet
B6: (All amounts in INR Lakhs, unless otherwise stated)
B7: Particulars | C7: 2021 | D7: =C7+1 -> 2022 | E7: =D7+1 -> 2023 | F7: =E7+1 -> 2024 | G7: =F7+1 -> 2025
B9: Assets
B10: Financial Assets
B11: Cash and bank balances | C11: 7638.83 | D11: 120.99 | E11: 294.74 | F11: 284.7 | G11: 49.18
B12: Bank Balances | C12: 9.79 | D12: 152.78 | E12: 106.02 | F12: 98.22 | G12: 102.77
B13: Receivables
B14: Trade Receivables
B15: Other Receivables | C15: 577.05 | D15: 230.41 | E15: 262.69 | F15: 252.58 | G15: 199.46
B16: Investments in associates accounted for using the equity method | C16: 0 | D16: 229117.91 | E16: 262650.13 | F16: 281033.31 | G16: 304669.13
B17: Investments | C17: 216675.61 | D17: 44668.35 | E17: 43858.98 | F17: 45919.59 | G17: 48110.18
B18: Other Financial assets | C18: 1572.52 | D18: 609.68 | E18: 445.01 | F18: 227.74 | G18: 41.66
B20: Total Financial Assets | C20: =SUM(C11:C18) -> 226473.8 | D20: =SUM(D11:D18) -> 274900.12 | E20: =SUM(E11:E18) -> 307617.57 | F20: =SUM(F11:F18) -> 327816.14 | G20: =SUM(G11:G18) -> 353172.38
B22: Non Financial Assets
B23: Current Tax assets (Net) | C23: 0 | D23: 105.2 | E23: 306.77 | F23: 533.01 | G23: 373.39
B24: Deferred Tax Asset (Net) | C24: 3913.66 | D24: 2415.08 | E24: 1813.25 | F24: 1098.4 | G24: 223.85
B25: Property, Plant and Equipment | C25: 321.67 | D25: 320.9 | E25: 320.18 | F25: 319.46 | G25: 318.74
B26: Other non-financial assets | C26: 24.73 | D26: 9.95 | E26: 11.88 | F26: 10.09 | G26: 10.94
B28: Total Non Financial Assets | C28: =SUM(C23:C26) -> 4260.06 | D28: =SUM(D23:D26) -> 2851.13 | E28: =SUM(E23:E26) -> 2452.08 | F28: =SUM(F23:F26) -> 1960.96 | G28: =SUM(G23:G26) -> 926.92
B30: TOTAL ASSETS | C30: =C28+C20 -> 230733.86 | D30: =D28+D20 -> 277751.25 | E30: =E28+E20 -> 310069.65 | F30: =F28+F20 -> 329777.1 | G30: =G28+G20 -> 354099.3
B32: LIABILITIES AND EQUITY
B33: Liabilities
B34: Financial Liabilities
B35: Payables | C35: 0 | D35: 0 | E35: 0 | F35: 0 | G35: 0
B36: Trade Payables | C36: 0 | D36: 0 | E36: 0 | F36: 0 | G36: 0
B37: total outstanding dues of micro enterprises and small enterprises | C37: 0 | D37: 0 | E37: 0 | F37: 0 | G37: 0
B38: total outstanding dues of creditors other than micro enterprises and small enterprises | C38: 0 | D38: 0 | E38: 0 | F38: 0 | G38: 0
B39: Other financial liabilities | C39: 81.27 | D39: 18.35 | E39: 13.46 | F39: 16.6 | G39: 7
B41: Total Financial Liabilities | C41: =SUM(C35:C39) -> 81.27 | D41: =SUM(D35:D39) -> 18.35 | E41: =SUM(E35:E39) -> 13.46 | F41: =SUM(F35:F39) -> 16.6 | G41: =SUM(G35:G39) -> 7
B43: Non Financial Liabilities
B44: Current tax liabilities (Net) | C44: 43.3 | D44: 0 | E44: 0 | F44: 0 | G44: 0
B45: Provisions | C45: 2.9 | D45: 1.55 | E45: 5.52 | F45: 3.11 | G45: 6.75
B46: Other non-financial liabilities | C46: 27.11 | D46: 47.65 | E46: 90.95 | F46: 40.09 | G46: 39.1
B48: Total Non Financial Liabilities | C48: =SUM(C44:C46) -> 73.31 | D48: =SUM(D44:D46) -> 49.2 | E48: =SUM(E44:E46) -> 96.47 | F48: =SUM(F44:F46) -> 43.2 | G48: =SUM(G44:G46) -> 45.85
B50: Equity
B51: Equity Share Capital | C51: 319.24 | D51: 319.24 | E51: 319.24 | F51: 319.24 | G51: 319.24
B52: Other Equity | C52: 230260.04 | D52: 277364.46 | E52: 309640.48 | F52: 329398.06 | G52: 353727.21
B54: Total Equity | C54: =SUM(C51:C53) -> 230579.28 | D54: =SUM(D51:D53) -> 277683.7 | E54: =SUM(E51:E53) -> 309959.72 | F54: =SUM(F51:F53) -> 329717.3 | G54: =SUM(G51:G53) -> 354046.45
B56: TOTAL LIABILITIES AND EQUITY | C56: =C54+C48+C41 -> 230733.86 | D56: =D54+D48+D41 -> 277751.25 | E56: =E54+E48+E41 -> 310069.65 | F56: =F54+F48+F41 -> 329777.1 | G56: =G54+G48+G41 -> 354099.3
B58: CHECK | C58: =C56=C30 -> TRUE | D58: =D56=D30 -> TRUE | E58: =E56=E30 -> TRUE | F58: =F56=F30 -> TRUE | G58: =G56=G30 -> TRUE

Sheet Revenue_BuildUp
B6: (All amounts in INR Lakhs, unless otherwise stated)
B7: Particulars | C7: 2021 | D7: =C7+1 -> 2022 | E7: =D7+1 -> 2023 | F7: =E7+1 -> 2024 | G7: =F7+1 -> 2025 | H7: =G7+1 -> 2026 | I7: =H7+1 -> 2027 | J7: =I7+1 -> 2028 | K7: =J7+1 -> 2029 | ... Q7: =P7+1 -> 2035
B9: Total Operational Revenue | C9: ='Historical P&L'!C13 -> 1978.51 | D9: ='Historical P&L'!D13 -> 3308.95 | E9: ='Historical P&L'!E13 -> 588.45 | F9: ='Historical P&L'!F13 -> 1490.13 | G9: ='Historical P&L'!G13 -> 2277.62 | H9: =G9*(1+H10) -> 3365.7807 | I9: =H9*(1+I10) -> 4652.2148 | J9: =I9*(1+J10) -> 6074.7122 | K9: =J9*(1+K10) -> 7560.6733 | L9: =K9*(1+L10) -> 9040.2319 | M9: =L9*(1+M10) -> 10455.508 | N9: =M9*(1+N10) -> 11764.982 | O9: =N9*(1+O10) -> 12943.763 | ... Q9: =P9*(1+Q10) -> 14877.81
B10: Y-o-Y Growth | D10: =D9/C9-1 -> 0.67244543 | E10: =E9/D9-1 -> -0.82216413 | F10: =F9/E9-1 -> 1.5322967 | G10: =G9/F9-1 -> 0.52847067 | H10: =CHOOSE(Assumptions!$C$8,Revenue_BuildUp!$H$30:$Q$30,Revenue_BuildUp!$H$31:$Q$31,Revenue_BuildUp!$H$32:$Q$32) -> 0.47776217 | I10: =CHOOSE(Assumptions!$C$8,Revenue_BuildUp!$H$30:$Q$30,Revenue_BuildUp!$H$31:$Q$31,Revenue_BuildUp!$H$32:$Q$32) -> 0.38220974 | J10: =CHOOSE(Assumptions!$C$8,Revenue_BuildUp!$H$30:$Q$30,Revenue_BuildUp!$H$31:$Q$31,Revenue_BuildUp!$H$32:$Q$32) -> 0.30576779 | K10: =CHOOSE(Assumptions!$C$8,Revenue_BuildUp!$H$30:$Q$30,Revenue_BuildUp!$H$31:$Q$31,Revenue_BuildUp!$H$32:$Q$32) -> 0.24461423 | L10: =CHOOSE(Assumptions!$C$8,Revenue_BuildUp!$H$30:$Q$30,Revenue_BuildUp!$H$31:$Q$31,Revenue_BuildUp!$H$32:$Q$32) -> 0.19569138 | M10: =CHOOSE(Assumptions!$C$8,Revenue_BuildUp!$H$30:$Q$30,Revenue_BuildUp!$H$31:$Q$31,Revenue_BuildUp!$H$32:$Q$32) -> 0.15655311 | N10: =CHOOSE(Assumptions!$C$8,Revenue_BuildUp!$H$30:$Q$30,Revenue_BuildUp!$H$31:$Q$31,Revenue_BuildUp!$H$32:$Q$32) -> 0.12524249 | O10: =CHOOSE(Assumptions!$C$8,Revenue_BuildUp!$H$30:$Q$30,Revenue_BuildUp!$H$31:$Q$31,Revenue_BuildUp!$H$32:$Q$32) -> 0.10019399 | ... Q10: =CHOOSE(Assumptions!$C$8,Revenue_BuildUp!$H$30:$Q$30,Revenue_BuildUp!$H$31:$Q$31,Revenue_BuildUp!$H$32:$Q$32) -> 0.064124153
B12: Revenue Break
B13: Interest Income | C13: ='Historical P&L'!C10 -> 779.91 | D13: ='Historical P&L'!D10 -> 393.67 | E13: ='Historical P&L'!E10 -> 335.7 | F13: ='Historical P&L'!F10 -> 102.87 | G13: ='Historical P&L'!G10 -> 119.48 | H13: =H14*H9 -> 811.24479 | I13: =I14*I9 -> 1121.3104 | J13: =J14*J9 -> 1464.1711 | K13: =K14*K9 -> 1822.3281 | L13: =L14*L9 -> 2178.942 | M13: =M14*M9 -> 2520.0622 | N13: =N14*N9 -> 2835.681 | O13: =O14*O9 -> 3119.7992 | ... Q13: =Q14*Q9 -> 3585.9572
B14: % of Revenue | C14: =C13/C$9 -> 0.39419058 | D14: =D13/D$9 -> 0.11897127 | E14: =E13/E$9 -> 0.57048177 | F14: =F13/F$9 -> 0.069034245 | G14: =G13/G$9 -> 0.052458268 | H14: =AVERAGE(C14:G14) -> 0.24102723 | I14: =H14 -> 0.24102723 | J14: =I14 -> 0.24102723 | K14: =J14 -> 0.24102723 | L14: =K14 -> 0.24102723 | M14: =L14 -> 0.24102723 | N14: =M14 -> 0.24102723 | O14: =N14 -> 0.24102723 | P14: =O14 -> 0.24102723 | Q14: =P14 -> 0.24102723
B16: Dividend Income | C16: ='Historical P&L'!C11 -> 6.38 | D16: ='Historical P&L'!D11 -> 263.68 | E16: ='Historical P&L'!E11 -> 192.98 | F16: ='Historical P&L'!F11 -> 229.05 | G16: ='Historical P&L'!G11 -> 225.33 | H16: =H17*H9 -> 446.6401 | I16: =I17*I9 -> 617.3503 | J16: =J17*J9 -> 806.11614 | K16: =K17*K9 -> 1003.3036 | L16: =L17*L9 -> 1199.6415 | M16: =M17*M9 -> 1387.4491 | N16: =N17*N9 -> 1561.2167 | O16: =O17*O9 -> 1717.6412 | ... Q16: =Q17*Q9 -> 1974.2898
B17: % of Revenue | C17: =C16/C$9 -> 0.0032246489 | D17: =D16/D$9 -> 0.07968691 | E17: =E16/E$9 -> 0.3279463 | F17: =F16/F$9 -> 0.15371142 | G17: =G16/G$9 -> 0.098932219 | H17: =AVERAGE(C17:G17) -> 0.1327003 | I17: =H17 -> 0.1327003 | J17: =I17 -> 0.1327003 | K17: =J17 -> 0.1327003 | L17: =K17 -> 0.1327003 | M17: =L17 -> 0.1327003 | N17: =M17 -> 0.1327003 | O17: =N17 -> 0.1327003 | P17: =O17 -> 0.1327003 | Q17: =P17 -> 0.1327003
B19: Net gain on fair value changes | C19: ='Historical P&L'!C12 -> 1192.22 | D19: ='Historical P&L'!D12 -> 2651.6 | E19: ='Historical P&L'!E12 -> 59.77 | F19: ='Historical P&L'!F12 -> 1158.21 | G19: ='Historical P&L'!G12 -> 1932.81 | H19: =H20*H9 -> 2107.8958 | I19: =I20*I9 -> 2913.5541 | J19: =J20*J9 -> 3804.4251 | K19: =K20*K9 -> 4735.0416 | L19: =L20*L9 -> 5661.6484 | M19: =M20*M9 -> 6547.9971 | N19: =N20*N9 -> 7368.0845 | O19: =O20*O9 -> 8106.3223 | ... Q19: =Q20*Q9 -> 9317.5627
B20: % of Revenue | C20: =C19/C$9 -> 0.60258477 | D20: =D19/D$9 -> 0.80134182 | E20: =E19/E$9 -> 0.10157193 | F20: =F19/F$9 -> 0.77725433 | G20: =G19/G$9 -> 0.84860951 | H20: =AVERAGE(C20:G20) -> 0.62627247 | I20: =H20 -> 0.62627247 | J20: =I20 -> 0.62627247 | K20: =J20 -> 0.62627247 | L20: =K20 -> 0.62627247 | M20: =L20 -> 0.62627247 | N20: =M20 -> 0.62627247 | O20: =N20 -> 0.62627247 | P20: =O20 -> 0.62627247 | Q20: =P20 -> 0.62627247
B22: Share of Profit of Associates | C22: ='Historical P&L'!C23 -> 11446.14 | D22: ='Historical P&L'!D23 -> 42760.92 | E22: ='Historical P&L'!E23 -> 22153.14 | F22: ='Historical P&L'!F23 -> 18121.32 | G22: ='Historical P&L'!G23 -> 25453.08 | H22: =H23*H9 -> 26806.142 | I22: =I23*I9 -> 37051.711 | J22: =J23*J9 -> 48380.93 | K22: =K23*K9 -> 60215.595 | L22: =L23*L9 -> 71999.268 | M22: =M23*M9 -> 83270.977 | N22: =N23*N9 -> 93700.041 | O22: =O23*O9 -> 103088.22 | ... Q22: =Q23*Q9 -> 118491.58
B23: (x) of Revenue | C23: =C22/C9 -> 5.7852323 | D23: =D22/C22-1 -> 2.7358376 | E23: =E22/E9 -> 37.646597 | F23: =F22/F9 -> 12.160899 | G23: =G22/G9 -> 11.175297 | H23: =AVERAGE(C23:D23,F23:G23) -> 7.9643164 | I23: =H23 -> 7.9643164 | J23: =I23 -> 7.9643164 | K23: =J23 -> 7.9643164 | L23: =K23 -> 7.9643164 | M23: =L23 -> 7.9643164 | N23: =M23 -> 7.9643164 | O23: =N23 -> 7.9643164 | P23: =O23 -> 7.9643164 | Q23: =P23 -> 7.9643164
B25: Other Income | C25: ='Historical P&L'!C14 -> 124.69 | D25: ='Historical P&L'!D14 -> 185.46 | E25: ='Historical P&L'!E14 -> 188.17 | F25: ='Historical P&L'!F14 -> 247.22 | G25: ='Historical P&L'!G14 -> 185.66 | H25: =H26*H9 -> 461.96171 | I25: =I26*I9 -> 638.52797 | J25: =J26*J9 -> 833.76926 | K25: =K26*K9 -> 1037.7211 | L25: =L26*L9 -> 1240.7942 | M25: =M26*M9 -> 1435.0443 | N25: =N26*N9 -> 1614.7729 | O25: =O26*O9 -> 1776.5634 | ... Q25: =Q26*Q9 -> 2042.0161
B26: % of Revenue | C26: =C25/C9 -> 0.063022173 | D26: =D25/D9 -> 0.056047991 | E26: =E25/E9 -> 0.31977228 | F26: =F25/F9 -> 0.16590499 | G26: =G25/G9 -> 0.081514915 | H26: =AVERAGE(C26:G26) -> 0.13725247 | I26: =H26 -> 0.13725247 | J26: =I26 -> 0.13725247 | K26: =J26 -> 0.13725247 | L26: =K26 -> 0.13725247 | M26: =L26 -> 0.13725247 | N26: =M26 -> 0.13725247 | O26: =N26 -> 0.13725247 | P26: =O26 -> 0.13725247 | Q26: =P26 -> 0.13725247
B28: Scenario
B30: Best Case | H30: =H31+5% -> 0.52776217 | I30: =H30*(1-$C$33) -> 0.42220974 | J30: =I30*(1-$C$33) -> 0.33776779 | K30: =J30*(1-$C$33) -> 0.27021423 | L30: =K30*(1-$C$33) -> 0.21617138 | M30: =L30*(1-$C$33) -> 0.17293711 | N30: =M30*(1-$C$33) -> 0.13834969 | O30: =N30*(1-$C$33) -> 0.11067975 | P30: =O30*(1-$C$33) -> 0.088543799 | Q30: =P30*(1-$C$33) -> 0.070835039
B31: Base Case | H31: =AVERAGE(C10:G10) -> 0.47776217 | I31: =H31*(1-$C$33) -> 0.38220974 | J31: =I31*(1-$C$33) -> 0.30576779 | K31: =J31*(1-$C$33) -> 0.24461423 | L31: =K31*(1-$C$33) -> 0.19569138 | M31: =L31*(1-$C$33) -> 0.15655311 | N31: =M31*(1-$C$33) -> 0.12524249 | O31: =N31*(1-$C$33) -> 0.10019399 | P31: =O31*(1-$C$33) -> 0.080155191 | Q31: =P31*(1-$C$33) -> 0.064124153
B32: Worst Case | H32: =H31-5% -> 0.42776217 | I32: =H32*(1-$C$33) -> 0.34220974 | J32: =I32*(1-$C$33) -> 0.27376779 | K32: =J32*(1-$C$33) -> 0.21901423 | L32: =K32*(1-$C$33) -> 0.17521138 | M32: =L32*(1-$C$33) -> 0.14016911 | N32: =M32*(1-$C$33) -> 0.11213529 | O32: =N32*(1-$C$33) -> 0.089708229 | P32: =O32*(1-$C$33) -> 0.071766583 | Q32: =P32*(1-$C$33) -> 0.057413266
B33: Annual Growth Tapering | C33: 0.2

Sheet Cost_BuildUp
B6: (All amounts in INR Lakhs, unless otherwise stated)
B7: Particulars | C7: 2021 | D7: =C7+1 -> 2022 | E7: =D7+1 -> 2023 | F7: =E7+1 -> 2024 | G7: =F7+1 -> 2025 | H7: =G7+1 -> 2026 | I7: =H7+1 -> 2027 | J7: =I7+1 -> 2028 | K7: =J7+1 -> 2029 | ... Q7: =P7+1 -> 2035
B9: Revenue | C9: =Revenue_BuildUp!C9 -> 1978.51 | D9: =Revenue_BuildUp!D9 -> 3308.95 | E9: =Revenue_BuildUp!E9 -> 588.45 | F9: =Revenue_BuildUp!F9 -> 1490.13 | G9: =Revenue_BuildUp!G9 -> 2277.62 | H9: =Revenue_BuildUp!H9 -> 3365.7807 | I9: =Revenue_BuildUp!I9 -> 4652.2148 | J9: =Revenue_BuildUp!J9 -> 6074.7122 | ... Q9: =Revenue_BuildUp!Q9 -> 14877.81
B11: Employee benefits expenses | C11: ='Historical P&L'!C17 -> 56.11 | D11: ='Historical P&L'!D17 -> 81.83 | E11: ='Historical P&L'!E17 -> 124.52 | F11: ='Historical P&L'!F17 -> 48.36 | G11: ='Historical P&L'!G17 -> 62.01 | H11: =H12*H9 -> 218.35551 | I11: =I12*I9 -> 301.81311 | J11: =J12*J9 -> 394.09783 | K11: =K12*K9 -> 490.49977 | L11: =L12*L9 -> 586.48635 | M11: =M12*M9 -> 678.30261 | N11: =N12*N9 -> 763.25492 | O11: =O12*O9 -> 839.72847 | ... Q11: =Q12*Q9 -> 965.20005
B12: % of Revenue | C12: =C11/C9 -> 0.028359725 | D12: =D11/D9 -> 0.024729899 | E12: =E11/E9 -> 0.21160676 | F12: =F11/F9 -> 0.032453544 | G12: =G11/G9 -> 0.027225788 | H12: =AVERAGE(C12:G12) -> 0.064875144 | I12: =H12 -> 0.064875144 | J12: =I12 -> 0.064875144 | K12: =J12 -> 0.064875144 | L12: =K12 -> 0.064875144 | M12: =L12 -> 0.064875144 | N12: =M12 -> 0.064875144 | O12: =N12 -> 0.064875144 | P12: =O12 -> 0.064875144 | Q12: =P12 -> 0.064875144
B14: Other expenses | C14: ='Historical P&L'!C19 -> 170.92 | D14: ='Historical P&L'!D19 -> 225.61 | E14: ='Historical P&L'!E19 -> 312.42 | F14: ='Historical P&L'!F19 -> 385.57 | G14: ='Historical P&L'!G19 -> 556.24 | H14: =H15*H9 -> 800.01866 | I14: =I15*I9 -> 1105.7936 | J14: =J15*J9 -> 1443.9096 | K14: =K15*K9 -> 1797.1105 | L14: =L15*L9 -> 2148.7895 | M14: =M15*M9 -> 2485.1892 | N14: =N15*N9 -> 2796.4405 | O14: =O15*O9 -> 3076.627 | ... Q14: =Q15*Q9 -> 3536.3342
B15: % of Revenue | C15: =C14/C9 -> 0.086388242 | D15: =D14/D9 -> 0.068181749 | E15: =E14/E9 -> 0.53092021 | F15: =F14/F9 -> 0.25874924 | G15: =G14/G9 -> 0.24421984 | H15: =AVERAGE(C15:G15) -> 0.23769186 | I15: =H15 -> 0.23769186 | J15: =I15 -> 0.23769186 | K15: =J15 -> 0.23769186 | L15: =K15 -> 0.23769186 | M15: =L15 -> 0.23769186 | N15: =M15 -> 0.23769186 | O15: =N15 -> 0.23769186 | P15: =O15 -> 0.23769186 | Q15: =P15 -> 0.23769186
B18: Taxes | C18: =SUM('Historical P&L'!C29:C30) -> 370.28 | D18: =SUM('Historical P&L'!D29:D30) -> 3039.3 | E18: =SUM('Historical P&L'!E29:E30) -> -351.16 | F18: =SUM('Historical P&L'!F29:F30) -> 935.96 | G18: =SUM('Historical P&L'!G29:G30) -> 1497.02 | H18: =H19*'Income Statement'!H30 -> 1772.1537 | I18: =I19*'Income Statement'!I30 -> 2449.516 | J18: =J19*'Income Statement'!J30 -> 3465.7724 | K18: =K19*'Income Statement'!K30 -> 4313.5383 | L18: =L19*'Income Statement'!L30 -> 5555.3991 | M18: =M19*'Income Statement'!M30 -> 6425.1328 | N18: =N19*'Income Statement'!N30 -> 7747.4049 | O18: =O19*'Income Statement'!O30 -> 8523.6651 | ... Q18: =Q19*'Income Statement'!Q30 -> 10451.793
B19: % of PBT | C19: =C18/'Income Statement'!C30 -> 0.027795815 | D19: =D18/'Income Statement'!D30 -> 0.06614778 | E19: =E18/'Income Statement'!E30 -> -0.015612593 | F19: =F18/'Income Statement'!F30 -> 0.0481857 | G19: =G18/'Income Statement'!G30 -> 0.05484114 | H19: =G19+Assumptions!C16 -> 0.05984114 | I19: =H19 -> 0.05984114 | J19: =I19+Assumptions!$C$16 -> 0.06484114 | K19: =J19 -> 0.06484114 | L19: =K19+Assumptions!$C$16 -> 0.06984114 | M19: =L19 -> 0.06984114 | N19: =M19+Assumptions!$C$16 -> 0.07484114 | O19: =N19 -> 0.07484114 | P19: =O19+Assumptions!$C$16 -> 0.07984114 | Q19: =P19 -> 0.07984114

Sheet FSA
B6: (All amounts in INR Lakhs, unless otherwise stated)
B7: Particulars | C7: 2021 | D7: =C7+1 -> 2022 | E7: =D7+1 -> 2023 | F7: =E7+1 -> 2024 | G7: =F7+1 -> 2025 | H7: =G7+1 -> 2026 | I7: =H7+1 -> 2027 | J7: =I7+1 -> 2028 | K7: =J7+1 -> 2029 | ... Q7: =P7+1 -> 2035
B9: Deperciation schedules
B10: PPE Opening | D10: =C13 -> 321.67 | E10: =D13 -> 320.9 | F10: =E13 -> 320.18 | G10: =F13 -> 319.46 | H10: =G13 -> 318.74 | I10: =H13 -> 317.53357 | J10: =I13 -> 316.33171 | K10: =J13 -> 315.13439 | ... Q10: =P13 -> 303.89365
B11: Plus -Capex | D11: =D13-D10+D12 -> -3.8635761e-14 | E11: =E13-E10+E12 -> 2.9531932e-14 | F11: =F13-F10+F12 -> -2.7311486e-14 | G11: =G13-G10+G12 -> 2.9531932e-14 | H11: =AVERAGE(D11:G11)*(1+Assumptions!$C$15) -> -1.7294499e-15 | I11: =AVERAGE(E11:H11)*(1+Assumptions!$C$15) -> 7.5432608e-15 | J11: =AVERAGE(F11:I11)*(1+Assumptions!$C$15) -> 2.0186071e-15 | K11: =AVERAGE(G11:J11)*(1+Assumptions!$C$15) -> 9.387793e-15 | L11: =AVERAGE(H11:K11)*(1+Assumptions!$C$15) -> 4.326578e-15 | M11: =AVERAGE(I11:L11)*(1+Assumptions!$C$15) -> 5.848155e-15 | N11: =AVERAGE(J11:M11)*(1+Assumptions!$C$15) -> 5.4222597e-15 | O11: =AVERAGE(K11:N11)*(1+Assumptions!$C$15) -> 6.2774274e-15 | ... Q11: =AVERAGE(M11:P11)*(1+Assumptions!$C$15) -> 5.7897523e-15
B12: Less-Dep | C12: ='Historical P&L'!C18 -> 0.88 | D12: ='Historical P&L'!D18 -> 0.77 | E12: ='Historical P&L'!E18 -> 0.72 | F12: ='Historical P&L'!F18 -> 0.72 | G12: ='Historical P&L'!G18 -> 0.72 | H12: =H10*H15 -> 1.2064298 | I12: =I10*I15 -> 1.2018634 | J12: =J10*J15 -> 1.1973144 | K12: =K10*K15 -> 1.6654841 | L12: =L10*L15 -> 1.6566821 | M12: =M10*M15 -> 1.6479265 | N12: =N10*N15 -> 2.1044637 | O12: =O10*O15 -> 2.0901849 | ... Q12: =Q10*Q15 -> 2.5177578
B13: PPE Closing | C13: ='Historical B_Sheet'!C25 -> 321.67 | D13: ='Historical B_Sheet'!D25 -> 320.9 | E13: ='Historical B_Sheet'!E25 -> 320.18 | F13: ='Historical B_Sheet'!F25 -> 319.46 | G13: ='Historical B_Sheet'!G25 -> 318.74 | H13: =H10+H11-H12 -> 317.53357 | I13: =I10+I11-I12 -> 316.33171 | J13: =J10+J11-J12 -> 315.13439 | K13: =K10+K11-K12 -> 313.46891 | L13: =L10+L11-L12 -> 311.81223 | M13: =M10+M11-M12 -> 310.1643 | N13: =N10+N11-N12 -> 308.05984 | O13: =O10+O11-O12 -> 305.96965 | ... Q13: =Q10+Q11-Q12 -> 301.37589
B15: Deperciation & Amotisartion Exp. (%of Opening PPE) | D15: =D12/D10 -> 0.0023937576 | E15: =E12/E10 -> 0.0022436896 | F15: =F12/F10 -> 0.0022487351 | G15: =G12/G10 -> 0.0022538033 | H15: =AVERAGE(D15:G15)+Assumptions!$C$17 -> 0.0037849964 | I15: =H15 -> 0.0037849964 | J15: =I15 -> 0.0037849964 | K15: =J15+Assumptions!C17 -> 0.0052849964 | L15: =K15 -> 0.0052849964 | M15: =L15 -> 0.0052849964 | N15: =M15+Assumptions!C17 -> 0.0067849964 | O15: =N15 -> 0.0067849964 | P15: =O15 -> 0.0067849964 | Q15: =P15+Assumptions!C17 -> 0.0082849964

Sheet Investment
B6: (All amounts in INR Lakhs, unless otherwise stated)
B7: Particulars | C7: 2021 | D7: =C7+1 -> 2022 | E7: =D7+1 -> 2023 | F7: =E7+1 -> 2024 | G7: =F7+1 -> 2025 | H7: =G7+1 -> 2026 | I7: =H7+1 -> 2027 | J7: =I7+1 -> 2028 | K7: =J7+1 -> 2029 | ... Q7: =P7+1 -> 2035
A9: # | B9: Investments in associates accounted for using the equity method
B10: Opening Balance | D10: =C12 -> 216675.61 | E10: =D12 -> 229117.91 | F10: =E12 -> 262650.13 | G10: =F12 -> 281033.31 | H10: =G12 -> 304669.13 | I10: =H12 -> 326475.61 | J10: =I12 -> 350777.57 | K10: =J12 -> 377932.94 | ... Q10: =P12 -> 630311.13
B11: Purchase/sales of Investment | D11: =D12-D10 -> 12442.3 | E11: =E12-E10 -> 33532.22 | F11: =F12-F10 -> 18383.18 | G11: =G12-G10 -> 23635.82 | H11: =H12-H10 -> 21806.485 | I11: =I12-I10 -> 24301.96 | J11: =J12-J10 -> 27155.369 | K11: =K12-K10 -> 30427.9 | ... Q11: =Q12-Q10 -> 64211.415
B12: Closing Balance | C12: ='Historical B_Sheet'!C17 -> 216675.61 | D12: ='Historical B_Sheet'!D16 -> 229117.91 | E12: ='Historical B_Sheet'!E16 -> 262650.13 | F12: ='Historical B_Sheet'!F16 -> 281033.31 | G12: ='Historical B_Sheet'!G16 -> 304669.13 | H12: =G12*(1+H14) -> 326475.61 | I12: =H12*(1+I14) -> 350777.57 | J12: =I12*(1+J14) -> 377932.94 | K12: =J12*(1+K14) -> 408360.84 | L12: =K12*(1+L14) -> 442553.64 | M12: =L12*(1+M14) -> 481091.7 | N12: =M12*(1+N14) -> 524661.46 | O12: =N12*(1+O14) -> 574077.7 | ... Q12: =P12*(1+Q14) -> 694522.55
B14: Investment Growth rate | C14: 0 | D14: =D12/C12-1 -> 0.05742363 | E14: =E12/D12-1 -> 0.14635355 | F14: =F12/E12-1 -> 0.069991132 | G14: =G12/F12-1 -> 0.084103269 | H14: =AVERAGE(C14:G14) -> 0.071574317 | I14: =H14*(1+Assumptions!$C$20) -> 0.074437289 | J14: =I14*(1+Assumptions!$C$20) -> 0.077414781 | K14: =J14*(1+Assumptions!$C$20) -> 0.080511372 | L14: =K14*(1+Assumptions!$C$20) -> 0.083731827 | M14: =L14*(1+Assumptions!$C$20) -> 0.0870811 | N14: =M14*(1+Assumptions!$C$20) -> 0.090564344 | O14: =N14*(1+Assumptions!$C$20) -> 0.094186918 | P14: =O14*(1+Assumptions!$C$20) -> 0.097954394 | Q14: =P14*(1+Assumptions!$C$20) -> 0.10187257
B15: Standard Deviation | C15: =_xlfn.STDEV.S(D14:G14) -> 0.039458571
A17: # | B17: Investments
B18: Opening Balance | D18: =C20 -> 0 | E18: =D20 -> 44668.35 | F18: =E20 -> 43858.98 | G18: =F20 -> 45919.59 | H18: =G20 -> 48110.18 | I18: =H20 -> 49338.08 | J18: =I20 -> 50635.096 | K18: =J20 -> 52006.143 | ... Q18: =P20 -> 62121.737
B19: Purchase/sales of Investment | D19: =D20-D18 -> 44668.35 | E19: =E20-E18 -> -809.37 | F19: =F20-F18 -> 2060.61 | G19: =G20-G18 -> 2190.59 | H19: =H20-H18 -> 1227.9 | I19: =I20-I18 -> 1297.0165 | J19: =J20-J18 -> 1371.0463 | K19: =K20-K18 -> 1450.4152 | ... Q19: =Q20-Q18 -> 2068.7339
B20: Closing Balance | D20: ='Historical B_Sheet'!D17 -> 44668.35 | E20: ='Historical B_Sheet'!E17 -> 43858.98 | F20: ='Historical B_Sheet'!F17 -> 45919.59 | G20: ='Historical B_Sheet'!G17 -> 48110.18 | H20: =G20*(1+H22) -> 49338.08 | I20: =H20*(1+I22) -> 50635.096 | J20: =I20*(1+J22) -> 52006.143 | K20: =J20*(1+K22) -> 53456.558 | L20: =K20*(1+L22) -> 54992.15 | M20: =L20*(1+M22) -> 56619.245 | N20: =M20*(1+N22) -> 58344.739 | O20: =N20*(1+O22) -> 60176.16 | ... Q20: =P20*(1+Q22) -> 64190.471
B22: Investment Growth rate | C22: 0 | D22: 0 | E22: =E20/D20-1 -> -0.018119541 | F22: =F20/E20-1 -> 0.046982625 | G22: =G20/F20-1 -> 0.047704912 | H22: =AVERAGE(E22:G22) -> 0.025522665 | I22: =H22*(1+Assumptions!$C$19) -> 0.026288345 | J22: =I22*(1+Assumptions!$C$19) -> 0.027076996 | K22: =J22*(1+Assumptions!$C$19) -> 0.027889305 | L22: =K22*(1+Assumptions!$C$19) -> 0.028725985 | M22: =L22*(1+Assumptions!$C$19) -> 0.029587764 | N22: =M22*(1+Assumptions!$C$19) -> 0.030475397 | O22: =N22*(1+Assumptions!$C$19) -> 0.031389659 | P22: =O22*(1+Assumptions!$C$19) -> 0.032331349 | Q22: =P22*(1+Assumptions!$C$19) -> 0.033301289
B23: Standard Deviation | C23: =_xlfn.STDEV.S(D22:G22) -> 0.033395503

Sheet Income Statement
B6: (All amounts in INR Lakhs, unless otherwise stated)
B7: Particulars | C7: 2021 | D7: =C7+1 -> 2022 | E7: =D7+1 -> 2023 | F7: =E7+1 -> 2024 | G7: =F7+1 -> 2025 | H7: =G7+1 -> 2026 | I7: =H7+1 -> 2027 | J7: =I7+1 -> 2028 | K7: =J7+1 -> 2029 | ... Q7: =P7+1 -> 2035
B9: Revenue from operations
B10: Interest Income | C10: =Revenue_BuildUp!C13 -> 779.91 | D10: =Revenue_BuildUp!D13 -> 393.67 | E10: =Revenue_BuildUp!E13 -> 335.7 | F10: =Revenue_BuildUp!F13 -> 102.87 | G10: =Revenue_BuildUp!G13 -> 119.48 | H10: =Revenue_BuildUp!H13 -> 811.24479 | I10: =Revenue_BuildUp!I13 -> 1121.3104 | J10: =Revenue_BuildUp!J13 -> 1464.1711 | ... Q10: =Revenue_BuildUp!Q13 -> 3585.9572
B11: Dividend Income | C11: =Revenue_BuildUp!C16 -> 6.38 | D11: =Revenue_BuildUp!D16 -> 263.68 | E11: =Revenue_BuildUp!E16 -> 192.98 | F11: =Revenue_BuildUp!F16 -> 229.05 | G11: =Revenue_BuildUp!G16 -> 225.33 | H11: =Revenue_BuildUp!H16 -> 446.6401 | I11: =Revenue_BuildUp!I16 -> 617.3503 | J11: =Revenue_BuildUp!J16 -> 806.11614 | ... Q11: =Revenue_BuildUp!Q16 -> 1974.2898
B12: Net gain on fair value changes | C12: =Revenue_BuildUp!C19 -> 1192.22 | D12: =Revenue_BuildUp!D19 -> 2651.6 | E12: =Revenue_BuildUp!E19 -> 59.77 | F12: =Revenue_BuildUp!F19 -> 1158.21 | G12: =Revenue_BuildUp!G19 -> 1932.81 | H12: =Revenue_BuildUp!H19 -> 2107.8958 | I12: =Revenue_BuildUp!I19 -> 2913.5541 | J12: =Revenue_BuildUp!J19 -> 3804.4251 | ... Q12: =Revenue_BuildUp!Q19 -> 9317.5627
B13: Total Revenue from operations | C13: =SUM(C10:C12) -> 1978.51 | D13: =SUM(D10:D12) -> 3308.95 | E13: =SUM(E10:E12) -> 588.45 | F13: =SUM(F10:F12) -> 1490.13 | G13: =SUM(G10:G12) -> 2277.62 | H13: =SUM(H10:H12) -> 3365.7807 | I13: =SUM(I10:I12) -> 4652.2148 | J13: =SUM(J10:J12) -> 6074.7122 | ... Q13: =SUM(Q10:Q12) -> 14877.81
B15: Expenses
B16: Employee benefits expenses | C16: =Cost_BuildUp!C11 -> 56.11 | D16: =Cost_BuildUp!D11 -> 81.83 | E16: =Cost_BuildUp!E11 -> 124.52 | F16: =Cost_BuildUp!F11 -> 48.36 | G16: =Cost_BuildUp!G11 -> 62.01 | H16: =Cost_BuildUp!H11 -> 218.35551 | I16: =Cost_BuildUp!I11 -> 301.81311 | J16: =Cost_BuildUp!J11 -> 394.09783 | ... Q16: =Cost_BuildUp!Q11 -> 965.20005
B17: Other expenses | C17: =Cost_BuildUp!C14 -> 170.92 | D17: =Cost_BuildUp!D14 -> 225.61 | E17: =Cost_BuildUp!E14 -> 312.42 | F17: =Cost_BuildUp!F14 -> 385.57 | G17: =Cost_BuildUp!G14 -> 556.24 | H17: =Cost_BuildUp!H14 -> 800.01866 | I17: =Cost_BuildUp!I14 -> 1105.7936 | J17: =Cost_BuildUp!J14 -> 1443.9096 | ... Q17: =Cost_BuildUp!Q14 -> 3536.3342
B18: Total Expenses | C18: =SUM(C16:C17) -> 227.03 | D18: =SUM(D16:D17) -> 307.44 | E18: =SUM(E16:E17) -> 436.94 | F18: =SUM(F16:F17) -> 433.93 | G18: =SUM(G16:G17) -> 618.25 | H18: =SUM(H16:H17) -> 1018.3742 | I18: =SUM(I16:I17) -> 1407.6067 | J18: =SUM(J16:J17) -> 1838.0075 | ... Q18: =SUM(Q16:Q17) -> 4501.5343
B20: EBITDA | C20: =C13-C18 -> 1751.48 | D20: =D13-D18 -> 3001.51 | E20: =E13-E18 -> 151.51 | F20: =F13-F18 -> 1056.2 | G20: =G13-G18 -> 1659.37 | H20: =H13-H18 -> 2347.4065 | I20: =I13-I18 -> 3244.6081 | J20: =J13-J18 -> 4236.7048 | ... Q20: =Q13-Q18 -> 10376.275
B22: D&A | C22: =FSA!C12 -> 0.88 | D22: =FSA!D12 -> 0.77 | E22: =FSA!E12 -> 0.72 | F22: =FSA!F12 -> 0.72 | G22: =FSA!G12 -> 0.72 | H22: =FSA!H12 -> 1.2064298 | I22: =FSA!I12 -> 1.2018634 | J22: =FSA!J12 -> 1.1973144 | ... Q22: =FSA!Q12 -> 2.5177578
B24: EBIT | C24: =C20-C22 -> 1750.6 | D24: =D20-D22 -> 3000.74 | E24: =E20-E22 -> 150.79 | F24: =F20-F22 -> 1055.48 | G24: =G20-G22 -> 1658.65 | H24: =H20-H22 -> 2346.2001 | I24: =I20-I22 -> 3243.4063 | J24: =J20-J22 -> 4235.5075 | ... Q24: =Q20-Q22 -> 10373.758
B26: Other Income | C26: =Revenue_BuildUp!C25 -> 124.69 | D26: =Revenue_BuildUp!D25 -> 185.46 | E26: =Revenue_BuildUp!E25 -> 188.17 | F26: =Revenue_BuildUp!F25 -> 247.22 | G26: =Revenue_BuildUp!G25 -> 185.66 | H26: =Revenue_BuildUp!H25 -> 461.96171 | I26: =Revenue_BuildUp!I25 -> 638.52797 | J26: =Revenue_BuildUp!J25 -> 833.76926 | ... Q26: =Revenue_BuildUp!Q25 -> 2042.0161
B27: Share of Profit of Associates | C27: =Revenue_BuildUp!C22 -> 11446.14 | D27: =Revenue_BuildUp!D22 -> 42760.92 | E27: =Revenue_BuildUp!E22 -> 22153.14 | F27: =Revenue_BuildUp!F22 -> 18121.32 | G27: =Revenue_BuildUp!G22 -> 25453.08 | H27: =Revenue_BuildUp!H22 -> 26806.142 | I27: =Revenue_BuildUp!I22 -> 37051.711 | J27: =Revenue_BuildUp!J22 -> 48380.93 | ... Q27: =Revenue_BuildUp!Q22 -> 118491.58
B30: EBT | C30: =C24+C26+C27 -> 13321.43 | D30: =D24+D26+D27 -> 45947.12 | E30: =E24+E26+E27 -> 22492.1 | F30: =F24+F26+F27 -> 19424.02 | G30: =G24+G26+G27 -> 27297.39 | H30: =H24+H26+H27 -> 29614.304 | I30: =I24+I26+I27 -> 40933.645 | J30: =J24+J26+J27 -> 53450.207 | ... Q30: =Q24+Q26+Q27 -> 130907.36
B32: Tax | C32: ='Historical P&L'!C31 -> 370.28 | D32: ='Historical P&L'!D31 -> 3039.3 | E32: ='Historical P&L'!E31 -> -351.16 | F32: ='Historical P&L'!F31 -> 935.96 | G32: ='Historical P&L'!G31 -> 1497.02 | H32: =H30*Cost_BuildUp!H19 -> 1772.1537 | I32: =I30*Cost_BuildUp!I19 -> 2449.516 | J32: =J30*Cost_BuildUp!J19 -> 3465.7724 | K32: =K30*Cost_BuildUp!K19 -> 4313.5383 | L32: =L30*Cost_BuildUp!L19 -> 5555.3991 | M32: =M30*Cost_BuildUp!M19 -> 6425.1328 | N32: =N30*Cost_BuildUp!N19 -> 7747.4049 | O32: =O30*Cost_BuildUp!O19 -> 8523.6651 | ... Q32: =Q30*Cost_BuildUp!Q19 -> 10451.793
B34: Net Profit | C34: =C30-C32 -> 12951.15 | D34: =D30-D32 -> 42907.82 | E34: =E30-E32 -> 22843.26 | F34: =F30-F32 -> 18488.06 | G34: =G30-G32 -> 25800.37 | H34: =H30-H32 -> 27842.15 | I34: =I30-I32 -> 38484.129 | J34: =J30-J32 -> 49984.435 | ... Q34: =Q30-Q32 -> 120455.57
B35: Net Profit Margin | C35: =C34/C13 -> 6.5459108 | D35: =D34/D13 -> 12.967201 | E35: =E34/E13 -> 38.819373 | F35: =F34/F13 -> 12.407011 | G35: =G34/G13 -> 11.327776 | H35: =H34/H13 -> 8.2721226 | I35: =I34/I13 -> 8.2722167 | J35: =J34/J13 -> 8.2282802 | ... Q35: =Q34/Q13 -> 8.0963238
B37: Dividend | C37: =-'Cash flow'!C44 -> 2.31 | D37: =-'Cash flow'!D44 -> 159.58 | E37: =-'Cash flow'!E44 -> 159.49 | F37: =-'Cash flow'!F44 -> 160.22 | G37: =-'Cash flow'!G44 -> 160.46 | H37: =H38*H34 -> 143.46977 | I37: =I38*I34 -> 198.30757 | J37: =J38*J34 -> 257.5683 | K37: =K38*K34 -> 320.57233 | L37: =L38*L34 -> 381.25776 | M37: =M38*M34 -> 440.94613 | N37: =N38*N34 -> 493.503 | O37: =O38*O34 -> 542.9501 | ... Q37: =Q38*Q34 -> 620.70393
B38: Dividened PayOut Ratio | C38: =C37/C34 -> 0.00017836254 | D38: =D37/D34 -> 0.0037191356 | E38: =E37/E34 -> 0.0069819281 | F38: =F37/F34 -> 0.0086661337 | G38: =G37/G34 -> 0.0062192907 | H38: =AVERAGE(C38:G38) -> 0.0051529701 | I38: =H38 -> 0.0051529701 | J38: =I38 -> 0.0051529701 | K38: =J38 -> 0.0051529701 | L38: =K38 -> 0.0051529701 | M38: =L38 -> 0.0051529701 | N38: =M38 -> 0.0051529701 | O38: =N38 -> 0.0051529701 | P38: =O38 -> 0.0051529701 | Q38: =P38 -> 0.0051529701
B40: Retained Earning | C40: =C34-C37 -> 12948.84 | D40: =D34-D37 -> 42748.24 | E40: =E34-E37 -> 22683.77 | F40: =F34-F37 -> 18327.84 | G40: =G34-G37 -> 25639.91 | H40: =H34-H37 -> 27698.681 | I40: =I34-I37 -> 38285.821 | J40: =J34-J37 -> 49726.866 | ... Q40: =Q34-Q37 -> 119834.86
B41: Retained Earning % | C41: =C40/C34 -> 0.99982164 | D41: =D40/D34 -> 0.99628086 | E41: =E40/E34 -> 0.99301807 | F41: =F40/F34 -> 0.99133387 | G41: =G40/G34 -> 0.99378071 | H41: =H40/H34 -> 0.99484703 | I41: =I40/I34 -> 0.99484703 | J41: =J40/J34 -> 0.99484703 | ... Q41: =Q40/Q34 -> 0.99484703

Sheet Balance_Sheet_Forecast
B6: (All amounts in INR Lakhs, unless otherwise stated)
B7: Particulars | C7: 2021 | D7: =C7+1 -> 2022 | E7: =D7+1 -> 2023 | F7: =E7+1 -> 2024 | G7: =F7+1 -> 2025 | H7: =G7+1 -> 2026 | I7: =H7+1 -> 2027 | J7: =I7+1 -> 2028 | K7: =J7+1 -> 2029 | ... Q7: =P7+1 -> 2035
B9: Assets
B10: Financial Assets
B11: Other Receivables | C11: ='Historical B_Sheet'!C15 -> 577.05 | D11: ='Historical B_Sheet'!D15 -> 230.41 | E11: ='Historical B_Sheet'!E15 -> 262.69 | F11: ='Historical B_Sheet'!F15 -> 252.58 | G11: ='Historical B_Sheet'!G15 -> 199.46 | H11: =H12*Revenue_BuildUp!H$9 -> 716.76127 | I11: =I12*Revenue_BuildUp!I$9 -> 990.71441 | J11: =J12*Revenue_BuildUp!J$9 -> 1293.643 | K11: =K12*Revenue_BuildUp!K$9 -> 1610.0864 | L11: =L12*Revenue_BuildUp!L$9 -> 1925.1665 | M11: =M12*Revenue_BuildUp!M$9 -> 2226.5573 | N11: =N12*Revenue_BuildUp!N$9 -> 2505.4169 | O11: =O12*Revenue_BuildUp!O$9 -> 2756.4446 | ... Q11: =Q12*Revenue_BuildUp!Q$9 -> 3168.3104
B12: (x) of Revenue | C12: =C11/Revenue_BuildUp!C$9 -> 0.29165887 | D12: =D11/Revenue_BuildUp!D$9 -> 0.069632361 | E12: =E11/Revenue_BuildUp!E$9 -> 0.44641006 | F12: =F11/Revenue_BuildUp!F$9 -> 0.16950199 | G12: =G11/Revenue_BuildUp!G$9 -> 0.087573871 | H12: =AVERAGE(C12:G12) -> 0.21295543 | I12: =H12 -> 0.21295543 | J12: =I12 -> 0.21295543 | K12: =J12 -> 0.21295543 | L12: =K12 -> 0.21295543 | M12: =L12 -> 0.21295543 | N12: =M12 -> 0.21295543 | O12: =N12 -> 0.21295543 | P12: =O12 -> 0.21295543 | Q12: =P12 -> 0.21295543
B14: Other Financial assets | C14: ='Historical B_Sheet'!C18 -> 1572.52 | D14: ='Historical B_Sheet'!D18 -> 609.68 | E14: ='Historical B_Sheet'!E18 -> 445.01 | F14: ='Historical B_Sheet'!F18 -> 227.74 | G14: ='Historical B_Sheet'!G18 -> 41.66 | H14: =H15*Revenue_BuildUp!H$9 -> 1283.3158 | I14: =I15*Revenue_BuildUp!I$9 -> 1773.8116 | J14: =J15*Revenue_BuildUp!J$9 -> 2316.186 | K14: =K15*Revenue_BuildUp!K$9 -> 2882.7581 | L14: =L15*Revenue_BuildUp!L$9 -> 3446.889 | M14: =M15*Revenue_BuildUp!M$9 -> 3986.5102 | N14: =N15*Revenue_BuildUp!N$9 -> 4485.7906 | O14: =O15*Revenue_BuildUp!O$9 -> 4935.2399 | ... Q14: =Q15*Revenue_BuildUp!Q$9 -> 5672.6596
B15: (x) of Revenue | C15: =C14/Revenue_BuildUp!C$9 -> 0.79480013 | D15: =D14/Revenue_BuildUp!D$9 -> 0.1842518 | E15: =E14/Revenue_BuildUp!E$9 -> 0.75624097 | F15: =F14/Revenue_BuildUp!F$9 -> 0.1528323 | G15: =G14/Revenue_BuildUp!G$9 -> 0.018291023 | H15: =AVERAGE(C15:G15) -> 0.38128325 | I15: =H15 -> 0.38128325 | J15: =I15 -> 0.38128325 | K15: =J15 -> 0.38128325 | L15: =K15 -> 0.38128325 | M15: =L15 -> 0.38128325 | N15: =M15 -> 0.38128325 | O15: =N15 -> 0.38128325 | P15: =O15 -> 0.38128325 | Q15: =P15 -> 0.38128325
B17: Non Financial Assets
B18: Current Tax assets (Net) | C18: ='Historical B_Sheet'!C23 -> 0 | D18: ='Historical B_Sheet'!D23 -> 105.2 | E18: ='Historical B_Sheet'!E23 -> 306.77 | F18: ='Historical B_Sheet'!F23 -> 533.01 | G18: ='Historical B_Sheet'!G23 -> 373.39 | H18: =H19*Revenue_BuildUp!H$9 -> 723.47023 | I18: =I19*Revenue_BuildUp!I$9 -> 999.9876 | J18: =J19*Revenue_BuildUp!J$9 -> 1305.7516 | K18: =K19*Revenue_BuildUp!K$9 -> 1625.157 | L18: =L19*Revenue_BuildUp!L$9 -> 1943.1862 | M18: =M19*Revenue_BuildUp!M$9 -> 2247.3981 | N18: =N19*Revenue_BuildUp!N$9 -> 2528.8678 | O18: =O19*Revenue_BuildUp!O$9 -> 2782.2452 | ... Q18: =Q19*Revenue_BuildUp!Q$9 -> 3197.9661
B19: (x) of Revenue | C19: =C18/Revenue_BuildUp!C$9 -> 0 | D19: =D18/Revenue_BuildUp!D$9 -> 0.031792563 | E19: =E18/Revenue_BuildUp!E$9 -> 0.52131872 | F19: =F18/Revenue_BuildUp!F$9 -> 0.35769362 | G19: =G18/Revenue_BuildUp!G$9 -> 0.16393867 | H19: =AVERAGE(C19:G19) -> 0.21494872 | I19: =H19 -> 0.21494872 | J19: =I19 -> 0.21494872 | K19: =J19 -> 0.21494872 | L19: =K19 -> 0.21494872 | M19: =L19 -> 0.21494872 | N19: =M19 -> 0.21494872 | O19: =N19 -> 0.21494872 | P19: =O19 -> 0.21494872 | Q19: =P19 -> 0.21494872
B21: Deferred Tax Asset (Net) | C21: ='Historical B_Sheet'!C24 -> 3913.66 | D21: ='Historical B_Sheet'!D24 -> 2415.08 | E21: ='Historical B_Sheet'!E24 -> 1813.25 | F21: ='Historical B_Sheet'!F24 -> 1098.4 | G21: ='Historical B_Sheet'!G24 -> 223.85 | H21: =H22*Revenue_BuildUp!H$9 -> 330.79706 | I21: =I22*Revenue_BuildUp!I$9 -> 457.23092 | J21: =J22*Revenue_BuildUp!J$9 -> 597.03741 | K21: =K22*Revenue_BuildUp!K$9 -> 743.08125 | L21: =L22*Revenue_BuildUp!L$9 -> 888.49585 | M21: =M22*Revenue_BuildUp!M$9 -> 1027.5926 | N21: =N22*Revenue_BuildUp!N$9 -> 1156.2909 | O21: =O22*Revenue_BuildUp!O$9 -> 1272.1443 | ... Q21: =Q22*Revenue_BuildUp!Q$9 -> 1462.2271
B22: (x) of Revenue | C22: =C21/Revenue_BuildUp!C$9 -> 1.9780845 | D22: =D21/Revenue_BuildUp!D$9 -> 0.72986295 | E22: =E21/Revenue_BuildUp!E$9 -> 3.0814003 | F22: =F21/Revenue_BuildUp!F$9 -> 0.7371169 | G22: =G21/Revenue_BuildUp!G$9 -> 0.098282418 | H22: =G22 -> 0.098282418 | I22: =H22 -> 0.098282418 | J22: =I22 -> 0.098282418 | K22: =J22 -> 0.098282418 | L22: =K22 -> 0.098282418 | M22: =L22 -> 0.098282418 | N22: =M22 -> 0.098282418 | O22: =N22 -> 0.098282418 | ... Q22: =P22 -> 0.098282418
B24: Other non-financial assets | C24: ='Historical B_Sheet'!C26 -> 24.73 | D24: ='Historical B_Sheet'!D26 -> 9.95 | E24: ='Historical B_Sheet'!E26 -> 11.88 | F24: ='Historical B_Sheet'!F26 -> 10.09 | G24: ='Historical B_Sheet'!G26 -> 10.94 | H24: =H25*Revenue_BuildUp!H$9 -> 31.819695 | I24: =I25*Revenue_BuildUp!I$9 -> 43.981493 | J24: =J25*Revenue_BuildUp!J$9 -> 57.429617 | K24: =K25*Revenue_BuildUp!K$9 -> 71.477718 | L24: =L25*Revenue_BuildUp!L$9 -> 85.465292 | M24: =M25*Revenue_BuildUp!M$9 -> 98.845149 | N24: =N25*Revenue_BuildUp!N$9 -> 111.22476 | O24: =O25*Revenue_BuildUp!O$9 -> 122.36881 | ... Q24: =Q25*Revenue_BuildUp!Q$9 -> 140.65307
B25: (x) of Revenue | C25: =C24/Revenue_BuildUp!C$9 -> 0.012499305 | D25: =D24/Revenue_BuildUp!D$9 -> 0.0030069962 | E25: =E24/Revenue_BuildUp!E$9 -> 0.020188631 | F25: =F24/Revenue_BuildUp!F$9 -> 0.0067712213 | G25: =G24/Revenue_BuildUp!G$9 -> 0.0048032595 | H25: =AVERAGE(C25:G25) -> 0.0094538826 | I25: =H25 -> 0.0094538826 | J25: =I25 -> 0.0094538826 | K25: =J25 -> 0.0094538826 | L25: =K25 -> 0.0094538826 | M25: =L25 -> 0.0094538826 | N25: =M25 -> 0.0094538826 | O25: =N25 -> 0.0094538826 | P25: =O25 -> 0.0094538826 | Q25: =P25 -> 0.0094538826
B27: Liabilities
B28: Financial Liabilities
B29: Other financial liabilities | C29: ='Historical B_Sheet'!C39 -> 81.27 | D29: ='Historical B_Sheet'!D39 -> 18.35 | E29: ='Historical B_Sheet'!E39 -> 13.46 | F29: ='Historical B_Sheet'!F39 -> 16.6 | G29: ='Historical B_Sheet'!G39 -> 7 | H29: =H30*Revenue_BuildUp!H$9 -> 56.349182 | I29: =I30*Revenue_BuildUp!I$9 -> 77.886388 | J29: =J30*Revenue_BuildUp!J$9 -> 101.70154 | K29: =K30*Revenue_BuildUp!K$9 -> 126.57918 | L29: =L30*Revenue_BuildUp!L$9 -> 151.34964 | M29: =M30*Revenue_BuildUp!M$9 -> 175.04389 | N29: =N30*Revenue_BuildUp!N$9 -> 196.96682 | O29: =O30*Revenue_BuildUp!O$9 -> 216.70171 | ... Q29: =Q30*Revenue_BuildUp!Q$9 -> 249.08112
B30: (x) of Revenue | C30: =C29/Revenue_BuildUp!C$9 -> 0.041076366 | D30: =D29/Revenue_BuildUp!D$9 -> 0.0055455658 | E30: =E29/Revenue_BuildUp!E$9 -> 0.022873651 | F30: =F29/Revenue_BuildUp!F$9 -> 0.011139968 | G30: =G29/Revenue_BuildUp!G$9 -> 0.0030733836 | H30: =AVERAGE(C30:G30) -> 0.016741787 | I30: =H30 -> 0.016741787 | J30: =I30 -> 0.016741787 | K30: =J30 -> 0.016741787 | L30: =K30 -> 0.016741787 | M30: =L30 -> 0.016741787 | N30: =M30 -> 0.016741787 | O30: =N30 -> 0.016741787 | P30: =O30 -> 0.016741787 | Q30: =P30 -> 0.016741787
B32: Non Financial Liabilities
B33: Provisions | C33: ='Historical B_Sheet'!C45 -> 2.9 | D33: ='Historical B_Sheet'!D45 -> 1.55 | E33: ='Historical B_Sheet'!E45 -> 5.52 | F33: ='Historical B_Sheet'!F45 -> 3.11 | G33: ='Historical B_Sheet'!G45 -> 6.75 | H33: =H34*Revenue_BuildUp!H$9 -> 11.016495 | I33: =I34*Revenue_BuildUp!I$9 -> 15.227107 | J33: =J34*Revenue_BuildUp!J$9 -> 19.883066 | K33: =K34*Revenue_BuildUp!K$9 -> 24.746746 | L33: =L34*Revenue_BuildUp!L$9 -> 29.589472 | M33: =M34*Revenue_BuildUp!M$9 -> 34.221795 | N33: =N34*Revenue_BuildUp!N$9 -> 38.507818 | O33: =O34*Revenue_BuildUp!O$9 -> 42.36607 | ... Q33: =Q34*Revenue_BuildUp!Q$9 -> 48.696375
B34: (x) of Revenue | C34: =C33/Revenue_BuildUp!C$9 -> 0.0014657495 | D34: =D33/Revenue_BuildUp!D$9 -> 0.00046842654 | E34: =E33/Revenue_BuildUp!E$9 -> 0.0093805761 | F34: =F33/Revenue_BuildUp!F$9 -> 0.0020870662 | G34: =G33/Revenue_BuildUp!G$9 -> 0.0029636199 | H34: =AVERAGE(C34:G34) -> 0.0032730877 | I34: =H34 -> 0.0032730877 | J34: =I34 -> 0.0032730877 | K34: =J34 -> 0.0032730877 | L34: =K34 -> 0.0032730877 | M34: =L34 -> 0.0032730877 | N34: =M34 -> 0.0032730877 | O34: =N34 -> 0.0032730877 | P34: =O34 -> 0.0032730877 | Q34: =P34 -> 0.0032730877
B36: Other non-financial liabilities | C36: ='Historical B_Sheet'!C46 -> 27.11 | D36: ='Historical B_Sheet'!D46 -> 47.65 | E36: ='Historical B_Sheet'!E46 -> 90.95 | F36: ='Historical B_Sheet'!F46 -> 40.09 | G36: ='Historical B_Sheet'!G46 -> 39.1 | H36: =H37*Revenue_BuildUp!H$9 -> 152.62596 | I36: =I37*Revenue_BuildUp!I$9 -> 210.96109 | J36: =J37*Revenue_BuildUp!J$9 -> 275.4662 | K36: =K37*Revenue_BuildUp!K$9 -> 342.84915 | L36: =L37*Revenue_BuildUp!L$9 -> 409.94178 | M36: =M37*Revenue_BuildUp!M$9 -> 474.11944 | N36: =N37*Revenue_BuildUp!N$9 -> 533.49933 | O36: =O37*Revenue_BuildUp!O$9 -> 586.95276 | ... Q36: =Q37*Revenue_BuildUp!Q$9 -> 674.65479
B37: (x) of Revenue | C37: =C36/Revenue_BuildUp!C$9 -> 0.01370223 | D37: =D36/Revenue_BuildUp!D$9 -> 0.014400338 | E37: =E36/Revenue_BuildUp!E$9 -> 0.15455859 | F37: =F36/Revenue_BuildUp!F$9 -> 0.026903693 | G37: =G36/Revenue_BuildUp!G$9 -> 0.017167043 | H37: =AVERAGE(C37:G37) -> 0.045346378 | I37: =H37 -> 0.045346378 | J37: =I37 -> 0.045346378 | K37: =J37 -> 0.045346378 | L37: =K37 -> 0.045346378 | M37: =L37 -> 0.045346378 | N37: =M37 -> 0.045346378 | O37: =N37 -> 0.045346378 | P37: =O37 -> 0.045346378 | Q37: =P37 -> 0.045346378

Sheet Net Working Capital
B7: Calculation of Net Working Capital
B8: (All amounts in INR Lakhs, unless otherwise stated)
B9: Particulars | C9: 2021 | D9: =C9+1 -> 2022 | E9: =D9+1 -> 2023 | F9: =E9+1 -> 2024 | G9: =F9+1 -> 2025 | H9: =G9+1 -> 2026 | I9: =H9+1 -> 2027 | J9: =I9+1 -> 2028 | K9: =J9+1 -> 2029 | ... Q9: =P9+1 -> 2035
B10: Financial Assets
B11: Other Receivables | C11: 577.05 | D11: 230.41 | E11: 262.69 | F11: 252.58 | G11: 199.46 | H11: ='Balance Sheet'!H17 -> 716.76127 | I11: ='Balance Sheet'!I17 -> 990.71441 | J11: ='Balance Sheet'!J17 -> 1293.643 | K11: ='Balance Sheet'!K17 -> 1610.0864 | L11: ='Balance Sheet'!L17 -> 1925.1665 | M11: ='Balance Sheet'!M17 -> 2226.5573 | N11: ='Balance Sheet'!N17 -> 2505.4169 | O11: ='Balance Sheet'!O17 -> 2756.4446 | ... Q11: ='Balance Sheet'!Q17 -> 3168.3104
B12: Other Financial assets | C12: 1572.52 | D12: 609.68 | E12: 445.01 | F12: 227.74 | G12: 41.66 | H12: ='Balance Sheet'!H20 -> 1283.3158 | I12: ='Balance Sheet'!I20 -> 1773.8116 | J12: ='Balance Sheet'!J20 -> 2316.186 | K12: ='Balance Sheet'!K20 -> 2882.7581 | L12: ='Balance Sheet'!L20 -> 3446.889 | M12: ='Balance Sheet'!M20 -> 3986.5102 | N12: ='Balance Sheet'!N20 -> 4485.7906 | O12: ='Balance Sheet'!O20 -> 4935.2399 | ... Q12: ='Balance Sheet'!Q20 -> 5672.6596
B13: Current Portion of Other Investment | C13: 2907.29 | D13: 20886.95 | E13: 5854.29 | F13: 7789.29 | G13: 11776.92 | H13: =H14*Investment!H20 -> 10152.965 | I13: =I14*Investment!I20 -> 10419.87 | J13: =J14*Investment!J20 -> 10702.008 | K13: =K14*Investment!K20 -> 11000.48 | L13: =L14*Investment!L20 -> 11316.48 | M13: =M14*Investment!M20 -> 11651.309 | N13: =N14*Investment!N20 -> 12006.387 | O13: =O14*Investment!O20 -> 12383.264 | ... Q13: =Q14*Investment!Q20 -> 13209.343
B14: % of Total Other Investment | C14: =C13/'Balance Sheet'!C19 -> 0.013417708 | D14: =D13/'Balance Sheet'!D19 -> 0.46760066 | E14: =E13/'Balance Sheet'!E19 -> 0.13347985 | F14: =F13/'Balance Sheet'!F19 -> 0.16962891 | G14: =G13/'Balance Sheet'!G19 -> 0.2447906 | H14: =AVERAGE(C14:G14) -> 0.20578355 | I14: =H14 -> 0.20578355 | J14: =I14 -> 0.20578355 | K14: =J14 -> 0.20578355 | L14: =K14 -> 0.20578355 | M14: =L14 -> 0.20578355 | N14: =M14 -> 0.20578355 | O14: =N14 -> 0.20578355 | P14: =O14 -> 0.20578355 | Q14: =P14 -> 0.20578355
B15: Total | C15: =SUM(C11:C13) -> 5056.86 | D15: =SUM(D11:D13) -> 21727.04 | E15: =SUM(E11:E13) -> 6561.99 | F15: =SUM(F11:F13) -> 8269.61 | G15: =SUM(G11:G13) -> 12018.04 | H15: =SUM(H11:H13) -> 12153.042 | I15: =SUM(I11:I13) -> 13184.396 | J15: =SUM(J11:J13) -> 14311.837 | ... Q15: =SUM(Q11:Q13) -> 22050.313
B17: Non Financial Assets
B18: Current tax assets | C18: 0 | D18: 105.2 | E18: 306.77 | F18: 533.01 | G18: 373.39 | H18: ='Balance Sheet'!H25 -> 723.47023 | I18: ='Balance Sheet'!I25 -> 999.9876 | J18: ='Balance Sheet'!J25 -> 1305.7516 | K18: ='Balance Sheet'!K25 -> 1625.157 | L18: ='Balance Sheet'!L25 -> 1943.1862 | M18: ='Balance Sheet'!M25 -> 2247.3981 | N18: ='Balance Sheet'!N25 -> 2528.8678 | O18: ='Balance Sheet'!O25 -> 2782.2452 | ... Q18: ='Balance Sheet'!Q25 -> 3197.9661
B19: Other non- Financial assets | C19: 24.73 | D19: 9.95 | E19: 11.88 | F19: 10.09 | G19: 10.94 | H19: ='Balance Sheet'!H28 -> 31.819695 | I19: ='Balance Sheet'!I28 -> 43.981493 | J19: ='Balance Sheet'!J28 -> 57.429617 | K19: ='Balance Sheet'!K28 -> 71.477718 | L19: ='Balance Sheet'!L28 -> 85.465292 | M19: ='Balance Sheet'!M28 -> 98.845149 | N19: ='Balance Sheet'!N28 -> 111.22476 | O19: ='Balance Sheet'!O28 -> 122.36881 | ... Q19: ='Balance Sheet'!Q28 -> 140.65307
B20: Total | C20: =SUM(C18:C19) -> 24.73 | D20: =SUM(D18:D19) -> 115.15 | E20: =SUM(E18:E19) -> 318.65 | F20: =SUM(F18:F19) -> 543.1 | G20: =SUM(G18:G19) -> 384.33 | H20: =SUM(H18:H19) -> 755.28993 | I20: =SUM(I18:I19) -> 1043.9691 | J20: =SUM(J18:J19) -> 1363.1812 | ... Q20: =SUM(Q18:Q19) -> 3338.6192
B22: Total Current Assets | C22: =C20+C15 -> 5081.59 | D22: =D20+D15 -> 21842.19 | E22: =E20+E15 -> 6880.64 | F22: =F20+F15 -> 8812.71 | G22: =G20+G15 -> 12402.37 | H22: =H20+H15 -> 12908.332 | I22: =I20+I15 -> 14228.365 | J22: =J20+J15 -> 15675.019 | ... Q22: =Q20+Q15 -> 25388.932
B24: Change in Current Assets | D24: =C22-D22 -> -16760.6 | E24: =D22-E22 -> 14961.55 | F24: =E22-F22 -> -1932.07 | G24: =F22-G22 -> -3589.66 | H24: =G22-H22 -> -505.96205 | I24: =H22-I22 -> -1320.0327 | J24: =I22-J22 -> -1446.6539 | K24: =J22-K22 -> -1514.9406 | ... Q24: =P22-Q22 -> -1159.6538
B26: Liabilities
B27: Financial Liabilities
B28: Other financial liabilities | C28: ='Balance Sheet'!C37 -> 81.27 | D28: ='Balance Sheet'!D37 -> 18.35 | E28: ='Balance Sheet'!E37 -> 13.46 | F28: ='Balance Sheet'!F37 -> 16.6 | G28: ='Balance Sheet'!G37 -> 7 | H28: ='Balance Sheet'!H37 -> 56.349182 | I28: ='Balance Sheet'!I37 -> 77.886388 | J28: ='Balance Sheet'!J37 -> 101.70154 | ... Q28: ='Balance Sheet'!Q37 -> 249.08112
B30: Total Financial Liabilities | C30: =SUM(C28:C29) -> 81.27 | D30: =SUM(D28:D29) -> 18.35 | E30: =SUM(E28:E29) -> 13.46 | F30: =SUM(F28:F29) -> 16.6 | G30: =SUM(G28:G29) -> 7 | H30: =SUM(H28:H29) -> 56.349182 | I30: =SUM(I28:I29) -> 77.886388 | J30: =SUM(J28:J29) -> 101.70154 | ... Q30: =SUM(Q28:Q29) -> 249.08112
B32: Non Financial Liabilities
B33: Current tax liabilities (Net) | C33: ='Balance Sheet'!C42 -> 43.3 | D33: ='Balance Sheet'!D42 -> 0 | E33: ='Balance Sheet'!E42 -> 0 | F33: ='Balance Sheet'!F42 -> 0 | G33: ='Balance Sheet'!G42 -> 0 | H33: ='Balance Sheet'!H42 -> 0 | I33: ='Balance Sheet'!I42 -> 0 | J33: ='Balance Sheet'!J42 -> 0 | ... Q33: ='Balance Sheet'!Q42 -> 0
B34: Provisions | C34: ='Balance Sheet'!C43 -> 2.9 | D34: ='Balance Sheet'!D43 -> 1.55 | E34: ='Balance Sheet'!E43 -> 5.52 | F34: ='Balance Sheet'!F43 -> 3.11 | G34: ='Balance Sheet'!G43 -> 6.75 | H34: ='Balance Sheet'!H43 -> 11.016495 | I34: ='Balance Sheet'!I43 -> 15.227107 | J34: ='Balance Sheet'!J43 -> 19.883066 | ... Q34: ='Balance Sheet'!Q43 -> 48.696375
B35: Other non-financial liabilities | C35: ='Balance Sheet'!C44 -> 27.11 | D35: ='Balance Sheet'!D44 -> 47.65 | E35: ='Balance Sheet'!E44 -> 90.95 | F35: ='Balance Sheet'!F44 -> 40.09 | G35: ='Balance Sheet'!G44 -> 39.1 | H35: ='Balance Sheet'!H44 -> 152.62596 | I35: ='Balance Sheet'!I44 -> 210.96109 | J35: ='Balance Sheet'!J44 -> 275.4662 | ... Q35: ='Balance Sheet'!Q44 -> 674.65479
B37: Total Non Financial Liabilities | C37: =SUM(C33:C35) -> 73.31 | D37: =SUM(D33:D35) -> 49.2 | E37: =SUM(E33:E35) -> 96.47 | F37: =SUM(F33:F35) -> 43.2 | G37: =SUM(G33:G35) -> 45.85 | H37: =SUM(H33:H35) -> 163.64246 | I37: =SUM(I33:I35) -> 226.1882 | J37: =SUM(J33:J35) -> 295.34926 | ... Q37: =SUM(Q33:Q35) -> 723.35116
B39: Total Current Liabilities | C39: =C37+C30 -> 154.58 | D39: =D37+D30 -> 67.55 | E39: =E37+E30 -> 109.93 | F39: =F37+F30 -> 59.8 | G39: =G37+G30 -> 52.85 | H39: =H37+H30 -> 219.99164 | I39: =I37+I30 -> 304.07459 | J39: =J37+J30 -> 397.0508 | ... Q39: =Q37+Q30 -> 972.43228
B41: Change in Current Laibilities | D41: =D39-C39 -> -87.03 | E41: =E39-D39 -> 42.38 | F41: =F39-E39 -> -50.13 | G41: =G39-F39 -> -6.95 | H41: =H39-G39 -> 167.14164 | I41: =I39-H39 -> 84.082947 | J41: =J39-I39 -> 92.976214 | K41: =K39-J39 -> 97.124276 | ... Q41: =Q39-P39 -> 58.598798
B43: Net Working Capital | D43: =D24+D41 -> -16847.63 | E43: =E24+E41 -> 15003.93 | F43: =F24+F41 -> -1982.2 | G43: =G24+G41 -> -3596.61 | H43: =H24+H41 -> -338.82041 | I43: =I24+I41 -> -1235.9498 | J43: =J24+J41 -> -1353.6777 | K43: =K24+K41 -> -1417.8164 | ... Q43: =Q24+Q41 -> -1101.055

Sheet Balance Sheet
B6: (All amounts in INR Lakhs, unless otherwise stated)
B7: Master Check | C7: =IF(SUM(C57:Q57)=0,"OK","Error") -> OK
B9: Particulars | C9: 2021 | D9: =C9+1 -> 2022 | E9: =D9+1 -> 2023 | F9: =E9+1 -> 2024 | G9: =F9+1 -> 2025 | H9: =G9+1 -> 2026 | I9: =H9+1 -> 2027 | J9: =I9+1 -> 2028 | K9: =J9+1 -> 2029 | ... Q9: =P9+1 -> 2035
B11: Assets
B12: Financial Assets
B13: Cash and bank balances | C13: ='Historical B_Sheet'!C11 -> 7638.83 | D13: ='Historical B_Sheet'!D11 -> 120.99 | E13: ='Historical B_Sheet'!E11 -> 294.74 | F13: ='Historical B_Sheet'!F11 -> 284.7 | G13: ='Historical B_Sheet'!G11 -> 49.18 | H13: ='Cash flow'!H50 -> 2644.9598 | I13: ='Cash flow'!I50 -> 14237.528 | J13: ='Cash flow'!J50 -> 34227.831 | K13: ='Cash flow'!K50 -> 62976.395 | L13: ='Cash flow'!L50 -> 99596.428 | M13: ='Cash flow'!M50 -> 143358.04 | N13: ='Cash flow'!N50 -> 192226.88 | O13: ='Cash flow'!O50 -> 244800.99 | ... Q13: ='Cash flow'!Q50 -> 351148.2
B14: Bank Balances | C14: ='Historical B_Sheet'!C12 -> 9.79 | D14: ='Historical B_Sheet'!D12 -> 152.78 | E14: ='Historical B_Sheet'!E12 -> 106.02 | F14: ='Historical B_Sheet'!F12 -> 98.22 | G14: ='Historical B_Sheet'!G12 -> 102.77 | H14: =G14 -> 102.77 | I14: =H14 -> 102.77 | J14: =I14 -> 102.77 | K14: =J14 -> 102.77 | L14: =K14 -> 102.77 | M14: =L14 -> 102.77 | N14: =M14 -> 102.77 | O14: =N14 -> 102.77 | ... Q14: =P14 -> 102.77
B15: Receivables
B16: Trade Receivables
B17: Other Receivables | C17: ='Historical B_Sheet'!C15 -> 577.05 | D17: ='Historical B_Sheet'!D15 -> 230.41 | E17: ='Historical B_Sheet'!E15 -> 262.69 | F17: ='Historical B_Sheet'!F15 -> 252.58 | G17: ='Historical B_Sheet'!G15 -> 199.46 | H17: =Balance_Sheet_Forecast!H11 -> 716.76127 | I17: =Balance_Sheet_Forecast!I11 -> 990.71441 | J17: =Balance_Sheet_Forecast!J11 -> 1293.643 | K17: =Balance_Sheet_Forecast!K11 -> 1610.0864 | L17: =Balance_Sheet_Forecast!L11 -> 1925.1665 | M17: =Balance_Sheet_Forecast!M11 -> 2226.5573 | N17: =Balance_Sheet_Forecast!N11 -> 2505.4169 | O17: =Balance_Sheet_Forecast!O11 -> 2756.4446 | ... Q17: =Balance_Sheet_Forecast!Q11 -> 3168.3104
B18: Investments in associates accounted for using the equity method | C18: ='Historical B_Sheet'!C16 -> 0 | D18: ='Historical B_Sheet'!D16 -> 229117.91 | E18: ='Historical B_Sheet'!E16 -> 262650.13 | F18: ='Historical B_Sheet'!F16 -> 281033.31 | G18: ='Historical B_Sheet'!G16 -> 304669.13 | H18: =Investment!H12 -> 326475.61 | I18: =Investment!I12 -> 350777.57 | J18: =Investment!J12 -> 377932.94 | K18: =Investment!K12 -> 408360.84 | L18: =Investment!L12 -> 442553.64 | M18: =Investment!M12 -> 481091.7 | N18: =Investment!N12 -> 524661.46 | O18: =Investment!O12 -> 574077.7 | ... Q18: =Investment!Q12 -> 694522.55
B19: Investments | C19: ='Historical B_Sheet'!C17 -> 216675.61 | D19: ='Historical B_Sheet'!D17 -> 44668.35 | E19: ='Historical B_Sheet'!E17 -> 43858.98 | F19: ='Historical B_Sheet'!F17 -> 45919.59 | G19: ='Historical B_Sheet'!G17 -> 48110.18 | H19: =Investment!H20 -> 49338.08 | I19: =Investment!I20 -> 50635.096 | J19: =Investment!J20 -> 52006.143 | K19: =Investment!K20 -> 53456.558 | L19: =Investment!L20 -> 54992.15 | M19: =Investment!M20 -> 56619.245 | N19: =Investment!N20 -> 58344.739 | O19: =Investment!O20 -> 60176.16 | ... Q19: =Investment!Q20 -> 64190.471
